Workbook

Sheet 표지

Sheet 목차
B6: Ⅰ. 요약 재무제표 | H6: Ⅲ. 신계약 매출지표 | N6: Ⅴ. 배당
B7: 연결 재무상태표 | E7: 1 | H7: 수입보험료 및 월초보험료 | K7: 9 | N7: 배당 및 발행주식수 | Q7: 14
B8: 연결 손익계산서 | E8: 2 | H8: APE(상품 및 채널별) | K8: 10
B9: 별도 재무상태표 | E9: 3 | H9: 판매조직 현황 | K9: 11
B10: 별도 손익계산서 | E10: 4
B12: Ⅱ. 주요 재무지표 | H12: Ⅳ. 자산운용 현황 | N12: Ⅵ. 재무제표
B13: 신계약 CSM 및 수익성 | E13: 5 | H13: 운용자산 | K13: 12 | N13: (연결)재무상태표(GAAP) | Q13: 15
B14: 보험부채 Movement | E14: 6 | H14: 자산건전성 | K14: 13 | N14: (연결)손익계산서(GAAP) | Q14: 16
B15: 효율지표 | E15: 7 | N15: (별도)재무상태표(GAAP) | Q15: 17
B16: 재무안전성(K-ICS) | E16: 8 | N16: (별도)손익계산서(GAAP) | Q16: 18
N17: (별도)재무상태표(SAP) | Q17: 19
N18: (별도)손익계산서(SAP) | Q18: 20

Sheet (연결) 요약 재무상태표
A1: Ⅰ. 요약 재무제표- 연결 재무상태표
A3: ■ 재무상태표 (연결) | Q3: (단위 : 십억원)
A4: 구분 | E4: 2025 | I4: 2026 | M4: QoQ | O4: 2025 | P4: 2026 | Q4: YoY
E5: 1Q | F5: 2Q | G5: 3Q | H5: 4Q | I5: 1Q | J5: 2Q | K5: 3Q | L5: 4Q | O5: 누적 | P5: 누적
E6: 2025.1~3 | F6: 2025.4~6 | G6: 2025.7~9 | H6: 2025.10~12 | I6: 2026.1~3 | J6: 2026.4~6 | K6: 2026.7~9 | L6: 2026.10~12 | O6: 2025.1~6 | P6: 2026.1~6
A7: 현금 및 현금성자산 | E7: 1948.466 | F7: 1948.466 | G7: 2827.41 | H7: 3103.115 | I7: 2351.2318 | J7: 3043.93 | M7: =IF(OR(I7<=0,J7<=0),"-",J7/I7-1) -> 0.29461079 | O7: =$F7 -> 1948.466 | P7: =$J7 -> 3043.93 | Q7: =IF(OR(P7<=0,O7<=0),"-",P7/O7-1) -> 0.56221869
A8: 당기손익-공정가치측정금융자산 | E8: 54475.054 | F8: 54475.054 | G8: 55805.601 | H8: 56064.369 | I8: 57831.771 | J8: 56879.495 | M8: =IF(OR(I8<=0,J8<=0),"-",J8/I8-1) -> -0.016466306 | O8: =$F8 -> 54475.054 | P8: =$J8 -> 56879.495 | Q8: =IF(OR(P8<=0,O8<=0),"-",P8/O8-1) -> 0.044138387
A9: 기타포괄손익-공정가치측정금융자산 | E9: 61747.501 | F9: 61747.501 | G9: 63726.813 | H9: 61939.817 | I9: 59453.317 | J9: 59679.503 | M9: =IF(OR(I9<=0,J9<=0),"-",J9/I9-1) -> 0.003804435 | O9: =$F9 -> 61747.501 | P9: =$J9 -> 59679.503 | Q9: =IF(OR(P9<=0,O9<=0),"-",P9/O9-1) -> -0.033491202
A10: 상각후원가측정금융자산 | E10: 38171.876 | F10: 38171.876 | G10: 47386.321 | H10: 48454.617 | I10: 48691.297 | J10: 56846.243 | M10: =IF(OR(I10<=0,J10<=0),"-",J10/I10-1) -> 0.16748262 | O10: =$F10 -> 38171.876 | P10: =$J10 -> 56846.243 | Q10: =IF(OR(P10<=0,O10<=0),"-",P10/O10-1) -> 0.48921795
A11: 재보험계약자산 | E11: 673.755 | F11: 673.755 | G11: 776.81 | H11: 1191.787 | I11: 1178.8858 | J11: 1178.21 | M11: =IF(OR(I11<=0,J11<=0),"-",J11/I11-1) -> -0.00057322241 | O11: =$F11 -> 673.755 | P11: =$J11 -> 1178.21 | Q11: =IF(OR(P11<=0,O11<=0),"-",P11/O11-1) -> 0.74872172
A12: 유형자산 | E12: 1880.197 | F12: 1880.197 | G12: 1979.335 | H12: 2005.736 | I12: 2052.5247 | J12: 2076.896 | M12: =IF(OR(I12<=0,J12<=0),"-",J12/I12-1) -> 0.01187381 | O12: =$F12 -> 1880.197 | P12: =$J12 -> 2076.896 | Q12: =IF(OR(P12<=0,O12<=0),"-",P12/O12-1) -> 0.10461617
A13: 투자부동산 | E13: 2408.219 | F13: 2408.219 | G13: 2352.477 | H13: 2331.997 | I13: 2342.6848 | J13: 2780.243 | M13: =IF(OR(I13<=0,J13<=0),"-",J13/I13-1) -> 0.1867764 | O13: =$F13 -> 2408.219 | P13: =$J13 -> 2780.243 | Q13: =IF(OR(P13<=0,O13<=0),"-",P13/O13-1) -> 0.15448097
A14: 무형자산 | E14: 706.677 | F14: 706.677 | G14: 1140.959 | H14: 1140.831 | I14: 1172.4229 | J14: 1159.773 | M14: =IF(OR(I14<=0,J14<=0),"-",J14/I14-1) -> -0.010789503 | O14: =$F14 -> 706.677 | P14: =$J14 -> 1159.773 | Q14: =IF(OR(P14<=0,O14<=0),"-",P14/O14-1) -> 0.64116421
A15: 기타자산 | E15: 440.241 | F15: 440.241 | G15: 443.447 | H15: 400.562 | I15: 491.95618 | J15: 522.251 | M15: =IF(OR(I15<=0,J15<=0),"-",J15/I15-1) -> 0.061580324 | O15: =$F15 -> 440.241 | P15: =$J15 -> 522.251 | Q15: =IF(OR(P15<=0,O15<=0),"-",P15/O15-1) -> 0.18628433
A16: 그 외 | E16: 2677.306 | F16: 2677.306 | G16: 2043.795 | H16: 1901.547 | I16: 2222.2069 | J16: 2298.291 | M16: =IF(OR(I16<=0,J16<=0),"-",J16/I16-1) -> 0.034238096 | O16: =$F16 -> 2677.306 | P16: =$J16 -> 2298.291 | Q16: =IF(OR(P16<=0,O16<=0),"-",P16/O16-1) -> -0.14156581
A17: 자산계 | E17: 165129.29 | F17: 165129.29 | G17: 178482.97 | H17: 178534.38 | I17: 177788.3 | J17: 186464.83 | M17: =IF(OR(I17<=0,J17<=0),"-",J17/I17-1) -> 0.048802638 | O17: =$F17 -> 165129.29 | P17: =$J17 -> 186464.83 | Q17: =IF(OR(P17<=0,O17<=0),"-",P17/O17-1) -> 0.12920508
A18: 보험계약부채 | E18: 118055.41 | F18: 118055.41 | G18: 117878.69 | H18: 113103.08 | I18: 107840.76 | J18: 105749.18 | M18: =IF(OR(I18<=0,J18<=0),"-",J18/I18-1) -> -0.019395036 | O18: =$F18 -> 118055.41 | P18: =$J18 -> 105749.18 | Q18: =IF(OR(P18<=0,O18<=0),"-",P18/O18-1) -> -0.10424114
... A31: 신종자본증권 | E31: 1695.105 | F31: 1695.105 | G31: 3068.453 | H31: 3068.453 | I31: 3068.4533 | J31: 3068.468 | M31: =IF(OR(I31<=0,J31<=0),"-",J31/I31-1) -> 4.798325e-06 | O31: =$F31 -> 1695.105 | P31: =$J31 -> 3068.468 | Q31: =IF(OR(P31<=0,O31<=0),"-",P31/O31-1) -> 0.81019347
A32: 기타포괄손익누계액 | E32: -2646.119 | F32: -2646.119 | G32: -2733.431 | H32: -1892.648 | I32: -1071.914 | J32: -220.064 | M32: =IF(OR(I32<=0,J32<=0),"-",J32/I32-1) -> - | O32: =$F32 -> -2646.119 | P32: =$J32 -> -220.064
A33: 이익잉여금 | E33: 8418.425 | F33: 8418.425 | G33: 8776.361 | H33: 8731.223 | I33: 9035.5026 | J33: 9414.567 | M33: =IF(OR(H33<=0,I33<=0),"-",I33/H33-1) -> 0.0348496 | O33: =$F33 -> 8418.425 | P33: =$J33 -> 9414.567 | Q33: =IF(OR(P33<=0,O33<=0),"-",P33/O33-1) -> 0.11832878
A34: 비지배지분 | E34: 2446.11 | F34: 2446.11 | G34: 2737.304 | H34: 2748.151 | I34: 2814.6019 | J34: 3032.964 | M34: =IF(OR(H34<=0,I34<=0),"-",I34/H34-1) -> 0.024180204 | O34: =$F34 -> 2446.11 | P34: =$J34 -> 3032.964 | Q34: =IF(OR(P34<=0,O34<=0),"-",P34/O34-1) -> 0.23991317
A35: 자본계 | E35: 13991.701 | F35: 13991.701 | G35: 15831.863 | H35: 16623.385 | I35: 17826.178 | J35: 19286.664 | M35: =IF(OR(H35<=0,I35<=0),"-",I35/H35-1) -> 0.072355459 | O35: =$F35 -> 13991.701 | P35: =$J35 -> 19286.664 | Q35: =IF(OR(P35<=0,O35<=0),"-",P35/O35-1) -> 0.37843597
A36: ※ GAAP 기준

Sheet (연결) 요약 손익계산서
A1: Ⅰ. 요약 재무제표- 연결 손익계산서
A3: ■ 손익계산서 (연결) | P3: (단위 : 십억원)
A4: 구분 | D4: 2025 | H4: 2026 | L4: QoQ | N4: 2025 | O4: 2026 | P4: YoY
D5: 1Q | E5: 2Q | F5: 3Q | G5: 4Q | H5: 1Q | I5: 2Q | J5: 3Q | K5: 4Q | N5: 누적 | O5: 누적
D6: 2025.1~3 | E6: 2025.4~6 | F6: 2025.7~9 | G6: 2025.10~12 | H6: 2026.1~3 | I6: 2026.4~6 | J6: 2026.7~9 | K6: 2026.10~12 | N6: 2025.1~6 | O6: 2026.1~6
A7: 보험손익 | D7: 233.355 | E7: 164.579 | F7: -13.263 | G7: 239.205 | H7: 146.18411 | I7: 340.414 | L7: =IF(OR(H7<=0,I7<=0),"-",I7/H7-1) -> 1.3286662 | N7: =$D7+$E7 -> 397.934 | O7: =$H7+$I7 -> 486.59811 | P7: =IF(OR(O7<=0,N7<=0),"-",O7/N7-1) -> 0.22281109
B8: 보험영업수익 | D8: 2867.906 | E8: 2960.693 | F8: 3022.99 | G8: 3293.577 | H8: 3160.0141 | I8: 3259.407 | L8: =IF(OR(H8<=0,I8<=0),"-",I8/H8-1) -> 0.031453314 | N8: =$D8+$E8 -> 5828.599 | O8: =$H8+$I8 -> 6419.4211 | P8: =IF(OR(O8<=0,N8<=0),"-",O8/N8-1) -> 0.10136605
B9: 보험서비스비용 | D9: 2634.551 | E9: 2796.114 | F9: 3036.253 | G9: 3054.372 | H9: 3013.83 | I9: 2918.993 | L9: =IF(OR(H9<=0,I9<=0),"-",I9/H9-1) -> -0.031467261 | N9: =$D9+$E9 -> 5430.665 | O9: =$H9+$I9 -> 5932.823 | P9: =IF(OR(O9<=0,N9<=0),"-",O9/N9-1) -> 0.092467124
A10: 투자손익 | D10: 138.004 | E10: 76.125 | F10: 368.152 | G10: -58.907 | H10: 334.59833 | I10: 286.368 | L10: =IF(OR(H10<=0,I10<=0),"-",I10/H10-1) -> -0.14414396 | N10: =$D10+$E10 -> 214.129 | O10: =$H10+$I10 -> 620.96633 | P10: =IF(OR(O10<=0,N10<=0),"-",O10/N10-1) -> 1.8999637
B11: 이자배당손익 | D11: 911.917 | E11: 880.872 | F11: 951.095 | G11: 993.056 | H11: 1027.8751 | I11: 1044.72 | L11: =IF(OR(H11<=0,I11<=0),"-",I11/H11-1) -> 0.016388063 | N11: =$D11+$E11 -> 1792.789 | O11: =$H11+$I11 -> 2072.5951 | P11: =IF(OR(O11<=0,N11<=0),"-",O11/N11-1) -> 0.15607309
B12: 금융상품 평가처분손익 | D12: 541.847 | E12: 1394.538 | F12: 1013.656 | G12: 828.684 | H12: 913.02371 | I12: 4104.27 | L12: =IF(OR(H12<=0,I12<=0),"-",I12/H12-1) -> 3.4952502 | N12: =$D12+$E12 -> 1936.385 | O12: =$H12+$I12 -> 5017.2937 | P12: =IF(OR(O12<=0,N12<=0),"-",O12/N12-1) -> 1.5910621
B13: 파생상품손익 | D13: -196.989 | E13: 726.11 | F13: -955.493 | G13: -1155.443 | H13: -1759.8381 | I13: -2161.431 | L13: =IF(OR(H13<=0,I13<=0),"-",I13/H13-1) -> - | N13: =$D13+$E13 -> 529.121 | O13: =$H13+$I13 -> -3921.2691 | P13: =IF(OR(O13<=0,N13<=0),"-",O13/N13-1) -> -
B14: 외환손익 | D14: 222.483 | E14: -1374.578 | F14: 759.398 | G14: 547.228 | H14: 1271.121 | I14: 449.554 | L14: =IF(OR(H14<=0,I14<=0),"-",I14/H14-1) -> -0.64633265 | N14: =$D14+$E14 -> -1152.095 | O14: =$H14+$I14 -> 1720.675 | P14: =IF(OR(O14<=0,N14<=0),"-",O14/N14-1) -> -
B15: 보험재금융손익 | D15: -1174.959 | E15: -1347.632 | F15: -1180.312 | G15: -1113.986 | H15: -954.65297 | I15: -2993.105 | L15: =IF(OR(H15<=0,I15<=0),"-",I15/H15-1) -> - | N15: =$D15+$E15 -> -2522.591 | O15: =$H15+$I15 -> -3947.758 | P15: =IF(OR(O15<=0,N15<=0),"-",O15/N15-1) -> -
B16: 기타투자손익 | D16: -166.295 | E16: -203.185 | F16: -220.192 | G16: -158.446 | H16: -162.93043 | I16: -157.64 | L16: =IF(OR(H16<=0,I16<=0),"-",I16/H16-1) -> - | N16: =$D16+$E16 -> -369.48 | O16: =$H16+$I16 -> -320.57043 | P16: =IF(OR(O16<=0,N16<=0),"-",O16/N16-1) -> -
A17: 영업이익 | D17: 371.359 | E17: 240.704 | F17: 354.889 | G17: 180.298 | H17: 480.78244 | I17: 626.782 | L17: =IF(OR(H17<=0,I17<=0),"-",I17/H17-1) -> 0.30367075 | N17: =$D17+$E17 -> 612.063 | O17: =$H17+$I17 -> 1107.5644 | P17: =IF(OR(O17<=0,N17<=0),"-",O17/N17-1) -> 0.80955953
A18: 영업외손익 | D18: 5.896 | E18: 8.086 | F18: -2.503 | G18: -26.249 | H18: 3.8212405 | I18: 0.532 | L18: =IF(OR(H18<=0,I18<=0),"-",I18/H18-1) -> -0.86077819 | N18: =$D18+$E18 -> 13.982 | O18: =$H18+$I18 -> 4.3532405 | P18: =IF(OR(O18<=0,N18<=0),"-",O18/N18-1) -> -0.68865395
A19: 세전이익 | D19: 377.255 | E19: 248.79 | F19: 352.386 | G19: 154.049 | H19: 484.60368 | I19: 627.314 | L19: =IF(OR(H19<=0,I19<=0),"-",I19/H19-1) -> 0.29448873 | N19: =$D19+$E19 -> 626.045 | O19: =$H19+$I19 -> 1111.9177 | P19: =IF(OR(O19<=0,N19<=0),"-",O19/N19-1) -> 0.77609865
A20: 당기순이익 | D20: 295.728 | E20: 165.765 | F20: 307.42 | G20: 67.406 | H20: 381.58179 | I20: 522.943 | L20: =IF(OR(H20<=0,I20<=0),"-",I20/H20-1) -> 0.37046111 | N20: =$D20+$E20 -> 461.493 | O20: =$H20+$I20 -> 904.52479 | P20: =IF(OR(O20<=0,N20<=0),"-",O20/N20-1) -> 0.95999676
B21: 지배기업의 소유주 귀속 | D21: 226.061 | E21: 125.095 | F21: 266.994 | G21: 23.16 | H21: 324.39422 | I21: 447.553 | L21: =IF(OR(H21<=0,I21<=0),"-",I21/H21-1) -> 0.37965773 | N21: =$D21+$E21 -> 351.156 | O21: =$H21+$I21 -> 771.94722 | P21: =IF(OR(O21<=0,N21<=0),"-",O21/N21-1) -> 1.1983028
A22: ※ GAAP 기준

Sheet (별도) 요약 재무상태표
A1: Ⅰ. 요약 재무제표- 별도 재무상태표
A3: ■ 재무상태표 (별도) | Q3: (단위 : 십억원)
A4: 구분 | E4: 2025 | I4: 2026 | M4: QoQ | O4: 2025 | P4: 2026 | Q4: YoY
E5: 1Q | F5: 2Q | G5: 3Q | H5: 4Q | I5: 1Q | J5: 2Q | K5: 3Q | L5: 4Q | O5: 누적 | P5: 누적
E6: 2025.1~3 | F6: 2025.4~6 | G6: 2025.7~9 | H6: 2025.10~12 | I6: 2026.1~3 | J6: 2026.4~6 | K6: 2026.7~9 | L6: 2026.10~12 | O6: 2025.1~6 | P6: 2026.1~6
A7: 운용자산 | E7: 107959.31 | F7: 108593.22 | G7: 109414.57 | H7: 107601.67 | I7: 105423.31 | J7: 103410.83 | M7: =IF(OR(I7<=0,J7<=0),"-",J7/I7-1) -> -0.019089499 | O7: =F7 -> 108593.22 | P7: =$J7 -> 103410.83 | Q7: =IF(OR(P7<=0,O7<=0),"-",P7/O7-1) -> -0.047722957
B8: 현금및예치금 | E8: 1418.1968 | F8: 1145.4291 | G8: 1210.109 | H8: 2482.1684 | I8: 1264.9308 | J8: 1238.7273 | M8: =IF(OR(I8<=0,J8<=0),"-",J8/I8-1) -> -0.020715349 | O8: =F8 -> 1145.4291 | P8: =$J8 -> 1238.7273 | Q8: =IF(OR(P8<=0,O8<=0),"-",P8/O8-1) -> 0.081452583
B9: 유가증권 | E9: 89477.845 | F9: 90320.668 | G9: 91106.369 | H9: 88459.784 | I9: 87775.375 | J9: 85369.618 | M9: =IF(OR(I9<=0,J9<=0),"-",J9/I9-1) -> -0.027408111 | O9: =F9 -> 90320.668 | P9: =$J9 -> 85369.618 | Q9: =IF(OR(P9<=0,O9<=0),"-",P9/O9-1) -> -0.054816354
C10: FVPL | E10: 26100.652 | F10: 26072.144 | G10: 26222.112 | H10: 24941.316 | I10: 25950.497 | J10: 23645.849 | M10: =IF(OR(I10<=0,J10<=0),"-",J10/I10-1) -> -0.088809399 | O10: =F10 -> 26072.144 | P10: =$J10 -> 23645.849 | Q10: =IF(OR(P10<=0,O10<=0),"-",P10/O10-1) -> -0.093060818
C11: FVOCI | E11: 47946.555 | F11: 49324.233 | G11: 49717.845 | H11: 48218.133 | I11: 46287.683 | J11: 46077.796 | M11: =IF(OR(I11<=0,J11<=0),"-",J11/I11-1) -> -0.004534416 | O11: =F11 -> 49324.233 | P11: =$J11 -> 46077.796 | Q11: =IF(OR(P11<=0,O11<=0),"-",P11/O11-1) -> -0.065818297
C12: AC | E12: 11488.648 | F12: 10696.275 | G12: 10671.675 | H12: 10689.107 | I12: 10909.031 | J12: 11014.679 | M12: =IF(OR(I12<=0,J12<=0),"-",J12/I12-1) -> 0.0096844863 | O12: =F12 -> 10696.275 | P12: =$J12 -> 11014.679 | Q12: =IF(OR(P12<=0,O12<=0),"-",P12/O12-1) -> 0.029767759
C13: 관계종속기업 | E13: 3941.9904 | F13: 4228.0165 | G13: 4494.7366 | H13: 4611.2275 | I13: 4628.1646 | J13: 4631.2947 | M13: =IF(OR(I13<=0,J13<=0),"-",J13/I13-1) -> 0.00067631307 | O13: =F13 -> 4228.0165 | P13: =$J13 -> 4631.2947 | Q13: =IF(OR(P13<=0,O13<=0),"-",P13/O13-1) -> 0.095382361
B14: 대출채권 | E14: 14833.3 | F14: 14902.079 | G14: 14871.138 | H14: 14441.501 | I14: 14143.148 | J14: 14479.401 | M14: =IF(OR(I14<=0,J14<=0),"-",J14/I14-1) -> 0.023774956 | O14: =F14 -> 14902.079 | P14: =$J14 -> 14479.401 | Q14: =IF(OR(P14<=0,O14<=0),"-",P14/O14-1) -> -0.028363738
B15: 부동산 | E15: 2229.9647 | F15: 2225.0426 | G15: 2226.9531 | H15: 2218.2149 | I15: 2239.8534 | J15: 2323.0832 | M15: =IF(OR(I15<=0,J15<=0),"-",J15/I15-1) -> 0.03715862 | O15: =F15 -> 2225.0426 | P15: =$J15 -> 2323.0832 | Q15: =IF(OR(P15<=0,O15<=0),"-",P15/O15-1) -> 0.04406237
A16: 비운용자산 | E16: 3086.3757 | F16: 2718.7703 | G16: 2394.9375 | H16: 2471.8271 | I16: 2488.4423 | J16: 2465.8194 | M16: =IF(OR(I16<=0,J16<=0),"-",J16/I16-1) -> -0.0090911658 | O16: =F16 -> 2718.7703 | P16: =$J16 -> 2465.8194 | Q16: =IF(OR(P16<=0,O16<=0),"-",P16/O16-1) -> -0.093038705
A17: 특별계정자산 | E17: 14715.196 | F17: 15485.043 | G17: 15390.168 | H17: 15703.087 | I17: 16105.942 | J17: 18694.341 | M17: =IF(OR(I17<=0,J17<=0),"-",J17/I17-1) -> 0.16071082 | O17: =F17 -> 15485.043 | P17: =$J17 -> 18694.341 | Q17: =IF(OR(P17<=0,O17<=0),"-",P17/O17-1) -> 0.20725146
A18: 자산계 | E18: 125760.88 | F18: 126797.03 | G18: 127199.67 | H18: 125776.58 | I18: 124017.69 | J18: 124570.99 | M18: =IF(OR(I18<=0,J18<=0),"-",J18/I18-1) -> 0.0044614449 | O18: =F18 -> 126797.03 | P18: =$J18 -> 124570.99 | Q18: =IF(OR(P18<=0,O18<=0),"-",P18/O18-1) -> -0.017555953
A19: 보험부채 | E19: 86969.682 | F19: 86109.314 | G19: 86269.387 | H19: 81759.639 | I19: 77173.203 | J19: 73062.463 | M19: =IF(OR(I19<=0,J19<=0),"-",J19/I19-1) -> -0.053266416 | O19: =F19 -> 86109.314 | P19: =$J19 -> 73062.463 | Q19: =IF(OR(P19<=0,O19<=0),"-",P19/O19-1) -> -0.15151498
B20: 최선추정부채(BEL) | E20: 76233.744 | F20: 75343.866 | G20: 75245.934 | H20: 71046.444 | I20: 66192.356 | J20: 61935.769 | M20: =IF(OR(I20<=0,J20<=0),"-",J20/I20-1) -> -0.064306318 | O20: =F20 -> 75343.866 | P20: =$J20 -> 61935.769 | Q20: =IF(OR(P20<=0,O20<=0),"-",P20/O20-1) -> -0.1779587
B21: 보험계약마진(CSM) | E21: 8865.7116 | F21: 8833.0966 | G21: 9059.4014 | H21: 8713.6538 | I21: 8920.9406 | J21: 8928.4648 | M21: =IF(OR(I21<=0,J21<=0),"-",J21/I21-1) -> 0.00084343127 | O21: =F21 -> 8833.0966 | P21: =$J21 -> 8928.4648 | Q21: =IF(OR(P21<=0,O21<=0),"-",P21/O21-1) -> 0.010796681
B22: 위험조정(RA) | E22: 1864.9854 | F22: 1926.4799 | G22: 1956.4203 | H22: 1993.9031 | I22: 2053.6291 | J22: 2191.8962 | M22: =IF(OR(I22<=0,J22<=0),"-",J22/I22-1) -> 0.06732818 | O22: =F22 -> 1926.4799 | P22: =$J22 -> 2191.8962 | Q22: =IF(OR(P22<=0,O22<=0),"-",P22/O22-1) -> 0.13777269
B23: 기타 | E23: 5.2410137 | F23: 5.8717408 | G23: 7.6315509 | H23: 5.6375034 | I23: 6.2770451 | J23: 6.3324819 | M23: =IF(OR(I23<=0,J23<=0),"-",J23/I23-1) -> 0.0088316712 | O23: =F23 -> 5.8717408 | P23: =$J23 -> 6.3324819 | Q23: =IF(OR(P23<=0,O23<=0),"-",P23/O23-1) -> 0.078467549
A24: 재보험계약부채 | E24: 39.321058 | F24: 37.974301 | G24: 39.894424 | H24: 32.679342 | I24: 30.774607 | J24: 28.530298 | M24: =IF(OR(I24<=0,J24<=0),"-",J24/I24-1) -> -0.072927282 | O24: =F24 -> 37.974301 | P24: =$J24 -> 28.530298 | Q24: =IF(OR(P24<=0,O24<=0),"-",P24/O24-1) -> -0.24869458
A25: 투자계약부채 | E25: 9261.1937 | F25: 9375.9371 | G25: 9327.2766 | H25: 10219.266 | I25: 9994.0011 | J25: 9658.5017 | M25: =IF(OR(I25<=0,J25<=0),"-",J25/I25-1) -> -0.033570078 | O25: =F25 -> 9375.9371 | P25: =$J25 -> 9658.5017 | Q25: =IF(OR(P25<=0,O25<=0),"-",P25/O25-1) -> 0.030137215
A26: 특별계정부채 | E26: 14737.153 | F26: 15468.197 | G26: 15409.417 | H26: 15727.191 | I26: 16112.784 | J26: 18696.581 | M26: =IF(OR(I26<=0,J26<=0),"-",J26/I26-1) -> 0.16035699 | O26: =F26 -> 15468.197 | P26: =$J26 -> 18696.581 | Q26: =IF(OR(P26<=0,O26<=0),"-",P26/O26-1) -> 0.20871107
A27: 그 외 | E27: 4587.6085 | F27: 4130.3176 | G27: 4440.0831 | H27: 5577.2225 | I27: 7297.2425 | J27: 8781.518 | M27: =IF(OR(I27<=0,J27<=0),"-",J27/I27-1) -> 0.20340225 | O27: =F27 -> 4130.3176 | P27: =$J27 -> 8781.518 | Q27: =IF(OR(P27<=0,O27<=0),"-",P27/O27-1) -> 1.126112
A28: 부채계 | E28: 115594.96 | F28: 115121.74 | G28: 115486.06 | H28: 113316 | I28: 110608 | J28: 110227.59 | M28: =IF(OR(I28<=0,J28<=0),"-",J28/I28-1) -> -0.0034392686 | O28: =F28 -> 115121.74 | P28: =$J28 -> 110227.59 | Q28: =IF(OR(P28<=0,O28<=0),"-",P28/O28-1) -> -0.04251279
A29: 자본금 | E29: 4342.65 | F29: 4342.65 | G29: 4342.65 | H29: 4342.65 | I29: 4342.65 | J29: 4342.65 | M29: =IF(OR(I29<=0,J29<=0),"-",J29/I29-1) -> 0 | O29: =F29 -> 4342.65 | P29: =$J29 -> 4342.65 | Q29: =IF(OR(P29<=0,O29<=0),"-",P29/O29-1) -> 0
A30: 자본잉여금 | E30: 485.28104 | F30: 485.28104 | G30: 485.28104 | H30: 485.28104 | I30: 485.28104 | J30: 485.28104 | M30: =IF(OR(I30<=0,J30<=0),"-",J30/I30-1) -> 0 | O30: =F30 -> 485.28104 | P30: =$J30 -> 485.28104 | Q30: =IF(OR(P30<=0,O30<=0),"-",P30/O30-1) -> 0
A31: 신종자본증권 | E31: 1695.1048 | F31: 3068.4533 | G31: 3068.4533 | H31: 3068.4533 | I31: 3068.4533 | J31: 3068.4676 | M31: =IF(OR(I31<=0,J31<=0),"-",J31/I31-1) -> 4.665401e-06 | O31: =F31 -> 3068.4533 | P31: =$J31 -> 3068.4676 | Q31: =IF(OR(P31<=0,O31<=0),"-",P31/O31-1) -> 4.665401e-06
A32: 이익잉여금 | E32: 6994.8591 | F32: 7038.5317 | G32: 7154.5308 | H32: 7085.335 | I32: 7313.0637 | J32: 7506.9425 | M32: =IF(OR(I32<=0,J32<=0),"-",J32/I32-1) -> 0.026511292 | O32: =F32 -> 7038.5317 | P32: =$J32 -> 7506.9425 | Q32: =IF(OR(P32<=0,O32<=0),"-",P32/O32-1) -> 0.066549501
A33: 자본조정 | E33: -1110.142 | F33: -1106.6961 | G33: -1106.6961 | H33: -1106.8091 | I33: -1095.4816 | J33: -1084.1542 | M33: =IF(OR(I33<=0,J33<=0),"-",J33/I33-1) -> - | O33: =F33 -> -1106.6961 | P33: =$J33 -> -1084.1542 | Q33: =IF(OR(P33<=0,O33<=0),"-",P33/O33-1) -> -
A34: 기타포괄손익누계액 | E34: -2241.8325 | F34: -2152.9282 | G34: -2230.6032 | H34: -1414.3252 | I34: -704.27971 | J34: 24.208503 | M34: =IF(OR(I34<=0,J34<=0),"-",J34/I34-1) -> - | O34: =F34 -> -2152.9282 | P34: =$J34 -> 24.208503 | Q34: =IF(OR(P34<=0,O34<=0),"-",P34/O34-1) -> -
A35: 자본계 | E35: 10165.921 | F35: 11675.292 | G35: 11713.616 | H35: 12460.585 | I35: 13409.687 | J35: 14343.395 | M35: =IF(OR(I35<=0,J35<=0),"-",J35/I35-1) -> 0.069629422 | O35: =F35 -> 11675.292 | P35: =$J35 -> 14343.395 | Q35: =IF(OR(P35<=0,O35<=0),"-",P35/O35-1) -> 0.22852565
A36: ※ SAP 기준

Sheet (별도) 요약 손익계산서
A1: Ⅰ. 요약 재무제표- 별도 손익계산서
A3: ■ 손익계산서 (별도) | P3: (단위 : 십억원)
A4: 구분 | D4: 2025 | H4: 2026 | L4: QoQ | N4: 2025 | O4: 2026 | P4: YoY
D5: 1Q | E5: 2Q | F5: 3Q | G5: 4Q | H5: 1Q | I5: 2Q | J5: 3Q | K5: 4Q | N5: 누적 | O5: 누적
D6: 2025.1~3 | E6: 2025.4~6 | F6: 2025.7~9 | G6: 2025.10~12 | H6: 2026.1~3 | I6: 2026.4~6 | J6: 2026.7~9 | K6: 2026.10~12 | N6: 2025.1~6 | O6: 2026.1~6
A7: 보험손익 | D7: 104.20755 | E7: 71.791813 | F7: -36.576485 | G7: 204.99642 | H7: 62.394015 | I7: 222.89946 | L7: =IF(OR(H7<=0,I7<=0),"-",I7/H7-1) -> 2.5724494 | N7: =$D7+$E7 -> 175.99936 | O7: =$H7+$I7 -> 285.29348 | P7: =IF(OR(O7<=0,N7<=0),"-",O7/N7-1) -> 0.62099156
B8: CSM상각 | D8: 198.63864 | E8: 195.8406 | F8: 195.99963 | G8: 196.81107 | H8: 191.44023 | I8: 181.58469 | L8: =IF(OR(H8<=0,I8<=0),"-",I8/H8-1) -> -0.051481036 | N8: =$D8+$E8 -> 394.47923 | O8: =$H8+$I8 -> 373.02491 | P8: =IF(OR(O8<=0,N8<=0),"-",O8/N8-1) -> -0.054386439
B9: RA상각 | D9: 38.877898 | E9: 37.188161 | F9: 39.500964 | G9: 39.992307 | H9: 44.340212 | I9: 47.728399 | L9: =IF(OR(H9<=0,I9<=0),"-",I9/H9-1) -> 0.076413413 | N9: =$D9+$E9 -> 76.066059 | O9: =$H9+$I9 -> 92.068612 | P9: =IF(OR(O9<=0,N9<=0),"-",O9/N9-1) -> 0.21037705
B10: 예실차 | D10: -29.178843 | E10: -37.877811 | F10: -126.36919 | G10: -116.10769 | H10: -91.876166 | I10: -55.745327 | L10: =IF(OR(H10<=0,I10<=0),"-",I10/H10-1) -> - | N10: =$D10+$E10 -> -67.056655 | O10: =$H10+$I10 -> -147.62149 | P10: =IF(OR(O10<=0,N10<=0),"-",O10/N10-1) -> -
B11: 보험금 예실차 | D11: -48.960445 | E11: -76.257901 | F11: -144.42105 | G11: -110.28908 | H11: -72.913025 | I11: -65.304662 | L11: =IF(OR(H11<=0,I11<=0),"-",I11/H11-1) -> - | N11: =$D11+$E11 -> -125.21835 | O11: =$H11+$I11 -> -138.21769 | P11: =IF(OR(O11<=0,N11<=0),"-",O11/N11-1) -> -
B12: 사업비 예실차 | D12: 19.781602 | E12: 38.38009 | F12: 18.051856 | G12: -5.8186129 | H12: -18.96314 | I12: 9.5593348 | L12: =IF(OR(H12<=0,I12<=0),"-",I12/H12-1) -> - | N12: =$D12+$E12 -> 58.161692 | O12: =$H12+$I12 -> -9.4038055 | P12: =IF(OR(O12<=0,N12<=0),"-",O12/N12-1) -> -
B13: 기타 | D13: -104.13014 | E13: -123.35913 | F13: -145.70788 | G13: 84.318543 | H13: -81.510259 | I13: 49.331704 | L13: =IF(OR(H13<=0,I13<=0),"-",I13/H13-1) -> - | N13: =$D13+$E13 -> -227.48928 | O13: =$H13+$I13 -> -32.178555 | P13: =IF(OR(O13<=0,N13<=0),"-",O13/N13-1) -> -
A14: 투자손익 | D14: 44.501418 | E14: -3.9758004 | F14: 215.07674 | G14: -168.7588 | H14: 241.9069 | I14: 112.90236 | L14: =IF(OR(H14<=0,I14<=0),"-",I14/H14-1) -> -0.53328176 | N14: =$D14+$E14 -> 40.525618 | O14: =$H14+$I14 -> 354.80926 | P14: =IF(OR(O14<=0,N14<=0),"-",O14/N14-1) -> 7.7551845
B15: 일반계정 투자손익 | D15: -20.856869 | E15: 15.900793 | F15: 247.20829 | G15: -63.638775 | H15: 245.84725 | I15: 48.602371 | L15: =IF(OR(H15<=0,I15<=0),"-",I15/H15-1) -> -0.80230663 | N15: =$D15+$E15 -> -4.9560758 | O15: =$H15+$I15 -> 294.44962 | P15: =IF(OR(O15<=0,N15<=0),"-",O15/N15-1) -> -
B16: 이자/배당수익 | D16: 642.94349 | E16: 684.73246 | F16: 718.78889 | G16: 753.92807 | H16: 719.9882 | I16: 647.25542 | L16: =IF(OR(H16<=0,I16<=0),"-",I16/H16-1) -> -0.10101941 | N16: =$D16+$E16 -> 1327.6759 | O16: =$H16+$I16 -> 1367.2436 | P16: =IF(OR(O16<=0,N16<=0),"-",O16/N16-1) -> 0.029802208
B17: 평가/처분익 | D17: 8.561288 | E17: 17.714862 | F17: 215.04096 | G17: -138.9492 | H17: 212.84672 | I17: 124.84632 | L17: =IF(OR(H17<=0,I17<=0),"-",I17/H17-1) -> -0.41344496 | N17: =$D17+$E17 -> 26.27615 | O17: =$H17+$I17 -> 337.69304 | P17: =IF(OR(O17<=0,N17<=0),"-",O17/N17-1) -> 11.851694
B18: 부담이자 | D18: -672.36164 | E18: -686.55317 | F18: -686.62156 | G18: -678.61765 | H18: -686.98768 | I18: -723.49936 | L18: =IF(OR(H18<=0,I18<=0),"-",I18/H18-1) -> - | N18: =$D18+$E18 -> -1358.9148 | O18: =$H18+$I18 -> -1410.487 | P18: =IF(OR(O18<=0,N18<=0),"-",O18/N18-1) -> -
B19: 변액금융손익 | D19: 86.348472 | E19: 2.2965284 | F19: 1.5337121 | G19: -79.838014 | H19: 22.297041 | I19: 64.329554 | L19: =IF(OR(H19<=0,I19<=0),"-",I19/H19-1) -> 1.8851162 | N19: =$D19+$E19 -> 88.645 | O19: =$H19+$I19 -> 86.626594 | P19: =IF(OR(O19<=0,N19<=0),"-",O19/N19-1) -> -0.022769539
B20: 퇴직계정손익 | D20: -20.990185 | E20: -22.164278 | F20: -33.665261 | G20: -25.282006 | H20: -26.23739 | I20: 0.25527633 | L20: =IF(OR(H20<=0,I20<=0),"-",I20/H20-1) -> - | N20: =$D20+$E20 -> -43.154463 | O20: =$H20+$I20 -> -25.982113 | P20: =IF(OR(O20<=0,N20<=0),"-",O20/N20-1) -> -
A21: 영업이익 | D21: 148.70897 | E21: 67.816013 | F21: 178.50026 | G21: 36.237616 | H21: 304.30091 | I21: 335.80182 | L21: =IF(OR(H21<=0,I21<=0),"-",I21/H21-1) -> 0.10351895 | N21: =$D21+$E21 -> 216.52498 | O21: =$H21+$I21 -> 640.10274 | P21: =IF(OR(O21<=0,N21<=0),"-",O21/N21-1) -> 1.9562536
A22: 영업외손익 | D22: 3.4213925 | E22: 3.494475 | F22: -8.1757819 | G22: -17.352671 | H22: 4.0348452 | I22: -15.527998 | L22: =IF(OR(H22<=0,I22<=0),"-",I22/H22-1) -> - | N22: =$D22+$E22 -> 6.9158675 | O22: =$H22+$I22 -> -11.493153 | P22: =IF(OR(O22<=0,N22<=0),"-",O22/N22-1) -> -
A23: 세전이익 | D23: 152.13036 | E23: 71.310488 | F23: 170.32447 | G23: 18.884945 | H23: 308.33576 | I23: 320.27383 | L23: =IF(OR(H23<=0,I23<=0),"-",I23/H23-1) -> 0.038717753 | N23: =$D23+$E23 -> 223.44085 | O23: =$H23+$I23 -> 628.60958 | P23: =IF(OR(O23<=0,N23<=0),"-",O23/N23-1) -> 1.8133155
A24: 당기순이익 | D24: 121.99133 | E24: 57.709886 | F24: 136.1141 | G24: -2.495426 | H24: 247.84368 | I24: 262.36831 | L24: =IF(OR(H24<=0,I24<=0),"-",I24/H24-1) -> 0.058604012 | N24: =$D24+$E24 -> 179.70122 | O24: =$H24+$I24 -> 510.21199 | P24: =IF(OR(O24<=0,N24<=0),"-",O24/N24-1) -> 1.8392239
A25: ※ SAP 기준

Sheet 신계약 CSM 및 수익성
A1: Ⅱ. 주요 재무지표- 신계약 CSM 및 수익성
A3: ■ 신계약 CSM | P3: (단위 : 십억원)
A4: 구분 | D4: 2025 | H4: 2026 | L4: QoQ | N4: 2025 | O4: 2026 | P4: YoY
D5: 1Q | E5: 2Q | F5: 3Q | G5: 4Q | H5: 1Q | I5: 2Q | J5: 3Q | K5: 4Q | N5: 누적 | O5: 누적
D6: 2025.1~3 | E6: 2025.4~6 | F6: 2025.7~9 | G6: 2025.10~12 | H6: 2026.1~3 | I6: 2026.4~6 | J6: 2026.7~9 | K6: 2026.10~12 | N6: 2025.1~6 | O6: 2026.1~6
A7: 신계약 CSM | D7: 488.19447 | E7: 437.32421 | F7: 564.29565 | G7: 576.44443 | H7: 610.93408 | I7: 689.2 | L7: =IF(OR(H7<=0,I7<=0),"-",I7/H7-1) -> 0.12810862 | N7: =$D7+$E7 -> 925.51868 | O7: =$H7+$I7 -> 1300.1341 | P7: =IF(OR(O7<=0,N7<=0),"-",O7/N7-1) -> 0.40476265
B8: 보장성 | D8: 458.53544 | E8: 415.72262 | F8: 543.67639 | G8: 558.85766 | H8: 560.60544 | I8: =I9+I10 -> 650.5043 | L8: =IF(OR(H8<=0,I8<=0),"-",I8/H8-1) -> 0.16036032 | N8: =$D8+$E8 -> 874.25807 | O8: =$H8+$I8 -> 1211.1097 | P8: =IF(OR(O8<=0,N8<=0),"-",O8/N8-1) -> 0.38530005
B9: 종신 | D9: 128.37715 | E9: 145.1235 | F9: 211.71533 | G9: 242.62789 | H9: 278.31218 | I9: 363.96677 | L9: =IF(OR(H9<=0,I9<=0),"-",I9/H9-1) -> 0.30776443 | N9: =$D9+$E9 -> 273.50065 | O9: =$H9+$I9 -> 642.27895 | P9: =IF(OR(O9<=0,N9<=0),"-",O9/N9-1) -> 1.3483636
B10: 건강 | D10: 330.1583 | E10: 270.59913 | F10: 331.96106 | G10: 316.22977 | H10: 282.29326 | I10: 286.53753 | L10: =IF(OR(H10<=0,I10<=0),"-",I10/H10-1) -> 0.015034992 | N10: =$D10+$E10 -> 600.75742 | O10: =$H10+$I10 -> 568.83079 | P10: =IF(OR(O10<=0,N10<=0),"-",O10/N10-1) -> -0.053143962
B11: 연금/저축 | D11: 29.65903 | E11: 21.601586 | F11: 20.619259 | G11: 17.58677 | H11: 50.298976 | I11: 38.676982 | L11: =IF(OR(H11<=0,I11<=0),"-",I11/H11-1) -> -0.23105827 | N11: =$D11+$E11 -> 51.260617 | O11: =$H11+$I11 -> 88.975958 | P11: =IF(OR(O11<=0,N11<=0),"-",O11/N11-1) -> 0.73575668
A13: ■ APE 대비 신계약 CSM 배수
A14: 구분 | D14: 2025 | H14: 2026 | L14: QoQ | N14: 2025 | O14: 2026 | P14: YoY
D15: 1Q | E15: 2Q | F15: 3Q | G15: 4Q | H15: 1Q | I15: 2Q | J15: 3Q | K15: 4Q | N15: 누적 | O15: 누적
D16: 2025.1~3 | E16: 2025.4~6 | F16: 2025.7~9 | G16: 2025.10~12 | H16: 2026.1~3 | I16: 2026.4~6 | J16: 2026.7~9 | K16: 2026.10~12 | N16: 2025.1~6 | O16: 2026.1~6
A17: 전체 수익성 | D17: 0.55401702 | E17: 0.49446752 | F17: 0.56100578 | G17: 0.65617026 | H17: 0.72276115 | I17: 0.93105899 | L17: =I17-H17 -> 0.20829783 | N17: =(D7+E7)/('APE(상품 및 채널별)'!D21+'APE(상품 및 채널별)'!E21) -> 0.52418756 | O17: =(H7+I7)/('APE(상품 및 채널별)'!H21+'APE(상품 및 채널별)'!I21) -> 0.82002024 | P17: =O17-N17 -> 0.29583267
B18: 보장성 | D18: 0.66635516 | E18: 0.55963419 | F18: 0.61849126 | G18: 0.70890453 | H18: 0.8004932 | I18: 1.0262686 | L18: =I18-H18 -> 0.22577536 | N18: =(D8+E8)/('APE(상품 및 채널별)'!D8+'APE(상품 및 채널별)'!E8+'APE(상품 및 채널별)'!D19+'APE(상품 및 채널별)'!E19) -> 0.61095409 | O18: =(H8+I8)/('APE(상품 및 채널별)'!H8+'APE(상품 및 채널별)'!I8+'APE(상품 및 채널별)'!H19+'APE(상품 및 채널별)'!I19) -> 0.90775661 | P18: =O18-N18 -> 0.29680252
B19: 종신 | D19: 0.28990412 | E19: 0.27730339 | F19: 0.33041102 | G19: 0.41449893 | H19: 0.59146886 | I19: 0.87531659 | L19: =I19-H19 -> 0.28384774 | N19: =(D9+E9)/('APE(상품 및 채널별)'!D9+'APE(상품 및 채널별)'!E9) -> 0.28307874 | O19: =(H9+I9)/('APE(상품 및 채널별)'!H9+'APE(상품 및 채널별)'!I9) -> 0.72462891 | P19: =O19-N19 -> 0.44155018
B20: 건강 | D20: 1.3459452 | E20: 1.2327488 | F20: 1.3931964 | G20: 1.5578778 | H20: 1.228532 | I20: 1.3141374 | L20: =I20-H20 -> 0.085605324 | N20: =(D10+E10)/('APE(상품 및 채널별)'!D11+'APE(상품 및 채널별)'!E11+'APE(상품 및 채널별)'!D19+'APE(상품 및 채널별)'!E19) -> 1.2924873 | O20: =(H10+I10)/('APE(상품 및 채널별)'!H11+'APE(상품 및 채널별)'!I11+'APE(상품 및 채널별)'!H19+'APE(상품 및 채널별)'!I19) -> 1.2702127 | P20: =O20-N20 -> -0.022274596
B21: 연금/저축 | D21: 0.15362145 | E21: 0.15256697 | F21: 0.16257688 | G21: 0.19506512 | H21: =H11/SUM('APE(상품 및 채널별)'!H12,'APE(상품 및 채널별)'!H15,'APE(상품 및 채널별)'!H20) -> 0.34700218 | I21: =I11/SUM('APE(상품 및 채널별)'!I12,'APE(상품 및 채널별)'!I15,'APE(상품 및 채널별)'!I20) -> 0.36364767 | L21: =I21-H21 -> 0.016645491 | N21: =(D11+E11)/('APE(상품 및 채널별)'!D12+'APE(상품 및 채널별)'!E12+'APE(상품 및 채널별)'!D15+'APE(상품 및 채널별)'!E15+'APE(상품 및 채널별)'!D20+'APE(상품 및 채널별)'!E20) -> 0.15317531 | O21: =(H11+I11)/('APE(상품 및 채널별)'!H12+'APE(상품 및 채널별)'!I12+'APE(상품 및 채널별)'!H15+'APE(상품 및 채널별)'!I15+'APE(상품 및 채널별)'!H20+'APE(상품 및 채널별)'!I20) -> 0.35404678 | P21: =O21-N21 -> 0.20087147
A22: ※ APE 대비 신계약 CSM 배수 = 신계약 CSM ÷ 상품별 APE
A23: ■ 월평균 월초 대비 신계약 CSM 배수
A24: 구분 | D24: 2025 | H24: 2026 | L24: QoQ | N24: 2025 | O24: 2026 | P24: YoY
D25: 1Q | E25: 2Q | F25: 3Q | G25: 4Q | H25: 1Q | I25: 2Q | J25: 3Q | K25: 4Q | N25: 누적 | O25: 누적
D26: 2025.1~3 | E26: 2025.4~6 | F26: 2025.7~9 | G26: 2025.10~12 | H26: 2026.1~3 | I26: 2026.4~6 | J26: 2026.7~9 | K26: 2026.10~12 | N26: 2025.1~6 | O26: 2026.1~6
A27: 전체 수익성 | D27: 7.7528105 | E27: 6.6899833 | F27: 7.217 | G27: 8.32552 | H27: 9.8399555 | I27: =(I7/3)/'수입보험료 및 월초보험료'!I36 -> 12.294129 | L27: =I27-H27 -> 2.4541734 | N27: =(AVERAGE(D7,E7)/3)/AVERAGE('수입보험료 및 월초보험료'!D36,'수입보험료 및 월초보험료'!E36) -> 7.2114593 | O27: =(AVERAGE(H7,I7)/3)/AVERAGE('수입보험료 및 월초보험료'!H36,'수입보험료 및 월초보험료'!I36) -> 11.004437 | P27: =O27-N27 -> 3.7929772
B28: 보장성 | D28: 7.9620671 | E28: 6.6954843 | F28: 7.3782046 | G28: 8.4815176 | H28: 9.5796971 | I28: =(I8/3)/'수입보험료 및 월초보험료'!I31 -> 12.326137 | L28: =I28-H28 -> 2.74644 | N28: =(AVERAGE(D8,E8)/3)/AVERAGE('수입보험료 및 월초보험료'!D31,'수입보험료 및 월초보험료'!E31) -> 7.3049638 | O28: =(AVERAGE(H8,I8)/3)/AVERAGE('수입보험료 및 월초보험료'!H31,'수입보험료 및 월초보험료'!I31) -> 10.882022 | P28: =O28-N28 -> 3.5770584
B29: 종신 | D29: 3.4781129 | E29: 3.3277573 | F29: 3.9649847 | G29: 4.9740302 | H29: 7.0972451 | I29: =(I9/3)/'수입보험료 및 월초보험료'!I32 -> 10.503731 | L29: =I29-H29 -> 3.4064856 | N29: =(AVERAGE(D9,E9)/3)/AVERAGE('수입보험료 및 월초보험료'!D32,'수입보험료 및 월초보험료'!E32) -> 3.3966797 | O29: =(AVERAGE(H9,I9)/3)/AVERAGE('수입보험료 및 월초보험료'!H32,'수입보험료 및 월초보험료'!I32) -> 8.6952725 | P29: =O29-N29 -> 5.2985928
B30: 건강 | D30: 15.957385 | E30: 14.64281 | F30: 16.360821 | G30: 18.479677 | H30: 14.622011 | I30: =(I10/3)/'수입보험료 및 월초보험료'!I33 -> 15.810542 | L30: =I30-H30 -> 1.1885312 | N30: =(AVERAGE(D10,E10)/3)/AVERAGE('수입보험료 및 월초보험료'!D33,'수입보험료 및 월초보험료'!E33) -> 15.337182 | O30: =(AVERAGE(H10,I10)/3)/AVERAGE('수입보험료 및 월초보험료'!H33,'수입보험료 및 월초보험료'!I33) -> 15.197497 | P30: =O30-N30 -> -0.13968549
B31: 연금/저축 | D31: 1.3102204 | E31: 1.4683829 | F31: 1.310765 | G31: 1.6220348 | H31: 2.3496304 | I31: 2.0602767 | L31: =I31-H31 -> -0.28935367 | N31: 1.3701675 | O31: 2.2109037 | P31: =O31-N31 -> 0.84073615
A32: ※ 월평균 신계약 CSM 배수 = 월평균 신계약 CSM ÷ 월평균 월초
A33: ※ 연금/저축은 월납물량 기준
A34: ※ 25년 2분기 부터 '일반보장' 명칭을 '건강보험'으로 변경

Sheet 보험부채 Movement
A1: Ⅱ. 주요 재무지표- 보험부채 Movement
A3: ■ 최선추정부채(BEL) | AI3: (단위 : 십억원)
A4: 구분 | D4: 2025 | T4: 2026 | X4: 2026 | AB4: QoQ | AG4: 2025 | AH4: 2026 | AI4: YoY
D5: 1Q | H5: 2Q | L5: 3Q | P5: 4Q | T5: 1Q | X5: 2Q | AG5: 누적 | AH5: 누적
E6: 고정형 | F6: 연동형 | G6: VFA | I6: 고정형 | J6: 연동형 | K6: VFA | M6: 고정형 | N6: 연동형 | O6: VFA | Q6: 고정형 | R6: 연동형 | S6: VFA | U6: 고정형 | V6: 연동형 | W6: VFA | Y6: 고정형 | Z6: 연동형 | AA6: VFA | AC6: 고정형 | AD6: 연동형 | AE6: VFA | AG6: 2025.1~6 | AH6: 2026.1~6
A7: 기시 최선추정부채 | D7: 86144.252 | E7: 38073.018 | F7: 33506.857 | G7: 14564.377 | H7: 90477.712 | I7: 40072.914 | J7: 35245.714 | K7: 15159.084 | L7: 90295.981 | M7: 39297.656 | N7: 35358.038 | O7: 15640.287 | P7: 90141.998 | Q7: 38704.925 | R7: 35535.501 | S7: 15901.572 | T7: 86228.273 | U7: 36231.25 | V7: 34014.075 | W7: 15982.947 | X7: 81676.957 | Y7: 32856.255 | Z7: 33004.234 | AA7: 15816.468 | AB7: =IF(OR(T7<=0,X7<=0),"-",X7/T7-1) -> -0.052782176 | AC7: =IF(OR(U7<=0,Y7<=0),"-",Y7/U7-1) -> -0.093151512 | AD7: =IF(OR(V7<=0,Z7<=0),"-",Z7/V7-1) -> -0.029688909 | AE7: =IF(OR(W7<=0,AA7<=0),"-",AA7/W7-1) -> -0.010416059 | AG7: =$D7 -> 86144.252 | AH7: =$T7 -> 86228.273 | AI7: =IF(OR(AH7<=0,AG7<=0),"-",AH7/AG7-1) -> 0.00097534475
B8: 신계약 | D8: -525.04627 | E8: -486.41126 | F8: -38.636517 | G8: 0.0015119 | H8: -423.29348 | I8: -400.18665 | J8: -23.105262 | K8: -0.001573353 | L8: -612.38596 | M8: -590.0971 | N8: -22.281764 | O8: -0.00709684 | P8: -632.59972 | Q8: -613.75159 | R8: -18.832501 | S8: -0.015624919 | T8: -675.40562 | U8: -622.35405 | V8: -53.051573 | W8: 0 | X8: -757.60208 | Y8: -716.74376 | Z8: -40.858317 | AA8: 0 | AB8: =IF(OR(T8<=0,X8<=0),"-",X8/T8-1) -> - | AC8: =IF(OR(U8<=0,Y8<=0),"-",Y8/U8-1) -> - | AD8: =IF(OR(V8<=0,Z8<=0),"-",Z8/V8-1) -> - | AE8: =IF(OR(W8<=0,AA8<=0),"-",AA8/W8-1) -> - | AG8: =$D8+$H8 -> -948.33975 | AH8: =$T8+$X8 -> -1433.0077 | AI8: =IF(OR(AH8<=0,AG8<=0),"-",AH8/AG8-1) -> -
B9: 이자부리 | D9: 795.47132 | E9: 292.75826 | F9: 257.35758 | G9: 245.35548 | H9: 1170.9327 | I9: 296.01574 | J9: 247.92583 | K9: 626.99118 | L9: 967.96272 | M9: 298.7623 | N9: 264.76356 | O9: 404.43686 | P9: 1197.5193 | Q9: 298.10831 | R9: 273.39881 | S9: 626.01222 | T9: 1138.4901 | U9: 296.5075 | V9: 281.76653 | W9: 560.2161 | X9: 2958.0724 | Y9: 298.72816 | Z9: 311.57155 | AA9: 2347.7727 | AB9: =IF(OR(T9<=0,X9<=0),"-",X9/T9-1) -> 1.5982416 | AC9: =IF(OR(U9<=0,Y9<=0),"-",Y9/U9-1) -> 0.0074893775 | AD9: =IF(OR(V9<=0,Z9<=0),"-",Z9/V9-1) -> 0.10577911 | AE9: =IF(OR(W9<=0,AA9<=0),"-",AA9/W9-1) -> 3.190834 | AG9: =$D9+$H9 -> 1966.4041 | AH9: =$T9+$X9 -> 4096.5625 | AI9: =IF(OR(AH9<=0,AG9<=0),"-",AH9/AG9-1) -> 1.0832761
B10: 가정변경 등 조정 | D10: 76.086263 | E10: 173.05401 | F10: -95.822817 | J10: 571.54736 | K10: 80.242729 | L10: 751.19046 | M10: 224.69904 | N10: 386.47857 | O10: 140.01285 | P10: 1174.2952 | Q10: 787.32 | R10: 281.19566 | S10: 105.77953 | T10: 257.75534 | U10: 50.184164 | V10: 164.22209 | W10: 43.349086 | X10: 513.92295 | Y10: 800.60331 | Z10: -122.43727 | AA10: -164.24309 | AB10: =IF(OR(T10<=0,X10<=0),"-",X10/T10-1) -> 0.99384019 | AC10: =IF(OR(U10<=0,Y10<=0),"-",Y10/U10-1) -> 14.953306 | AD10: =IF(OR(V10<=0,Z10<=0),"-",Z10/V10-1) -> - | AE10: =IF(OR(W10<=0,AA10<=0),"-",AA10/W10-1) -> - | AG10: =$D10+$H10 -> 76.086263 | AH10: =$T10+$X10 -> 771.67829 | AI10: =IF(OR(AH10<=0,AG10<=0),"-",AH10/AG10-1) -> 9.1421501
B11: 할인율 변동 | D11: 3125.2587 | E11: 1988.454 | F11: 735.39643 | J11: -460.55825 | K11: -133.34312 | L11: -802.09284 | M11: -419.07207 | N11: -292.90444 | O11: -90.116331 | P11: -4656.5009 | Q11: -2932.5198 | R11: -1285.3347 | S11: -438.64641 | T11: -4926.1157 | U11: -3349.4481 | V11: -1073.956 | W11: -502.71158 | X11: -4186.8067 | Y11: -2907.0298 | Z11: -773.44506 | AA11: -506.33177 | AB11: =IF(OR(T11<=0,X11<=0),"-",X11/T11-1) -> - | AC11: =IF(OR(U11<=0,Y11<=0),"-",Y11/U11-1) -> - | AD11: =IF(OR(V11<=0,Z11<=0),"-",Z11/V11-1) -> - | AE11: =IF(OR(W11<=0,AA11<=0),"-",AA11/W11-1) -> - | AG11: =$D11+$H11 -> 3125.2587 | AH11: =$T11+$X11 -> -9112.9223 | AI11: =IF(OR(AH11<=0,AG11<=0),"-",AH11/AG11-1) -> -
B12: 기타 | D12: 861.68937 | E12: 32.0405 | F12: 880.56194 | J12: -223.4851 | K12: -92.686814 | L12: -458.65684 | M12: -107.02267 | N12: -158.59341 | O12: -193.04077 | P12: -996.43958 | Q12: -12.831706 | R12: -771.85317 | S12: -211.7547 | T12: -346.04002 | U12: 250.11475 | V12: -328.82185 | W12: -267.33293 | X12: -164.1556 | Y12: 343.88688 | Z12: -240.8062 | AA12: -267.23628 | AB12: =IF(OR(T12<=0,X12<=0),"-",X12/T12-1) -> - | AC12: =IF(OR(U12<=0,Y12<=0),"-",Y12/U12-1) -> 0.37491643 | AD12: =IF(OR(V12<=0,Z12<=0),"-",Z12/V12-1) -> - | AE12: =IF(OR(W12<=0,AA12<=0),"-",AA12/W12-1) -> - | AG12: =$D12+$H12 -> 861.68937 | AH12: =$T12+$X12 -> -510.19563 | AI12: =IF(OR(AH12<=0,AG12<=0),"-",AH12/AG12-1) -> -
A13: 기말 최선추정부채 | D13: 90477.712 | E13: 40072.914 | F13: 35245.714 | G13: 15159.084 | H13: 90295.981 | I13: 39297.656 | J13: 35358.038 | K13: 15640.287 | L13: 90141.998 | M13: 38704.925 | N13: 35535.501 | O13: 15901.572 | P13: 86228.273 | Q13: 36231.25 | R13: 34014.075 | S13: 15982.947 | T13: 81676.957 | U13: 32856.255 | V13: 33004.234 | W13: 15816.468 | X13: 80040.388 | Y13: 30675.699 | Z13: 32138.259 | AA13: 17226.43 | AB13: =IF(OR(T13<=0,X13<=0),"-",X13/T13-1) -> -0.020037096 | AC13: =IF(OR(U13<=0,Y13<=0),"-",Y13/U13-1) -> -0.066366519 | AD13: =IF(OR(V13<=0,Z13<=0),"-",Z13/V13-1) -> -0.026238309 | AE13: =IF(OR(W13<=0,AA13<=0),"-",AA13/W13-1) -> 0.089145158 | AG13: =$H13 -> 90295.981 | AH13: =$X13 -> 80040.388 | AI13: =IF(OR(AH13<=0,AG13<=0),"-",AH13/AG13-1) -> -0.11357751
A14: ※ 보험료배분접근법 포함
A15: ■ 보험계약마진(CSM)
A16: 구분 | D16: 2025 | H16: 2024 | T16: 2026 | X16: 2026 | AB16: QoQ | AG16: 2025 | AH16: 2026 | AI16: YoY
D17: 1Q | H17: 2Q | L17: 3Q | P17: 4Q | T17: 1Q | X17: 2Q | AG17: 누적 | AH17: 누적
E18: 고정형 | F18: 연동형 | G18: VFA | I18: 고정형 | J18: 연동형 | K18: VFA | M18: 고정형 | N18: 연동형 | O18: VFA | Q18: 고정형 | R18: 연동형 | S18: VFA | U18: 고정형 | V18: 연동형 | W18: VFA | Y18: 고정형 | Z18: 연동형 | AA18: VFA | AC18: 고정형 | AD18: 연동형 | AE18: VFA | AG18: 2025.1~6 | AH18: 2026.1~6
A19: 기시 보험계약마진 | D19: 9109.141 | E19: 6464.2112 | F19: 2345.1159 | G19: 299.81395 | H19: 8865.7116 | I19: 6669.7699 | J19: 2182.8212 | K19: 13.120502 | L19: 8833.0966 | M19: 6836.7581 | N19: 1984.4435 | O19: 11.894969 | P19: 9059.4014 | Q19: 7160.2738 | R19: 1888.1081 | S19: 11.019522 | T19: 8713.6538 | U19: 6778.8431 | V19: 1924.624 | W19: 10.186651 | X19: 8920.9406 | Y19: 7081.3211 | Z19: 1830.3867 | AA19: 9.2327838 | AB19: =IF(OR(T19<=0,X19<=0),"-",X19/T19-1) -> 0.023788736 | AC19: =IF(OR(U19<=0,Y19<=0),"-",Y19/U19-1) -> 0.044620881 | AD19: =IF(OR(V19<=0,Z19<=0),"-",Z19/V19-1) -> -0.048963996 | AE19: =IF(OR(W19<=0,AA19<=0),"-",AA19/W19-1) -> -0.093638912 | AG19: =$D19 -> 9109.141 | AH19: =$T19 -> 8713.6538 | AI19: =IF(OR(AH19<=0,AG19<=0),"-",AH19/AG19-1) -> -0.043416526
B20: 신계약 | D20: 488.19447 | E20: 452.72946 | F20: 35.463753 | G20: 0.001259991 | H20: 437.32421 | I20: 415.72262 | J20: 21.600257 | K20: 0.001329568 | L20: 564.29565 | M20: 543.67639 | N20: 20.611735 | O20: 0.007523743 | P20: 576.44443 | Q20: 558.85766 | R20: 17.572866 | S20: 0.01390334 | T20: 610.93408 | U20: 560.60544 | V20: 50.328639 | W20: 0 | X20: 689.18129 | Y20: 650.5043 | Z20: 38.676982 | AA20: 0 | AB20: =IF(OR(T20<=0,X20<=0),"-",X20/T20-1) -> 0.12807799 | AC20: =IF(OR(U20<=0,Y20<=0),"-",Y20/U20-1) -> 0.16036032 | AD20: =IF(OR(V20<=0,Z20<=0),"-",Z20/V20-1) -> -0.23151147 | AE20: =IF(OR(W20<=0,AA20<=0),"-",AA20/W20-1) -> - | AG20: =$D20+$H20 -> 925.51868 | AH20: =$T20+$X20 -> 1300.1154 | AI20: =IF(OR(AH20<=0,AG20<=0),"-",AH20/AG20-1) -> 0.40474243
B21: 이자부리 | D21: 88.637081 | E21: 66.786354 | F21: 21.850727 | G21: 0 | H21: 88.332026 | I21: 68.169218 | J21: 20.162809 | K21: 0 | L21: 89.284975 | M21: 70.929076 | N21: 18.3559 | O21: 0 | P21: 91.513518 | Q21: 74.100583 | R21: 17.412935 | S21: 0 | T21: 88.54187 | U21: 71.067338 | V21: 17.474532 | W21: 0 | X21: 91.902613 | Y21: 75.295993 | Z21: 16.606619 | AA21: 0 | AB21: =IF(OR(T21<=0,X21<=0),"-",X21/T21-1) -> 0.037956538 | AC21: =IF(OR(U21<=0,Y21<=0),"-",Y21/U21-1) -> 0.0595021 | AD21: =IF(OR(V21<=0,Z21<=0),"-",Z21/V21-1) -> -0.049667308 | AE21: =IF(OR(W21<=0,AA21<=0),"-",AA21/W21-1) -> - | AG21: =$D21+$H21 -> 176.96911 | AH21: =$T21+$X21 -> 180.44448 | AI21: =IF(OR(AH21<=0,AG21<=0),"-",AH21/AG21-1) -> 0.019638316
B22: 가정변경 등 조정 | D22: -621.62237 | E22: -175.33781 | F22: -159.93888 | G22: -286.34567 | H22: -362.43057 | I22: -175.81732 | J22: -185.68445 | K22: -0.9287964 | L22: -231.27623 | M22: -146.65265 | N22: -84.012396 | O22: -0.61118733 | P22: -816.89452 | Q22: -873.29649 | R22: 56.997384 | S22: -0.59540699 | T22: -300.74892 | U22: -190.10027 | V22: -109.91995 | W22: -0.72869336 | X22: -591.97501 | Y22: -962.1922 | Z22: 253.41298 | AA22: 116.80422 | AB22: =IF(OR(T22<=0,X22<=0),"-",X22/T22-1) -> - | AC22: =IF(OR(U22<=0,Y22<=0),"-",Y22/U22-1) -> - | AD22: =IF(OR(V22<=0,Z22<=0),"-",Z22/V22-1) -> - | AE22: =IF(OR(W22<=0,AA22<=0),"-",AA22/W22-1) -> - | AG22: =$D22+$H22 -> -984.05293 | AH22: =$T22+$X22 -> -892.72393 | AI22: =IF(OR(AH22<=0,AG22<=0),"-",AH22/AG22-1) -> -
B23: 상각 | D23: -198.63864 | E23: -138.6193 | F23: -59.670305 | G23: -0.34903462 | H23: -195.8406 | I23: -141.08629 | J23: -54.456242 | K23: -0.29806616 | L23: -195.99963 | M23: -144.43712 | N23: -51.29072 | O23: -0.27178407 | P23: -196.81107 | Q23: -141.09242 | R23: -55.467282 | S23: -0.25136732 | T23: -191.44023 | U23: -139.09456 | V23: -52.120496 | W23: -0.22517352 | X23: -181.58469 | Y23: -125.32864 | Z23: -53.726372 | AA23: -2.5296778 | AB23: =IF(OR(T23<=0,X23<=0),"-",X23/T23-1) -> - | AC23: =IF(OR(U23<=0,Y23<=0),"-",Y23/U23-1) -> - | AD23: =IF(OR(V23<=0,Z23<=0),"-",Z23/V23-1) -> - | AE23: =IF(OR(W23<=0,AA23<=0),"-",AA23/W23-1) -> - | AG23: =$D23+$H23 -> -394.47923 | AH23: =$T23+$X23 -> -373.02491 | AI23: =IF(OR(AH23<=0,AG23<=0),"-",AH23/AG23-1) -> -
A24: 기말 보험계약마진 | D24: 8865.7116 | E24: 6669.7699 | F24: 2182.8212 | G24: 13.120502 | H24: 8833.0966 | I24: 6836.7581 | J24: 1984.4435 | K24: 11.894969 | L24: 9059.4014 | M24: 7160.2738 | N24: 1888.1081 | O24: 11.019522 | P24: 8713.6538 | Q24: 6778.8431 | R24: 1924.624 | S24: 10.186651 | T24: 8920.9406 | U24: 7081.3211 | V24: 1830.3867 | W24: 9.2327838 | X24: 8928.4648 | Y24: 6719.6006 | Z24: 2085.3569 | AA24: 123.50732 | AB24: =IF(OR(T24<=0,X24<=0),"-",X24/T24-1) -> 0.00084343127 | AC24: =IF(OR(U24<=0,Y24<=0),"-",Y24/U24-1) -> -0.051080941 | AD24: =IF(OR(V24<=0,Z24<=0),"-",Z24/V24-1) -> 0.13929855 | AE24: =IF(OR(W24<=0,AA24<=0),"-",AA24/W24-1) -> 12.37704 | AG24: =$H24 -> 8833.0966 | AH24: =$X24 -> 8928.4648 | AI24: =IF(OR(AH24<=0,AG24<=0),"-",AH24/AG24-1) -> 0.010796681
A26: ■ 위험조정(RA)
A27: 구분 | D27: 2025 | T27: 2026 | X27: 2026 | AB27: QoQ | AG27: 2025 | AH27: 2026 | AI27: YoY
D28: 1Q | H28: 2Q | L28: 3Q | P28: 4Q | T28: 1Q | X28: 2Q | AG28: 누적 | AH28: 누적
E29: 고정형 | F29: 연동형 | G29: VFA | I29: 고정형 | J29: 연동형 | K29: VFA | M29: 고정형 | N29: 연동형 | O29: VFA | Q29: 고정형 | R29: 연동형 | S29: VFA | U29: 고정형 | V29: 연동형 | W29: VFA | Y29: 고정형 | Z29: 연동형 | AA29: VFA | AC29: 고정형 | AD29: 연동형 | AE29: VFA | AG29: 2025.1~6 | AH29: 2026.1~6
A30: 기시 위험조정 | D30: 1898.7946 | E30: 1063.3144 | F30: 611.71574 | G30: 223.76452 | H30: 1864.9854 | I30: 1071.8598 | J30: 574.18423 | K30: 218.94134 | L30: 1926.4799 | M30: 1128.9139 | N30: 578.09977 | O30: 219.46621 | P30: 1956.4203 | Q30: 1168.7545 | R30: 568.29901 | S30: 219.36681 | T30: 1993.9031 | U30: 1183.022 | V30: 580.99101 | W30: 229.89015 | X30: 2053.6291 | Y30: 1239.4892 | Z30: 579.57813 | AA30: 234.56179 | AB30: =IF(OR(T30<=0,X30<=0),"-",X30/T30-1) -> 0.029954287 | AC30: =IF(OR(U30<=0,Y30<=0),"-",Y30/U30-1) -> 0.04773131 | AD30: =IF(OR(V30<=0,Z30<=0),"-",Z30/V30-1) -> -0.0024318447 | AE30: =IF(OR(W30<=0,AA30<=0),"-",AA30/W30-1) -> 0.020321174 | AG30: =$D30 -> 1898.7946 | AH30: =$T30 -> 1993.9031 | AI30: =IF(OR(AH30<=0,AG30<=0),"-",AH30/AG30-1) -> 0.050088893
B31: 신계약 | D31: 67.754715 | E31: 62.419232 | F31: 5.3343721 | G31: 0.001111407 | H31: 60.205449 | I31: 58.067829 | J31: 2.1368902 | K31: 0.000730641 | L31: 74.493879 | M31: 72.251603 | N31: 2.2413244 | O31: 0.000951111 | P31: 69.711781 | Q31: 68.087448 | R31: 1.6216868 | S31: 0.002646813 | T31: 71.113301 | U31: 67.928813 | V31: 3.184488 | W31: 0 | X31: 71.417668 | Y31: 69.052576 | Z31: 2.3650914 | AA31: 0 | AB31: =IF(OR(T31<=0,X31<=0),"-",X31/T31-1) -> 0.0042800248 | AC31: =IF(OR(U31<=0,Y31<=0),"-",Y31/U31-1) -> 0.016543249 | AD31: =IF(OR(V31<=0,Z31<=0),"-",Z31/V31-1) -> -0.25730874 | AE31: =IF(OR(W31<=0,AA31<=0),"-",AA31/W31-1) -> - | AG31: =$D31+$H31 -> 127.96016 | AH31: =$T31+$X31 -> 142.53097 | AI31: =IF(OR(AH31<=0,AG31<=0),"-",AH31/AG31-1) -> 0.11386985
B32: 가정변경 등 조정 | D32: -55.02283 | E32: -28.977957 | F32: -26.065082 | G32: 0.020209709 | H32: 37.937161 | I32: 19.383472 | J32: 13.828838 | K32: 4.7248513 | L32: -12.787321 | M32: -9.0273022 | N32: -5.0986914 | O32: 1.3386728 | P32: 5.647801 | Q32: -25.377767 | R32: 18.701305 | S32: 12.324263 | T32: 30.300547 | U32: 16.538892 | V32: 5.935797 | W32: 7.8258583 | X32: 115.57883 | Y32: 8.9932353 | Z32: 72.243912 | AA32: 34.341685 | AB32: =IF(OR(T32<=0,X32<=0),"-",X32/T32-1) -> 2.814414 | AC32: =IF(OR(U32<=0,Y32<=0),"-",Y32/U32-1) -> -0.45623714 | AD32: =IF(OR(V32<=0,Z32<=0),"-",Z32/V32-1) -> 11.170887 | AE32: =IF(OR(W32<=0,AA32<=0),"-",AA32/W32-1) -> 3.3882324 | AG32: =$D32+$H32 -> -17.085669 | AH32: =$T32+$X32 -> 145.87938 | AI32: =IF(OR(AH32<=0,AG32<=0),"-",AH32/AG32-1) -> -
B33: 환입 | D33: -38.877898 | E33: -23.709984 | F33: -12.166733 | G33: -3.0011811 | H33: -37.188161 | I33: -21.658719 | J33: -11.976848 | K33: -3.5525931 | L33: -39.500964 | M33: -27.337027 | N33: -9.3699243 | O33: -2.7940131 | P33: -39.992307 | Q33: -28.014487 | R33: -9.0885204 | S33: -2.8892989 | T33: -44.340212 | U33: -30.675973 | V33: -10.451162 | W33: -3.2130774 | X33: -47.728399 | Y33: -33.898104 | Z33: -10.660281 | AA33: -3.1700136 | AB33: =IF(OR(T33<=0,X33<=0),"-",X33/T33-1) -> - | AC33: =IF(OR(U33<=0,Y33<=0),"-",Y33/U33-1) -> - | AD33: =IF(OR(V33<=0,Z33<=0),"-",Z33/V33-1) -> - | AE33: =IF(OR(W33<=0,AA33<=0),"-",AA33/W33-1) -> - | AG33: =$D33+$H33 -> -76.066059 | AH33: =$T33+$X33 -> -92.068612 | AI33: =IF(OR(AH33<=0,AG33<=0),"-",AH33/AG33-1) -> -
B34: 기타 | D34: -7.6632056 | E34: -1.1858255 | F34: -4.6340626 | G34: -1.8433175 | H34: 0.54003647 | I34: 1.2614973 | J34: -0.073341351 | K34: -0.64811953 | L34: 7.7347907 | M34: 3.9532779 | N34: 2.4265264 | O34: 1.3549865 | P34: 2.1155936 | Q34: -0.42766974 | R34: 1.4575336 | S34: 1.0857297 | T34: 2.6523108 | U34: 2.6754569 | V34: -0.08200291 | W34: 0.058856779 | X34: -1.0009905 | Y34: -0.583477 | Z34: 0.006113586 | AA34: -0.42362711 | AB34: =IF(OR(T34<=0,X34<=0),"-",X34/T34-1) -> - | AC34: =IF(OR(U34<=0,Y34<=0),"-",Y34/U34-1) -> - | AD34: =IF(OR(V34<=0,Z34<=0),"-",Z34/V34-1) -> - | AE34: =IF(OR(W34<=0,AA34<=0),"-",AA34/W34-1) -> - | AG34: =$D34+$H34 -> -7.1231692 | AH34: =$T34+$X34 -> 1.6513202 | AI34: =IF(OR(AH34<=0,AG34<=0),"-",AH34/AG34-1) -> -
A35: 기말 위험조정 | D35: 1864.9854 | E35: 1071.8598 | F35: 574.18423 | G35: 218.94134 | H35: 1926.4799 | I35: 1128.9139 | J35: 578.09977 | K35: 219.46621 | L35: 1956.4203 | M35: 1168.7545 | N35: 568.29901 | O35: 219.36681 | P35: 1993.9031 | Q35: 1183.022 | R35: 580.99101 | S35: 229.89015 | T35: 2053.6291 | U35: 1239.4892 | V35: 579.57813 | W35: 234.56179 | X35: 2191.8962 | Y35: 1283.0534 | Z35: 643.53297 | AA35: 265.30983 | AB35: =IF(OR(T35<=0,X35<=0),"-",X35/T35-1) -> 0.06732818 | AC35: =IF(OR(U35<=0,Y35<=0),"-",Y35/U35-1) -> 0.035146923 | AD35: =IF(OR(V35<=0,Z35<=0),"-",Z35/V35-1) -> 0.11034722 | AE35: =IF(OR(W35<=0,AA35<=0),"-",AA35/W35-1) -> 0.13108719 | AG35: =$H35 -> 1926.4799 | AH35: =$X35 -> 2191.8962 | AI35: =IF(OR(AH35<=0,AG35<=0),"-",AH35/AG35-1) -> 0.13777269

Sheet 효율지표
A1: Ⅱ. 주요 재무지표- 효율지표
A3: ■ 사업비율 / 손해율 | P3: (단위 : 십억원)
A4: 구분 | D4: 2025 | H4: 2026 | L4: QoQ | N4: 2025 | O4: 2026 | P4: YoY
D5: 1Q | E5: 2Q | F5: 3Q | G5: 4Q | H5: 1Q | I5: 2Q | J5: 3Q | K5: 4Q | N5: 누적 | O5: 누적
D6: 2025.1~3 | E6: 2025.4~6 | F6: 2025.7~9 | G6: 2025.10~12 | H6: 2026.1~3 | I6: 2026.4~6 | J6: 2026.7~9 | K6: 2026.10~12 | N6: 2025.1~6 | O6: 2026.1~6
A7: 조정 사업비율 | D7: 0.29558324 | E7: 0.30642218 | F7: 0.37729573 | G7: 0.23484151 | H7: 0.31546055 | I7: 0.32086877 | L7: =I7-H7 -> 0.0054082203 | N7: =N9/N8 -> 0.30092235 | O7: =O9/O8 -> 0.31808338 | P7: =O7-N7 -> 0.017161035
B8: 조정 수입보험료 | D8: 3773.7349 | E8: 3663.4467 | F8: 3575.5024 | G8: 5578.6064 | H8: 3948.5228 | I8: 3718.0704 | L8: =IF(OR(H8<=0,I8<=0),"-",I8/H8-1) -> -0.058364201 | N8: =$D8+E8 -> 7437.1817 | O8: =$H8+I8 -> 7666.5932 | P8: =IF(OR(O8<=0,N8<=0),"-",O8/N8-1) -> 0.030846567
B9: 실제 사업비 | D9: 1115.4528 | E9: 1122.5614 | F9: 1349.0218 | G9: 1310.0884 | H9: 1245.6032 | I9: 1193.0127 | L9: =IF(OR(H9<=0,I9<=0),"-",I9/H9-1) -> -0.042220903 | N9: =$D9+E9 -> 2238.0141 | O9: =$H9+I9 -> 2438.6159 | P9: =IF(OR(O9<=0,N9<=0),"-",O9/N9-1) -> 0.089633806
A10: 손해율 | D10: 0.82624731 | E10: 0.84666813 | F10: 0.9292353 | G10: 0.87404675 | H10: 0.89210995 | I10: 0.88656658 | L10: =I10-H10 -> -0.0055433673 | N10: =N11/N13 -> 0.83651923 | O10: =O11/O13 -> 0.88932856 | P10: =O10-N10 -> 0.052809337
B11: 사고보험금 | D11: 624.34083 | E11: 651 | F11: 725.42576 | G11: 692.89 | H11: 714.88805 | I11: 715.43693 | L11: =IF(OR(H11<=0,I11<=0),"-",I11/H11-1) -> 0.00076779579 | N11: 1275.3408 | O11: 1430.325 | P11: =IF(OR(O11<=0,N11<=0),"-",O11/N11-1) -> 0.12152371
B12: IBNR | D12: -10.775583 | E12: 26.856768 | F12: 44.616561 | G12: 36.596849 | H12: 8.8125811 | I12: 20.630975 | L12: =IF(OR(H12<=0,I12<=0),"-",I12/H12-1) -> 1.341082 | N12: 16.081185 | O12: 29.443556 | P12: =IF(OR(O12<=0,N12<=0),"-",O12/N12-1) -> 0.83093205
B13: 위험보험료 | D13: 755.63433 | E13: 768.94609 | F13: 780.66961 | G13: 792.73792 | H13: 801.34522 | I13: 806.97485 | L13: =IF(OR(H13<=0,I13<=0),"-",I13/H13-1) -> 0.0070252204 | N13: 1524.5804 | O13: 1608.3201 | P13: =IF(OR(O13<=0,N13<=0),"-",O13/N13-1) -> 0.054926362
A14: ※ 조정 수입보험료 : 일시납의 1/10 반영
A15: ※ 손해율=사고보험금(IBNR 포함)÷위험보험료
A17: ■ 계약유지율
A18: 구분 | D18: 2025 | H18: 2026 | L18: QoQ | N18: 2025 | O18: 2026 | P18: YoY
D19: 1Q | E19: 2Q | F19: 3Q | G19: 4Q | H19: 1Q | I19: 2Q | J19: 3Q | K19: 4Q | N19: 누적 | O19: 누적
D20: 2025.1~3 | E20: 2025.4~6 | F20: 2025.7~9 | G20: 2025.10~12 | H20: 2026.1~3 | I20: 2026.4~6 | J20: 2026.7~9 | K20: 2026.10~12 | N20: 2025.1~6 | O20: 2026.1~6
A21: 13회차 계약유지율 | D21: 0.882 | E21: 0.891 | F21: 0.896 | G21: 0.894 | H21: 0.90150989 | I21: 0.898 | L21: =I21-H21 -> -0.0035098881 | N21: 0.886 | O21: 0.9 | P21: =O21-N21 -> 0.014
A22: 25회차 계약유지율 | D22: 0.831 | E22: 0.77 | F22: 0.781 | G22: 0.721 | H22: 0.76890071 | I22: 0.78 | L22: =I22-H22 -> 0.011099288 | N22: 0.801 | O22: 0.774 | P22: =O22-N22 -> -0.027
A24: ■ 평균 부담금리
A25: 구분 | D25: 2025 | H25: 2026 | L25: QoQ | N25: 2025 | O25: 2026 | P25: YoY
D26: 1Q | E26: 2Q | F26: 3Q | G26: 4Q | H26: 1Q | I26: 2Q | J26: 3Q | K26: 4Q | N26: 누적 | O26: 누적
D27: 2025.1~3 | E27: 2025.4~6 | F27: 2025.7~9 | G27: 2025.10~12 | H27: 2026.1~3 | I27: 2026.4~6 | J27: 2026.7~9 | K27: 2026.10~12 | N27: 2025.1~6 | O27: 2026.1~6
A28: 평균 부담금리 | D28: 0.032886907 | E28: 0.032932434 | F28: 0.032949137 | G28: 0.032460731 | H28: 0.032939979 | I28: 0.034513781 | L28: =I28-H28 -> 0.0015738027 | N28: =E28 -> 0.032932434 | O28: =I28 -> 0.034513781 | P28: =O28-N28 -> 0.001581347

Sheet 재무안전성
A1: Ⅱ. 주요 재무지표- 재무안전성
C2: 신뱅
A3: ■ K-ICS / 듀레이션 갭 | P3: (단위 : 십억원, 년)
A4: 구분 | D4: 2025 | H4: 2026 | L4: QoQ | N4: 2025 | O4: 2026 | P4: YoY
D5: 1Q | E5: 2Q | F5: 3Q | G5: 4Q | H5: 1Q | I5: 2Q | J5: 3Q | K5: 4Q | N5: 누적 | O5: 누적
D6: 2025.1~3 | E6: 2025.4~6 | F6: 2025.7~9 | G6: 2025.10~12 | H6: 2026.1~3 | I6: 2026.4~6 | J6: 2026.7~9 | K6: 2026.10~12 | N6: 2025.1~6 | O6: 2026.1~6
A7: 지급여력비율 | D7: 1.54093 | E7: 1.60615 | F7: 1.58244 | G7: 1.57517 | H7: 1.62121 | I7: 1.669768 | L7: =I7-H7 -> 0.048558006 | N7: =E7 -> 1.60615 | O7: =I7 -> 1.669768 | P7: =O7-N7 -> 0.063618006
B8: 지급여력금액 | D8: 21074.507 | E8: 22263.443 | F8: 22542.639 | G8: 22901.084 | H8: 24041.506 | I8: 25213.452 | L8: =IF(OR(I8<=0,H8<=0),"-",I8/H8-1) -> 0.048746766 | N8: =E8 -> 22263.443 | O8: =I8 -> 25213.452 | P8: =IF(OR(O8<=0,N8<=0),"-",O8/N8-1) -> 0.13250463
B9: 지급여력기준금액 | D9: 13676.442 | E9: 13861.397 | F9: 14245.459 | G9: 14538.834 | H9: 14829.357 | I9: 15099.973 | L9: =IF(OR(I9<=0,H9<=0),"-",I9/H9-1) -> 0.01824865 | N9: =E9 -> 13861.397 | O9: =I9 -> 15099.973 | P9: =IF(OR(O9<=0,N9<=0),"-",O9/N9-1) -> 0.089354315
A10: 듀레이션 갭 | D10: -0.27 | E10: -0.11 | F10: -0.15784061 | G10: -0.024728199 | H10: 0.41975957 | I10: 0.9340828 | L10: =I10-H10 -> 0.51432323 | N10: =E10 -> -0.11 | O10: =I10 -> 0.9340828 | P10: =O10-N10 -> 1.0440828
B11: 자산 듀레이션 | D11: 11.8 | E11: 11.88 | F11: 11.97756 | G11: 11.686701 | H11: 11.319566 | I11: 11.364603 | L11: =I11-H11 -> 0.045036833 | N11: =E11 -> 11.88 | O11: =I11 -> 11.364603 | P11: =O11-N11 -> -0.51539707
B12: 부채 듀레이션 | D12: 11.58 | E12: 11.62 | F12: 11.713522 | G12: 11.11207 | H12: 10.666596 | I12: 10.098735 | L12: =I12-H12 -> -0.56786073 | N12: =E12 -> 11.62 | O12: =I12 -> 10.098735 | P12: =O12-N12 -> -1.5212647
A13: ※ K-ICS 기준 적용
A14: ※ 듀레이션 갭 = 금리부자산 듀레이션 – 금리부부채 듀레이션 × (금리부부채 금액 ÷ 금리부자산 금액)

Sheet 수입보험료 및 월초보험료
A1: Ⅲ. 신계약 매출 지표 - 수입보험료 및 월초보험료
A3: ■ 수입보험료 | P3: (단위 : 십억원)
A4: 구분 | D4: 2025 | H4: 2026 | L4: QoQ | N4: 2025 | O4: 2026 | P4: YoY
D5: 1Q | E5: 2Q | F5: 3Q | G5: 4Q | H5: 1Q | I5: 2Q | J5: 3Q | K5: 4Q | N5: 누적 | O5: 누적
D6: 2025.1~3 | E6: 2025.4~6 | F6: 2025.7~9 | G6: 2025.10~12 | H6: 2026.1~3 | I6: 2026.4~6 | J6: 2026.7~9 | K6: 2026.10~12 | N6: 2025.1~6 | O6: 2026.1~6
A7: 개인보험 | D7: 4399.8273 | E7: 4222.448 | F7: 3987.0576 | G7: 3921.7255 | H7: 4439.1951 | I7: 4053.8906 | L7: =IF(OR(H7<=0,I7<=0),"-",I7/H7-1) -> -0.086796011 | N7: =D7+E7 -> 8622.2753 | O7: =H7+I7 -> 8493.0857 | P7: =IF(OR(O7<=0,N7<=0),"-",O7/N7-1) -> -0.01498324
B8: 보장성보험 | D8: 2598.4272 | E8: 2689.5597 | F8: 2806.2554 | G8: 2922.3457 | H8: 3012.7234 | I8: 3071.6293 | L8: =IF(OR(H8<=0,I8<=0),"-",I8/H8-1) -> 0.01955239 | N8: =D8+E8 -> 5287.9869 | O8: =H8+I8 -> 6084.3527 | P8: =IF(OR(O8<=0,N8<=0),"-",O8/N8-1) -> 0.15059905
B9: 종신/CI보험 | D9: 1752.4916 | E9: 1819.1147 | F9: 1912.8969 | G9: 2010.0301 | H9: 2079.5991 | I9: 2118.4693 | L9: =IF(OR(H9<=0,I9<=0),"-",I9/H9-1) -> 0.018691188 | N9: =D9+E9 -> 3571.6063 | O9: =H9+I9 -> 4198.0683 | P9: =IF(OR(O9<=0,N9<=0),"-",O9/N9-1) -> 0.17540064
B10: (변액종신/CI) | D10: 247.74127 | E10: 236.19755 | F10: 226.99459 | G10: 218.04632 | H10: 206.29476 | I10: 193.88154 | L10: =IF(OR(H10<=0,I10<=0),"-",I10/H10-1) -> -0.060172281 | N10: =D10+E10 -> 483.93882 | O10: =H10+I10 -> 400.1763 | P10: =IF(OR(O10<=0,N10<=0),"-",O10/N10-1) -> -0.17308494
B11: 건강보험 | D11: 845.93554 | E11: 870.44504 | F11: 893.35843 | G11: 912.31562 | H11: 933.12429 | I11: 953.16005 | L11: =IF(OR(H11<=0,I11<=0),"-",I11/H11-1) -> 0.0214717 | N11: =D11+E11 -> 1716.3806 | O11: =H11+I11 -> 1886.2843 | P11: =IF(OR(O11<=0,N11<=0),"-",O11/N11-1) -> 0.098989567
B12: 연금보험 | D12: 1742.3571 | E12: 1490.5644 | F12: 1139.5344 | G12: 968.82499 | H12: 1400.3829 | I12: 958.01745 | L12: =IF(OR(H12<=0,I12<=0),"-",I12/H12-1) -> -0.31588893 | N12: =D12+E12 -> 3232.9214 | O12: =H12+I12 -> 2358.4004 | P12: =IF(OR(O12<=0,N12<=0),"-",O12/N12-1) -> -0.27050489
B13: 일반연금 | D13: 1712.5008 | E13: 1462.0508 | F13: 1112.737 | G13: 943.36373 | H13: 1376.4233 | I13: 935.67978 | L13: =IF(OR(H13<=0,I13<=0),"-",I13/H13-1) -> -0.32020926 | N13: =D13+E13 -> 3174.5516 | O13: =H13+I13 -> 2312.103 | P13: =IF(OR(O13<=0,N13<=0),"-",O13/N13-1) -> -0.27167571
B14: 변액연금 | D14: 29.85627 | E14: 28.513583 | F14: 26.797415 | G14: 25.461259 | H14: 23.959662 | I14: 22.337673 | L14: =IF(OR(H14<=0,I14<=0),"-",I14/H14-1) -> -0.067696682 | N14: =D14+E14 -> 58.369853 | O14: =H14+I14 -> 46.297335 | P14: =IF(OR(O14<=0,N14<=0),"-",O14/N14-1) -> -0.20682797
B15: 저축보험 | D15: 59.043023 | E15: 42.32395 | F15: 41.267884 | G15: 30.55486 | H15: 26.088761 | I15: 24.243866 | L15: =IF(OR(H15<=0,I15<=0),"-",I15/H15-1) -> -0.07071608 | N15: =D15+E15 -> 101.36697 | O15: =H15+I15 -> 50.332627 | P15: =IF(OR(O15<=0,N15<=0),"-",O15/N15-1) -> -0.50346128
B16: 일반저축 | D16: 45.440563 | E16: 29.20083 | F16: 28.319879 | G16: 17.665573 | H16: 12.610399 | I16: 10.422429 | L16: =IF(OR(H16<=0,I16<=0),"-",I16/H16-1) -> -0.17350518 | N16: =D16+E16 -> 74.641393 | O16: =H16+I16 -> 23.032828 | P16: =IF(OR(O16<=0,N16<=0),"-",O16/N16-1) -> -0.69142017
B17: 변액저축 | D17: 13.60246 | E17: 13.12312 | F17: 12.948005 | G17: 12.889287 | H17: 13.478362 | I17: 13.821437 | L17: =IF(OR(H17<=0,I17<=0),"-",I17/H17-1) -> 0.025453734 | N17: =D17+E17 -> 26.72558 | O17: =H17+I17 -> 27.299799 | P17: =IF(OR(O17<=0,N17<=0),"-",O17/N17-1) -> 0.021485757
A18: 단체보험 | D18: 33.687567 | E18: 39.355781 | F18: 31.599434 | G18: 30.579115 | H18: 34.060088 | I18: 36.862567 | L18: =IF(OR(H18<=0,I18<=0),"-",I18/H18-1) -> 0.082280437 | N18: =D18+E18 -> 73.043348 | O18: =H18+I18 -> 70.922656 | P18: =IF(OR(O18<=0,N18<=0),"-",O18/N18-1) -> -0.029033342
B19: 보장성 | D19: 6.0692115 | E19: 5.4815996 | F19: 3.9491002 | G19: 2.4514841 | H19: 5.5748702 | I19: 5.5512272 | L19: =IF(OR(H19<=0,I19<=0),"-",I19/H19-1) -> -0.0042409988 | N19: =D19+E19 -> 11.550811 | O19: =H19+I19 -> 11.126097 | P19: =IF(OR(O19<=0,N19<=0),"-",O19/N19-1) -> -0.036769172
B20: 저축성 | D20: 27.618355 | E20: 33.874182 | F20: 27.650334 | G20: 28.127631 | H20: 28.485218 | I20: 31.31134 | L20: =IF(OR(H20<=0,I20<=0),"-",I20/H20-1) -> 0.099213633 | N20: =D20+E20 -> 61.492537 | O20: =H20+I20 -> 59.796558 | P20: =IF(OR(O20<=0,N20<=0),"-",O20/N20-1) -> -0.027580238
A21: 퇴직 | D21: 491.41035 | E21: 326.87773 | F21: 164.14097 | G21: 2136.4943 | H21: 401.80393 | I21: 220.14851 | L21: =IF(OR(H21<=0,I21<=0),"-",I21/H21-1) -> -0.45209967 | N21: =D21+E21 -> 818.28808 | O21: =H21+I21 -> 621.95244 | P21: =IF(OR(O21<=0,N21<=0),"-",O21/N21-1) -> -0.23993462
A22: 수입보험료 합계 | D22: 4924.9252 | E22: 4588.6815 | F22: 4182.798 | G22: 6088.7989 | H22: 4875.0591 | I22: 4310.9017 | L22: =IF(OR(H22<=0,I22<=0),"-",I22/H22-1) -> -0.11572319 | N22: =D22+E22 -> 9513.6067 | O22: =H22+I22 -> 9185.9608 | P22: =IF(OR(O22<=0,N22<=0),"-",O22/N22-1) -> -0.03443972
A23: 보장성보험 | D23: 58.745633 | E23: 63.237104 | F23: 69.928944 | G23: 74.002321 | H23: 67.474314 | I23: 75.222835 | L23: =IF(OR(H23<=0,I23<=0),"-",I23/H23-1) -> 0.1148366 | N23: =(N8+N19)/(N22-N21) -> 0.60947021 | O23: =(O8+O19)/(O22-O21) -> 0.71175535 | P23: =(O23-N23)*100 -> 10.228514
A24: 저축성보험 | D24: 41.254367 | E24: 36.762896 | F24: 30.071056 | G24: 25.997679 | H24: 32.525686 | I24: 24.777165 | L24: =IF(OR(H24<=0,I24<=0),"-",I24/H24-1) -> -0.23822775 | N24: =(N12+N15+N20)/(N22-N21) -> 0.39052979 | O24: =(O12+O15+O20)/(O22-O21) -> 0.28824465 | P24: =(O24-N24)*100 -> -10.228514
A25: ※ 보장성보험 및 저축성보험 비중은 전체 수입보험료에서 퇴직보험료를 제외한 수입보험료에 대한 비중
A27: ■ 월평균 월초보험료 | P27: (단위 : 십억원)
A28: 구분 | D28: 2025 | H28: 2026 | L28: QoQ | N28: 2025 | O28: 2026 | P28: YoY
D29: 1Q | E29: 2Q | F29: 3Q | G29: 4Q | H29: 1Q | I29: 2Q | J29: 3Q | K29: 4Q | N29: 누적 | O29: 누적
D30: 2025.1~3 | E30: 2025.4~6 | F30: 2025.7~9 | G30: 2025.10~12 | H30: 2026.1~3 | I30: 2026.4~6 | J30: 2026.7~9 | K30: 2026.10~12 | N30: 2025.1~6 | O30: 2026.1~6
A31: 보장성보험 | D31: 19.196667 | E31: 20.696667 | F31: 24.562271 | G31: 21.963744 | H31: 19.506721 | I31: 17.591462 | L31: =IF(OR(H31<=0,I31<=0),"-",I31/H31-1) -> -0.098184592 | N31: 19.946667 | O31: 18.549091 | P31: =IF(OR(O31<=0,N31<=0),"-",O31/N31-1) -> -0.07006561
B32: 종신/CI보험 | D32: 12.303333 | E32: 14.536667 | F32: 17.798751 | G32: 16.259645 | H32: 13.071372 | I32: 11.550397 | L32: =IF(OR(H32<=0,I32<=0),"-",I32/H32-1) -> -0.11635923 | N32: 13.42 | O32: 12.310884 | P32: =IF(OR(O32<=0,N32<=0),"-",O32/N32-1) -> -0.082646488
B33: 건강보험 | D33: 6.8966667 | E33: 6.16 | F33: 6.7633333 | G33: 5.7040998 | H33: 6.4353495 | I33: 6.0410648 | L33: =IF(OR(H33<=0,I33<=0),"-",I33/H33-1) -> -0.061268573 | N33: 6.5283333 | O33: 6.2382072 | P33: =IF(OR(O33<=0,N33<=0),"-",O33/N33-1) -> -0.044441078
A34: 연금보험 | D34: 1.3266667 | E34: 1.0066667 | F34: 1.4332101 | G34: 1.0449556 | H34: 0.95214894 | I34: 1.0352731 | L34: =IF(OR(H34<=0,I34<=0),"-",I34/H34-1) -> 0.087301619 | N34: 1.1666667 | O34: 0.99371101 | P34: =IF(OR(O34<=0,N34<=0),"-",O34/N34-1) -> -0.14824771
A35: 저축보험 | D35: 0.46666667 | E35: 0.086666667 | F35: 0.067779108 | G35: 0.070716149 | H35: 0.23682247 | I35: 0.059691695 | L35: =IF(OR(H35<=0,I35<=0),"-",I35/H35-1) -> -0.7479475 | N35: 0.27666667 | O35: 0.14825708 | P35: =IF(OR(O35<=0,N35<=0),"-",O35/N35-1) -> -0.46413103
A36: 월초보험료 합계 | D36: 20.99 | E36: 21.79 | F36: 26.06326 | G36: 23.079416 | H36: 20.695692 | I36: =I31+I34+I35 -> 18.686426 | L36: =IF(OR(H36<=0,I36<=0),"-",I36/H36-1) -> -0.097086197 | N36: 21.391667 | O36: 19.691059 | P36: =IF(OR(O36<=0,N36<=0),"-",O36/N36-1) -> -0.079498587
A37: ※ 월초보험료 산출 시 일시납 제외

Sheet APE(상품 및 채널별)
A1: Ⅲ. 신계약 매출 지표 - APE(상품 및 채널별)
A3: ■ 상품별 APE | P3: (단위 : 십억원)
A4: 구분 | D4: 2025 | H4: 2026 | L4: QoQ | N4: 2025 | O4: 2026 | P4: YoY
D5: 1Q | E5: 2Q | F5: 3Q | G5: 4Q | H5: 1Q | I5: 2Q | J5: 3Q | K5: 4Q | N5: 누적 | O5: 누적
D6: 2025.1~3 | E6: 2025.4~6 | F6: 2025.7~9 | G6: 2025.10~12 | H6: 2026.1~3 | I6: 2026.4~6 | J6: 2026.7~9 | K6: 2026.10~12 | N6: 2025.1~6 | O6: 2026.1~6
A7: 개인보험 | D7: 862.49665 | E7: 879.30816 | F7: 1002.7198 | G7: 876.28277 | H7: 835.27994 | I7: 737.63642 | L7: =IF(OR(H7<=0,I7<=0),"-",I7/H7-1) -> -0.11689915 | N7: =D7+E7 -> 1741.8048 | O7: =H7+I7 -> 1572.9164 | P7: =IF(OR(O7<=0,N7<=0),"-",O7/N7-1) -> -0.096961754
