Workbook

Sheet 2512
C3: □ 2025년 동업사 경영지표 | T3: 2026.04.01
C5: 1. 재무상태표 현황
T6: (단위 : 억원)
C7: 구분 | I7: 미래에셋생명 | J7: 삼성생명 | K7: 교보생명 | L7: 한화생명 | M7: 신한라이프 | N7: 동양생명 | O7: KB라이프 | P7: 삼성화재 | Q7: 현대해상 | R7: 메리츠화재 | S7: KB손보 | T7: DB손보
C8: 자산 | I8: =[1]작업!I9 -> 328551.82 | J8: =[1]작업!J9 -> 3099482.9 | K8: =[1]작업!K9 -> 1281657.9 | L8: =[1]작업!L9 -> 1257765.8 | M8: =[1]작업!M9 -> 594480.32 | N8: =[1]작업!N9 -> 353152.58 | O8: =[1]작업!O9 -> 352289.34 | P8: =[1]작업!P9 -> 938090.44 | ... T8: =[1]작업!T9 -> 594088.28
C9: FVPL | I9: =[1]작업!I10 -> 169444.47 | J9: =[1]작업!J10 -> 382096.35 | K9: =[1]작업!K10 -> 341828.23 | L9: =[1]작업!L10 -> 323201.24 | M9: =[1]작업!M10 -> 132652.76 | N9: =[1]작업!N10 -> 53751.04 | O9: =[1]작업!O10 -> 92426.37 | P9: =[1]작업!P10 -> 127057.77 | ... T9: =[1]작업!T10 -> 177224.66
C10: (비중) | I10: =[1]작업!I11 -> 0.51573133 | J10: =[1]작업!J11 -> 0.12327745 | K10: =[1]작업!K11 -> 0.26670784 | L10: =[1]작업!L11 -> 0.25696456 | M10: =[1]작업!M11 -> 0.22314071 | N10: =[1]작업!N11 -> 0.15220345 | O10: =[1]작업!O11 -> 0.26235926 | P10: =[1]작업!P11 -> 0.13544298 | ... T10: =[1]작업!T11 -> 0.29831368
C11: FVOCI | I11: =[1]작업!I12 -> 116635.57 | J11: =[1]작업!J12 -> 1968888.3 | K11: =[1]작업!K12 -> 608298.88 | L11: =[1]작업!L12 -> 482181.33 | M11: =[1]작업!M12 -> 352884.58 | N11: =[1]작업!N12 -> 228378.35 | O11: =[1]작업!O12 -> 221531.57 | P11: =[1]작업!P12 -> 434306.81 | ... T11: =[1]작업!T12 -> 201214.38
C12: AC | I12: =[1]작업!I13 -> 28014.504 | J12: =[1]작업!J13 -> 411156.26 | K12: =[1]작업!K13 -> 215464.74 | L12: =[1]작업!L13 -> 280714.2 | M12: =[1]작업!M13 -> 39503.44 | N12: =[1]작업!N13 -> 56226.03 | O12: =[1]작업!O13 -> 16958.85 | P12: =[1]작업!P13 -> 300857.43 | ... T12: =[1]작업!T13 -> 157633.73
C13: 부채 | I13: =[1]작업!I14 -> 304186.8 | J13: =[1]작업!J14 -> 2535314.8 | K13: =[1]작업!K14 -> 1205110.4 | L13: =[1]작업!L14 -> 1133078.1 | M13: =[1]작업!M14 -> 532087.38 | N13: =[1]작업!N14 -> 337812.87 | O13: =[1]작업!O14 -> 310103.46 | P13: =[1]작업!P14 -> 731812.67 | ... T13: =[1]작업!T14 -> 495539.27
C14: BEL | I14: =[1]작업!I15 -> 245312.29 | J14: =[1]작업!J15 -> 1844632.6 | K14: =[1]작업!K15 -> 889399.68 | L14: =[1]작업!L15 -> 862224.89 | M14: =[1]작업!M15 -> 389601.52 | N14: =[1]작업!N15 -> 252112.7 | O14: =[1]작업!O15 -> 246632.98 | P14: =[1]작업!P15 -> 250474.79 | ... T14: =[1]작업!T15 -> 120958.09
C15: CSM | I15: =[1]작업!I16 -> 20584.231 | J15: =[1]작업!J16 -> 132178.74 | K15: =[1]작업!K16 -> 65109.61 | L15: =[1]작업!L16 -> 87136.52 | M15: =[1]작업!M16 -> 75537.34 | N15: =[1]작업!N16 -> 24570.95 | O15: =[1]작업!O16 -> 32637.75 | P15: =[1]작업!P16 -> 141676.64 | ... T15: =[1]작업!T16 -> 122053.43
C16: (전년비 증감율) | I16: =I83 -> -0.0095220699 | J16: =J83 -> 0.024480735 | K16: =K83 -> 0.011323756 | L16: =L83 -> -0.043416717 | M16: =M83 -> 0.045627741 | N16: =N83 -> -0.080114545 | O16: =O83 -> 0.084127302 | P16: =P83 -> 0.0066616176 | ... T16: =T83 -> -0.0021595424
C17: (부채대비 CSM 비중) | I17: =[1]작업!I17 -> 0.067669705 | J17: =[1]작업!J17 -> 0.052135041 | K17: =[1]작업!K17 -> 0.054027924 | L17: =[1]작업!L17 -> 0.076902486 | M17: =[1]작업!M17 -> 0.14196416 | N17: =[1]작업!N17 -> 0.072735387 | O17: =[1]작업!O17 -> 0.10524794 | P17: =[1]작업!P17 -> 0.19359687 | ... T17: =[1]작업!T17 -> 0.24630425
C18: RA | I18: =[1]작업!I18 -> 4060.445 | J18: =[1]작업!J18 -> 31652.09 | K18: =[1]작업!K18 -> 13818.29 | L18: =[1]작업!L18 -> 19939.03 | M18: =[1]작업!M18 -> 13975.85 | N18: =[1]작업!N18 -> 4767.14 | O18: =[1]작업!O18 -> 5502.97 | P18: =[1]작업!P18 -> 18956.91 | ... T18: =[1]작업!T18 -> 18367.53
C19: 자기자본(신종자본증권제외) | I19: =[1]작업!I19 -> 24365.016 | J19: =[1]작업!J19 -> 564168.15 | K19: =[1]작업!K19 -> 54490.33 | L19: =[1]작업!L19 -> 94003.23 | M19: =[1]작업!M19 -> 62392.94 | N19: =[1]작업!N19 -> 15339.71 | O19: =[1]작업!O19 -> 41687.88 | P19: =[1]작업!P19 -> 206277.77 | ... T19: =[1]작업!T19 -> 89898.95
C20: (전기대비) | I20: =[1]작업!I20 -> -1167.3639 | J20: =[1]작업!J20 -> 259283.18 | K20: =[1]작업!K20 -> 3485.3844 | L20: =[1]작업!L20 -> 1487.83 | M20: =[1]작업!M20 -> -5235.56 | N20: =[1]작업!N20 -> -1344.1964 | O20: =[1]작업!O20 -> -3185.7 | P20: =[1]작업!P20 -> 53319.397 | ... T20: =[1]작업!T20 -> 5738.9633
C21: (자본증감율) | I21: =+I20/(I19-I20) -> -0.045720922 | J21: =+J20/(J19-J20) -> 0.85042952 | K21: =+K20/(K19-K20) -> 0.068334246 | L21: =+L20/(L19-L20) -> 0.016081971 | M21: =+M20/(M19-M20) -> -0.077416474 | N21: =+N20/(N19-N20) -> -0.080568445 | O21: =+O20/(O19-O20) -> -0.070992776 | P21: =+P20/(P19-P20) -> 0.34858763 | ... T21: =+T20/(T19-T20) -> 0.068191115
C22: 이익잉여금 | I22: =[1]작업!I22 -> 20678.245 | J22: =[1]작업!J22 -> 150629.44 | K22: =[1]작업!K22 -> 75757.824 | L22: =[1]작업!L22 -> 70853.36 | M22: =[1]작업!M22 -> 69683.97 | N22: =[1]작업!N22 -> 16044.17 | O22: =[1]작업!O22 -> 31590.18 | P22: =[1]작업!P22 -> 140898.61 | ... T22: =[1]작업!T22 -> 112011.39
C23: (전기대비) | I23: =+[1]작업!I56 -> 1249.0039 | J23: =+[1]작업!J56 -> 10623.58 | K23: =+[1]작업!K56 -> 5417.8032 | L23: =+[1]작업!L56 -> 1988.6 | M23: =+[1]작업!M56 -> 1309.77 | N23: =+[1]작업!N56 -> 429.19 | O23: =+[1]작업!O56 -> 130.88 | P23: =+[1]작업!P56 -> 6446.9078 | ... T23: =+[1]작업!T56 -> 10965.06
C24: 기타포괄손익 | I24: =[1]작업!I23 -> -4322.4669 | J24: =[1]작업!J23 -> 433581.09 | K24: =[1]작업!K23 -> -23979.81 | L24: =[1]작업!L23 -> -14061.35 | M24: =[1]작업!M23 -> -21282.91 | N24: =[1]작업!N23 -> -12240.13 | O24: =[1]작업!O23 -> 314.67 | P24: =[1]작업!P23 -> 67876.289 | ... T24: =[1]작업!T23 -> -22293
C25: (전기대비) | I25: =[1]작업!I24 -> -2416.3678 | J25: =[1]작업!J24 -> 248659.6 | K25: =[1]작업!K24 -> -1934.5182 | L25: =[1]작업!L24 -> -568.56 | M25: =[1]작업!M24 -> -6539.63 | N25: =[1]작업!N24 -> -1206.93 | O25: =[1]작업!O24 -> -3316.58 | P25: =[1]작업!P24 -> 44191.651 | ... T25: =[1]작업!T24 -> -6198.45
C26: (자기자본 대비 기타포괄손익 증감율) | I26: =[1]작업!I25 -> -0.094639351 | J26: =[1]작업!J25 -> 0.81558497 | K26: =[1]작업!K25 -> -0.037928051 | L26: =[1]작업!L25 -> -0.0061455714 | M26: =[1]작업!M25 -> -0.096699321 | N26: =[1]작업!N25 -> -0.072340972 | O26: =[1]작업!O25 -> -0.073909414 | P26: =[1]작업!P25 -> 0.28891292 | ... T26: =[1]작업!T25 -> -0.073650796
C27: (보험계약부채대비 기타포괄손익 증감율) | I27: =[1]작업!I26 -> -0.0092057677 | J27: =[1]작업!J26 -> 0.12300364 | K27: =[1]작업!K26 -> -0.0020483819 | L27: =[1]작업!L26 -> -0.00058525045 | M27: =[1]작업!M26 -> -0.013506266 | N27: =[1]작업!N26 -> -0.0042766399 | O27: =[1]작업!O26 -> -0.012188945 | P27: =[1]작업!P26 -> 0.10029729 | ... T27: =[1]작업!T26 -> -0.024445729
C28: * 당사 특별계정자산 : 실적배당형퇴직연금 3,501억, 변액보험 13조 1,371억 / 부채 BEL, CSM, RA : 재보, 보험료배분접근법 적용 제외 기준, 보험순부채 기준
C29: * 삼성생명, 삼성화재 : 삼성전자 등 지분증권 영향으로 기타포괄손익 전기대비 증가 (삼성생명 : 전자 영향 24조(세후) 제외시 기타포괄손익 약 1조 증가, 삼성화재 : 전자 영향 5.8조 추정(세전))
C31: 2. 자본 세부
T32: (단위 : 억원)
C33: 구분 | I33: 미래에셋생명 | J33: 삼성생명 | K33: 교보생명 | L33: 한화생명 | M33: 신한라이프 | N33: 동양생명 | O33: KB라이프 | P33: 삼성화재 | Q33: 현대해상 | R33: 메리츠화재 | S33: KB손보 | T33: DB손보
C34: 이익잉여금 | I34: =[1]작업!I63 -> 20678.245 | J34: =[1]작업!J63 -> 150629.44 | K34: =[1]작업!K63 -> 75757.824 | L34: =[1]작업!L63 -> 70853.36 | M34: =[1]작업!M63 -> 69683.97 | N34: =[1]작업!N63 -> 16044.17 | O34: =[1]작업!O63 -> 31590.18 | P34: =[1]작업!P63 -> 140898.61 | ... T34: =[1]작업!T63 -> 112011.39
C35: 해약환급금준비금 | I35: =[1]작업!I64 -> 12199.682 | L35: =[1]작업!L64 -> 65077.896 | M35: =[1]작업!M64 -> 49183.55 | N35: =[1]작업!N64 -> 11066.14 | O35: =[1]작업!O64 -> 13611.55 | P35: =[1]작업!P64 -> 41300.7 | Q35: =[1]작업!Q64 -> 39166.146 | R35: =[1]작업!R64 -> 29765.66 | S35: =[1]작업!S64 -> 36462.36 | T35: =[1]작업!T64 -> 45412.874
C36: (이익잉여금 대비 해약환급금 준비금 비율) | I36: =[1]작업!I65 -> 0.58997667 | L36: =[1]작업!L65 -> 0.91848708 | M36: =[1]작업!M65 -> 0.70580867 | N36: =[1]작업!N65 -> 0.68972967 | O36: =[1]작업!O65 -> 0.43087915 | P36: =[1]작업!P65 -> 0.29312353 | Q36: =[1]작업!Q65 -> 0.49249164 | R36: =[1]작업!R65 -> 0.47450639 | S36: =[1]작업!S65 -> 0.52396308 | T36: =[1]작업!T65 -> 0.40543085
C37: (자기자본 대비 해약환급금 준비금 비율) | I37: =[1]작업!I66 -> 0.50070487 | L37: =[1]작업!L66 -> 0.69229425 | M37: =[1]작업!M66 -> 0.7882871 | N37: =[1]작업!N66 -> 0.72140477 | O37: =[1]작업!O66 -> 0.32651097 | P37: =[1]작업!P66 -> 0.20021886 | Q37: =[1]작업!Q66 -> 0.8020118 | R37: =[1]작업!R66 -> 0.52449361 | S37: =[1]작업!S66 -> 0.63776225 | T37: =[1]작업!T66 -> 0.50515466
C38: (보험계약부채 대비 해약환급금 준비금 비율) | I38: =I35/(I14+I15+I18) -> 0.04519121 | L38: =L35/(L14+L15+L18) -> 0.067139035 | M38: =M35/(M14+M15+M18) -> 0.10265506 | N38: =N35/(N14+N15+N18) -> 0.039318206 | O38: =O35/(O14+O15+O18) -> 0.047797778 | P38: =P35/(P14+P15+P18) -> 0.10046184 | Q38: =Q35/(Q14+Q15+Q18) -> 0.13446755 | R38: =R35/(R14+R15+R18) -> 0.13441001 | S38: =S35/(S14+S15+S18) -> 0.16429883 | T38: =T35/(T14+T15+T18) -> 0.17374336
C39: 기타포괄손익 | I39: =[1]작업!I67 -> -4322.4669 | J39: =[1]작업!J67 -> 433581.09 | K39: =[1]작업!K67 -> -23979.81 | L39: =[1]작업!L67 -> -14061.35 | M39: =[1]작업!M67 -> -21282.91 | N39: =[1]작업!N67 -> -12240.13 | O39: =[1]작업!O67 -> 314.67 | P39: =[1]작업!P67 -> 67876.289 | ... T39: =[1]작업!T67 -> -22293
C40: FVOCI평가손익 | I40: =[1]작업!I68 -> -10667.856 | J40: =[1]작업!J68 -> 353864.95 | K40: =[1]작업!K68 -> -54687.86 | L40: =[1]작업!L68 -> -48833.68 | M40: =[1]작업!M68 -> -34536.83 | N40: =[1]작업!N68 -> -17978.56 | O40: =[1]작업!O68 -> -11128.16 | P40: =[1]작업!P68 -> 62437.88 | ... T40: =[1]작업!T68 -> -32018.6
C41: (전기대비) | I41: =[1]작업!I69 -> -6186.4263 | J41: =[1]작업!J69 -> 199872.86 | K41: =[1]작업!K69 -> -23731.72 | L41: =[1]작업!L69 -> -27446.83 | M41: =[1]작업!M69 -> -17779.47 | N41: =[1]작업!N69 -> -8206.31 | O41: =[1]작업!O69 -> -10497.18 | P41: =[1]작업!P69 -> 37212.39 | ... T41: =[1]작업!T69 -> -12076.35
C42: 보험부채순금융손익 | I42: =[1]작업!I71 -> 6300.6274 | J42: =[1]작업!J71 -> 81594.6 | K42: =[1]작업!K71 -> 24147.08 | L42: =[1]작업!L71 -> 32318.18 | M42: =[1]작업!M71 -> 13555.93 | N42: =[1]작업!N71 -> 5711.96 | O42: =[1]작업!O71 -> 11511.21 | P42: =[1]작업!P71 -> 6894.83 | ... T42: =[1]작업!T71 -> 7636.21
C43: (전기대비) | I43: =[1]작업!I72 -> 3709.3574 | J43: =[1]작업!J72 -> 48987.2 | K43: =[1]작업!K72 -> 21802.44 | L43: =[1]작업!L72 -> 26923.13 | M43: =[1]작업!M72 -> 11252.01 | N43: =[1]작업!N72 -> 6941.23 | O43: =[1]작업!O72 -> 7152.46 | P43: =[1]작업!P72 -> 7140.29 | ... T43: =[1]작업!T72 -> 5907.29
C44: 운용자산 | I44: =[1]작업!I74 -> 185410 | J44: =[1]작업!J74 -> 2753258 | K44: =[1]작업!K74 -> 1072542.6 | L44: =[1]작업!L74 -> 1229822 | M44: =[1]작업!M74 -> 511751 | N44: =[1]작업!N74 -> 326955.93 | O44: =[1]작업!O74 -> 0 | P44: =[1]작업!P74 -> 901521.63 | ... T44: =[1]작업!T74 -> 560935.65
...

Sheet 2309
C3: □ 2023년 3분기 동업사 경영지표 현황(메리츠화재 수정공시 반영) | S3: 2024.02.19
C5: 1. 자산 현황
T6: (단위 : 억원)
C7: 구분 | I7: 미래에셋생명 | J7: 삼성생명 | K7: 교보생명 | L7: 한화생명 | M7: 신한라이프 | N7: 동양생명 | O7: KB라이프 | P7: 삼성화재 | Q7: 현대해상 | R7: 메리츠화재 | S7: KB손보 | T7: DB손보
C8: 자산 | I8: 321110.6 | J8: 2614976.6 | K8: 1047988.4 | L8: 1093896.2 | M8: 561464.91 | N8: 308939.11 | O8: 293906.89 | P8: 793478.21 | Q8: 415398.04 | R8: 358121.19 | S8: 352791.42 | T8: 445600.31
C9: FVPL | I9: 160083.01 | J9: 357891.44 | K9: 308165.16 | L9: 273744.48 | M9: 115452.58 | N9: 59042.454 | O9: 79716.8 | P9: 105911.39 | Q9: 87396.43 | R9: 73819.84 | S9: 93301.91 | T9: 104012.01
C10: (비중) | I10: 0.49852921 | J10: 0.1368622 | K10: 0.29405398 | L10: 0.25024722 | M10: 0.20562742 | N10: 0.19111357 | O10: 0.27123148 | P10: 0.13347738 | Q10: 0.21039201 | R10: 0.20613089 | S10: 0.26446763 | T10: 0.23341997
C11: FVOCI | I11: 110327.22 | J11: 1523490.8 | K11: 459395.99 | L11: 357619.82 | M11: 329341.32 | N11: 169083.56 | O11: 179334.07 | P11: 351672.47 | Q11: 178954.76 | R11: 244173.18 | S11: 161889.05 | T11: 180715.06
C12: AC | I12: 42227.439 | J12: 499554.55 | K12: 215462.5 | L12: 298387.82 | M12: 90919.09 | N12: 70614.245 | O12: 18750.22 | P12: 292416.2 | Q12: 110481.67 | R12: 11822.191 | S12: 61680.19 | T12: 108505.79
C13: 부채 | I13: 291407.84 | J13: 2234584.8 | K13: 943395.53 | L13: 968620.02 | M13: 474500.48 | N13: 276237.22 | O13: 236253.33 | P13: 647263.51 | Q13: 348741.63 | R13: 305450.17 | S13: 291862.96 | T13: 360987.85
C14: BEL | I14: 217069.01 | J14: 1601576.5 | K14: 721055.68 | L14: 710209.3 | M14: 331951.96 | N14: 212771.12 | O14: 175880.24 | P14: 280559.18 | Q14: 142348.21 | R14: 54554.49 | S14: 78378.06 | T14: 68541.67
C15: CSM | I15: 19439.84 | J15: 116519.94 | K15: 63948.39 | L15: 97991.15 | M15: 72029.59 | N15: 25748.3 | O15: 32139.54 | P15: 132593.41 | Q15: 89036.626 | R15: 102857.92 | S15: 91843.19 | T15: 115694.16
C16: (비중) | I16: 0.066710079 | J16: 0.052143889 | K16: 0.067785344 | L16: 0.10116573 | M16: 0.15180088 | N16: 0.093210829 | O16: 0.13603846 | P16: 0.20485229 | Q16: 0.25530828 | R16: 0.33674206 | S16: 0.31467916 | T16: 0.32049323
C17: RA | I17: 3951 | J17: 31505.09 | K17: 12229.51 | L17: 16501.44 | M17: 11426.02 | N17: 4524.79 | O17: 4563.5 | P17: 14685.45 | Q17: 17108.185 | R17: 18488.77 | S17: 11274.2 | T17: 15492.69
C18: 자기자본 | I18: 29702.76 | J18: 380391.82 | K18: 104592.89 | L18: 125276.16 | M18: 86964.43 | N18: 32701.888 | O18: 57653.56 | P18: 146214.69 | Q18: 66656.415 | R18: 52671.015 | S18: 60928.46 | T18: 84612.461
C19: 이익잉여금 | I19: 17474.676 | J19: 129211.15 | K19: 63900.322 | L19: 62389.554 | M19: 65811.03 | N19: 12833.324 | O19: 57653.56 | P19: 118642.32 | Q19: 64848.325 | R19: 42792.261 | S19: 55711.75 | T19: 83284.896
C20: 기타포괄 | I20: 4218.8457 | J20: 271223.05 | K20: 21907.943 | L20: 20853.84 | M20: 4161.31 | N20: 4324.8239 | O20: 16727.07 | P20: 32750.341 | Q20: 923.55707 | R20: 5427.4459 | S20: 1399.67 | T20: 2119.3569
C21: * 당사 특별계정자산 : 실적배당형퇴직연금 1,711억, 변액보험 116,018억 / 부채 BEL, CSM, RA : 재보, 보험료배분접근법 적용 제외 기준, 보험부채 기준
C23: [참고] 당사 FVPL 자산 현황
R24: (단위 : 억원)
C25: 구분 | I25: 일반계정 (신개인/자산연계 포함) | K25: 변액보험 | M25: 퇴직보험/ 퇴직연금(원리금보장) | O25: 퇴직연금 (실적배당형) | Q25: 합계
C27: FVPL | I27: 37902.564 | K27: 110246.01 | M27: 9896.9649 | O27: 1619.1823 | Q27: 159664.72
D28: 주식/출자금 | I28: 2374.2521 | K28: 2171.8153 | M28: 100.86712 | O28: 0 | Q28: 4646.9345
D29: (비중) | I29: 0.062640935 | K29: 0.019699717 | M29: 0.010191722 | O29: 0 | Q29: 0.029104328
D30: 해외주식 | I30: 20.074932 | K30: 21961.149 | M30: 0 | O30: 439.47111 | Q30: 22420.695
D31: (비중) | I31: 0.00052964576 | K31: 0.1992013 | M31: 0 | O31: 0.27141546 | Q31: 0.1404236
D32: 국내채권 | I32: 583.43622 | K32: 0 | M32: 165.35053 | O32: 0 | Q32: 748.78675
D33: (비중) | I33: 0.015393054 | K33: 0 | M33: 0.016707196 | O33: 0 | Q33: 0.0046897444
D34: 해외채권 | I34: 0 | K34: 0 | M34: 704.26409 | O34: 0 | Q34: 704.26409
D35: (비중) | I35: 0 | K35: 0 | M35: 0.071159603 | O35: 0 | Q35: 0.0044108935
D36: 수익증권 | I36: 34394.897 | K36: 54697.31 | M36: 8926.4831 | O36: 754.55833 | Q36: 98773.248
D37: (비중) | I37: 0.90745566 | K37: 0.49613867 | M37: 0.90194148 | O37: 0.46601197 | Q37: 0.61862912
D38: 외화수익증권 | I38: 0 | K38: 31415.723 | M38: 0 | O38: 425.15284 | Q38: 31840.876
D39: (비중) | I39: 0 | K39: 0.28496017 | M39: 0 | O39: 0.26257256 | Q39: 0.19942336
... D41: (비중) | I41: 0.013980705 | K41: 1.4546558e-07 | M41: 0 | O41: 0 | Q41: 0.0033189586
C42: * 감독회계 기준
C43: * 공시기준 FVPL자산 16조 83억(파생상품자산, 기타예금 분류 차이)
C45: 2. 재무건전성(정정공시 반영)
T46: (단위 : 억원)
C47: 구분 | I47: 미래에셋생명 | J47: 삼성생명 | K47: 교보생명 | L47: 한화생명 | M47: 신한라이프 | N47: 동양생명 | O47: KB라이프 | P47: 삼성화재 | Q47: 현대해상 | R47: 메리츠화재 | S47: KB손보 | T47: DB손보
...

Sheet 전분기대비
C3: □ 전기대비 | S3: 2024.04.03
C5: 1. 자산 현황
T6: (단위 : 억원)
C7: 구분 | I7: 미래에셋생명 | J7: 삼성생명 | K7: 교보생명 | L7: 한화생명 | M7: 신한라이프 | N7: 동양생명 | O7: KB라이프 | P7: 삼성화재 | Q7: 현대해상 | R7: 메리츠화재 | S7: KB손보 | T7: DB손보
C8: 자산 | I8: ='2512'!I8-'2309'!I8 -> 7441.222 | J8: ='2512'!J8-'2309'!J8 -> 484506.36 | K8: ='2512'!K8-'2309'!K8 -> 233669.53 | L8: ='2512'!L8-'2309'!L8 -> 163869.64 | M8: ='2512'!M8-'2309'!M8 -> 33015.41 | N8: ='2512'!N8-'2309'!N8 -> 44213.475 | O8: ='2512'!O8-'2309'!O8 -> 58382.45 | P8: ='2512'!P8-'2309'!P8 -> 144612.24 | ... T8: ='2512'!T8-'2309'!T8 -> 148487.97
C9: FVPL | I9: ='2512'!I9-'2309'!I9 -> 9361.4559 | J9: ='2512'!J9-'2309'!J9 -> 24204.91 | K9: ='2512'!K9-'2309'!K9 -> 33663.063 | L9: ='2512'!L9-'2309'!L9 -> 49456.759 | M9: ='2512'!M9-'2309'!M9 -> 17200.18 | N9: ='2512'!N9-'2309'!N9 -> -5291.414 | O9: ='2512'!O9-'2309'!O9 -> 12709.57 | P9: ='2512'!P9-'2309'!P9 -> 21146.376 | ... T9: ='2512'!T9-'2309'!T9 -> 73212.65
C10: (비중) | I10: ='2512'!I10-'2309'!I10 -> 0.017202125 | J10: ='2512'!J10-'2309'!J10 -> -0.013584748 | K10: ='2512'!K10-'2309'!K10 -> -0.027346136 | L10: ='2512'!L10-'2309'!L10 -> 0.0067173377 | M10: ='2512'!M10-'2309'!M10 -> 0.01751329 | N10: ='2512'!N10-'2309'!N10 -> -0.038910119 | O10: ='2512'!O10-'2309'!O10 -> -0.008872219 | P10: ='2512'!P10-'2309'!P10 -> 0.0019656041 | ... T10: ='2512'!T10-'2309'!T10 -> 0.064893708
C11: FVOCI | I11: ='2512'!I11-'2309'!I11 -> 6308.3534 | J11: ='2512'!J11-'2309'!J11 -> 445397.56 | K11: ='2512'!K11-'2309'!K11 -> 148902.89 | L11: ='2512'!L11-'2309'!L11 -> 124561.51 | M11: ='2512'!M11-'2309'!M11 -> 23543.26 | N11: ='2512'!N11-'2309'!N11 -> 59294.789 | O11: ='2512'!O11-'2309'!O11 -> 42197.5 | P11: ='2512'!P11-'2309'!P11 -> 82634.346 | ... T11: ='2512'!T11-'2309'!T11 -> 20499.319
C12: AC | I12: ='2512'!I12-'2309'!I12 -> -14212.935 | J12: ='2512'!J12-'2309'!J12 -> -88398.29 | K12: ='2512'!K12-'2309'!K12 -> 2.238762 | L12: ='2512'!L12-'2309'!L12 -> -17673.623 | M12: ='2512'!M12-'2309'!M12 -> -51415.65 | N12: ='2512'!N12-'2309'!N12 -> -14388.215 | O12: ='2512'!O12-'2309'!O12 -> -1791.37 | P12: ='2512'!P12-'2309'!P12 -> 8441.2315 | ... T12: ='2512'!T12-'2309'!T12 -> 49127.935
C13: 부채 | I13: ='2512'!I13-'2309'!I13 -> 12778.966 | J13: ='2512'!J13-'2309'!J13 -> 300730.03 | K13: ='2512'!K13-'2309'!K13 -> 261714.82 | L13: ='2512'!L13-'2309'!L13 -> 164458.04 | M13: ='2512'!M13-'2309'!M13 -> 57586.9 | N13: ='2512'!N13-'2309'!N13 -> 61575.653 | O13: ='2512'!O13-'2309'!O13 -> 73850.13 | P13: ='2512'!P13-'2309'!P13 -> 84549.159 | ... T13: ='2512'!T13-'2309'!T13 -> 134551.42
C14: BEL | I14: ='2512'!I14-'2309'!I14 -> 28243.276 | J14: ='2512'!J14-'2309'!J14 -> 243056.09 | K14: ='2512'!K14-'2309'!K14 -> 168344 | L14: ='2512'!L14-'2309'!L14 -> 152015.59 | M14: ='2512'!M14-'2309'!M14 -> 57649.56 | N14: ='2512'!N14-'2309'!N14 -> 39341.58 | O14: ='2512'!O14-'2309'!O14 -> 70752.74 | P14: ='2512'!P14-'2309'!P14 -> -30084.39 | ... T14: ='2512'!T14-'2309'!T14 -> 52416.42
C15: CSM | I15: ='2512'!I15-'2309'!I15 -> 1144.3912 | J15: ='2512'!J15-'2309'!J15 -> 15658.8 | K15: ='2512'!K15-'2309'!K15 -> 1161.22 | L15: ='2512'!L15-'2309'!L15 -> -10854.63 | M15: ='2512'!M15-'2309'!M15 -> 3507.75 | N15: ='2512'!N15-'2309'!N15 -> -1177.35 | O15: ='2512'!O15-'2309'!O15 -> 498.21 | P15: ='2512'!P15-'2309'!P15 -> 9083.23 | ... T15: ='2512'!T15-'2309'!T15 -> 6359.27
C16: (비중) | I16: ='2512'!I17-'2309'!I16 -> 0.00095962533 | J16: ='2512'!J17-'2309'!J16 -> -8.8483472e-06 | K16: ='2512'!K17-'2309'!K16 -> -0.01375742 | L16: ='2512'!L17-'2309'!L16 -> -0.024263242 | M16: ='2512'!M17-'2309'!M16 -> -0.0098367152 | N16: ='2512'!N17-'2309'!N16 -> -0.020475442 | O16: ='2512'!O17-'2309'!O16 -> -0.030790525 | P16: ='2512'!P17-'2309'!P16 -> -0.011255419 | ... T16: ='2512'!T17-'2309'!T16 -> -0.074188975
C17: RA | I17: ='2512'!I18-'2309'!I17 -> 109.44501 | J17: ='2512'!J18-'2309'!J17 -> 147 | K17: ='2512'!K18-'2309'!K17 -> 1588.78 | L17: ='2512'!L18-'2309'!L17 -> 3437.59 | M17: ='2512'!M18-'2309'!M17 -> 2549.83 | N17: ='2512'!N18-'2309'!N17 -> 242.35 | O17: ='2512'!O18-'2309'!O17 -> 939.47 | P17: ='2512'!P18-'2309'!P17 -> 4271.46 | ... T17: ='2512'!T18-'2309'!T17 -> 2874.84
C18: 자기자본 | I18: ='2512'!I19-'2309'!I18 -> -5337.7441 | J18: ='2512'!J19-'2309'!J18 -> 183776.33 | K18: ='2512'!K19-'2309'!K18 -> -50102.556 | L18: ='2512'!L19-'2309'!L18 -> -31272.933 | M18: ='2512'!M19-'2309'!M18 -> -24571.49 | N18: ='2512'!N19-'2309'!N18 -> -17362.178 | O18: ='2512'!O19-'2309'!O18 -> -15965.68 | P18: ='2512'!P19-'2309'!P18 -> 60063.078 | ... T18: ='2512'!T19-'2309'!T18 -> 5286.4888
C19: 이익잉여금 | I19: ='2512'!I22-'2309'!I19 -> 3203.5686 | J19: ='2512'!J22-'2309'!J19 -> 21418.29 | K19: ='2512'!K22-'2309'!K19 -> 11857.503 | L19: ='2512'!L22-'2309'!L19 -> 8463.8062 | M19: ='2512'!M22-'2309'!M19 -> 3872.94 | N19: ='2512'!N22-'2309'!N19 -> 3210.8457 | O19: ='2512'!O22-'2309'!O19 -> -26063.38 | P19: ='2512'!P22-'2309'!P19 -> 22256.292 | ... T19: ='2512'!T22-'2309'!T19 -> 28726.494
C20: 기타포괄 | I20: ='2512'!I24-'2309'!I20 -> -8541.3126 | J20: ='2512'!J24-'2309'!J20 -> 162358.04 | K20: ='2512'!K24-'2309'!K20 -> -45887.754 | L20: ='2512'!L24-'2309'!L20 -> -34915.19 | M20: ='2512'!M24-'2309'!M20 -> -25444.22 | N20: ='2512'!N24-'2309'!N20 -> -16564.954 | O20: ='2512'!O24-'2309'!O20 -> -16412.4 | P20: ='2512'!P24-'2309'!P20 -> 35125.948 | ... T20: ='2512'!T24-'2309'!T20 -> -24412.357
C23: [참고] 당사 FVPL 자산 현황
R24: (단위 : 억원)
C25: 구분 | I25: 일반계정 (신개인/자산연계 포함) | K25: 변액보험 | M25: 퇴직보험/ 퇴직연금(원리금보장) | O25: 퇴직연금 (실적배당형) | Q25: 합계
C27: FVPL
D28: 주식/출자금
D29: (비중)
D30: 해외주식
D31: (비중)
D32: 국내채권
D33: (비중)
D34: 해외채권
D35: (비중)
D36: 수익증권
D37: (비중)
D38: 외화수익증권
D39: (비중)
... D41: (비중)
C42: * 감독회계 기준
C45: 2. 재무건전성(잠정치)
T46: (단위 : 억원)
C47: 구분 | I47: 미래에셋생명 | J47: 삼성생명 | K47: 교보생명 | L47: 한화생명 | M47: 신한라이프 | N47: 동양생명 | O47: KB라이프 | P47: 삼성화재 | Q47: 현대해상 | R47: 메리츠화재 | S47: KB손보 | T47: DB손보
C48: K-ICS | I48: ='2512'!I51-'2309'!I48 -> -0.277 | L48: ='2512'!L51-'2309'!L48 -> -0.268 | M48: ='2512'!M51-'2309'!M48 -> -0.034 | N48: ='2512'!N51-'2309'!N48 -> -0.039 | O48: ='2512'!O51-'2309'!O48 -> -0.0477 | P48: ='2512'!P51-'2309'!P48 -> -0.0039 | Q48: ='2512'!Q51-'2309'!Q48 -> 0.18 | R48: ='2512'!R51-'2309'!R48 -> 0.105 | S48: ='2512'!S51-'2309'!S48 -> -0.0248 | T48: ='2512'!T51-'2309'!T48 -> 0.037
C49: 가용자본 | I49: ='2512'!I52-'2309'!I49 -> -3838.64 | L49: ='2512'!L52-'2309'!L49 -> 9075.48 | M49: ='2512'!M52-'2309'!M49 -> -13990 | N49: ='2512'!N52-'2309'!N49 -> -3866.99 | O49: ='2512'!O52-'2309'!O49 -> -12618.58 | P49: ='2512'!P52-'2309'!P49 -> 65993 | Q49: ='2512'!Q52-'2309'!Q49 -> 12867.56 | R49: ='2512'!R52-'2309'!R49 -> 1282.08 | S49: ='2512'!S52-'2309'!S49 -> 4124.16 | T49: ='2512'!T52-'2309'!T49 -> 22914.84
...
