Workbook

Sheet 작업
C1: 기준월 | I1: 2512 | J1: =ROUNDUP(RIGHT(I1,2)/3,0)
C4: 1. 자산 구성현황
O7: (단위 : 억원)
C8: 구분 | I8: 미래 | J8: 삼성 | K8: 교보 | L8: 한화 | M8: 신한라이프 | N8: 동양 | O8: KB라이프 | P8: 삼성화재 | Q8: 현대해상 | R8: 메리츠화재 | S8: KB손보 | T8: DB손보
A9: =DATA!D$1 | C9: 자산 | I9: =VLOOKUP($I$1&I$8,DATA!$A:$EB,작업!$A9,0)/100 | J9: =VLOOKUP($I$1&J$8,DATA!$A:$EB,작업!$A9,0)/100 | K9: =VLOOKUP($I$1&K$8,DATA!$A:$EB,작업!$A9,0)/100 | L9: =VLOOKUP($I$1&L$8,DATA!$A:$EB,작업!$A9,0)/100 | M9: =VLOOKUP($I$1&M$8,DATA!$A:$EB,작업!$A9,0)/100 | N9: =VLOOKUP($I$1&N$8,DATA!$A:$EB,작업!$A9,0)/100 | O9: =VLOOKUP($I$1&O$8,DATA!$A:$EB,작업!$A9,0)/100 | P9: =VLOOKUP($I$1&P$8,DATA!$A:$EB,작업!$A9,0)/100 | ... T9: =VLOOKUP($I$1&T$8,DATA!$A:$EB,작업!$A9,0)/100
A10: =DATA!E1 | C10: FVPL | I10: =VLOOKUP($I$1&I$8,DATA!$A:$EB,작업!$A10,0)/100 | J10: =VLOOKUP($I$1&J$8,DATA!$A:$EB,작업!$A10,0)/100 | K10: =VLOOKUP($I$1&K$8,DATA!$A:$EB,작업!$A10,0)/100 | L10: =VLOOKUP($I$1&L$8,DATA!$A:$EB,작업!$A10,0)/100 | M10: =VLOOKUP($I$1&M$8,DATA!$A:$EB,작업!$A10,0)/100 | N10: =VLOOKUP($I$1&N$8,DATA!$A:$EB,작업!$A10,0)/100 | O10: =VLOOKUP($I$1&O$8,DATA!$A:$EB,작업!$A10,0)/100 | P10: =VLOOKUP($I$1&P$8,DATA!$A:$EB,작업!$A10,0)/100 | ... T10: =VLOOKUP($I$1&T$8,DATA!$A:$EB,작업!$A10,0)/100
C11: (비중) | I11: =I10/I9 | J11: =J10/J9 | K11: =K10/K9 | L11: =L10/L9 | M11: =M10/M9 | N11: =N10/N9 | O11: =O10/O9 | P11: =P10/P9 | ... T11: =T10/T9
A12: =DATA!F1 | C12: FVOCI | I12: =VLOOKUP($I$1&I$8,DATA!$A:$EB,작업!$A12,0)/100 | J12: =VLOOKUP($I$1&J$8,DATA!$A:$EB,작업!$A12,0)/100 | K12: =VLOOKUP($I$1&K$8,DATA!$A:$EB,작업!$A12,0)/100 | L12: =VLOOKUP($I$1&L$8,DATA!$A:$EB,작업!$A12,0)/100 | M12: =VLOOKUP($I$1&M$8,DATA!$A:$EB,작업!$A12,0)/100 | N12: =VLOOKUP($I$1&N$8,DATA!$A:$EB,작업!$A12,0)/100 | O12: =VLOOKUP($I$1&O$8,DATA!$A:$EB,작업!$A12,0)/100 | P12: =VLOOKUP($I$1&P$8,DATA!$A:$EB,작업!$A12,0)/100 | ... T12: =VLOOKUP($I$1&T$8,DATA!$A:$EB,작업!$A12,0)/100
A13: =DATA!G1 | C13: AC | I13: =VLOOKUP($I$1&I$8,DATA!$A:$EB,작업!$A13,0)/100 | J13: =VLOOKUP($I$1&J$8,DATA!$A:$EB,작업!$A13,0)/100 | K13: =VLOOKUP($I$1&K$8,DATA!$A:$EB,작업!$A13,0)/100 | L13: =VLOOKUP($I$1&L$8,DATA!$A:$EB,작업!$A13,0)/100 | M13: =VLOOKUP($I$1&M$8,DATA!$A:$EB,작업!$A13,0)/100 | N13: =VLOOKUP($I$1&N$8,DATA!$A:$EB,작업!$A13,0)/100 | O13: =VLOOKUP($I$1&O$8,DATA!$A:$EB,작업!$A13,0)/100 | P13: =VLOOKUP($I$1&P$8,DATA!$A:$EB,작업!$A13,0)/100 | ... T13: =VLOOKUP($I$1&T$8,DATA!$A:$EB,작업!$A13,0)/100
A14: =DATA!L1 | C14: 부채 | I14: =VLOOKUP($I$1&I$8,DATA!$A:$EB,작업!$A14,0)/100 | J14: =VLOOKUP($I$1&J$8,DATA!$A:$EB,작업!$A14,0)/100 | K14: =VLOOKUP($I$1&K$8,DATA!$A:$EB,작업!$A14,0)/100 | L14: =VLOOKUP($I$1&L$8,DATA!$A:$EB,작업!$A14,0)/100 | M14: =VLOOKUP($I$1&M$8,DATA!$A:$EB,작업!$A14,0)/100 | N14: =VLOOKUP($I$1&N$8,DATA!$A:$EB,작업!$A14,0)/100 | O14: =VLOOKUP($I$1&O$8,DATA!$A:$EB,작업!$A14,0)/100 | P14: =VLOOKUP($I$1&P$8,DATA!$A:$EB,작업!$A14,0)/100 | ... T14: =VLOOKUP($I$1&T$8,DATA!$A:$EB,작업!$A14,0)/100
A15: =DATA!BU1 | C15: BEL | I15: =VLOOKUP($I$1&I$8,DATA!$A:$EB,작업!$A15,0)/100 | J15: =VLOOKUP($I$1&J$8,DATA!$A:$EB,작업!$A15,0)/100 | K15: =VLOOKUP($I$1&K$8,DATA!$A:$EB,작업!$A15,0)/100 | L15: =VLOOKUP($I$1&L$8,DATA!$A:$EB,작업!$A15,0)/100 | M15: =VLOOKUP($I$1&M$8,DATA!$A:$EB,작업!$A15,0)/100 | N15: =VLOOKUP($I$1&N$8,DATA!$A:$EB,작업!$A15,0)/100 | O15: =VLOOKUP($I$1&O$8,DATA!$A:$EB,작업!$A15,0)/100 | P15: =VLOOKUP($I$1&P$8,DATA!$A:$EB,작업!$A15,0)/100 | ... T15: =VLOOKUP($I$1&T$8,DATA!$A:$EB,작업!$A15,0)/100
A16: =DATA!BW1 | C16: CSM | I16: =VLOOKUP($I$1&I$8,DATA!$A:$EB,작업!$A16,0)/100 | J16: =VLOOKUP($I$1&J$8,DATA!$A:$EB,작업!$A16,0)/100 | K16: =VLOOKUP($I$1&K$8,DATA!$A:$EB,작업!$A16,0)/100 | L16: =VLOOKUP($I$1&L$8,DATA!$A:$EB,작업!$A16,0)/100 | M16: =VLOOKUP($I$1&M$8,DATA!$A:$EB,작업!$A16,0)/100 | N16: =VLOOKUP($I$1&N$8,DATA!$A:$EB,작업!$A16,0)/100 | O16: =VLOOKUP($I$1&O$8,DATA!$A:$EB,작업!$A16,0)/100 | P16: =VLOOKUP($I$1&P$8,DATA!$A:$EB,작업!$A16,0)/100 | ... T16: =VLOOKUP($I$1&T$8,DATA!$A:$EB,작업!$A16,0)/100
C17: (비중) | I17: =I16/I14 | J17: =J16/J14 | K17: =K16/K14 | L17: =L16/L14 | M17: =M16/M14 | N17: =N16/N14 | O17: =O16/O14 | P17: =P16/P14 | ... T17: =T16/T14
A18: =DATA!BV1 | C18: RA | I18: =VLOOKUP($I$1&I$8,DATA!$A:$EB,작업!$A18,0)/100 | J18: =VLOOKUP($I$1&J$8,DATA!$A:$EB,작업!$A18,0)/100 | K18: =VLOOKUP($I$1&K$8,DATA!$A:$EB,작업!$A18,0)/100 | L18: =VLOOKUP($I$1&L$8,DATA!$A:$EB,작업!$A18,0)/100 | M18: =VLOOKUP($I$1&M$8,DATA!$A:$EB,작업!$A18,0)/100 | N18: =VLOOKUP($I$1&N$8,DATA!$A:$EB,작업!$A18,0)/100 | O18: =VLOOKUP($I$1&O$8,DATA!$A:$EB,작업!$A18,0)/100 | P18: =VLOOKUP($I$1&P$8,DATA!$A:$EB,작업!$A18,0)/100 | ... T18: =VLOOKUP($I$1&T$8,DATA!$A:$EB,작업!$A18,0)/100
A19: =DATA!N1 | C19: 자기자본_신종자본증권제외 | I19: =VLOOKUP($I$1&I$8,DATA!$A:$EB,작업!$A19,0)/100 | J19: =VLOOKUP($I$1&J$8,DATA!$A:$EB,작업!$A19,0)/100 | K19: =VLOOKUP($I$1&K$8,DATA!$A:$EB,작업!$A19,0)/100 | L19: =VLOOKUP($I$1&L$8,DATA!$A:$EB,작업!$A19,0)/100 | M19: =VLOOKUP($I$1&M$8,DATA!$A:$EB,작업!$A19,0)/100 | N19: =VLOOKUP($I$1&N$8,DATA!$A:$EB,작업!$A19,0)/100 | O19: =VLOOKUP($I$1&O$8,DATA!$A:$EB,작업!$A19,0)/100 | P19: =VLOOKUP($I$1&P$8,DATA!$A:$EB,작업!$A19,0)/100 | ... T19: =VLOOKUP($I$1&T$8,DATA!$A:$EB,작업!$A19,0)/100
C20: (전기자본 대비) | I20: =+I37 | J20: =+J37 | K20: =+K37 | L20: =+L37 | M20: =+M37 | N20: =+N37 | O20: =+O37 | P20: =+P37 | ... T20: =+T37
C21: (자본증감율) | I21: =+I20/(I19-I20) | J21: =+J20/(J19-J20) | K21: =+K20/(K19-K20) | L21: =+L20/(L19-L20) | M21: =+M20/(M19-M20) | N21: =+N20/(N19-N20) | O21: =+O20/(O19-O20) | P21: =+P20/(P19-P20) | ... T21: =+T20/(T19-T20)
A22: =DATA!R1 | C22: 이익잉여금 | I22: =VLOOKUP($I$1&I$8,DATA!$A:$EB,작업!$A22,0)/100 | J22: =VLOOKUP($I$1&J$8,DATA!$A:$EB,작업!$A22,0)/100 | K22: =VLOOKUP($I$1&K$8,DATA!$A:$EB,작업!$A22,0)/100 | L22: =VLOOKUP($I$1&L$8,DATA!$A:$EB,작업!$A22,0)/100 | M22: =VLOOKUP($I$1&M$8,DATA!$A:$EB,작업!$A22,0)/100 | N22: =VLOOKUP($I$1&N$8,DATA!$A:$EB,작업!$A22,0)/100 | O22: =VLOOKUP($I$1&O$8,DATA!$A:$EB,작업!$A22,0)/100 | P22: =VLOOKUP($I$1&P$8,DATA!$A:$EB,작업!$A22,0)/100 | ... T22: =VLOOKUP($I$1&T$8,DATA!$A:$EB,작업!$A22,0)/100
A23: =DATA!Q1 | C23: 기타포괄 | I23: =VLOOKUP($I$1&I$8,DATA!$A:$EB,작업!$A23,0)/100 | J23: =VLOOKUP($I$1&J$8,DATA!$A:$EB,작업!$A23,0)/100 | K23: =VLOOKUP($I$1&K$8,DATA!$A:$EB,작업!$A23,0)/100 | L23: =VLOOKUP($I$1&L$8,DATA!$A:$EB,작업!$A23,0)/100 | M23: =VLOOKUP($I$1&M$8,DATA!$A:$EB,작업!$A23,0)/100 | N23: =VLOOKUP($I$1&N$8,DATA!$A:$EB,작업!$A23,0)/100 | O23: =VLOOKUP($I$1&O$8,DATA!$A:$EB,작업!$A23,0)/100 | P23: =VLOOKUP($I$1&P$8,DATA!$A:$EB,작업!$A23,0)/100 | ... T23: =VLOOKUP($I$1&T$8,DATA!$A:$EB,작업!$A23,0)/100
C24: (기타포괄손익 증감) | I24: =I23-I38 | J24: =J23-J38 | K24: =K23-K38 | L24: =L23-L38 | M24: =M23-M38 | N24: =N23-N38 | O24: =O23-O38 | P24: =P23-P38 | ... T24: =T23-T38
C25: (자기자본 대비 기타포괄손익 증감율) | I25: =I24/I36 | J25: =J24/J36 | K25: =K24/K36 | L25: =L24/L36 | M25: =M24/M36 | N25: =N24/N36 | O25: =O24/O36 | P25: =P24/P36 | ... T25: =T24/T36
C26: (보험계약부채대비 기타포괄손익 증감율) | I26: =I24/I45 | J26: =J24/J45 | K26: =K24/K45 | L26: =L24/L45 | M26: =M24/M45 | N26: =N24/N45 | O26: =O24/O45 | P26: =P24/P45 | ... T26: =T24/T45
A29: =DATA!O1 | C29: 자기자본 | I29: =VLOOKUP($I$1&I$8,DATA!$A:$EB,작업!$A29,0)/100 | J29: =VLOOKUP($I$1&J$8,DATA!$A:$EB,작업!$A29,0)/100 | K29: =VLOOKUP($I$1&K$8,DATA!$A:$EB,작업!$A29,0)/100 | L29: =VLOOKUP($I$1&L$8,DATA!$A:$EB,작업!$A29,0)/100 | M29: =VLOOKUP($I$1&M$8,DATA!$A:$EB,작업!$A29,0)/100 | N29: =VLOOKUP($I$1&N$8,DATA!$A:$EB,작업!$A29,0)/100 | O29: =VLOOKUP($I$1&O$8,DATA!$A:$EB,작업!$A29,0)/100 | P29: =VLOOKUP($I$1&P$8,DATA!$A:$EB,작업!$A29,0)/100 | ... T29: =VLOOKUP($I$1&T$8,DATA!$A:$EB,작업!$A29,0)/100
C33: - 금융자산비중 | I33: =+I22/I9 | J33: =+J22/J9 | K33: =+K22/K9 | L33: =+L22/L9 | M33: =+M22/M9 | N33: =+N22/N9 | O33: =+O22/O9 | P33: =+P22/P9 | ... T33: =+T22/T9
A36: =DATA!T1 | C36: * 전기자기자본 | I36: =VLOOKUP($I$1&I$8,DATA!$A:$EB,작업!$A36,0)/100 | J36: =VLOOKUP($I$1&J$8,DATA!$A:$EB,작업!$A36,0)/100 | K36: =VLOOKUP($I$1&K$8,DATA!$A:$EB,작업!$A36,0)/100 | L36: =VLOOKUP($I$1&L$8,DATA!$A:$EB,작업!$A36,0)/100 | M36: =VLOOKUP($I$1&M$8,DATA!$A:$EB,작업!$A36,0)/100 | N36: =VLOOKUP($I$1&N$8,DATA!$A:$EB,작업!$A36,0)/100 | O36: =VLOOKUP($I$1&O$8,DATA!$A:$EB,작업!$A36,0)/100 | P36: =VLOOKUP($I$1&P$8,DATA!$A:$EB,작업!$A36,0)/100 | ... T36: =VLOOKUP($I$1&T$8,DATA!$A:$EB,작업!$A36,0)/100 | X36: =58000*(1-25%)/P36
C37: - 전기대비 증감 | I37: =I19-I36 | J37: =J19-J36 | K37: =K19-K36 | L37: =L19-L36 | M37: =M19-M36 | N37: =N19-N36 | O37: =O19-O36 | P37: =P19-P36 | ... T37: =T19-T36
A38: =DATA!BC1 | C38: * 전기기타포괄 | I38: =VLOOKUP($I$1&I$8,DATA!$A:$EB,작업!$A38,0)/100 | J38: =VLOOKUP($I$1&J$8,DATA!$A:$EB,작업!$A38,0)/100 | K38: =VLOOKUP($I$1&K$8,DATA!$A:$EB,작업!$A38,0)/100 | L38: =VLOOKUP($I$1&L$8,DATA!$A:$EB,작업!$A38,0)/100 | M38: =VLOOKUP($I$1&M$8,DATA!$A:$EB,작업!$A38,0)/100 | N38: =VLOOKUP($I$1&N$8,DATA!$A:$EB,작업!$A38,0)/100 | O38: =VLOOKUP($I$1&O$8,DATA!$A:$EB,작업!$A38,0)/100 | P38: =VLOOKUP($I$1&P$8,DATA!$A:$EB,작업!$A38,0)/100 | ... T38: =VLOOKUP($I$1&T$8,DATA!$A:$EB,작업!$A38,0)/100
A39: =DATA!BN1 | C39: 1) 결산배당 | I39: =VLOOKUP($I$1&I$8,DATA!$A:$EB,작업!$A39,0)/100 | J39: =VLOOKUP($I$1&J$8,DATA!$A:$EB,작업!$A39,0)/100 | K39: =VLOOKUP($I$1&K$8,DATA!$A:$EB,작업!$A39,0)/100 | L39: =VLOOKUP($I$1&L$8,DATA!$A:$EB,작업!$A39,0)/100 | M39: =VLOOKUP($I$1&M$8,DATA!$A:$EB,작업!$A39,0)/100 | N39: =VLOOKUP($I$1&N$8,DATA!$A:$EB,작업!$A39,0)/100 | O39: =VLOOKUP($I$1&O$8,DATA!$A:$EB,작업!$A39,0)/100 | P39: =VLOOKUP($I$1&P$8,DATA!$A:$EB,작업!$A39,0)/100 | ... T39: =VLOOKUP($I$1&T$8,DATA!$A:$EB,작업!$A39,0)/100
A40: =DATA!BR1 | C40: 2) 기타배당 | I40: =VLOOKUP($I$1&I$8,DATA!$A:$EB,작업!$A40,0)/100 | J40: =VLOOKUP($I$1&J$8,DATA!$A:$EB,작업!$A40,0)/100 | K40: =VLOOKUP($I$1&K$8,DATA!$A:$EB,작업!$A40,0)/100 | L40: =VLOOKUP($I$1&L$8,DATA!$A:$EB,작업!$A40,0)/100 | M40: =VLOOKUP($I$1&M$8,DATA!$A:$EB,작업!$A40,0)/100 | N40: =VLOOKUP($I$1&N$8,DATA!$A:$EB,작업!$A40,0)/100 | O40: =VLOOKUP($I$1&O$8,DATA!$A:$EB,작업!$A40,0)/100 | P40: =VLOOKUP($I$1&P$8,DATA!$A:$EB,작업!$A40,0)/100 | ... T40: =VLOOKUP($I$1&T$8,DATA!$A:$EB,작업!$A40,0)/100
C41: 배당합계 | I41: =I39+I40 | J41: =J39+J40 | K41: =K39+K40 | L41: =L39+L40 | M41: =M39+M40 | N41: =N39+N40 | O41: =O39+O40 | P41: =P39+P40 | ... T41: =T39+T40
C42: 배당제외 자본증가금액 | I42: =I37-I41 | J42: =J37-J41 | K42: =K37-K41 | L42: =L37-L41 | M42: =M37-M41 | N42: =N37-N41 | O42: =O37-O41 | P42: =P37-P41 | ... T42: =T37-T41
C43: - 배당제외 기준 자본증가율 | I43: =I42/I36 | J43: =J42/J36 | K43: =K42/K36 | L43: =L42/L36 | M43: =M42/M36 | N43: =N42/N36 | O43: =O42/O36 | P43: =P42/P36 | ... T43: =T42/T36
C45: * 전기 BEL+RA+CSM | I45: =전기말!I6 | J45: =전기말!J6 | K45: =전기말!K6 | L45: =전기말!L6 | M45: =전기말!M6 | N45: =전기말!N6 | O45: =전기말!O6 | P45: =전기말!P6 | ... T45: =전기말!T6
A46: =DATA!M1 | C46: 보험계약부채 | I46: =VLOOKUP($I$1&I$8,DATA!$A:$EB,작업!$A46,0)/100 | J46: =VLOOKUP($I$1&J$8,DATA!$A:$EB,작업!$A46,0)/100 | K46: =VLOOKUP($I$1&K$8,DATA!$A:$EB,작업!$A46,0)/100 | L46: =VLOOKUP($I$1&L$8,DATA!$A:$EB,작업!$A46,0)/100 | M46: =VLOOKUP($I$1&M$8,DATA!$A:$EB,작업!$A46,0)/100 | N46: =VLOOKUP($I$1&N$8,DATA!$A:$EB,작업!$A46,0)/100 | O46: =VLOOKUP($I$1&O$8,DATA!$A:$EB,작업!$A46,0)/100 | P46: =VLOOKUP($I$1&P$8,DATA!$A:$EB,작업!$A46,0)/100 | ... T46: =VLOOKUP($I$1&T$8,DATA!$A:$EB,작업!$A46,0)/100
I47: =I23/I46 | J47: =J23/J46 | K47: =K23/K46 | L47: =L23/L46 | M47: =M23/M46 | N47: =N23/N46 | O47: =O23/O46 | P47: =P23/P46 | ... T47: =T23/T46
I48: =I72/I46 | J48: =J72/J46 | K48: =K72/K46 | L48: =L72/L46 | M48: =M72/M46 | N48: =N72/N46 | O48: =O72/O46 | P48: =P72/P46 | ... T48: =T72/T46
C49: *전기보험계약부채
A55: =DATA!BM1 | C55: * 전기말 이익잉여금 | I55: =VLOOKUP($I$1&I$8,DATA!$A:$EB,작업!$A55,0)/100 | J55: =VLOOKUP($I$1&J$8,DATA!$A:$EB,작업!$A55,0)/100 | K55: =VLOOKUP($I$1&K$8,DATA!$A:$EB,작업!$A55,0)/100 | L55: =VLOOKUP($I$1&L$8,DATA!$A:$EB,작업!$A55,0)/100 | M55: =VLOOKUP($I$1&M$8,DATA!$A:$EB,작업!$A55,0)/100 | N55: =VLOOKUP($I$1&N$8,DATA!$A:$EB,작업!$A55,0)/100 | O55: =VLOOKUP($I$1&O$8,DATA!$A:$EB,작업!$A55,0)/100 | P55: =VLOOKUP($I$1&P$8,DATA!$A:$EB,작업!$A55,0)/100 | ... T55: =VLOOKUP($I$1&T$8,DATA!$A:$EB,작업!$A55,0)/100
D56: 전기말 대비 | I56: =+I22-I55 | J56: =+J22-J55 | K56: =+K22-K55 | L56: =+L22-L55 | M56: =+M22-M55 | N56: =+N22-N55 | O56: =+O22-O55 | P56: =+P22-P55 | ... T56: =+T22-T55
C60: 2. 자본 세부
...

Sheet 2412
C1: 기준월 | I1: 2412 | J1: =ROUNDUP(RIGHT(I1,2)/3,0)
C4: 1. 자산 구성현황
O7: (단위 : 억원)
C8: 구분 | I8: 미래 | J8: 삼성 | K8: 교보 | L8: 한화 | M8: 신한라이프 | N8: 동양 | O8: KB라이프 | P8: 삼성화재 | Q8: 현대해상 | R8: 메리츠화재 | S8: KB손보 | T8: DB손보
A9: =DATA!D$1 | C9: 자산 | I9: =VLOOKUP($I$1&I$8,DATA!$A:$EB,'2412'!$A9,0)/100 | J9: =VLOOKUP($I$1&J$8,DATA!$A:$EB,'2412'!$A9,0)/100 | K9: =VLOOKUP($I$1&K$8,DATA!$A:$EB,'2412'!$A9,0)/100 | L9: =VLOOKUP($I$1&L$8,DATA!$A:$EB,'2412'!$A9,0)/100 | M9: =VLOOKUP($I$1&M$8,DATA!$A:$EB,'2412'!$A9,0)/100 | N9: =VLOOKUP($I$1&N$8,DATA!$A:$EB,'2412'!$A9,0)/100 | O9: =VLOOKUP($I$1&O$8,DATA!$A:$EB,'2412'!$A9,0)/100 | P9: =VLOOKUP($I$1&P$8,DATA!$A:$EB,'2412'!$A9,0)/100 | ... T9: =VLOOKUP($I$1&T$8,DATA!$A:$EB,'2412'!$A9,0)/100
A10: =DATA!E1 | C10: FVPL | I10: =VLOOKUP($I$1&I$8,DATA!$A:$EB,'2412'!$A10,0)/100 | J10: =VLOOKUP($I$1&J$8,DATA!$A:$EB,'2412'!$A10,0)/100 | K10: =VLOOKUP($I$1&K$8,DATA!$A:$EB,'2412'!$A10,0)/100 | L10: =VLOOKUP($I$1&L$8,DATA!$A:$EB,'2412'!$A10,0)/100 | M10: =VLOOKUP($I$1&M$8,DATA!$A:$EB,'2412'!$A10,0)/100 | N10: =VLOOKUP($I$1&N$8,DATA!$A:$EB,'2412'!$A10,0)/100 | O10: =VLOOKUP($I$1&O$8,DATA!$A:$EB,'2412'!$A10,0)/100 | P10: =VLOOKUP($I$1&P$8,DATA!$A:$EB,'2412'!$A10,0)/100 | ... T10: =VLOOKUP($I$1&T$8,DATA!$A:$EB,'2412'!$A10,0)/100
C11: (비중) | I11: =I10/I9 | J11: =J10/J9 | K11: =K10/K9 | L11: =L10/L9 | M11: =M10/M9 | N11: =N10/N9 | O11: =O10/O9 | P11: =P10/P9 | ... T11: =T10/T9
A12: =DATA!F1 | C12: FVOCI | I12: =VLOOKUP($I$1&I$8,DATA!$A:$EB,'2412'!$A12,0)/100 | J12: =VLOOKUP($I$1&J$8,DATA!$A:$EB,'2412'!$A12,0)/100 | K12: =VLOOKUP($I$1&K$8,DATA!$A:$EB,'2412'!$A12,0)/100 | L12: =VLOOKUP($I$1&L$8,DATA!$A:$EB,'2412'!$A12,0)/100 | M12: =VLOOKUP($I$1&M$8,DATA!$A:$EB,'2412'!$A12,0)/100 | N12: =VLOOKUP($I$1&N$8,DATA!$A:$EB,'2412'!$A12,0)/100 | O12: =VLOOKUP($I$1&O$8,DATA!$A:$EB,'2412'!$A12,0)/100 | P12: =VLOOKUP($I$1&P$8,DATA!$A:$EB,'2412'!$A12,0)/100 | ... T12: =VLOOKUP($I$1&T$8,DATA!$A:$EB,'2412'!$A12,0)/100
A13: =DATA!G1 | C13: AC | I13: =VLOOKUP($I$1&I$8,DATA!$A:$EB,'2412'!$A13,0)/100 | J13: =VLOOKUP($I$1&J$8,DATA!$A:$EB,'2412'!$A13,0)/100 | K13: =VLOOKUP($I$1&K$8,DATA!$A:$EB,'2412'!$A13,0)/100 | L13: =VLOOKUP($I$1&L$8,DATA!$A:$EB,'2412'!$A13,0)/100 | M13: =VLOOKUP($I$1&M$8,DATA!$A:$EB,'2412'!$A13,0)/100 | N13: =VLOOKUP($I$1&N$8,DATA!$A:$EB,'2412'!$A13,0)/100 | O13: =VLOOKUP($I$1&O$8,DATA!$A:$EB,'2412'!$A13,0)/100 | P13: =VLOOKUP($I$1&P$8,DATA!$A:$EB,'2412'!$A13,0)/100 | ... T13: =VLOOKUP($I$1&T$8,DATA!$A:$EB,'2412'!$A13,0)/100
A14: =DATA!L1 | C14: 부채 | I14: =VLOOKUP($I$1&I$8,DATA!$A:$EB,'2412'!$A14,0)/100 | J14: =VLOOKUP($I$1&J$8,DATA!$A:$EB,'2412'!$A14,0)/100 | K14: =VLOOKUP($I$1&K$8,DATA!$A:$EB,'2412'!$A14,0)/100 | L14: =VLOOKUP($I$1&L$8,DATA!$A:$EB,'2412'!$A14,0)/100 | M14: =VLOOKUP($I$1&M$8,DATA!$A:$EB,'2412'!$A14,0)/100 | N14: =VLOOKUP($I$1&N$8,DATA!$A:$EB,'2412'!$A14,0)/100 | O14: =VLOOKUP($I$1&O$8,DATA!$A:$EB,'2412'!$A14,0)/100 | P14: =VLOOKUP($I$1&P$8,DATA!$A:$EB,'2412'!$A14,0)/100 | ... T14: =VLOOKUP($I$1&T$8,DATA!$A:$EB,'2412'!$A14,0)/100
A15: =DATA!BU1 | C15: BEL | I15: =VLOOKUP($I$1&I$8,DATA!$A:$EB,'2412'!$A15,0)/100 | J15: =VLOOKUP($I$1&J$8,DATA!$A:$EB,'2412'!$A15,0)/100 | K15: =VLOOKUP($I$1&K$8,DATA!$A:$EB,'2412'!$A15,0)/100 | L15: =VLOOKUP($I$1&L$8,DATA!$A:$EB,'2412'!$A15,0)/100 | M15: =VLOOKUP($I$1&M$8,DATA!$A:$EB,'2412'!$A15,0)/100 | N15: =VLOOKUP($I$1&N$8,DATA!$A:$EB,'2412'!$A15,0)/100 | O15: =VLOOKUP($I$1&O$8,DATA!$A:$EB,'2412'!$A15,0)/100 | P15: =VLOOKUP($I$1&P$8,DATA!$A:$EB,'2412'!$A15,0)/100 | ... T15: =VLOOKUP($I$1&T$8,DATA!$A:$EB,'2412'!$A15,0)/100
A16: =DATA!BW1 | C16: CSM | I16: =VLOOKUP($I$1&I$8,DATA!$A:$EB,'2412'!$A16,0)/100 | J16: =VLOOKUP($I$1&J$8,DATA!$A:$EB,'2412'!$A16,0)/100 | K16: =VLOOKUP($I$1&K$8,DATA!$A:$EB,'2412'!$A16,0)/100 | L16: =VLOOKUP($I$1&L$8,DATA!$A:$EB,'2412'!$A16,0)/100 | M16: =VLOOKUP($I$1&M$8,DATA!$A:$EB,'2412'!$A16,0)/100 | N16: =VLOOKUP($I$1&N$8,DATA!$A:$EB,'2412'!$A16,0)/100 | O16: =VLOOKUP($I$1&O$8,DATA!$A:$EB,'2412'!$A16,0)/100 | P16: =VLOOKUP($I$1&P$8,DATA!$A:$EB,'2412'!$A16,0)/100 | ... T16: =VLOOKUP($I$1&T$8,DATA!$A:$EB,'2412'!$A16,0)/100
C17: (비중) | I17: =I16/I14 | J17: =J16/J14 | K17: =K16/K14 | L17: =L16/L14 | M17: =M16/M14 | N17: =N16/N14 | O17: =O16/O14 | P17: =P16/P14 | ... T17: =T16/T14
A18: =DATA!BV1 | C18: RA | I18: =VLOOKUP($I$1&I$8,DATA!$A:$EB,'2412'!$A18,0)/100 | J18: =VLOOKUP($I$1&J$8,DATA!$A:$EB,'2412'!$A18,0)/100 | K18: =VLOOKUP($I$1&K$8,DATA!$A:$EB,'2412'!$A18,0)/100 | L18: =VLOOKUP($I$1&L$8,DATA!$A:$EB,'2412'!$A18,0)/100 | M18: =VLOOKUP($I$1&M$8,DATA!$A:$EB,'2412'!$A18,0)/100 | N18: =VLOOKUP($I$1&N$8,DATA!$A:$EB,'2412'!$A18,0)/100 | O18: =VLOOKUP($I$1&O$8,DATA!$A:$EB,'2412'!$A18,0)/100 | P18: =VLOOKUP($I$1&P$8,DATA!$A:$EB,'2412'!$A18,0)/100 | ... T18: =VLOOKUP($I$1&T$8,DATA!$A:$EB,'2412'!$A18,0)/100
A19: =DATA!N1 | C19: 자기자본_신종자본증권제외 | I19: =VLOOKUP($I$1&I$8,DATA!$A:$EB,'2412'!$A19,0)/100 | J19: =VLOOKUP($I$1&J$8,DATA!$A:$EB,'2412'!$A19,0)/100 | K19: =VLOOKUP($I$1&K$8,DATA!$A:$EB,'2412'!$A19,0)/100 | L19: =VLOOKUP($I$1&L$8,DATA!$A:$EB,'2412'!$A19,0)/100 | M19: =VLOOKUP($I$1&M$8,DATA!$A:$EB,'2412'!$A19,0)/100 | N19: =VLOOKUP($I$1&N$8,DATA!$A:$EB,'2412'!$A19,0)/100 | O19: =VLOOKUP($I$1&O$8,DATA!$A:$EB,'2412'!$A19,0)/100 | P19: =VLOOKUP($I$1&P$8,DATA!$A:$EB,'2412'!$A19,0)/100 | ... T19: =VLOOKUP($I$1&T$8,DATA!$A:$EB,'2412'!$A19,0)/100
C20: (전기자본 대비) | I20: =+I37 | J20: =+J37 | K20: =+K37 | L20: =+L37 | M20: =+M37 | N20: =+N37 | O20: =+O37 | P20: =+P37 | ... T20: =+T37
C21: (자본증감율) | I21: =+I20/(I19-I20) | J21: =+J20/(J19-J20) | K21: =+K20/(K19-K20) | L21: =+L20/(L19-L20) | M21: =+M20/(M19-M20) | N21: =+N20/(N19-N20) | O21: =+O20/(O19-O20) | P21: =+P20/(P19-P20) | ... T21: =+T20/(T19-T20)
A22: =DATA!R1 | C22: 이익잉여금 | I22: =VLOOKUP($I$1&I$8,DATA!$A:$EB,'2412'!$A22,0)/100 | J22: =VLOOKUP($I$1&J$8,DATA!$A:$EB,'2412'!$A22,0)/100 | K22: =VLOOKUP($I$1&K$8,DATA!$A:$EB,'2412'!$A22,0)/100 | L22: =VLOOKUP($I$1&L$8,DATA!$A:$EB,'2412'!$A22,0)/100 | M22: =VLOOKUP($I$1&M$8,DATA!$A:$EB,'2412'!$A22,0)/100 | N22: =VLOOKUP($I$1&N$8,DATA!$A:$EB,'2412'!$A22,0)/100 | O22: =VLOOKUP($I$1&O$8,DATA!$A:$EB,'2412'!$A22,0)/100 | P22: =VLOOKUP($I$1&P$8,DATA!$A:$EB,'2412'!$A22,0)/100 | ... T22: =VLOOKUP($I$1&T$8,DATA!$A:$EB,'2412'!$A22,0)/100
A23: =DATA!Q1 | C23: 기타포괄 | I23: =VLOOKUP($I$1&I$8,DATA!$A:$EB,'2412'!$A23,0)/100 | J23: =VLOOKUP($I$1&J$8,DATA!$A:$EB,'2412'!$A23,0)/100 | K23: =VLOOKUP($I$1&K$8,DATA!$A:$EB,'2412'!$A23,0)/100 | L23: =VLOOKUP($I$1&L$8,DATA!$A:$EB,'2412'!$A23,0)/100 | M23: =VLOOKUP($I$1&M$8,DATA!$A:$EB,'2412'!$A23,0)/100 | N23: =VLOOKUP($I$1&N$8,DATA!$A:$EB,'2412'!$A23,0)/100 | O23: =VLOOKUP($I$1&O$8,DATA!$A:$EB,'2412'!$A23,0)/100 | P23: =VLOOKUP($I$1&P$8,DATA!$A:$EB,'2412'!$A23,0)/100 | ... T23: =VLOOKUP($I$1&T$8,DATA!$A:$EB,'2412'!$A23,0)/100
C24: (기타포괄손익 증감) | I24: =I23-I38 | J24: =J23-J38 | K24: =K23-K38 | L24: =L23-L38 | M24: =M23-M38 | N24: =N23-N38 | O24: =O23-O38 | P24: =P23-P38 | ... T24: =T23-T38
C25: (자기자본 대비 기타포괄손익 증감율) | I25: =I24/I36 | J25: =J24/J36 | K25: =K24/K36 | L25: =L24/L36 | M25: =M24/M36 | N25: =N24/N36 | O25: =O24/O36 | P25: =P24/P36 | ... T25: =T24/T36
C26: (보험계약부채대비 기타포괄손익 증감율) | I26: =I24/I45 | J26: =J24/J45 | K26: =K24/K45 | L26: =L24/L45 | M26: =M24/M45 | N26: =N24/N45 | O26: =O24/O45 | P26: =P24/P45 | ... T26: =T24/T45
A29: =DATA!O1 | C29: 자기자본 | I29: =VLOOKUP($I$1&I$8,DATA!$A:$EB,'2412'!$A29,0)/100 | J29: =VLOOKUP($I$1&J$8,DATA!$A:$EB,'2412'!$A29,0)/100 | K29: =VLOOKUP($I$1&K$8,DATA!$A:$EB,'2412'!$A29,0)/100 | L29: =VLOOKUP($I$1&L$8,DATA!$A:$EB,'2412'!$A29,0)/100 | M29: =VLOOKUP($I$1&M$8,DATA!$A:$EB,'2412'!$A29,0)/100 | N29: =VLOOKUP($I$1&N$8,DATA!$A:$EB,'2412'!$A29,0)/100 | O29: =VLOOKUP($I$1&O$8,DATA!$A:$EB,'2412'!$A29,0)/100 | P29: =VLOOKUP($I$1&P$8,DATA!$A:$EB,'2412'!$A29,0)/100 | ... T29: =VLOOKUP($I$1&T$8,DATA!$A:$EB,'2412'!$A29,0)/100
C33: - 금융자산비중 | I33: =+I22/I9 | J33: =+J22/J9 | K33: =+K22/K9 | L33: =+L22/L9 | M33: =+M22/M9 | N33: =+N22/N9 | O33: =+O22/O9 | P33: =+P22/P9 | ... T33: =+T22/T9
A36: =DATA!T1 | C36: * 전기자기자본 | I36: =VLOOKUP($I$1&I$8,DATA!$A:$EB,'2412'!$A36,0)/100 | J36: =VLOOKUP($I$1&J$8,DATA!$A:$EB,'2412'!$A36,0)/100 | K36: =VLOOKUP($I$1&K$8,DATA!$A:$EB,'2412'!$A36,0)/100 | L36: =VLOOKUP($I$1&L$8,DATA!$A:$EB,'2412'!$A36,0)/100 | M36: =VLOOKUP($I$1&M$8,DATA!$A:$EB,'2412'!$A36,0)/100 | N36: =VLOOKUP($I$1&N$8,DATA!$A:$EB,'2412'!$A36,0)/100 | O36: =VLOOKUP($I$1&O$8,DATA!$A:$EB,'2412'!$A36,0)/100 | P36: =VLOOKUP($I$1&P$8,DATA!$A:$EB,'2412'!$A36,0)/100 | ... T36: =VLOOKUP($I$1&T$8,DATA!$A:$EB,'2412'!$A36,0)/100
C37: - 전기대비 증감 | I37: =I19-I36 | J37: =J19-J36 | K37: =K19-K36 | L37: =L19-L36 | M37: =M19-M36 | N37: =N19-N36 | O37: =O19-O36 | P37: =P19-P36 | ... T37: =T19-T36
A38: =DATA!BC1 | C38: * 전기기타포괄 | I38: =VLOOKUP($I$1&I$8,DATA!$A:$EB,'2412'!$A38,0)/100 | J38: =VLOOKUP($I$1&J$8,DATA!$A:$EB,'2412'!$A38,0)/100 | K38: =VLOOKUP($I$1&K$8,DATA!$A:$EB,'2412'!$A38,0)/100 | L38: =VLOOKUP($I$1&L$8,DATA!$A:$EB,'2412'!$A38,0)/100 | M38: =VLOOKUP($I$1&M$8,DATA!$A:$EB,'2412'!$A38,0)/100 | N38: =VLOOKUP($I$1&N$8,DATA!$A:$EB,'2412'!$A38,0)/100 | O38: =VLOOKUP($I$1&O$8,DATA!$A:$EB,'2412'!$A38,0)/100 | P38: =VLOOKUP($I$1&P$8,DATA!$A:$EB,'2412'!$A38,0)/100 | ... T38: =VLOOKUP($I$1&T$8,DATA!$A:$EB,'2412'!$A38,0)/100
A39: =DATA!BN1 | C39: 1) 결산배당 | I39: =VLOOKUP($I$1&I$8,DATA!$A:$EB,'2412'!$A39,0)/100 | J39: =VLOOKUP($I$1&J$8,DATA!$A:$EB,'2412'!$A39,0)/100 | K39: =VLOOKUP($I$1&K$8,DATA!$A:$EB,'2412'!$A39,0)/100 | L39: =VLOOKUP($I$1&L$8,DATA!$A:$EB,'2412'!$A39,0)/100 | M39: =VLOOKUP($I$1&M$8,DATA!$A:$EB,'2412'!$A39,0)/100 | N39: =VLOOKUP($I$1&N$8,DATA!$A:$EB,'2412'!$A39,0)/100 | O39: =VLOOKUP($I$1&O$8,DATA!$A:$EB,'2412'!$A39,0)/100 | P39: =VLOOKUP($I$1&P$8,DATA!$A:$EB,'2412'!$A39,0)/100 | ... T39: =VLOOKUP($I$1&T$8,DATA!$A:$EB,'2412'!$A39,0)/100
A40: =DATA!BR1 | C40: 2) 기타배당 | I40: =VLOOKUP($I$1&I$8,DATA!$A:$EB,'2412'!$A40,0)/100 | J40: =VLOOKUP($I$1&J$8,DATA!$A:$EB,'2412'!$A40,0)/100 | K40: =VLOOKUP($I$1&K$8,DATA!$A:$EB,'2412'!$A40,0)/100 | L40: =VLOOKUP($I$1&L$8,DATA!$A:$EB,'2412'!$A40,0)/100 | M40: =VLOOKUP($I$1&M$8,DATA!$A:$EB,'2412'!$A40,0)/100 | N40: =VLOOKUP($I$1&N$8,DATA!$A:$EB,'2412'!$A40,0)/100 | O40: =VLOOKUP($I$1&O$8,DATA!$A:$EB,'2412'!$A40,0)/100 | P40: =VLOOKUP($I$1&P$8,DATA!$A:$EB,'2412'!$A40,0)/100 | ... T40: =VLOOKUP($I$1&T$8,DATA!$A:$EB,'2412'!$A40,0)/100
C41: 배당합계 | I41: =I39+I40 | J41: =J39+J40 | K41: =K39+K40 | L41: =L39+L40 | M41: =M39+M40 | N41: =N39+N40 | O41: =O39+O40 | P41: =P39+P40 | ... T41: =T39+T40
C42: 배당제외 자본증가금액 | I42: =I37-I41 | J42: =J37-J41 | K42: =K37-K41 | L42: =L37-L41 | M42: =M37-M41 | N42: =N37-N41 | O42: =O37-O41 | P42: =P37-P41 | ... T42: =T37-T41
C43: - 배당제외 기준 자본증가율 | I43: =I42/I36 | J43: =J42/J36 | K43: =K42/K36 | L43: =L42/L36 | M43: =M42/M36 | N43: =N42/N36 | O43: =O42/O36 | P43: =P42/P36 | ... T43: =T42/T36
C45: * 전기 BEL+RA+CSM | I45: =전기말!I6 | J45: =전기말!J6 | K45: =전기말!K6 | L45: =전기말!L6 | M45: =전기말!M6 | N45: =전기말!N6 | O45: =전기말!O6 | P45: =전기말!P6 | ... T45: =전기말!T6
A46: =DATA!M1 | C46: 보험계약부채 | I46: =VLOOKUP($I$1&I$8,DATA!$A:$EB,'2412'!$A46,0)/100 | J46: =VLOOKUP($I$1&J$8,DATA!$A:$EB,'2412'!$A46,0)/100 | K46: =VLOOKUP($I$1&K$8,DATA!$A:$EB,'2412'!$A46,0)/100 | L46: =VLOOKUP($I$1&L$8,DATA!$A:$EB,'2412'!$A46,0)/100 | M46: =VLOOKUP($I$1&M$8,DATA!$A:$EB,'2412'!$A46,0)/100 | N46: =VLOOKUP($I$1&N$8,DATA!$A:$EB,'2412'!$A46,0)/100 | O46: =VLOOKUP($I$1&O$8,DATA!$A:$EB,'2412'!$A46,0)/100 | P46: =VLOOKUP($I$1&P$8,DATA!$A:$EB,'2412'!$A46,0)/100 | ... T46: =VLOOKUP($I$1&T$8,DATA!$A:$EB,'2412'!$A46,0)/100
I47: =I23/I46 | J47: =J23/J46 | K47: =K23/K46 | L47: =L23/L46 | M47: =M23/M46 | N47: =N23/N46 | O47: =O23/O46 | P47: =P23/P46 | ... T47: =T23/T46
I48: =I72/I46 | J48: =J72/J46 | K48: =K72/K46 | L48: =L72/L46 | M48: =M72/M46 | N48: =N72/N46 | O48: =O72/O46 | P48: =P72/P46 | ... T48: =T72/T46
C49: *전기보험계약부채
A55: =DATA!BM1 | C55: * 전기말 이익잉여금 | I55: =VLOOKUP($I$1&I$8,DATA!$A:$EB,'2412'!$A55,0)/100 | J55: =VLOOKUP($I$1&J$8,DATA!$A:$EB,'2412'!$A55,0)/100 | K55: =VLOOKUP($I$1&K$8,DATA!$A:$EB,'2412'!$A55,0)/100 | L55: =VLOOKUP($I$1&L$8,DATA!$A:$EB,'2412'!$A55,0)/100 | M55: =VLOOKUP($I$1&M$8,DATA!$A:$EB,'2412'!$A55,0)/100 | N55: =VLOOKUP($I$1&N$8,DATA!$A:$EB,'2412'!$A55,0)/100 | O55: =VLOOKUP($I$1&O$8,DATA!$A:$EB,'2412'!$A55,0)/100 | P55: =VLOOKUP($I$1&P$8,DATA!$A:$EB,'2412'!$A55,0)/100 | ... T55: =VLOOKUP($I$1&T$8,DATA!$A:$EB,'2412'!$A55,0)/100
D56: 전기말 대비 | I56: =+I22-I55 | J56: =+J22-J55 | K56: =+K22-K55 | L56: =+L22-L55 | M56: =+M22-M55 | N56: =+N22-N55 | O56: =+O22-O55 | P56: =+P22-P55 | ... T56: =+T22-T55
I57: =I22-'2406'!I20 | J57: =J22-'2406'!J20 | K57: =K22-'2406'!K20 | L57: =L22-'2406'!L20 | M57: =M22-'2406'!M20 | N57: =N22-'2406'!N20 | O57: =O22-'2406'!O20 | P57: =P22-'2406'!P20 | ... T57: =T22-'2406'!T20
...

Sheet 2312
C1: 기준월 | I1: 2312 | J1: =ROUNDUP(RIGHT(I1,2)/3,0)
C4: 1. 자산 구성현황
O7: (단위 : 억원)
C8: 구분 | I8: 미래 | J8: 삼성 | K8: 교보 | L8: 한화 | M8: 신한라이프 | N8: 동양 | O8: KB라이프 | P8: 삼성화재 | Q8: 현대해상 | R8: 메리츠화재 | S8: KB손보 | T8: DB손보
A9: =DATA!D$1 | C9: 자산 | I9: =VLOOKUP($I$1&I$8,DATA!$A:$EB,'2312'!$A9,0)/100 | J9: =VLOOKUP($I$1&J$8,DATA!$A:$EB,'2312'!$A9,0)/100 | K9: =VLOOKUP($I$1&K$8,DATA!$A:$EB,'2312'!$A9,0)/100 | L9: =VLOOKUP($I$1&L$8,DATA!$A:$EB,'2312'!$A9,0)/100 | M9: =VLOOKUP($I$1&M$8,DATA!$A:$EB,'2312'!$A9,0)/100 | N9: =VLOOKUP($I$1&N$8,DATA!$A:$EB,'2312'!$A9,0)/100 | O9: =VLOOKUP($I$1&O$8,DATA!$A:$EB,'2312'!$A9,0)/100 | P9: =VLOOKUP($I$1&P$8,DATA!$A:$EB,'2312'!$A9,0)/100 | ... T9: =VLOOKUP($I$1&T$8,DATA!$A:$EB,'2312'!$A9,0)/100
A10: =DATA!E1 | C10: FVPL | I10: =VLOOKUP($I$1&I$8,DATA!$A:$EB,'2312'!$A10,0)/100 | J10: =VLOOKUP($I$1&J$8,DATA!$A:$EB,'2312'!$A10,0)/100 | K10: =VLOOKUP($I$1&K$8,DATA!$A:$EB,'2312'!$A10,0)/100 | L10: =VLOOKUP($I$1&L$8,DATA!$A:$EB,'2312'!$A10,0)/100 | M10: =VLOOKUP($I$1&M$8,DATA!$A:$EB,'2312'!$A10,0)/100 | N10: =VLOOKUP($I$1&N$8,DATA!$A:$EB,'2312'!$A10,0)/100 | O10: =VLOOKUP($I$1&O$8,DATA!$A:$EB,'2312'!$A10,0)/100 | P10: =VLOOKUP($I$1&P$8,DATA!$A:$EB,'2312'!$A10,0)/100 | ... T10: =VLOOKUP($I$1&T$8,DATA!$A:$EB,'2312'!$A10,0)/100
C11: (비중) | I11: =I10/I9 | J11: =J10/J9 | K11: =K10/K9 | L11: =L10/L9 | M11: =M10/M9 | N11: =N10/N9 | O11: =O10/O9 | P11: =P10/P9 | ... T11: =T10/T9
A12: =DATA!F1 | C12: FVOCI | I12: =VLOOKUP($I$1&I$8,DATA!$A:$EB,'2312'!$A12,0)/100 | J12: =VLOOKUP($I$1&J$8,DATA!$A:$EB,'2312'!$A12,0)/100 | K12: =VLOOKUP($I$1&K$8,DATA!$A:$EB,'2312'!$A12,0)/100 | L12: =VLOOKUP($I$1&L$8,DATA!$A:$EB,'2312'!$A12,0)/100 | M12: =VLOOKUP($I$1&M$8,DATA!$A:$EB,'2312'!$A12,0)/100 | N12: =VLOOKUP($I$1&N$8,DATA!$A:$EB,'2312'!$A12,0)/100 | O12: =VLOOKUP($I$1&O$8,DATA!$A:$EB,'2312'!$A12,0)/100 | P12: =VLOOKUP($I$1&P$8,DATA!$A:$EB,'2312'!$A12,0)/100 | ... T12: =VLOOKUP($I$1&T$8,DATA!$A:$EB,'2312'!$A12,0)/100
A13: =DATA!G1 | C13: AC | I13: =VLOOKUP($I$1&I$8,DATA!$A:$EB,'2312'!$A13,0)/100 | J13: =VLOOKUP($I$1&J$8,DATA!$A:$EB,'2312'!$A13,0)/100 | K13: =VLOOKUP($I$1&K$8,DATA!$A:$EB,'2312'!$A13,0)/100 | L13: =VLOOKUP($I$1&L$8,DATA!$A:$EB,'2312'!$A13,0)/100 | M13: =VLOOKUP($I$1&M$8,DATA!$A:$EB,'2312'!$A13,0)/100 | N13: =VLOOKUP($I$1&N$8,DATA!$A:$EB,'2312'!$A13,0)/100 | O13: =VLOOKUP($I$1&O$8,DATA!$A:$EB,'2312'!$A13,0)/100 | P13: =VLOOKUP($I$1&P$8,DATA!$A:$EB,'2312'!$A13,0)/100 | ... T13: =VLOOKUP($I$1&T$8,DATA!$A:$EB,'2312'!$A13,0)/100
A14: =DATA!L1 | C14: 부채 | I14: =VLOOKUP($I$1&I$8,DATA!$A:$EB,'2312'!$A14,0)/100 | J14: =VLOOKUP($I$1&J$8,DATA!$A:$EB,'2312'!$A14,0)/100 | K14: =VLOOKUP($I$1&K$8,DATA!$A:$EB,'2312'!$A14,0)/100 | L14: =VLOOKUP($I$1&L$8,DATA!$A:$EB,'2312'!$A14,0)/100 | M14: =VLOOKUP($I$1&M$8,DATA!$A:$EB,'2312'!$A14,0)/100 | N14: =VLOOKUP($I$1&N$8,DATA!$A:$EB,'2312'!$A14,0)/100 | O14: =VLOOKUP($I$1&O$8,DATA!$A:$EB,'2312'!$A14,0)/100 | P14: =VLOOKUP($I$1&P$8,DATA!$A:$EB,'2312'!$A14,0)/100 | ... T14: =VLOOKUP($I$1&T$8,DATA!$A:$EB,'2312'!$A14,0)/100
A15: =DATA!BU1 | C15: BEL | I15: =VLOOKUP($I$1&I$8,DATA!$A:$EB,'2312'!$A15,0)/100 | J15: =VLOOKUP($I$1&J$8,DATA!$A:$EB,'2312'!$A15,0)/100 | K15: =VLOOKUP($I$1&K$8,DATA!$A:$EB,'2312'!$A15,0)/100 | L15: =VLOOKUP($I$1&L$8,DATA!$A:$EB,'2312'!$A15,0)/100 | M15: =VLOOKUP($I$1&M$8,DATA!$A:$EB,'2312'!$A15,0)/100 | N15: =VLOOKUP($I$1&N$8,DATA!$A:$EB,'2312'!$A15,0)/100 | O15: =VLOOKUP($I$1&O$8,DATA!$A:$EB,'2312'!$A15,0)/100 | P15: =VLOOKUP($I$1&P$8,DATA!$A:$EB,'2312'!$A15,0)/100 | ... T15: =VLOOKUP($I$1&T$8,DATA!$A:$EB,'2312'!$A15,0)/100
A16: =DATA!BW1 | C16: CSM | I16: =VLOOKUP($I$1&I$8,DATA!$A:$EB,'2312'!$A16,0)/100 | J16: =VLOOKUP($I$1&J$8,DATA!$A:$EB,'2312'!$A16,0)/100 | K16: =VLOOKUP($I$1&K$8,DATA!$A:$EB,'2312'!$A16,0)/100 | L16: =VLOOKUP($I$1&L$8,DATA!$A:$EB,'2312'!$A16,0)/100 | M16: =VLOOKUP($I$1&M$8,DATA!$A:$EB,'2312'!$A16,0)/100 | N16: =VLOOKUP($I$1&N$8,DATA!$A:$EB,'2312'!$A16,0)/100 | O16: =VLOOKUP($I$1&O$8,DATA!$A:$EB,'2312'!$A16,0)/100 | P16: =VLOOKUP($I$1&P$8,DATA!$A:$EB,'2312'!$A16,0)/100 | ... T16: =VLOOKUP($I$1&T$8,DATA!$A:$EB,'2312'!$A16,0)/100
C17: (비중) | I17: =I16/I14 | J17: =J16/J14 | K17: =K16/K14 | L17: =L16/L14 | M17: =M16/M14 | N17: =N16/N14 | O17: =O16/O14 | P17: =P16/P14 | ... T17: =T16/T14
A18: =DATA!BV1 | C18: RA | I18: =VLOOKUP($I$1&I$8,DATA!$A:$EB,'2312'!$A18,0)/100 | J18: =VLOOKUP($I$1&J$8,DATA!$A:$EB,'2312'!$A18,0)/100 | K18: =VLOOKUP($I$1&K$8,DATA!$A:$EB,'2312'!$A18,0)/100 | L18: =VLOOKUP($I$1&L$8,DATA!$A:$EB,'2312'!$A18,0)/100 | M18: =VLOOKUP($I$1&M$8,DATA!$A:$EB,'2312'!$A18,0)/100 | N18: =VLOOKUP($I$1&N$8,DATA!$A:$EB,'2312'!$A18,0)/100 | O18: =VLOOKUP($I$1&O$8,DATA!$A:$EB,'2312'!$A18,0)/100 | P18: =VLOOKUP($I$1&P$8,DATA!$A:$EB,'2312'!$A18,0)/100 | ... T18: =VLOOKUP($I$1&T$8,DATA!$A:$EB,'2312'!$A18,0)/100
A19: =DATA!N1 | C19: 자기자본_신종자본증권제외 | I19: =VLOOKUP($I$1&I$8,DATA!$A:$EB,'2312'!$A19,0)/100 | J19: =VLOOKUP($I$1&J$8,DATA!$A:$EB,'2312'!$A19,0)/100 | K19: =VLOOKUP($I$1&K$8,DATA!$A:$EB,'2312'!$A19,0)/100 | L19: =VLOOKUP($I$1&L$8,DATA!$A:$EB,'2312'!$A19,0)/100 | M19: =VLOOKUP($I$1&M$8,DATA!$A:$EB,'2312'!$A19,0)/100 | N19: =VLOOKUP($I$1&N$8,DATA!$A:$EB,'2312'!$A19,0)/100 | O19: =VLOOKUP($I$1&O$8,DATA!$A:$EB,'2312'!$A19,0)/100 | P19: =VLOOKUP($I$1&P$8,DATA!$A:$EB,'2312'!$A19,0)/100 | ... T19: =VLOOKUP($I$1&T$8,DATA!$A:$EB,'2312'!$A19,0)/100
C20: (전기자본 대비) | I20: =+I37 | J20: =+J37 | K20: =+K37 | L20: =+L37 | M20: =+M37 | N20: =+N37 | O20: =+O37 | P20: =+P37 | ... T20: =+T37
C21: (자본증감율) | I21: =+I20/(I19-I20) | J21: =+J20/(J19-J20) | K21: =+K20/(K19-K20) | L21: =+L20/(L19-L20) | M21: =+M20/(M19-M20) | N21: =+N20/(N19-N20) | O21: =+O20/(O19-O20) | P21: =+P20/(P19-P20) | ... T21: =+T20/(T19-T20)
A22: =DATA!R1 | C22: 이익잉여금 | I22: =VLOOKUP($I$1&I$8,DATA!$A:$EB,'2312'!$A22,0)/100 | J22: =VLOOKUP($I$1&J$8,DATA!$A:$EB,'2312'!$A22,0)/100 | K22: =VLOOKUP($I$1&K$8,DATA!$A:$EB,'2312'!$A22,0)/100 | L22: =VLOOKUP($I$1&L$8,DATA!$A:$EB,'2312'!$A22,0)/100 | M22: =VLOOKUP($I$1&M$8,DATA!$A:$EB,'2312'!$A22,0)/100 | N22: =VLOOKUP($I$1&N$8,DATA!$A:$EB,'2312'!$A22,0)/100 | O22: =VLOOKUP($I$1&O$8,DATA!$A:$EB,'2312'!$A22,0)/100 | P22: =VLOOKUP($I$1&P$8,DATA!$A:$EB,'2312'!$A22,0)/100 | ... T22: =VLOOKUP($I$1&T$8,DATA!$A:$EB,'2312'!$A22,0)/100
A23: =DATA!Q1 | C23: 기타포괄 | I23: =VLOOKUP($I$1&I$8,DATA!$A:$EB,'2312'!$A23,0)/100 | J23: =VLOOKUP($I$1&J$8,DATA!$A:$EB,'2312'!$A23,0)/100 | K23: =VLOOKUP($I$1&K$8,DATA!$A:$EB,'2312'!$A23,0)/100 | L23: =VLOOKUP($I$1&L$8,DATA!$A:$EB,'2312'!$A23,0)/100 | M23: =VLOOKUP($I$1&M$8,DATA!$A:$EB,'2312'!$A23,0)/100 | N23: =VLOOKUP($I$1&N$8,DATA!$A:$EB,'2312'!$A23,0)/100 | O23: =VLOOKUP($I$1&O$8,DATA!$A:$EB,'2312'!$A23,0)/100 | P23: =VLOOKUP($I$1&P$8,DATA!$A:$EB,'2312'!$A23,0)/100 | ... T23: =VLOOKUP($I$1&T$8,DATA!$A:$EB,'2312'!$A23,0)/100
C24: (기타포괄손익 증감) | I24: =I23-I38 | J24: =J23-J38 | K24: =K23-K38 | L24: =L23-L38 | M24: =M23-M38 | N24: =N23-N38 | O24: =O23-O38 | P24: =P23-P38 | ... T24: =T23-T38
C25: (자기자본 대비 기타포괄손익 증감율) | I25: =I24/I36 | J25: =J24/J36 | K25: =K24/K36 | L25: =L24/L36 | M25: =M24/M36 | N25: =N24/N36 | O25: =O24/O36 | P25: =P24/P36 | ... T25: =T24/T36
C26: (보험계약부채대비 기타포괄손익 증감율) | I26: =I24/I45 | J26: =J24/J45 | K26: =K24/K45 | L26: =L24/L45 | M26: =M24/M45 | N26: =N24/N45 | O26: =O24/O45 | P26: =P24/P45 | ... T26: =T24/T45
A29: =DATA!O1 | C29: 자기자본 | I29: =VLOOKUP($I$1&I$8,DATA!$A:$EB,'2312'!$A29,0)/100 | J29: =VLOOKUP($I$1&J$8,DATA!$A:$EB,'2312'!$A29,0)/100 | K29: =VLOOKUP($I$1&K$8,DATA!$A:$EB,'2312'!$A29,0)/100 | L29: =VLOOKUP($I$1&L$8,DATA!$A:$EB,'2312'!$A29,0)/100 | M29: =VLOOKUP($I$1&M$8,DATA!$A:$EB,'2312'!$A29,0)/100 | N29: =VLOOKUP($I$1&N$8,DATA!$A:$EB,'2312'!$A29,0)/100 | O29: =VLOOKUP($I$1&O$8,DATA!$A:$EB,'2312'!$A29,0)/100 | P29: =VLOOKUP($I$1&P$8,DATA!$A:$EB,'2312'!$A29,0)/100 | ... T29: =VLOOKUP($I$1&T$8,DATA!$A:$EB,'2312'!$A29,0)/100
C33: - 금융자산비중 | I33: =+I22/I9 | J33: =+J22/J9 | K33: =+K22/K9 | L33: =+L22/L9 | M33: =+M22/M9 | N33: =+N22/N9 | O33: =+O22/O9 | P33: =+P22/P9 | ... T33: =+T22/T9
A36: =DATA!T1 | C36: * 전기자기자본 | I36: =VLOOKUP($I$1&I$8,DATA!$A:$EB,'2312'!$A36,0)/100 | J36: =VLOOKUP($I$1&J$8,DATA!$A:$EB,'2312'!$A36,0)/100 | K36: =VLOOKUP($I$1&K$8,DATA!$A:$EB,'2312'!$A36,0)/100 | L36: =VLOOKUP($I$1&L$8,DATA!$A:$EB,'2312'!$A36,0)/100 | M36: =VLOOKUP($I$1&M$8,DATA!$A:$EB,'2312'!$A36,0)/100 | N36: =VLOOKUP($I$1&N$8,DATA!$A:$EB,'2312'!$A36,0)/100 | O36: =VLOOKUP($I$1&O$8,DATA!$A:$EB,'2312'!$A36,0)/100 | P36: =VLOOKUP($I$1&P$8,DATA!$A:$EB,'2312'!$A36,0)/100 | ... T36: =VLOOKUP($I$1&T$8,DATA!$A:$EB,'2312'!$A36,0)/100
C37: - 전기대비 증감 | I37: =I19-I36 | J37: =J19-J36 | K37: =K19-K36 | L37: =L19-L36 | M37: =M19-M36 | N37: =N19-N36 | O37: =O19-O36 | P37: =P19-P36 | ... T37: =T19-T36
A38: =DATA!BC1 | C38: * 전기기타포괄 | I38: =VLOOKUP($I$1&I$8,DATA!$A:$EB,'2312'!$A38,0)/100 | J38: =VLOOKUP($I$1&J$8,DATA!$A:$EB,'2312'!$A38,0)/100 | K38: =VLOOKUP($I$1&K$8,DATA!$A:$EB,'2312'!$A38,0)/100 | L38: =VLOOKUP($I$1&L$8,DATA!$A:$EB,'2312'!$A38,0)/100 | M38: =VLOOKUP($I$1&M$8,DATA!$A:$EB,'2312'!$A38,0)/100 | N38: =VLOOKUP($I$1&N$8,DATA!$A:$EB,'2312'!$A38,0)/100 | O38: =VLOOKUP($I$1&O$8,DATA!$A:$EB,'2312'!$A38,0)/100 | P38: =VLOOKUP($I$1&P$8,DATA!$A:$EB,'2312'!$A38,0)/100 | ... T38: =VLOOKUP($I$1&T$8,DATA!$A:$EB,'2312'!$A38,0)/100
A39: =DATA!BN1 | C39: 1) 결산배당 | I39: =VLOOKUP($I$1&I$8,DATA!$A:$EB,'2312'!$A39,0)/100 | J39: =VLOOKUP($I$1&J$8,DATA!$A:$EB,'2312'!$A39,0)/100 | K39: =VLOOKUP($I$1&K$8,DATA!$A:$EB,'2312'!$A39,0)/100 | L39: =VLOOKUP($I$1&L$8,DATA!$A:$EB,'2312'!$A39,0)/100 | M39: =VLOOKUP($I$1&M$8,DATA!$A:$EB,'2312'!$A39,0)/100 | N39: =VLOOKUP($I$1&N$8,DATA!$A:$EB,'2312'!$A39,0)/100 | O39: =VLOOKUP($I$1&O$8,DATA!$A:$EB,'2312'!$A39,0)/100 | P39: =VLOOKUP($I$1&P$8,DATA!$A:$EB,'2312'!$A39,0)/100 | ... T39: =VLOOKUP($I$1&T$8,DATA!$A:$EB,'2312'!$A39,0)/100
A40: =DATA!BR1 | C40: 2) 기타배당 | I40: =VLOOKUP($I$1&I$8,DATA!$A:$EB,'2312'!$A40,0)/100 | J40: =VLOOKUP($I$1&J$8,DATA!$A:$EB,'2312'!$A40,0)/100 | K40: =VLOOKUP($I$1&K$8,DATA!$A:$EB,'2312'!$A40,0)/100 | L40: =VLOOKUP($I$1&L$8,DATA!$A:$EB,'2312'!$A40,0)/100 | M40: =VLOOKUP($I$1&M$8,DATA!$A:$EB,'2312'!$A40,0)/100 | N40: =VLOOKUP($I$1&N$8,DATA!$A:$EB,'2312'!$A40,0)/100 | O40: =VLOOKUP($I$1&O$8,DATA!$A:$EB,'2312'!$A40,0)/100 | P40: =VLOOKUP($I$1&P$8,DATA!$A:$EB,'2312'!$A40,0)/100 | ... T40: =VLOOKUP($I$1&T$8,DATA!$A:$EB,'2312'!$A40,0)/100
C41: 배당합계 | I41: =I39+I40 | J41: =J39+J40 | K41: =K39+K40 | L41: =L39+L40 | M41: =M39+M40 | N41: =N39+N40 | O41: =O39+O40 | P41: =P39+P40 | ... T41: =T39+T40
C42: 배당제외 자본증가금액 | I42: =I37-I41 | J42: =J37-J41 | K42: =K37-K41 | L42: =L37-L41 | M42: =M37-M41 | N42: =N37-N41 | O42: =O37-O41 | P42: =P37-P41 | ... T42: =T37-T41
C43: - 배당제외 기준 자본증가율 | I43: =I42/I36 | J43: =J42/J36 | K43: =K42/K36 | L43: =L42/L36 | M43: =M42/M36 | N43: =N42/N36 | O43: =O42/O36 | P43: =P42/P36 | ... T43: =T42/T36
C45: * 전기 BEL+RA+CSM | I45: =전기말!I6 | J45: =전기말!J6 | K45: =전기말!K6 | L45: =전기말!L6 | M45: =전기말!M6 | N45: =전기말!N6 | O45: =전기말!O6 | P45: =전기말!P6 | ... T45: =전기말!T6
A46: =DATA!M1 | C46: 보험계약부채 | I46: =VLOOKUP($I$1&I$8,DATA!$A:$EB,'2312'!$A46,0)/100 | J46: =VLOOKUP($I$1&J$8,DATA!$A:$EB,'2312'!$A46,0)/100 | K46: =VLOOKUP($I$1&K$8,DATA!$A:$EB,'2312'!$A46,0)/100 | L46: =VLOOKUP($I$1&L$8,DATA!$A:$EB,'2312'!$A46,0)/100 | M46: =VLOOKUP($I$1&M$8,DATA!$A:$EB,'2312'!$A46,0)/100 | N46: =VLOOKUP($I$1&N$8,DATA!$A:$EB,'2312'!$A46,0)/100 | O46: =VLOOKUP($I$1&O$8,DATA!$A:$EB,'2312'!$A46,0)/100 | P46: =VLOOKUP($I$1&P$8,DATA!$A:$EB,'2312'!$A46,0)/100 | ... T46: =VLOOKUP($I$1&T$8,DATA!$A:$EB,'2312'!$A46,0)/100
I47: =I23/I46 | J47: =J23/J46 | K47: =K23/K46 | L47: =L23/L46 | M47: =M23/M46 | N47: =N23/N46 | O47: =O23/O46 | P47: =P23/P46 | ... T47: =T23/T46
I48: =I72/I46 | J48: =J72/J46 | K48: =K72/K46 | L48: =L72/L46 | M48: =M72/M46 | N48: =N72/N46 | O48: =O72/O46 | P48: =P72/P46 | ... T48: =T72/T46
C49: *전기보험계약부채
A55: =DATA!BM1 | C55: * 전기말 이익잉여금 | I55: =VLOOKUP($I$1&I$8,DATA!$A:$EB,'2312'!$A55,0)/100 | J55: =VLOOKUP($I$1&J$8,DATA!$A:$EB,'2312'!$A55,0)/100 | K55: =VLOOKUP($I$1&K$8,DATA!$A:$EB,'2312'!$A55,0)/100 | L55: =VLOOKUP($I$1&L$8,DATA!$A:$EB,'2312'!$A55,0)/100 | M55: =VLOOKUP($I$1&M$8,DATA!$A:$EB,'2312'!$A55,0)/100 | N55: =VLOOKUP($I$1&N$8,DATA!$A:$EB,'2312'!$A55,0)/100 | O55: =VLOOKUP($I$1&O$8,DATA!$A:$EB,'2312'!$A55,0)/100 | P55: =VLOOKUP($I$1&P$8,DATA!$A:$EB,'2312'!$A55,0)/100 | ... T55: =VLOOKUP($I$1&T$8,DATA!$A:$EB,'2312'!$A55,0)/100
D56: 전기말 대비 | I56: =+I22-I55 | J56: =+J22-J55 | K56: =+K22-K55 | L56: =+L22-L55 | M56: =+M22-M55 | N56: =+N22-N55 | O56: =+O22-O55 | P56: =+P22-P55 | ... T56: =+T22-T55
I57: =I22-'2406'!I20 | J57: =J22-'2406'!J20 | K57: =K22-'2406'!K20 | L57: =L22-'2406'!L20 | M57: =M22-'2406'!M20 | N57: =N22-'2406'!N20 | O57: =O22-'2406'!O20 | P57: =P22-'2406'!P20 | ... T57: =T22-'2406'!T20
...

Sheet 2406
C1: 기준월 | I1: 2406 | J1: =ROUNDUP(RIGHT(I1,2)/3,0)
C4: 1. 자산 구성현황
O7: (단위 : 억원)
C8: 구분 | I8: 미래 | J8: 삼성 | K8: 교보 | L8: 한화 | M8: 신한라이프 | N8: 동양 | O8: KB라이프 | P8: 삼성화재 | Q8: 현대해상 | R8: 메리츠화재 | S8: KB손보 | T8: DB손보
A9: =DATA!D$1 | C9: 자산 | I9: =VLOOKUP($I$1&I$8,DATA!$A:$EB,'2406'!$A9,0)/100 | J9: =VLOOKUP($I$1&J$8,DATA!$A:$EB,'2406'!$A9,0)/100 | K9: =VLOOKUP($I$1&K$8,DATA!$A:$EB,'2406'!$A9,0)/100 | L9: =VLOOKUP($I$1&L$8,DATA!$A:$EB,'2406'!$A9,0)/100 | M9: =VLOOKUP($I$1&M$8,DATA!$A:$EB,'2406'!$A9,0)/100 | N9: =VLOOKUP($I$1&N$8,DATA!$A:$EB,'2406'!$A9,0)/100 | O9: =VLOOKUP($I$1&O$8,DATA!$A:$EB,'2406'!$A9,0)/100 | P9: =VLOOKUP($I$1&P$8,DATA!$A:$EB,'2406'!$A9,0)/100 | ... T9: =VLOOKUP($I$1&T$8,DATA!$A:$EB,'2406'!$A9,0)/100
A10: =DATA!E1 | C10: FVPL | I10: =VLOOKUP($I$1&I$8,DATA!$A:$EB,'2406'!$A10,0)/100 | J10: =VLOOKUP($I$1&J$8,DATA!$A:$EB,'2406'!$A10,0)/100 | K10: =VLOOKUP($I$1&K$8,DATA!$A:$EB,'2406'!$A10,0)/100 | L10: =VLOOKUP($I$1&L$8,DATA!$A:$EB,'2406'!$A10,0)/100 | M10: =VLOOKUP($I$1&M$8,DATA!$A:$EB,'2406'!$A10,0)/100 | N10: =VLOOKUP($I$1&N$8,DATA!$A:$EB,'2406'!$A10,0)/100 | O10: =VLOOKUP($I$1&O$8,DATA!$A:$EB,'2406'!$A10,0)/100 | P10: =VLOOKUP($I$1&P$8,DATA!$A:$EB,'2406'!$A10,0)/100 | ... T10: =VLOOKUP($I$1&T$8,DATA!$A:$EB,'2406'!$A10,0)/100
C11: (비중) | I11: =I10/I9 | J11: =J10/J9 | K11: =K10/K9 | L11: =L10/L9 | M11: =M10/M9 | N11: =N10/N9 | O11: =O10/O9 | P11: =P10/P9 | ... T11: =T10/T9
A12: =DATA!F1 | C12: FVOCI | I12: =VLOOKUP($I$1&I$8,DATA!$A:$EB,'2406'!$A12,0)/100 | J12: =VLOOKUP($I$1&J$8,DATA!$A:$EB,'2406'!$A12,0)/100 | K12: =VLOOKUP($I$1&K$8,DATA!$A:$EB,'2406'!$A12,0)/100 | L12: =VLOOKUP($I$1&L$8,DATA!$A:$EB,'2406'!$A12,0)/100 | M12: =VLOOKUP($I$1&M$8,DATA!$A:$EB,'2406'!$A12,0)/100 | N12: =VLOOKUP($I$1&N$8,DATA!$A:$EB,'2406'!$A12,0)/100 | O12: =VLOOKUP($I$1&O$8,DATA!$A:$EB,'2406'!$A12,0)/100 | P12: =VLOOKUP($I$1&P$8,DATA!$A:$EB,'2406'!$A12,0)/100 | ... T12: =VLOOKUP($I$1&T$8,DATA!$A:$EB,'2406'!$A12,0)/100
A13: =DATA!G1 | C13: AC | I13: =VLOOKUP($I$1&I$8,DATA!$A:$EB,'2406'!$A13,0)/100 | J13: =VLOOKUP($I$1&J$8,DATA!$A:$EB,'2406'!$A13,0)/100 | K13: =VLOOKUP($I$1&K$8,DATA!$A:$EB,'2406'!$A13,0)/100 | L13: =VLOOKUP($I$1&L$8,DATA!$A:$EB,'2406'!$A13,0)/100 | M13: =VLOOKUP($I$1&M$8,DATA!$A:$EB,'2406'!$A13,0)/100 | N13: =VLOOKUP($I$1&N$8,DATA!$A:$EB,'2406'!$A13,0)/100 | O13: =VLOOKUP($I$1&O$8,DATA!$A:$EB,'2406'!$A13,0)/100 | P13: =VLOOKUP($I$1&P$8,DATA!$A:$EB,'2406'!$A13,0)/100 | ... T13: =VLOOKUP($I$1&T$8,DATA!$A:$EB,'2406'!$A13,0)/100
A14: =DATA!L1 | C14: 부채 | I14: =VLOOKUP($I$1&I$8,DATA!$A:$EB,'2406'!$A14,0)/100 | J14: =VLOOKUP($I$1&J$8,DATA!$A:$EB,'2406'!$A14,0)/100 | K14: =VLOOKUP($I$1&K$8,DATA!$A:$EB,'2406'!$A14,0)/100 | L14: =VLOOKUP($I$1&L$8,DATA!$A:$EB,'2406'!$A14,0)/100 | M14: =VLOOKUP($I$1&M$8,DATA!$A:$EB,'2406'!$A14,0)/100 | N14: =VLOOKUP($I$1&N$8,DATA!$A:$EB,'2406'!$A14,0)/100 | O14: =VLOOKUP($I$1&O$8,DATA!$A:$EB,'2406'!$A14,0)/100 | P14: =VLOOKUP($I$1&P$8,DATA!$A:$EB,'2406'!$A14,0)/100 | ... T14: =VLOOKUP($I$1&T$8,DATA!$A:$EB,'2406'!$A14,0)/100
A15: =DATA!BU1 | C15: BEL | I15: =VLOOKUP($I$1&I$8,DATA!$A:$EB,'2406'!$A15,0)/100 | J15: =VLOOKUP($I$1&J$8,DATA!$A:$EB,'2406'!$A15,0)/100 | K15: =VLOOKUP($I$1&K$8,DATA!$A:$EB,'2406'!$A15,0)/100 | L15: =VLOOKUP($I$1&L$8,DATA!$A:$EB,'2406'!$A15,0)/100 | M15: =VLOOKUP($I$1&M$8,DATA!$A:$EB,'2406'!$A15,0)/100 | N15: =VLOOKUP($I$1&N$8,DATA!$A:$EB,'2406'!$A15,0)/100 | O15: =VLOOKUP($I$1&O$8,DATA!$A:$EB,'2406'!$A15,0)/100 | P15: =VLOOKUP($I$1&P$8,DATA!$A:$EB,'2406'!$A15,0)/100 | ... T15: =VLOOKUP($I$1&T$8,DATA!$A:$EB,'2406'!$A15,0)/100
A16: =DATA!BW1 | C16: CSM | I16: =VLOOKUP($I$1&I$8,DATA!$A:$EB,'2406'!$A16,0)/100 | J16: =VLOOKUP($I$1&J$8,DATA!$A:$EB,'2406'!$A16,0)/100 | K16: =VLOOKUP($I$1&K$8,DATA!$A:$EB,'2406'!$A16,0)/100 | L16: =VLOOKUP($I$1&L$8,DATA!$A:$EB,'2406'!$A16,0)/100 | M16: =VLOOKUP($I$1&M$8,DATA!$A:$EB,'2406'!$A16,0)/100 | N16: =VLOOKUP($I$1&N$8,DATA!$A:$EB,'2406'!$A16,0)/100 | O16: =VLOOKUP($I$1&O$8,DATA!$A:$EB,'2406'!$A16,0)/100 | P16: =VLOOKUP($I$1&P$8,DATA!$A:$EB,'2406'!$A16,0)/100 | ... T16: =VLOOKUP($I$1&T$8,DATA!$A:$EB,'2406'!$A16,0)/100
C17: (비중) | I17: =I16/I14 | J17: =J16/J14 | K17: =K16/K14 | L17: =L16/L14 | M17: =M16/M14 | N17: =N16/N14 | O17: =O16/O14 | P17: =P16/P14 | ... T17: =T16/T14
A18: =DATA!BV1 | C18: RA | I18: =VLOOKUP($I$1&I$8,DATA!$A:$EB,'2406'!$A18,0)/100 | J18: =VLOOKUP($I$1&J$8,DATA!$A:$EB,'2406'!$A18,0)/100 | K18: =VLOOKUP($I$1&K$8,DATA!$A:$EB,'2406'!$A18,0)/100 | L18: =VLOOKUP($I$1&L$8,DATA!$A:$EB,'2406'!$A18,0)/100 | M18: =VLOOKUP($I$1&M$8,DATA!$A:$EB,'2406'!$A18,0)/100 | N18: =VLOOKUP($I$1&N$8,DATA!$A:$EB,'2406'!$A18,0)/100 | O18: =VLOOKUP($I$1&O$8,DATA!$A:$EB,'2406'!$A18,0)/100 | P18: =VLOOKUP($I$1&P$8,DATA!$A:$EB,'2406'!$A18,0)/100 | ... T18: =VLOOKUP($I$1&T$8,DATA!$A:$EB,'2406'!$A18,0)/100
A19: =DATA!N1 | C19: 자기자본 | I19: =VLOOKUP($I$1&I$8,DATA!$A:$EB,'2406'!$A19,0)/100 | J19: =VLOOKUP($I$1&J$8,DATA!$A:$EB,'2406'!$A19,0)/100 | K19: =VLOOKUP($I$1&K$8,DATA!$A:$EB,'2406'!$A19,0)/100 | L19: =VLOOKUP($I$1&L$8,DATA!$A:$EB,'2406'!$A19,0)/100 | M19: =VLOOKUP($I$1&M$8,DATA!$A:$EB,'2406'!$A19,0)/100 | N19: =VLOOKUP($I$1&N$8,DATA!$A:$EB,'2406'!$A19,0)/100 | O19: =VLOOKUP($I$1&O$8,DATA!$A:$EB,'2406'!$A19,0)/100 | P19: =VLOOKUP($I$1&P$8,DATA!$A:$EB,'2406'!$A19,0)/100 | ... T19: =VLOOKUP($I$1&T$8,DATA!$A:$EB,'2406'!$A19,0)/100
A20: =DATA!R1 | C20: 이익잉여금 | I20: =VLOOKUP($I$1&I$8,DATA!$A:$EB,'2406'!$A20,0)/100 | J20: =VLOOKUP($I$1&J$8,DATA!$A:$EB,'2406'!$A20,0)/100 | K20: =VLOOKUP($I$1&K$8,DATA!$A:$EB,'2406'!$A20,0)/100 | L20: =VLOOKUP($I$1&L$8,DATA!$A:$EB,'2406'!$A20,0)/100 | M20: =VLOOKUP($I$1&M$8,DATA!$A:$EB,'2406'!$A20,0)/100 | N20: =VLOOKUP($I$1&N$8,DATA!$A:$EB,'2406'!$A20,0)/100 | O20: =VLOOKUP($I$1&O$8,DATA!$A:$EB,'2406'!$A20,0)/100 | P20: =VLOOKUP($I$1&P$8,DATA!$A:$EB,'2406'!$A20,0)/100 | ... T20: =VLOOKUP($I$1&T$8,DATA!$A:$EB,'2406'!$A20,0)/100
A21: =DATA!Q1 | C21: 기타포괄 | I21: =VLOOKUP($I$1&I$8,DATA!$A:$EB,'2406'!$A21,0)/100 | J21: =VLOOKUP($I$1&J$8,DATA!$A:$EB,'2406'!$A21,0)/100 | K21: =VLOOKUP($I$1&K$8,DATA!$A:$EB,'2406'!$A21,0)/100 | L21: =VLOOKUP($I$1&L$8,DATA!$A:$EB,'2406'!$A21,0)/100 | M21: =VLOOKUP($I$1&M$8,DATA!$A:$EB,'2406'!$A21,0)/100 | N21: =VLOOKUP($I$1&N$8,DATA!$A:$EB,'2406'!$A21,0)/100 | O21: =VLOOKUP($I$1&O$8,DATA!$A:$EB,'2406'!$A21,0)/100 | P21: =VLOOKUP($I$1&P$8,DATA!$A:$EB,'2406'!$A21,0)/100 | ... T21: =VLOOKUP($I$1&T$8,DATA!$A:$EB,'2406'!$A21,0)/100
C22: - 금융자산비중 | I22: =+I20/I9 | J22: =+J20/J9 | K22: =+K20/K9 | L22: =+L20/L9 | M22: =+M20/M9 | N22: =+N20/N9 | O22: =+O20/O9 | P22: =+P20/P9 | ... T22: =+T20/T9
A25: =DATA!T1 | C25: * 전기자기자본 | I25: =VLOOKUP($I$1&I$8,DATA!$A:$EB,'2406'!$A25,0)/100 | J25: =VLOOKUP($I$1&J$8,DATA!$A:$EB,'2406'!$A25,0)/100 | K25: =VLOOKUP($I$1&K$8,DATA!$A:$EB,'2406'!$A25,0)/100 | L25: =VLOOKUP($I$1&L$8,DATA!$A:$EB,'2406'!$A25,0)/100 | M25: =VLOOKUP($I$1&M$8,DATA!$A:$EB,'2406'!$A25,0)/100 | N25: =VLOOKUP($I$1&N$8,DATA!$A:$EB,'2406'!$A25,0)/100 | O25: =VLOOKUP($I$1&O$8,DATA!$A:$EB,'2406'!$A25,0)/100 | P25: =VLOOKUP($I$1&P$8,DATA!$A:$EB,'2406'!$A25,0)/100 | ... T25: =VLOOKUP($I$1&T$8,DATA!$A:$EB,'2406'!$A25,0)/100
C26: - 전기대비 증감 | I26: =I19-I25 | J26: =J19-J25 | K26: =K19-K25 | L26: =L19-L25 | M26: =M19-M25 | N26: =N19-N25 | O26: =O19-O25 | P26: =P19-P25 | ... T26: =T19-T25
A27: =DATA!BC1 | C27: * 전기기타포괄 | I27: =VLOOKUP($I$1&I$8,DATA!$A:$EB,'2406'!$A27,0)/100 | J27: =VLOOKUP($I$1&J$8,DATA!$A:$EB,'2406'!$A27,0)/100 | K27: =VLOOKUP($I$1&K$8,DATA!$A:$EB,'2406'!$A27,0)/100 | L27: =VLOOKUP($I$1&L$8,DATA!$A:$EB,'2406'!$A27,0)/100 | M27: =VLOOKUP($I$1&M$8,DATA!$A:$EB,'2406'!$A27,0)/100 | N27: =VLOOKUP($I$1&N$8,DATA!$A:$EB,'2406'!$A27,0)/100 | O27: =VLOOKUP($I$1&O$8,DATA!$A:$EB,'2406'!$A27,0)/100 | P27: =VLOOKUP($I$1&P$8,DATA!$A:$EB,'2406'!$A27,0)/100 | ... T27: =VLOOKUP($I$1&T$8,DATA!$A:$EB,'2406'!$A27,0)/100
A28: =DATA!BN1 | C28: 1) 결산배당 | I28: =VLOOKUP($I$1&I$8,DATA!$A:$EB,'2406'!$A28,0)/100 | J28: =VLOOKUP($I$1&J$8,DATA!$A:$EB,'2406'!$A28,0)/100 | K28: =VLOOKUP($I$1&K$8,DATA!$A:$EB,'2406'!$A28,0)/100 | L28: =VLOOKUP($I$1&L$8,DATA!$A:$EB,'2406'!$A28,0)/100 | M28: =VLOOKUP($I$1&M$8,DATA!$A:$EB,'2406'!$A28,0)/100 | N28: =VLOOKUP($I$1&N$8,DATA!$A:$EB,'2406'!$A28,0)/100 | O28: =VLOOKUP($I$1&O$8,DATA!$A:$EB,'2406'!$A28,0)/100 | P28: =VLOOKUP($I$1&P$8,DATA!$A:$EB,'2406'!$A28,0)/100 | ... T28: =VLOOKUP($I$1&T$8,DATA!$A:$EB,'2406'!$A28,0)/100
A29: =DATA!BR1 | C29: 2) 기타배당 | I29: =VLOOKUP($I$1&I$8,DATA!$A:$EB,'2406'!$A29,0)/100 | J29: =VLOOKUP($I$1&J$8,DATA!$A:$EB,'2406'!$A29,0)/100 | K29: =VLOOKUP($I$1&K$8,DATA!$A:$EB,'2406'!$A29,0)/100 | L29: =VLOOKUP($I$1&L$8,DATA!$A:$EB,'2406'!$A29,0)/100 | M29: =VLOOKUP($I$1&M$8,DATA!$A:$EB,'2406'!$A29,0)/100 | N29: =VLOOKUP($I$1&N$8,DATA!$A:$EB,'2406'!$A29,0)/100 | O29: =VLOOKUP($I$1&O$8,DATA!$A:$EB,'2406'!$A29,0)/100 | P29: =VLOOKUP($I$1&P$8,DATA!$A:$EB,'2406'!$A29,0)/100 | ... T29: =VLOOKUP($I$1&T$8,DATA!$A:$EB,'2406'!$A29,0)/100
C30: 배당합계 | I30: =I28+I29 | J30: =J28+J29 | K30: =K28+K29 | L30: =L28+L29 | M30: =M28+M29 | N30: =N28+N29 | O30: =O28+O29 | P30: =P28+P29 | ... T30: =T28+T29
C31: 배당제외 자본증가금액 | I31: =I26-I30 | J31: =J26-J30 | K31: =K26-K30 | L31: =L26-L30 | M31: =M26-M30 | N31: =N26-N30 | O31: =O26-O30 | P31: =P26-P30 | ... T31: =T26-T30
C32: - 배당제외 기준 자본증가율 | I32: =I31/I25 | J32: =J31/J25 | K32: =K31/K25 | L32: =L31/L25 | M32: =M31/M25 | N32: =N31/N25 | O32: =O31/O25 | P32: =P31/P25 | ... T32: =T31/T25
A35: =DATA!$BF$1 | C35: * 기타포괄손익 부채 변동금액 | I35: =VLOOKUP($I$1&I$8,DATA!$A:$EB,'2406'!$A35,0)/100 | J35: =VLOOKUP($I$1&J$8,DATA!$A:$EB,'2406'!$A35,0)/100 | K35: =VLOOKUP($I$1&K$8,DATA!$A:$EB,'2406'!$A35,0)/100 | L35: =VLOOKUP($I$1&L$8,DATA!$A:$EB,'2406'!$A35,0)/100 | M35: =VLOOKUP($I$1&M$8,DATA!$A:$EB,'2406'!$A35,0)/100 | N35: =VLOOKUP($I$1&N$8,DATA!$A:$EB,'2406'!$A35,0)/100 | O35: =VLOOKUP($I$1&O$8,DATA!$A:$EB,'2406'!$A35,0)/100 | P35: =VLOOKUP($I$1&P$8,DATA!$A:$EB,'2406'!$A35,0)/100 | ... T35: =VLOOKUP($I$1&T$8,DATA!$A:$EB,'2406'!$A35,0)/100
C36: 부채변동금액 / (bel+ra+csm) | I36: =I35/(I15+I16+I18) | J36: =J35/(J15+J16+J18) | K36: =K35/(K15+K16+K18) | L36: =L35/(L15+L16+L18) | M36: =M35/(M15+M16+M18) | N36: =N35/(N15+N16+N18) | O36: =O35/(O15+O16+O18) | P36: =P35/(P15+P16+P18) | ... T36: =T35/(T15+T16+T18)
A37: =DATA!$BD$1 | C37: * 기타포괄손익 자산 변동금액 | I37: =VLOOKUP($I$1&I$8,DATA!$A:$EB,'2406'!$A37,0)/100 | J37: =VLOOKUP($I$1&J$8,DATA!$A:$EB,'2406'!$A37,0)/100 | K37: =VLOOKUP($I$1&K$8,DATA!$A:$EB,'2406'!$A37,0)/100 | L37: =VLOOKUP($I$1&L$8,DATA!$A:$EB,'2406'!$A37,0)/100 | M37: =VLOOKUP($I$1&M$8,DATA!$A:$EB,'2406'!$A37,0)/100 | N37: =VLOOKUP($I$1&N$8,DATA!$A:$EB,'2406'!$A37,0)/100 | O37: =VLOOKUP($I$1&O$8,DATA!$A:$EB,'2406'!$A37,0)/100 | P37: =VLOOKUP($I$1&P$8,DATA!$A:$EB,'2406'!$A37,0)/100 | ... T37: =VLOOKUP($I$1&T$8,DATA!$A:$EB,'2406'!$A37,0)/100
C38: 부채변동금액 / (bel+ra+csm) | I38: =I37/(I15+I16+I18) | J38: =J37/(J15+J16+J18) | K38: =K37/(K15+K16+K18) | L38: =L37/(L15+L16+L18) | M38: =M37/(M15+M16+M18) | N38: =N37/(N15+N16+N18) | O38: =O37/(O15+O16+O18) | P38: =P37/(P15+P16+P18) | ... T38: =T37/(T15+T16+T18)
A40: =DATA!BM1 | C40: * 전기말 이익잉여금 | I40: =VLOOKUP($I$1&I$8,DATA!$A:$EB,'2406'!$A40,0)/100 | J40: =VLOOKUP($I$1&J$8,DATA!$A:$EB,'2406'!$A40,0)/100 | K40: =VLOOKUP($I$1&K$8,DATA!$A:$EB,'2406'!$A40,0)/100 | L40: =VLOOKUP($I$1&L$8,DATA!$A:$EB,'2406'!$A40,0)/100 | M40: =VLOOKUP($I$1&M$8,DATA!$A:$EB,'2406'!$A40,0)/100 | N40: =VLOOKUP($I$1&N$8,DATA!$A:$EB,'2406'!$A40,0)/100 | O40: =VLOOKUP($I$1&O$8,DATA!$A:$EB,'2406'!$A40,0)/100 | P40: =VLOOKUP($I$1&P$8,DATA!$A:$EB,'2406'!$A40,0)/100 | ... T40: =VLOOKUP($I$1&T$8,DATA!$A:$EB,'2406'!$A40,0)/100
D41: 전기말 대비 | I41: =+I20-I40 | J41: =+J20-J40 | K41: =+K20-K40 | L41: =+L20-L40 | M41: =+M20-M40 | N41: =+N20-N40 | O41: =+O20-O40 | P41: =+P20-P40 | ... T41: =+T20-T40
D42: 2Q | I42: =+I20-'2403'!I20 | J42: =+J20-'2403'!J20 | K42: =+K20-'2403'!K20 | L42: =+L20-'2403'!L20 | M42: =+M20-'2403'!M20 | N42: =+N20-'2403'!N20 | O42: =+O20-'2403'!O20 | P42: =+P20-'2403'!P20 | ... T42: =+T20-'2403'!T20
C47: 2. 재무건전성(잠정치)
T48: (단위 : 억원)
C49: 구분 | I49: 미래에셋생명 | J49: 삼성생명 | K49: 교보생명 | L49: 한화생명 | M49: 신한라이프 | N49: 동양생명 | O49: KB라이프 | P49: 삼성화재 | Q49: 현대해상 | R49: 메리츠화재 | S49: KB손보 | T49: DB손보
A50: =DATA!$CN$1 | C50: K-ICS | I50: =VLOOKUP($I$1&I$8,DATA!$A:$EB,'2406'!$A50,0) | J50: =VLOOKUP($I$1&J$8,DATA!$A:$EB,'2406'!$A50,0) | K50: =VLOOKUP($I$1&K$8,DATA!$A:$EB,'2406'!$A50,0) | L50: =VLOOKUP($I$1&L$8,DATA!$A:$EB,'2406'!$A50,0) | M50: =VLOOKUP($I$1&M$8,DATA!$A:$EB,'2406'!$A50,0) | N50: =VLOOKUP($I$1&N$8,DATA!$A:$EB,'2406'!$A50,0) | O50: =VLOOKUP($I$1&O$8,DATA!$A:$EB,'2406'!$A50,0) | P50: =VLOOKUP($I$1&P$8,DATA!$A:$EB,'2406'!$A50,0) | ... T50: =VLOOKUP($I$1&T$8,DATA!$A:$EB,'2406'!$A50,0)
A51: =DATA!$CO$1 | C51: 가용자본 | I51: =VLOOKUP($I$1&I$8,DATA!$A:$EB,'2406'!$A51,0)/100 | J51: =VLOOKUP($I$1&J$8,DATA!$A:$EB,'2406'!$A51,0)/100 | K51: =VLOOKUP($I$1&K$8,DATA!$A:$EB,'2406'!$A51,0)/100 | L51: =VLOOKUP($I$1&L$8,DATA!$A:$EB,'2406'!$A51,0)/100 | M51: =VLOOKUP($I$1&M$8,DATA!$A:$EB,'2406'!$A51,0)/100 | N51: =VLOOKUP($I$1&N$8,DATA!$A:$EB,'2406'!$A51,0)/100 | O51: =VLOOKUP($I$1&O$8,DATA!$A:$EB,'2406'!$A51,0)/100 | P51: =VLOOKUP($I$1&P$8,DATA!$A:$EB,'2406'!$A51,0)/100 | ... T51: =VLOOKUP($I$1&T$8,DATA!$A:$EB,'2406'!$A51,0)/100
A52: =DATA!$CP$1 | C52: 요구자본 | I52: =VLOOKUP($I$1&I$8,DATA!$A:$EB,'2406'!$A52,0)/100 | J52: =VLOOKUP($I$1&J$8,DATA!$A:$EB,'2406'!$A52,0)/100 | K52: =VLOOKUP($I$1&K$8,DATA!$A:$EB,'2406'!$A52,0)/100 | L52: =VLOOKUP($I$1&L$8,DATA!$A:$EB,'2406'!$A52,0)/100 | M52: =VLOOKUP($I$1&M$8,DATA!$A:$EB,'2406'!$A52,0)/100 | N52: =VLOOKUP($I$1&N$8,DATA!$A:$EB,'2406'!$A52,0)/100 | O52: =VLOOKUP($I$1&O$8,DATA!$A:$EB,'2406'!$A52,0)/100 | P52: =VLOOKUP($I$1&P$8,DATA!$A:$EB,'2406'!$A52,0)/100 | ... T52: =VLOOKUP($I$1&T$8,DATA!$A:$EB,'2406'!$A52,0)/100
C53: * 경과조치 전
...

Sheet 2403
C1: 기준월 | I1: 2403 | J1: =ROUNDUP(RIGHT(I1,2)/3,0)
C4: 1. 자산 구성현황
O7: (단위 : 억원)
C8: 구분 | I8: 미래 | J8: 삼성 | K8: 교보 | L8: 한화 | M8: 신한라이프 | N8: 동양 | O8: KB라이프 | P8: 삼성화재 | Q8: 현대해상 | R8: 메리츠화재 | S8: KB손보 | T8: DB손보
A9: =DATA!D$1 | C9: 자산 | I9: =VLOOKUP($I$1&I$8,DATA!$A:$EB,'2403'!$A9,0)/100 | J9: =VLOOKUP($I$1&J$8,DATA!$A:$EB,'2403'!$A9,0)/100 | K9: =VLOOKUP($I$1&K$8,DATA!$A:$EB,'2403'!$A9,0)/100 | L9: =VLOOKUP($I$1&L$8,DATA!$A:$EB,'2403'!$A9,0)/100 | M9: =VLOOKUP($I$1&M$8,DATA!$A:$EB,'2403'!$A9,0)/100 | N9: =VLOOKUP($I$1&N$8,DATA!$A:$EB,'2403'!$A9,0)/100 | O9: =VLOOKUP($I$1&O$8,DATA!$A:$EB,'2403'!$A9,0)/100 | P9: =VLOOKUP($I$1&P$8,DATA!$A:$EB,'2403'!$A9,0)/100 | ... T9: =VLOOKUP($I$1&T$8,DATA!$A:$EB,'2403'!$A9,0)/100
A10: =DATA!E1 | C10: FVPL | I10: =VLOOKUP($I$1&I$8,DATA!$A:$EB,'2403'!$A10,0)/100 | J10: =VLOOKUP($I$1&J$8,DATA!$A:$EB,'2403'!$A10,0)/100 | K10: =VLOOKUP($I$1&K$8,DATA!$A:$EB,'2403'!$A10,0)/100 | L10: =VLOOKUP($I$1&L$8,DATA!$A:$EB,'2403'!$A10,0)/100 | M10: =VLOOKUP($I$1&M$8,DATA!$A:$EB,'2403'!$A10,0)/100 | N10: =VLOOKUP($I$1&N$8,DATA!$A:$EB,'2403'!$A10,0)/100 | O10: =VLOOKUP($I$1&O$8,DATA!$A:$EB,'2403'!$A10,0)/100 | P10: =VLOOKUP($I$1&P$8,DATA!$A:$EB,'2403'!$A10,0)/100 | ... T10: =VLOOKUP($I$1&T$8,DATA!$A:$EB,'2403'!$A10,0)/100
C11: (비중) | I11: =I10/I9 | J11: =J10/J9 | K11: =K10/K9 | L11: =L10/L9 | M11: =M10/M9 | N11: =N10/N9 | O11: =O10/O9 | P11: =P10/P9 | ... T11: =T10/T9
A12: =DATA!F1 | C12: FVOCI | I12: =VLOOKUP($I$1&I$8,DATA!$A:$EB,'2403'!$A12,0)/100 | J12: =VLOOKUP($I$1&J$8,DATA!$A:$EB,'2403'!$A12,0)/100 | K12: =VLOOKUP($I$1&K$8,DATA!$A:$EB,'2403'!$A12,0)/100 | L12: =VLOOKUP($I$1&L$8,DATA!$A:$EB,'2403'!$A12,0)/100 | M12: =VLOOKUP($I$1&M$8,DATA!$A:$EB,'2403'!$A12,0)/100 | N12: =VLOOKUP($I$1&N$8,DATA!$A:$EB,'2403'!$A12,0)/100 | O12: =VLOOKUP($I$1&O$8,DATA!$A:$EB,'2403'!$A12,0)/100 | P12: =VLOOKUP($I$1&P$8,DATA!$A:$EB,'2403'!$A12,0)/100 | ... T12: =VLOOKUP($I$1&T$8,DATA!$A:$EB,'2403'!$A12,0)/100
A13: =DATA!G1 | C13: AC | I13: =VLOOKUP($I$1&I$8,DATA!$A:$EB,'2403'!$A13,0)/100 | J13: =VLOOKUP($I$1&J$8,DATA!$A:$EB,'2403'!$A13,0)/100 | K13: =VLOOKUP($I$1&K$8,DATA!$A:$EB,'2403'!$A13,0)/100 | L13: =VLOOKUP($I$1&L$8,DATA!$A:$EB,'2403'!$A13,0)/100 | M13: =VLOOKUP($I$1&M$8,DATA!$A:$EB,'2403'!$A13,0)/100 | N13: =VLOOKUP($I$1&N$8,DATA!$A:$EB,'2403'!$A13,0)/100 | O13: =VLOOKUP($I$1&O$8,DATA!$A:$EB,'2403'!$A13,0)/100 | P13: =VLOOKUP($I$1&P$8,DATA!$A:$EB,'2403'!$A13,0)/100 | ... T13: =VLOOKUP($I$1&T$8,DATA!$A:$EB,'2403'!$A13,0)/100
A14: =DATA!L1 | C14: 부채 | I14: =VLOOKUP($I$1&I$8,DATA!$A:$EB,'2403'!$A14,0)/100 | J14: =VLOOKUP($I$1&J$8,DATA!$A:$EB,'2403'!$A14,0)/100 | K14: =VLOOKUP($I$1&K$8,DATA!$A:$EB,'2403'!$A14,0)/100 | L14: =VLOOKUP($I$1&L$8,DATA!$A:$EB,'2403'!$A14,0)/100 | M14: =VLOOKUP($I$1&M$8,DATA!$A:$EB,'2403'!$A14,0)/100 | N14: =VLOOKUP($I$1&N$8,DATA!$A:$EB,'2403'!$A14,0)/100 | O14: =VLOOKUP($I$1&O$8,DATA!$A:$EB,'2403'!$A14,0)/100 | P14: =VLOOKUP($I$1&P$8,DATA!$A:$EB,'2403'!$A14,0)/100 | ... T14: =VLOOKUP($I$1&T$8,DATA!$A:$EB,'2403'!$A14,0)/100
A15: =DATA!BU1 | C15: BEL | I15: =VLOOKUP($I$1&I$8,DATA!$A:$EB,'2403'!$A15,0)/100 | J15: =VLOOKUP($I$1&J$8,DATA!$A:$EB,'2403'!$A15,0)/100 | K15: =VLOOKUP($I$1&K$8,DATA!$A:$EB,'2403'!$A15,0)/100 | L15: =VLOOKUP($I$1&L$8,DATA!$A:$EB,'2403'!$A15,0)/100 | M15: =VLOOKUP($I$1&M$8,DATA!$A:$EB,'2403'!$A15,0)/100 | N15: =VLOOKUP($I$1&N$8,DATA!$A:$EB,'2403'!$A15,0)/100 | O15: =VLOOKUP($I$1&O$8,DATA!$A:$EB,'2403'!$A15,0)/100 | P15: =VLOOKUP($I$1&P$8,DATA!$A:$EB,'2403'!$A15,0)/100 | ... T15: =VLOOKUP($I$1&T$8,DATA!$A:$EB,'2403'!$A15,0)/100
A16: =DATA!BW1 | C16: CSM | I16: =VLOOKUP($I$1&I$8,DATA!$A:$EB,'2403'!$A16,0)/100 | J16: =VLOOKUP($I$1&J$8,DATA!$A:$EB,'2403'!$A16,0)/100 | K16: =VLOOKUP($I$1&K$8,DATA!$A:$EB,'2403'!$A16,0)/100 | L16: =VLOOKUP($I$1&L$8,DATA!$A:$EB,'2403'!$A16,0)/100 | M16: =VLOOKUP($I$1&M$8,DATA!$A:$EB,'2403'!$A16,0)/100 | N16: =VLOOKUP($I$1&N$8,DATA!$A:$EB,'2403'!$A16,0)/100 | O16: =VLOOKUP($I$1&O$8,DATA!$A:$EB,'2403'!$A16,0)/100 | P16: =VLOOKUP($I$1&P$8,DATA!$A:$EB,'2403'!$A16,0)/100 | ... T16: =VLOOKUP($I$1&T$8,DATA!$A:$EB,'2403'!$A16,0)/100
C17: (비중) | I17: =I16/I14 | J17: =J16/J14 | K17: =K16/K14 | L17: =L16/L14 | M17: =M16/M14 | N17: =N16/N14 | O17: =O16/O14 | P17: =P16/P14 | ... T17: =T16/T14
A18: =DATA!BV1 | C18: RA | I18: =VLOOKUP($I$1&I$8,DATA!$A:$EB,'2403'!$A18,0)/100 | J18: =VLOOKUP($I$1&J$8,DATA!$A:$EB,'2403'!$A18,0)/100 | K18: =VLOOKUP($I$1&K$8,DATA!$A:$EB,'2403'!$A18,0)/100 | L18: =VLOOKUP($I$1&L$8,DATA!$A:$EB,'2403'!$A18,0)/100 | M18: =VLOOKUP($I$1&M$8,DATA!$A:$EB,'2403'!$A18,0)/100 | N18: =VLOOKUP($I$1&N$8,DATA!$A:$EB,'2403'!$A18,0)/100 | O18: =VLOOKUP($I$1&O$8,DATA!$A:$EB,'2403'!$A18,0)/100 | P18: =VLOOKUP($I$1&P$8,DATA!$A:$EB,'2403'!$A18,0)/100 | ... T18: =VLOOKUP($I$1&T$8,DATA!$A:$EB,'2403'!$A18,0)/100
A19: =DATA!N1 | C19: 자기자본 | I19: =VLOOKUP($I$1&I$8,DATA!$A:$EB,'2403'!$A19,0)/100 | J19: =VLOOKUP($I$1&J$8,DATA!$A:$EB,'2403'!$A19,0)/100 | K19: =VLOOKUP($I$1&K$8,DATA!$A:$EB,'2403'!$A19,0)/100 | L19: =VLOOKUP($I$1&L$8,DATA!$A:$EB,'2403'!$A19,0)/100 | M19: =VLOOKUP($I$1&M$8,DATA!$A:$EB,'2403'!$A19,0)/100 | N19: =VLOOKUP($I$1&N$8,DATA!$A:$EB,'2403'!$A19,0)/100 | O19: =VLOOKUP($I$1&O$8,DATA!$A:$EB,'2403'!$A19,0)/100 | P19: =VLOOKUP($I$1&P$8,DATA!$A:$EB,'2403'!$A19,0)/100 | ... T19: =VLOOKUP($I$1&T$8,DATA!$A:$EB,'2403'!$A19,0)/100
A20: =DATA!R1 | C20: 이익잉여금 | I20: =VLOOKUP($I$1&I$8,DATA!$A:$EB,'2403'!$A20,0)/100 | J20: =VLOOKUP($I$1&J$8,DATA!$A:$EB,'2403'!$A20,0)/100 | K20: =VLOOKUP($I$1&K$8,DATA!$A:$EB,'2403'!$A20,0)/100 | L20: =VLOOKUP($I$1&L$8,DATA!$A:$EB,'2403'!$A20,0)/100 | M20: =VLOOKUP($I$1&M$8,DATA!$A:$EB,'2403'!$A20,0)/100 | N20: =VLOOKUP($I$1&N$8,DATA!$A:$EB,'2403'!$A20,0)/100 | O20: =VLOOKUP($I$1&O$8,DATA!$A:$EB,'2403'!$A20,0)/100 | P20: =VLOOKUP($I$1&P$8,DATA!$A:$EB,'2403'!$A20,0)/100 | ... T20: =VLOOKUP($I$1&T$8,DATA!$A:$EB,'2403'!$A20,0)/100
A21: =DATA!Q1 | C21: 기타포괄 | I21: =VLOOKUP($I$1&I$8,DATA!$A:$EB,'2403'!$A21,0)/100 | J21: =VLOOKUP($I$1&J$8,DATA!$A:$EB,'2403'!$A21,0)/100 | K21: =VLOOKUP($I$1&K$8,DATA!$A:$EB,'2403'!$A21,0)/100 | L21: =VLOOKUP($I$1&L$8,DATA!$A:$EB,'2403'!$A21,0)/100 | M21: =VLOOKUP($I$1&M$8,DATA!$A:$EB,'2403'!$A21,0)/100 | N21: =VLOOKUP($I$1&N$8,DATA!$A:$EB,'2403'!$A21,0)/100 | O21: =VLOOKUP($I$1&O$8,DATA!$A:$EB,'2403'!$A21,0)/100 | P21: =VLOOKUP($I$1&P$8,DATA!$A:$EB,'2403'!$A21,0)/100 | ... T21: =VLOOKUP($I$1&T$8,DATA!$A:$EB,'2403'!$A21,0)/100
C22: - 금융자산비중 | I22: =+I20/I9 | J22: =+J20/J9 | K22: =+K20/K9 | L22: =+L20/L9 | M22: =+M20/M9 | N22: =+N20/N9 | O22: =+O20/O9 | P22: =+P20/P9 | ... T22: =+T20/T9
A25: =DATA!T1 | C25: * 전기자기자본 | I25: =VLOOKUP($I$1&I$8,DATA!$A:$EB,'2403'!$A25,0)/100 | J25: =VLOOKUP($I$1&J$8,DATA!$A:$EB,'2403'!$A25,0)/100 | K25: =VLOOKUP($I$1&K$8,DATA!$A:$EB,'2403'!$A25,0)/100 | L25: =VLOOKUP($I$1&L$8,DATA!$A:$EB,'2403'!$A25,0)/100 | M25: =VLOOKUP($I$1&M$8,DATA!$A:$EB,'2403'!$A25,0)/100 | N25: =VLOOKUP($I$1&N$8,DATA!$A:$EB,'2403'!$A25,0)/100 | O25: =VLOOKUP($I$1&O$8,DATA!$A:$EB,'2403'!$A25,0)/100 | P25: =VLOOKUP($I$1&P$8,DATA!$A:$EB,'2403'!$A25,0)/100 | ... T25: =VLOOKUP($I$1&T$8,DATA!$A:$EB,'2403'!$A25,0)/100
C26: - 전기대비 증감 | I26: =I19-I25 | J26: =J19-J25 | K26: =K19-K25 | L26: =L19-L25 | M26: =M19-M25 | N26: =N19-N25 | O26: =O19-O25 | P26: =P19-P25 | ... T26: =T19-T25
A27: =DATA!BC1 | C27: * 전기기타포괄 | I27: =VLOOKUP($I$1&I$8,DATA!$A:$EB,'2403'!$A27,0)/100 | J27: =VLOOKUP($I$1&J$8,DATA!$A:$EB,'2403'!$A27,0)/100 | K27: =VLOOKUP($I$1&K$8,DATA!$A:$EB,'2403'!$A27,0)/100 | L27: =VLOOKUP($I$1&L$8,DATA!$A:$EB,'2403'!$A27,0)/100 | M27: =VLOOKUP($I$1&M$8,DATA!$A:$EB,'2403'!$A27,0)/100 | N27: =VLOOKUP($I$1&N$8,DATA!$A:$EB,'2403'!$A27,0)/100 | O27: =VLOOKUP($I$1&O$8,DATA!$A:$EB,'2403'!$A27,0)/100 | P27: =VLOOKUP($I$1&P$8,DATA!$A:$EB,'2403'!$A27,0)/100 | ... T27: =VLOOKUP($I$1&T$8,DATA!$A:$EB,'2403'!$A27,0)/100
A28: =DATA!BN1 | C28: 1) 결산배당 | I28: =VLOOKUP($I$1&I$8,DATA!$A:$EB,'2403'!$A28,0)/100 | J28: =VLOOKUP($I$1&J$8,DATA!$A:$EB,'2403'!$A28,0)/100 | K28: =VLOOKUP($I$1&K$8,DATA!$A:$EB,'2403'!$A28,0)/100 | L28: =VLOOKUP($I$1&L$8,DATA!$A:$EB,'2403'!$A28,0)/100 | M28: =VLOOKUP($I$1&M$8,DATA!$A:$EB,'2403'!$A28,0)/100 | N28: =VLOOKUP($I$1&N$8,DATA!$A:$EB,'2403'!$A28,0)/100 | O28: =VLOOKUP($I$1&O$8,DATA!$A:$EB,'2403'!$A28,0)/100 | P28: =VLOOKUP($I$1&P$8,DATA!$A:$EB,'2403'!$A28,0)/100 | ... T28: =VLOOKUP($I$1&T$8,DATA!$A:$EB,'2403'!$A28,0)/100
A29: =DATA!BR1 | C29: 2) 기타배당 | I29: =VLOOKUP($I$1&I$8,DATA!$A:$EB,'2403'!$A29,0)/100 | J29: =VLOOKUP($I$1&J$8,DATA!$A:$EB,'2403'!$A29,0)/100 | K29: =VLOOKUP($I$1&K$8,DATA!$A:$EB,'2403'!$A29,0)/100 | L29: =VLOOKUP($I$1&L$8,DATA!$A:$EB,'2403'!$A29,0)/100 | M29: =VLOOKUP($I$1&M$8,DATA!$A:$EB,'2403'!$A29,0)/100 | N29: =VLOOKUP($I$1&N$8,DATA!$A:$EB,'2403'!$A29,0)/100 | O29: =VLOOKUP($I$1&O$8,DATA!$A:$EB,'2403'!$A29,0)/100 | P29: =VLOOKUP($I$1&P$8,DATA!$A:$EB,'2403'!$A29,0)/100 | ... T29: =VLOOKUP($I$1&T$8,DATA!$A:$EB,'2403'!$A29,0)/100
C30: 배당합계 | I30: =I28+I29 | J30: =J28+J29 | K30: =K28+K29 | L30: =L28+L29 | M30: =M28+M29 | N30: =N28+N29 | O30: =O28+O29 | P30: =P28+P29 | ... T30: =T28+T29
