Workbook
Name language: [1]INDEX!$E$103:$E$104
Name language: [2]INDEX!$E$102:$E$103
Name language: [3]INDEX!$E$103:$E$104
Name language: [4]INDEX!$E$102:$E$103
Name language: [4]INDEX!$E$102:$E$103
Name language: [5]INDEX!$E$103:$E$104
Name language: [6]INDEX!$E$103:$E$104
Name language: [7]INDEX!$E$102:$E$103
Name language: [8]INDEX!$E$102:$E$103
Name language: [8]INDEX!$E$102:$E$103
Name language: [9]INDEX!$E$103:$E$104
Name language: [10]INDEX!$E$103:$E$104
Name language: INDEX!$E$103:$E$104
Name 손익분석: [11]INDEX!$G$9

Sheet INDEX
G2: =VLOOKUP(G103,$G$103:$H$138,$F$103,0) -> 재무 실적 | I2: =VLOOKUP(G124,$G$103:$H$138,$F$103,0) -> 경영효율성
G3: =VLOOKUP(G104,$G$103:$H$138,$F$103,0) -> 재무실적 요약 | I3: =VLOOKUP(G124,$G$103:$H$138,$F$103,0) -> 경영효율성
G4: =VLOOKUP(G105,$G$103:$H$138,$F$103,0) -> K-IFRS 재무상태표 | I4: =VLOOKUP(G125,$G$103:$H$138,$F$103,0) -> 손해율
G5: =VLOOKUP(G106,$G$103:$H$138,$F$103,0) -> K-IFRS 손익계산서 | I5: =VLOOKUP(G126,$G$103:$H$138,$F$103,0) -> 유지율
G6: =VLOOKUP(G107,$G$103:$H$138,$F$103,0) -> 보험회계기준 (SAP) 재무상태표 | I6: =VLOOKUP(G127,$G$103:$H$138,$F$103,0) -> 보유고객
G7: =VLOOKUP(G108,$G$103:$H$138,$F$103,0) -> 보험회계기준 (SAP) 손익계산서
G8: =VLOOKUP(G140,$G$103:$H$141,$F$103,0) -> CSM 현황 | I8: =VLOOKUP(G129,$G$103:$H$138,$F$103,0) -> 자산운용
G9: =VLOOKUP(G109,$G$103:$H$138,$F$103,0) -> 손익현황 | I9: =VLOOKUP(G130,$G$103:$H$138,$F$103,0) -> 자산 포트폴리오
B10: 2025 Q4 | G10: =VLOOKUP(G110,$G$103:$H$138,$F$103,0) -> 신계약현황 | I10: =VLOOKUP(G131,$G$103:$H$138,$F$103,0) -> 자산별 투자성과
B11: d | I11: =VLOOKUP(G132,$G$103:$H$138,$F$103,0) -> 자산건전성
G12: =VLOOKUP(G112,$G$103:$H$138,$F$103,0) -> 수입보험료 실적
G13: =VLOOKUP(G113,$G$103:$H$138,$F$103,0) -> 수입보험료 | I13: =VLOOKUP(G134,$G$103:$H$138,$F$103,0) -> 재무안정성
G14: =VLOOKUP(G114,$G$103:$H$138,$F$103,0) -> 초회보험료 | I14: =VLOOKUP(G135,$G$103:$H$138,$F$103,0) -> 적립금비중
G15: =VLOOKUP(G115,$G$103:$H$138,$F$103,0) -> 초년도보험료 | I15: =VLOOKUP(G136,$G$103:$H$138,$F$103,0) -> 평균부담금리
G16: =VLOOKUP(G116,$G$103:$H$138,$F$103,0) -> 채널별 초회보험료 | I16: =VLOOKUP(G137,$G$103:$H$138,$F$103,0) -> 자산부채 듀레이션
G17: =VLOOKUP(G117,$G$103:$H$138,$F$103,0) -> 채널별 초년도보험료 | I17: =VLOOKUP(G138,$G$103:$H$138,$F$103,0) -> 자산부채 금리
G18: =VLOOKUP(G118,$G$103:$H$138,$F$103,0) -> 상품/채널별 APE
I19: =VLOOKUP(G142,$G$103:$H$142,$F$103,0) -> 자회사
G20: =VLOOKUP(G120,$G$103:$H$138,$F$103,0) -> Fee-Biz 실적 | I20: =VLOOKUP(G143,$G$103:$H$143,$F$103,0) -> 미래에셋금융서비스
G21: =VLOOKUP(G121,$G$103:$H$138,$F$103,0) -> 변액보험
G22: =VLOOKUP(G122,$G$103:$H$138,$F$103,0) -> 퇴직연금 | I22: =VLOOKUP(G145,$G$103:$H$146,$F$103,0) -> 부채 변동
I23: =VLOOKUP(G146,$G$103:$H$146,$F$103,0) -> 잔여보장부채 무브먼트
G37: 0
D101: LANGUAGE SELECTOR
E103: KOREAN | F103: 1 | G103: 재무 실적 | H103: Financial Results
E104: ENGLISH | G104: 재무실적 요약 | H104: Condensed F/S
G105: K-IFRS 재무상태표 | H105: K-IFRS Balance Sheet
G106: K-IFRS 손익계산서 | H106: K-IFRS Income Statement
G107: 보험회계기준 (SAP) 재무상태표 | H107: SAP Balance Sheet
G108: 보험회계기준 (SAP) 손익계산서 | H108: SAP Income Statement
G109: 손익현황 | H109: Earnings Results
G110: 신계약현황 | H110: New Business
G112: 수입보험료 실적 | H112: Premium Income
G113: 수입보험료 | H113: Premium Breakdown
G114: 초회보험료 | H114: Initial Premium
G115: 초년도보험료 | H115: First Year Premium
G116: 채널별 초회보험료 | H116: Initial Premium by Channel
G117: 채널별 초년도보험료 | H117: First Year Premium by Channel
... G146: 잔여보장부채 무브먼트 | H146: Movement of Liabilities for Remaining Coverage

Sheet SUMMARY
B1: =[9]INDEX!$G$3 -> 재무실적 요약 | C1: Financial Highlights
B2: (BN KRW, %, %p)
B4: 별도기준 | C4: Unconsolidated Basis | D4: =I4 -> 2025 | E4: =N4 -> 2024 | F4: YoY | I4: 2025 | N4: 2024 | Q4: 2023 | V4: 2022 | Z4: 2021
D5: =I5 -> 4 | E5: =M5 -> 4 | I5: 4 | J5: 3 | K5: 2 | L5: 1 | M5: 4 | N5: 3 | O5: 2 | P5: 1 | Q5: 4 | R5: 3 | S5: 2 | T5: 1 | V5: 4 | W5: 3 | X5: 2 | Y5: 1 | Z5: FY
B6: 자산총계 | C6: Total Assets | D6: =I6 -> 32855.182 | E6: =M6 -> 32404.439 | F6: =+IFERROR(IF(E6<0,-(D6/E6-1),(D6/E6-1)),0) -> 0.013909919 | I6: 32855.182 | J6: 33165.463 | K6: 32215.468 | L6: 32214.589 | M6: 32404.439 | N6: 32232.653 | O6: 32188.593 | P6: 32333.017 | Q6: 33046.193 | R6: 32111.06 | S6: 32951.333 | T6: 33150.631 | V6: 34991.095 | W6: 36813.714 | X6: 36977.267 | Y6: 38438.524
B7: 부채총계 | C7: Total Liabilities | D7: =I7 -> 30418.68 | E7: =M7 -> 29851.201 | F7: =+IFERROR(IF(E7<0,-(D7/E7-1),(D7/E7-1)),0) -> 0.019010275 | I7: 30418.68 | J7: 30683.352 | K7: 29744.746 | L7: 29747.791 | M7: 29851.201 | N7: 29703.68 | O7: 29660.895 | P7: 29599.142 | Q7: 30027.166 | R7: 29140.784 | S7: 30008.69 | T7: 30274.4 | V7: 30902.57 | W7: 32521.422 | X7: 33072.626 | Y7: 35087.284
B8: 자본총계 | C8: Total Equity | D8: =I8 -> 2436.5016 | E8: =M8 -> 2553.2379 | F8: =+IFERROR(IF(E8<0,-(D8/E8-1),(D8/E8-1)),0) -> -0.045720922 | I8: 2436.5016 | J8: 2482.1114 | K8: 2470.7229 | L8: 2466.7972 | M8: 2553.2379 | N8: 2528.9733 | O8: 2527.6974 | P8: 2733.8755 | Q8: 3019.0271 | R8: 2970.276 | S8: 2942.6434 | T8: 2876.2309 | V8: 4088.5253 | W8: 4292.292 | X8: 3904.6406 | Y8: 3351.2394 | Z8: 2694.5031
D9: =D5 -> 4 | E9: =E5 -> 4 | F9: YoY | K9: =K8/M8-1 -> -0.03231781
B10: 보험서비스손익 | C10: Insurance service income | D10: =SUM(I10:L10) -> 111.99011 | E10: =SUM(M10:P10) -> 119.27554 | F10: =+IFERROR(IF(E10<0,-(D10/E10-1),(D10/E10-1)),0) -> -0.061080709 | I10: -5.880676 | J10: 34.30921 | K10: 44.676269 | L10: 38.885307 | M10: 19.855061 | N10: 31.404157 | O10: 45.718813 | P10: 22.297512 | Q10: 57.394659 | R10: 27.339907 | S10: 40.567695 | T10: 43.698505 | V10: 21.695846 | W10: 26.28169 | X10: 37.2643 | Y10: 37.705991
B11: 투자손익 | C11: Investment income | D11: =SUM(I11:L11) -> 73.866157 | E11: =SUM(M11:P11) -> -4.33664 | F11: =+IFERROR(IF(E11<0,-(D11/E11-1),(D11/E11-1)),0) -> 18.033038 | I11: 28.907445 | J11: 24.543101 | K11: 20.063001 | L11: 0.35260888 | M11: 33.294063 | N11: -27.967507 | O11: -30.821484 | P11: 21.158288 | Q11: -119.39884 | R11: -0.74453509 | S11: 3.7496379 | T11: 93.769318 | V11: -79.149764 | W11: 46.372237 | X11: 21.964919 | Y11: 38.640954
B12: 영업외손익 | C12: Non-Operating Income | D12: =SUM(I12:L12) -> 3.4005108 | E12: =SUM(M12:P12) -> 0.88398245 | F12: =+IFERROR(IF(E12<0,-(D12/E12-1),(D12/E12-1)),0) -> 2.846808 | I12: 6.0941748 | J12: -0.31653275 | K12: -1.4037297 | L12: -0.9734016 | M12: 0.99597178 | N12: -2.0731538 | O12: 3.3419551 | P12: -1.3807906 | Q12: -0.5314674 | R12: -0.80410659 | S12: -1.0082205 | T12: -1.6733323 | V12: 3.7365747 | W12: 1.1965876 | X12: -1.3374574 | Y12: -1.4611123
B13: 세전이익 | C13: Earnings Before Tax | D13: =SUM(I13:L13) -> 189.25678 | E13: =SUM(M13:P13) -> 115.82289 | F13: =+IFERROR(IF(E13<0,-(D13/E13-1),(D13/E13-1)),0) -> 0.63401882 | I13: 29.120944 | J13: 58.535778 | K13: 63.33554 | L13: 38.264514 | M13: 54.145096 | N13: 1.3634963 | O13: 18.239284 | P13: 42.07501 | Q13: -62.535653 | R13: 25.791266 | S13: 43.309113 | T13: 135.79449 | V13: -53.717343 | W13: 73.850514 | X13: 57.891762 | Y13: 74.885832
B14: 법인세비용 | C14: Income Tax Expenses | D14: =SUM(I14:L14) -> 64.356388 | E14: =SUM(M14:P14) -> -9.2160661 | F14: =+IFERROR(IF(E14<0,-(D14/E14-1),(D14/E14-1)),0) -> 7.9830649 | I14: 25.417778 | J14: 12.011954 | K14: 12.981909 | L14: 13.944746 | M14: -23.511844 | N14: 0.31603338 | O14: 4.2275306 | P14: 9.7522136 | Q14: -12.504168 | R14: 1.3247385 | S14: 9.2795916 | T14: 35.0592 | V14: -20.191077 | W14: 17.943629 | X14: 13.179629 | Y14: 18.507928
B15: 당기순이익 | C15: Net Income | D15: =SUM(I15:L15) -> 124.90039 | E15: =SUM(M15:P15) -> 125.03895 | F15: =+IFERROR(IF(E15<0,-(D15/E15-1),(D15/E15-1)),0) -> -0.0011081636 | I15: 3.7031661 | J15: 46.523824 | K15: 50.353631 | L15: 24.319768 | M15: 77.65694 | N15: 1.0474629 | O15: 14.011753 | P15: 32.322796 | Q15: -50.031485 | R15: 24.466527 | S15: 34.029521 | T15: 100.73529 | V15: -33.526266 | W15: 55.906885 | X15: 44.712132 | Y15: 56.377905
B16: ROE (YTD) | C16: ROE (YTD) | D16: =I16 -> 0.05006289 | E16: =M16 -> 0.04487904 | F16: =D16-E16 -> 0.0051838495 | I16: =SUM(I15:L15)/(SUM(I8,$M$8)/2)*(4/I5) -> 0.05006289 | J16: =SUM(J15:L15)/(SUM(J8,$M$8)/2)*(4/J5) -> 0.064184741 | K16: =SUM(K15:L15)/(SUM(K8,$M$8)/2)*(4/K5) -> 0.059453807 | L16: =SUM(L15)/(SUM(L8,$M$8)/2)*(4/L5) -> 0.038756331 | M16: =SUM(M15:P15)/(SUM(M8,$Q$8)/2)*(4/M5) -> 0.04487904 | N16: =SUM(N15:P15)/(SUM(N8,$Q$8)/2)*(4/N5) -> 0.022774338 | O16: =SUM(O15:P15)/(SUM(O8,$Q$8)/2)*(4/O5) -> 0.033413991 | P16: =SUM(P15)/(SUM(P8,$Q$8)/2)*(4/P5) -> 0.044948158 | Q16: =(SUM(Q15:T15)/(SUM(Q8,$AB$8)/2)*(4/Q5)) -> 0.07234109 | R16: =(SUM(R15:T15)/(SUM(R8,$AB$8)/2)*(4/R5)) -> 0.14295537 | S16: =(SUM(S15:U15)/(SUM(S8,$AB$8)/2)*(4/S5)) -> 0.18318878 | T16: =SUM(T15)/(SUM(T8,$AB$8)/2)*(4/T5) -> 0.28018694 | V16: =(SUM(V15:X15)/(SUM(V8+$Z$8)/2)*(4/V5)) -> 0.019782536 | W16: =(SUM(W15:Y15)/(SUM(W8+$Z$8)/2)*(4/W5)) -> 0.059921389 | X16: =(SUM(X15:Z15)/(SUM(X8+$Z$8)/2)*(4/X5)) -> 0.061274639 | Y16: =(SUM(Y15)/(SUM(Y8:$Z$8)/2)*(4/Y5)) -> 0.074601795
T17: IFRS 17 & IFRS 9 ◀ | V17: ▶IFRS 17 + IAS 39
M18: =D23/M23-1 -> -0.045076091
B19: 연결기준 | C19: Consolidated Basis | D19: =D4 -> 2025 | E19: =E4 -> 2024 | F19: YoY | K19: 2025 | N19: 2024 | Q19: 2023 | V19: 2022 | Z19: 2021
D20: =D5 -> 4 | E20: =E5 -> 4 | I20: 4 | J20: 3 | K20: 2 | L20: 1 | M20: 4 | N20: 3 | O20: 2 | P20: 1 | Q20: 4 | R20: 3 | S20: 2 | T20: 1 | V20: 4 | W20: 3 | X20: 2 | Y20: 1 | Z20: FY
B21: 자산총계 | C21: Total Assets | D21: =I21 -> 32920.825 | E21: =M21 -> 32493.624 | F21: =+IFERROR(IF(E21<0,-(D21/E21-1),(D21/E21-1)),0) -> 0.013147242 | I21: 32920.825 | J21: 33221.046 | K21: 32262.704 | L21: 32292.185 | M21: 32493.624 | N21: 32311.033 | O21: 32269.311 | P21: 32398.401 | Q21: 33092.023 | R21: 32212.292 | S21: 33053.385 | T21: 33188.803 | V21: 35041.5 | W21: 36745.351 | X21: 36936.579 | Y21: 38443.846
B22: 부채총계 | C22: Total Liabilities | D22: =I22 -> 30472.73 | E22: =M22 -> 29929.969 | F22: =+IFERROR(IF(E22<0,-(D22/E22-1),(D22/E22-1)),0) -> 0.018134367 | I22: 30472.73 | J22: 30729.498 | K22: 29786.394 | L22: 29814.766 | M22: 29929.969 | N22: 29777.861 | O22: 29737.477 | P22: 29662.595 | Q22: 30076.512 | R22: 29198.963 | S22: 30106.555 | T22: 30322.635 | V22: 30954.6 | W22: 32490.388 | X22: 33056.819 | Y22: 35123.626
B23: 자본총계 | C23: Total Equity | D23: =I23 -> 2448.0951 | E23: =M23 -> 2563.6547 | F23: =+IFERROR(IF(E23<0,-(D23/E23-1),(D23/E23-1)),0) -> -0.045076091 | I23: 2448.0951 | J23: 2491.5482 | K23: 2476.3106 | L23: 2477.4191 | M23: 2563.6547 | N23: 2533.172 | O23: 2531.8337 | P23: 2735.8059 | Q23: 3015.5111 | R23: 3013.3291 | S23: 2946.8304 | T23: 2866.1683 | V23: 4086.9469 | W23: 4254.963 | X23: 3879.7601 | Y23: 3320.2202
D24: =D20 -> 4 | E24: =E20 -> 4 | F24: YoY
B25: 보험서비스손익 | C25: Insurance service income | D25: =SUM(I25:L25) -> 77.004455 | E25: =SUM(M25:P25) -> 84.835761 | F25: =+IFERROR(IF(E25<0,-(D25/E25-1),(D25/E25-1)),0) -> -0.092311375 | I25: -17.474328 | J25: 26.371814 | K25: 36.656362 | L25: 31.450608 | M25: 8.0693026 | N25: 23.588147 | O25: 52.578253 | P25: 0.60005782 | Q25: 0.60005782 | R25: 12.291645 | S25: 27.381107 | T25: 24.494263 | V25: 11.251813 | W25: -2.9381434 | X25: 18.08135 | Y25: 17.281628
B26: 투자손익 | C26: Investment income | D26: =SUM(I26:L26) -> 117.50719 | E26: =SUM(M26:P26) -> 37.294734 | F26: =+IFERROR(IF(E26<0,-(D26/E26-1),(D26/E26-1)),0) -> 2.1507716 | I26: 45.81892 | J26: 35.402674 | K26: 28.38263 | L26: 7.9029618 | M26: 44.286762 | N26: -19.188509 | O26: -34.967611 | P26: 47.164091 | Q26: 47.164091 | R26: -3.113065 | S26: 25.804546 | T26: 115.64915 | V26: -65.481568 | W26: 82.575643 | X26: 41.650388 | Y26: 59.972617
B27: 영업외손익 | C27: Non-Operating Income | D27: =SUM(I27:L27) -> 4.1979196 | E27: =SUM(M27:P27) -> 1.0014912 | F27: =+IFERROR(IF(E27<0,-(D27/E27-1),(D27/E27-1)),0) -> 3.191669 | I27: 6.5440642 | J27: -0.071592624 | K27: -1.2866364 | L27: -0.98791555 | M27: 0.99295031 | N27: -2.0881124 | O27: 3.4873949 | P27: -1.3907415 | Q27: -4.1530448 | R27: 54.4 | S27: -0.85692421 | T27: -1.6587341 | V27: 3.654817 | W27: 1.2096452 | X27: -1.4630999 | Y27: -1.2601205
B28: 세전이익 | C28: Earnings Before Tax | D28: =SUM(I28:L28) -> 198.70956 | E28: =SUM(M28:P28) -> 123.13199 | F28: =+IFERROR(IF(E28<0,-(D28/E28-1),(D28/E28-1)),0) -> 0.6137932 | I28: 34.888656 | J28: 61.702895 | K28: 63.752355 | L28: 38.365654 | M28: 53.349015 | N28: 2.3115258 | O28: 21.098038 | P28: 46.373407 | Q28: 144.57265 | R28: 63.57218 | S28: 52.328729 | T28: 138.48468 | V28: -50.574939 | W28: 80.847145 | X28: 58.268638 | Y28: 75.994125
B29: 법인세비용 | C29: Income Tax Expenses | D29: =SUM(I29:L29) -> 67.933129 | E29: =SUM(M29:P29) -> -12.982885 | F29: =+IFERROR(IF(E29<0,-(D29/E29-1),(D29/E29-1)),0) -> 6.2325141 | I29: 29.34346 | J29: 11.946903 | K29: 13.06019 | L29: 13.582576 | M29: -27.697249 | N29: 0.50945688 | O29: 4.346611 | P29: 9.8582966 | Q29: 43.167939 | R29: 3.1808692 | S29: 6.9935997 | T29: 35.904757 | V29: -25.927837 | W29: 30.891043 | X29: 13.104666 | Y29: 21.651948
B30: 당기순이익 | C30: Net Income | D30: =SUM(I30:L30) -> 130.77643 | E30: =SUM(M30:P30) -> 136.11487 | F30: =+IFERROR(IF(E30<0,-(D30/E30-1),(D30/E30-1)),0) -> -0.0392201 | I30: 5.5451961 | J30: 49.755992 | K30: 50.692165 | L30: 24.783078 | M30: 81.046264 | N30: 1.8020689 | O30: 16.751427 | P30: 36.51511 | Q30: 101.40471 | R30: 60.391311 | S30: 45.335129 | T30: 102.57993 | V30: -24.647102 | W30: 49.956101 | X30: 45.163973 | Y30: 54.342177
B31: ROE (YTD) | C31: ROE (YTD) | D31: =I31 -> 0.052187933 | E31: =M31 -> 0.048793986 | F31: =D31-E31 -> 0.0033939467 | I31: =SUM(I30:L30)/(SUM(I23,M23)/2)*(4/I20) -> 0.052187933 | J31: =SUM(J30:L30)/(SUM(J23,M23)/2)*(4/J20) -> 0.066060644 | K31: =SUM(K30:L30)/(SUM(K23,M23)/2)*(4/K20) -> 0.059901399 | L31: =SUM(L30)/(SUM(L23,M23)/2)*(4/L20) -> 0.03932984 | M31: =SUM(M30:P30)/(SUM(M23,Q23)/2)*(4/M20) -> 0.048793986 | N31: =SUM(N30:P30)/(SUM(N23,Q23)/2)*(4/N20) -> 0.02646567 | O31: =SUM(O30:P30)/(SUM(O23,Q23)/2)*(4/O20) -> 0.038408672 | P31: =SUM(P30)/(SUM(P23,Q23)/2)*(4/P20) -> 0.050791998 | Q31: =SUM(Q30:T30)/(SUM(Q23,$AB$23)/2)*(4/Q20) -> 0.205412 | R31: =SUM(R30:T30)/(SUM(R23,$AB$23)/2)*(4/R20) -> 0.18434217 | S31: =SUM(S30:T30)/(SUM(S23,$AB$23)/2)*(4/S20) -> 0.20077851 | T31: =SUM(T30)/(SUM(T23,$AB$23)/2)*(4/T20) -> 0.28631934 | V31: =SUM(V30:X30)/(SUM(V23,$Z$23)/2)*(4/V20) -> 0.034486855 | W31: =SUM(W30:Y30)/(SUM(W23,$Z$23)/2)*(4/W20) -> 0.09367085 | X31: =SUM(X30:Y30)/(SUM(X23,Z23)/2)*(4/X20) -> 0.10259 | Y31: =SUM(Y30)/(SUM(Y23:$Z$23)/2)*(4/Y20) -> 0.13093632
D32: 25 Q4 | E32: 24 Q4 | F32: YTD | I32: =I20 -> 4 | J32: =J20 -> 3 | K32: =K20 -> 2 | L32: =L20 -> 1 | M32: =M20 -> 4 | N32: =N20 -> 3 | O32: =O20 -> 2 | P32: =P20 -> 1 | Q32: 4 | R32: 3 | S32: 2 | T32: 1 | V32: 4 | W32: 3 | X32: 2 | Y32: 1
B33: K-ICS 비율* | C33: K-ICS Ratio | D33: =D34/D35 -> 1.778836 | E33: =E34/E35 -> 1.9239452 | F33: =D33-E33 -> -0.14510921 | I33: =I34/I35 -> 1.778836 | J33: =J34/J35 -> 1.8297502 | K33: =K34/K35 -> 1.8349775 | L33: =L34/L35 -> 1.8327744 | M33: =M34/M35 -> 1.9239452 | N33: =N34/N35 -> 1.9378836 | O33: =O34/O35 -> 1.9798853 | P33: =P34/P35 -> 2.0716063 | Q33: =Q34/Q35 -> 2.1124457 | R33: 2.0544753 | S33: 2.0971471 | T33: 2.1837034 | V33: =V34/V35 -> 1.9152245 | W33: =W34/W35 -> 1.8340133 | X33: =X34/X35 -> 1.8646034 | Y33: =Y34/Y35 -> 1.8141082
B34: 지급여력금액 | C34: Solvency Capital | D34: =I34 -> 3698.2 | E34: =M34 -> 3579.6384 | F34: =+IFERROR(IF(E34<0,-(D34/E34-1),(D34/E34-1)),0) -> 0.033121113 | I34: 3698.2 | J34: 3666.9416 | K34: 3548.5268 | L34: 3451.1218 | M34: 3579.6384 | N34: 3408.5465 | O34: 3451.9017 | P34: 3604.7089 | Q34: 3815.5943 | R34: 4086.1028 | S34: 4097.0541 | T34: 4047.446 | V34: 3590.1157 | W34: 1933.4664 | X34: 1983.6369 | Y34: 1956.2716
B35: 위험기준지급여력금액 | C35: Required Capital | D35: =I35 -> 2079 | E35: =M35 -> 1860.5719 | F35: =+IFERROR(IF(E35<0,-(D35/E35-1),(D35/E35-1)),0) -> 0.11739835 | I35: 2079 | J35: 2004.0668 | K35: 1933.8258 | L35: 1883.0041 | M35: 1860.5719 | N35: 1758.9015 | O35: 1743.4857 | P35: 1740.055 | Q35: 1806.2449 | R35: 1998.6711 | S35: 1953.6322 | T35: 1853.478 | V35: 1874.5142 | W35: 1054.2271 | X35: 1063.8385 | Y35: 1078.3655
D36: =D28-E28 -> 75.577575 | I36: =I33-J33 -> -0.050914205 | J36: =J33-K33 -> -0.0052273371 | T36: IFRS 17 & IFRS 9 ◀ | V36: ▶IFRS 17 + IAS 39
B37: ▶ *) FY2022 Q4부터 K-ICS비율 기재, 당 분기는 추정치로 기재
B38: *) K-ICS represented from FY2022 Q4, and K-ICS for the current quarter is an estimate

Sheet KIFRS-BS
B1: =[4]INDEX!G4 -> K-IFRS 재무상태표 | C1: Financial Statements K-IFRS | AA1: =B1 -> K-IFRS 재무상태표
B2: (BN KRW, %, %p) | AA2: (BN KRW, %, %p)
B4: 별도 재무상태표 | C4: Unconsolidated B/S | D4: =SUMMARY!D4 -> 2025 | E4: =SUMMARY!E4 -> 2024 | F4: YoY | I4: 2025 | M4: 2024 | Q4: 2023 | U4: 2022 | AA4: 연결 재무상태표 | AB4: Consolidated B/S | AC4: =D4 -> 2025 | AD4: =E4 -> 2024 | AE4: YoY | AH4: 2025 | AL4: 2024 | AP4: 2023 | AT4: 2022
D5: =I5 -> Q4 | E5: =M5 -> Q4 | I5: Q4 | J5: Q3 | K5: Q2 | L5: Q1 | M5: Q4 | N5: Q3 | O5: Q2 | P5: Q1 | Q5: Q4 | R5: Q3 | S5: Q2 | T5: Q1 | U5: Q4 | V5: Q3 | W5: Q2 | X5: Q1 | AC5: =D5 -> Q4 | AD5: =E5 -> Q4 | AH5: Q4 | AI5: Q3 | AJ5: Q2 | AK5: Q1 | AL5: Q4 | AM5: Q3 | AN5: Q2 | AO5: Q1 | AP5: Q4 | AQ5: Q3 | AR5: Q2 | AS5: Q1 | AT5: Q4 | AU5: Q3 | AV5: Q2 | AW5: Q1
B6: 현금및현금성자산 | C6: Cash and cash equivalents | D6: =I6 -> 969.62 | E6: =M6 -> 921.9397 | F6: =IFERROR(IF(D6*E6<0,"-", IF(E6<0,-(D6/E6-1),(D6/E6-1))),0) -> 0.051717373 | I6: 969.62 | J6: 844.62282 | K6: 755.02019 | L6: 759.4889 | M6: 921.9397 | N6: 713.30968 | O6: 681.20769 | P6: 763.20705 | Q6: 1227.2485 | R6: 507.69983 | S6: 505.20667 | T6: 618.40593 | U6: 916.71105 | V6: 518.42812 | W6: ='[12]202206 BS(17및39기준)'!$X$12/1000000000 -> 521.7341 | X6: 671.3237 | AA6: 현금및현금성자산 | AB6: Cash and cash equivalents | AC6: =AH6 -> 982.15285 | AD6: =AL6 -> 932.1848 | AE6: =IFERROR(IF(AC6*AD6<0,"-", IF(AD6<0,-(AC6/AD6-1),(AC6/AD6-1))),0) -> 0.053603165 | AH6: 982.15285 | AI6: 855.30123 | AJ6: 763.67179 | AK6: 768.36804 | AL6: 932.1848 | AM6: 734.58002 | AN6: 702.53872 | AO6: 777.94916 | AP6: 1240.1903 | AQ6: 564.89408 | AR6: 519.50741 | AS6: 633.73853 | AT6: 941.89894 | AU6: 540.85937 | AV6: 552.2069 | AW6: 705.81954
B7: 당기손익-공정가치측정금융자산 | C7: Financial assets measured at fair value through profit or loss | D7: =I7 -> 16944.447 | E7: =M7 -> 15392.284 | F7: =IFERROR(IF(D7*E7<0,"-", IF(E7<0,-(D7/E7-1),(D7/E7-1))),0) -> 0.10084029 | I7: 16944.447 | J7: 16558.857 | K7: 15656.029 | L7: 15112.992 | M7: 15392.284 | N7: 15649.98 | O7: 15956.867 | P7: 16239.529 | Q7: 15850.238 | R7: 16008.301 | S7: 16432.039 | T7: 16441.119 | U7: 0 | V7: 0 | W7: 0 | X7: 0 | AA7: 당기손익-공정가치측정금융자산 | AB7: Fair value profit or loss financial assets | AC7: =AH7 -> 16948.053 | AD7: =AL7 -> 15422.585 | AE7: =IFERROR(IF(AC7*AD7<0,"-", IF(AD7<0,-(AC7/AD7-1),(AC7/AD7-1))),0) -> 0.098911238 | AH7: 16948.053 | AI7: 16563.484 | AJ7: 15652.467 | AK7: 15135.181 | AL7: 15422.585 | AM7: 15714.811 | AN7: 16012.987 | AO7: 16264.2 | AP7: 15868.274 | AQ7: 16065.55 | AR7: 16485.139 | AS7: 16432.28
B8: 기타포괄손익-공정가치측정금융자산 | C8: Fair value other comprehensive income financial assets | D8: =I8 -> 11663.557 | E8: =M8 -> 11969.183 | F8: =IFERROR(IF(D8*E8<0,"-", IF(E8<0,-(D8/E8-1),(D8/E8-1))),0) -> -0.025534405 | I8: 11663.557 | J8: 12326.567 | K8: 12053.809 | L8: 12442.118 | M8: 11969.183 | N8: 11814.069 | O8: 11285.427 | P8: 10964.242 | Q8: 11226.454 | R8: 11032.722 | S8: 11286.579 | T8: 11257.619 | U8: 0 | V8: 0 | W8: 0 | X8: 0 | AA8: 기타포괄손익-공정가치측정금융자산 | AB8: Fair value other comprehensive income financial assets | AC8: =AH8 -> 11663.557 | AD8: =AL8 -> 11969.183 | AE8: =IFERROR(IF(AC8*AD8<0,"-", IF(AD8<0,-(AC8/AD8-1),(AC8/AD8-1))),0) -> -0.025534405 | AH8: 11663.557 | AI8: 12326.567 | AJ8: 12053.809 | AK8: 12442.118 | AL8: 11969.183 | AM8: 11814.069 | AN8: 11285.427 | AO8: 10964.242 | AP8: 11226.454 | AQ8: 11032.722 | AR8: 11286.579 | AS8: 11257.619
B9: 상각후원가측정금융자산 | C9: Amortized cost financial assets | D9: =I9 -> 0 | E9: =M9 -> 0 | F9: =IFERROR(IF(D9*E9<0,"-", IF(E9<0,-(D9/E9-1),(D9/E9-1))),0) -> 0 | K9: 0 | L9: 0 | M9: 0 | N9: 0 | O9: 0 | P9: 0 | Q9: 0 | R9: 107.0486 | S9: 106.68145 | T9: 106.2235 | U9: 0 | V9: 0 | W9: 0 | X9: 0 | AA9: 상각후원가측정금융자산 | AB9: Amortized cost financial assets | AC9: =AH9 -> 0 | AD9: =AL9 -> 0 | AE9: =IFERROR(IF(AC9*AD9<0,"-", IF(AD9<0,-(AC9/AD9-1),(AC9/AD9-1))),0) -> 0 | AP9: 0 | AQ9: 107.0486 | AR9: 106.68145 | AS9: 106.2235
B10: 상각후원가측정대여금및수취채권 | C10: Amortized cost loans and receivables | D10: =I10 -> 2801.4504 | E10: =M10 -> 3499.4634 | F10: =IFERROR(IF(D10*E10<0,"-", IF(E10<0,-(D10/E10-1),(D10/E10-1))),0) -> -0.19946288 | I10: 2801.4504 | J10: 2883.514 | K10: 3067.0061 | L10: 3110.8277 | M10: 3499.4634 | N10: 3420.3512 | O10: 3831.4191 | P10: 3913.1983 | Q10: 4193.4674 | R10: 4115.6953 | S10: 4298.3258 | T10: 4358.1414 | U10: 0 | V10: 0 | W10: 0 | X10: 0 | AA10: 상각후원가측정대여금및수취채권 | AB10: Amortized cost loans and receivables | AC10: =AH10 -> 2881.4165 | AD10: =AL10 -> 3586.235 | AE10: =IFERROR(IF(AC10*AD10<0,"-", IF(AD10<0,-(AC10/AD10-1),(AC10/AD10-1))),0) -> -0.19653438 | AH10: 2881.4165 | AI10: 2963.7312 | AJ10: 3144.866 | AK10: 3192.3909 | AL10: 3586.235 | AM10: 3453.2854 | AN10: 3875.5302 | AO10: 3978.5065 | AP10: 4254.2938 | AQ10: 4145.9337 | AR10: 4337.4868 | AS10: 4399.2037
B11: 파생상품자산* | C11: Derivatives assets | D11: =I11 -> 28.506931 | E11: =M11 -> 238.17821 | F11: =IFERROR(IF(D11*E11<0,"-", IF(E11<0,-(D11/E11-1),(D11/E11-1))),0) -> -0.8803126 | I11: 28.506931 | J11: 141.19189 | K11: 291.83457 | L11: 336.6121 | M11: 238.17821 | N11: 269.18108 | O11: 97.756521 | P11: 69.234655 | Q11: 202.09472 | AA11: 파생상품자산 | AB11: Derivatives assets | AC11: =AH11 -> 31.088117 | AD11: =AL11 -> 238.17821 | AH11: 31.088117 | AI11: 141.19189 | AJ11: 295.1324 | AK11: 336.6121 | AL11: 238.17821 | AM11: 269.18108 | AN11: 97.756521 | AO11: 69.2 | AP11: 202.09472
B12: 종속기업투자주식 | C12: Investments in subsidiaries | D12: =I12 -> 142.04297 | E12: =M12 -> 142.04297 | F12: =IFERROR(IF(D12*E12<0,"-", IF(E12<0,-(D12/E12-1),(D12/E12-1))),0) -> 0 | I12: 142.04297 | J12: 142.04297 | K12: 142.04297 | L12: 142.04297 | M12: 142.04297 | N12: 142.04297 | O12: 142.04297 | P12: 142.04297 | Q12: 142.04297 | R12: 142.04297 | S12: 142.04297 | T12: 142.04297 | U12: 142.04297 | V12: 142.04297 | W12: ='[12]202206 BS(17및39기준)'!$X$110/1000000000 -> 142.04297 | X12: 142.04297 | AA12: 관계기업투자주식 | AB12: Investments in subsidiaries | AC12: =AH12 -> 78.496022 | AD12: =AL12 -> 84.308539 | AE12: =IFERROR(IF(AC12*AD12<0,"-", IF(AD12<0,-(AC12/AD12-1),(AC12/AD12-1))),0) -> -0.068943399 | AH12: 78.496022 | AI12: 77.386405 | AJ12: 76.943424 | AK12: 83.094261 | AL12: 84.308539 | AM12: 80.380294 | AN12: 80.425267 | AO12: 80.771018 | AP12: 78.659011 | AQ12: 79.857887 | AR12: 78.688551 | AS12: 75.518176 | AT12: 68.996458 | AU12: 75.652591 | AV12: 72.864087 | AW12: 72.296687
B13: 재보험계약자산 | C13: Reinsurance contract assets | D13: =I13 -> 37.355227 | E13: =M13 -> 29.754049 | F13: =IFERROR(IF(D13*E13<0,"-", IF(E13<0,-(D13/E13-1),(D13/E13-1))),0) -> 0.25546703 | I13: 37.355227 | J13: 35.615424 | K13: 30.622189 | L13: 27.189943 | M13: 29.754049 | N13: 28.884463 | O13: 26.43551 | P13: 24.546811 | Q13: 24.241131 | R13: 23.232249 | S13: 18.264456 | T13: 17.814597 | U13: 21.072555 | V13: 18.89734 | W13: ='[12]202206 BS(17및39기준)'!$X$160/1000000000 -> 16.274572 | X13: 14.699403 | AA13: 재보험계약자산 | AB13: Reinsurance contract assets | AC13: =AH13 -> 37.355227 | AD13: =AL13 -> 29.754049 | AE13: =IFERROR(IF(AC13*AD13<0,"-", IF(AD13<0,-(AC13/AD13-1),(AC13/AD13-1))),0) -> 0.25546703 | AH13: 37.355227 | AI13: 35.615424 | AJ13: 30.622189 | AK13: 27.189943 | AL13: 29.754049 | AM13: 28.884463 | AN13: 26.43551 | AO13: 24.546811 | AP13: 24.241131 | AQ13: 23.232249 | AR13: 18.264456 | AS13: 17.814597 | AT13: 21.072555 | AU13: 18.89734 | AV13: 16.274572 | AW13: 14.699403
B14: 유형자산 | C14: Tangible assets | D14: =I14 -> 88.612255 | E14: =M14 -> 95.90689 | F14: =IFERROR(IF(D14*E14<0,"-", IF(E14<0,-(D14/E14-1),(D14/E14-1))),0) -> -0.076059554 | I14: 88.612255 | J14: 88.579486 | K14: 91.945785 | L14: 94.110977 | M14: 95.90689 | N14: 90.089673 | O14: 92.276336 | P14: 92.707465 | Q14: 82.398665 | R14: 84.586468 | S14: 86.571404 | T14: 87.27067 | U14: 89.841052 | V14: 90.273192 | W14: ='[12]202206 BS(17및39기준)'!$X$168/1000000000 -> 94.898882 | X14: 96.105008 | AA14: 유형자산 | AB14: Tangible assets | AC14: =AH14 -> 95.345558 | AD14: =AL14 -> 102.37784 | AE14: =IFERROR(IF(AC14*AD14<0,"-", IF(AD14<0,-(AC14/AD14-1),(AC14/AD14-1))),0) -> -0.068689448 | AH14: 95.345558 | AI14: 94.954809 | AJ14: 99.185753 | AK14: 102.51351 | AL14: 102.37784 | AM14: 97.955409 | AN14: 101.40307 | AO14: 103.54285 | AP14: 89.642834 | AQ14: 92.572749 | AR14: 94.951976 | AS14: 95.961637 | AT14: 99.052884 | AU14: 101.07364 | AV14: 107.11983 | AW14: 111.62603
B15: 투자부동산 | C15: Investment in real estate | D15: =I15 -> 0 | E15: =M15 -> 0 | F15: =IFERROR(IF(D15*E15<0,"-", IF(E15<0,-(D15/E15-1),(D15/E15-1))),0) -> 0 | J15: 0 | K15: 0 | L15: 0 | M15: 0 | N15: 0 | O15: 0 | P15: 0 | Q15: 0 | R15: 0 | S15: 0 | T15: 0 | U15: 0 | V15: 0.39671993 | W15: ='[12]202206 BS(17및39기준)'!$X$190/1000000000 -> 0.40106329 | X15: 0.40540665 | AA15: 투자부동산 | AB15: Investment in real estate | AC15: =AH15 -> 0 | AD15: =AL15 | AE15: =IFERROR(IF(AC15*AD15<0,"-", IF(AD15<0,-(AC15/AD15-1),(AC15/AD15-1))),0) -> 0 | AH15: 0 | AI15: 0 | AJ15: 0 | AK15: 0 | AM15: 0 | AN15: 0 | AO15: 0 | AQ15: 0 | AR15: 40.354212 | AS15: 38.129054 | AT15: 42.647263 | AU15: 40.768124 | AV15: 41.823329 | AW15: 35.429156
B16: 무형자산 | C16: Intangible assets | D16: =I16 -> 27.860665 | E16: =M16 -> 31.396666 | F16: =IFERROR(IF(D16*E16<0,"-", IF(E16<0,-(D16/E16-1),(D16/E16-1))),0) -> -0.11262347 | I16: 27.860665 | J16: 31.664802 | K16: 30.797092 | L16: 33.05772 | M16: 31.396666 | N16: 30.860278 | O16: 33.586913 | P16: 36.163701 | Q16: 39.451616 | R16: 39.121364 | S16: 38.034476 | T16: 37.605681 | U16: 40.580946 | V16: 40.722345 | W16: ='[12]202206 BS(17및39기준)'!$X$198/1000000000 -> 43.330049 | X16: 46.022686 | AA16: 무형자산 | AB16: Intangible assets | AC16: =AH16 -> 28.55143 | AD16: =AL16 -> 31.913695 | AE16: =IFERROR(IF(AC16*AD16<0,"-", IF(AD16<0,-(AC16/AD16-1),(AC16/AD16-1))),0) -> -0.10535492 | AH16: 28.55143 | AI16: 32.415564 | AJ16: 31.611416 | AK16: 33.562825 | AL16: 31.913695 | AM16: 31.380678 | AN16: 34.14903 | AO16: 36.555716 | AP16: 39.871623 | AQ16: 39.506415 | AR16: 38.400615 | AS16: 37.997903 | AT16: 40.883601 | AU16: 41.229853 | AV16: 43.872593 | AW16: 46.600632
B17: 당기/이연법인세자산 | C17: Current/Deferred tax assets | D17: =I17 -> 81.38152 | E17: =M17 -> 77.265029 | F17: =IFERROR(IF(D17*E17<0,"-", IF(E17<0,-(D17/E17-1),(D17/E17-1))),0) -> 0.053277544 | I17: 81.38152 | J17: 67.433069 | K17: 46.391678 | L17: 105.2547 | M17: 77.265029 | N17: 65.780204 | O17: 30.646934 | P17: 75.895042 | Q17: 54.265765 | R17: 43.776388 | S17: 26.298066 | T17: 70.372656 | U17: 49.599011 | V17: 146.08034 | W17: =('[12]202206 BS(17및39기준)'!$X$207+'[12]202206 BS(17및39기준)'!$X$208)/1000000000 -> 94.573814 | X17: 70.471202 | AA17: 당기/이연법인세자산 | AB17: Current/Deferred tax assets | AC17: =AH17 -> 81.38152 | AD17: =AL17 -> 76.069044 | AE17: =IFERROR(IF(AC17*AD17<0,"-", IF(AD17<0,-(AC17/AD17-1),(AC17/AD17-1))),0) -> 0.069837557 | AH17: 81.38152 | AI17: 67.433069 | AJ17: 46.391678 | AK17: 104.76129 | AL17: 76.069044 | AM17: 65.780204 | AN17: 30.646934 | AO17: 75.894472 | AP17: 53.376079 | AQ17: 43.038421 | AR17: 25.693519 | AS17: 70.372656 | AT17: 48.7 | AU17: 20.081953 | AV17: 7.6694908 | AW17: 54.676898
B18: 기타자산 | C18: Other assets | D18: =I18 -> 70.347835 | E18: =M18 -> 7.0241426 | F18: =IFERROR(IF(D18*E18<0,"-", IF(E18<0,-(D18/E18-1),(D18/E18-1))),0) -> 9.0151491 | I18: 70.347835 | J18: 45.375303 | K18: 49.970359 | L18: 50.894161 | M18: 7.0241426 | N18: 8.1044417 | O18: 10.926691 | P18: 12.250387 | Q18: 4.2897519 | R18: 6.8333451 | S18: 11.289393 | T18: 14.015854 | U18: 7.6959271 | V18: 18.954167 | W18: ='[12]202206 BS(17및39기준)'!$X$209/1000000000 -> 16.921847 | X18: 15.111433 | AA18: 기타자산 | AB18: Other assets | AC18: =AH18 -> 93.428107 | AD18: =AL18 -> 20.833712 | AE18: =IFERROR(IF(AC18*AD18<0,"-", IF(AD18<0,-(AC18/AD18-1),(AC18/AD18-1))),0) -> 3.4844677 | AH18: 93.428107 | AI18: 62.965188 | AJ18: 68.004055 | AK18: 66.393112 | AL18: 20.833712 | AM18: 20.725821 | AN18: 22.010718 | AO18: 23.040548 | AP18: 14.925172 | AQ18: 17.935837 | AR18: 21.637624 | AS18: 23.945364 | AT18: 17.615291 | AU18: 23.142493 | AV18: 24.683081 | AW18: 22.198884
B20: 자산계 | C20: Total assets | D20: =I20 -> 32855.182 | E20: =M20 -> 32404.439 | F20: =IFERROR(IF(D20*E20<0,"-", IF(E20<0,-(D20/E20-1),(D20/E20-1))),0) -> 0.013909919 | I20: =SUM(I6:I18) -> 32855.182 | J20: 33165.463 | K20: 32215.468 | L20: 32214.589 | M20: 32404.439 | N20: =SUM(N6:N18) -> 32232.653 | O20: 32188.593 | P20: 32333.017 | Q20: 33046.193 | R20: =SUM(R6:R19) -> 32111.06 | S20: =SUM(S6:S19) -> 32951.333 | T20: =SUM(T6:T19) -> 33150.631 | U20: =SUM(U6:U19) -> 1267.5435 | V20: =SUM(V6:V19) -> 975.79519 | W20: =SUM(W6:W19) -> 930.1773 | X20: 38438.524 | AA20: 자산계 | AB20: Total assets | AC20: =AH20 -> 32920.825 | AD20: =AL20 -> 32493.624 | AE20: =IFERROR(IF(AC20*AD20<0,"-", IF(AD20<0,-(AC20/AD20-1),(AC20/AD20-1))),0) -> 0.013147242 | AH20: 32920.825 | AI20: =SUM(AI6:AI18) -> 33221.046 | AJ20: 32262.704 | AK20: 32292.185 | AL20: 32493.624 | AM20: 32311.033 | AN20: 32269.311 | AO20: 32398.449 | AP20: 33092.023 | AQ20: =SUM(AQ6:AQ19) -> 32212.292 | AR20: =SUM(AR6:AR19) -> 33053.385 | AS20: =SUM(AS6:AS19) -> 33188.803 | AT20: =SUM(AT6:AT19) -> 1280.867 | AU20: =SUM(AU6:AU19) -> 861.70537 | AV20: =SUM(AV6:AV19) -> 866.51389 | AW20: 38443.846
B21: 보험계약부채 | C21: Insurance contract liabilities | D21: =I21 -> 26996.698 | E21: =M21 -> 26248.412 | F21: =IFERROR(IF(D21*E21<0,"-", IF(E21<0,-(D21/E21-1),(D21/E21-1))),0) -> 0.028507874 | I21: 26996.698 | J21: 27342.068 | K21: 26726.92 | L21: 26550.413 | M21: 26248.412 | N21: 26174.335 | O21: 26039.097 | P21: 25784.114 | Q21: 25645.534 | R21: 24045.986 | S21: 24896.21 | T21: 25045.177 | U21: 24226.62 | V21: 24626.604 | W21: ='[12]202206 BS(17및39기준)'!$X$244/1000000000 -> 25468.918 | X21: 27685.787 | AA21: 보험계약부채 | AB21: Insurance contract liabilities | AC21: =AH21 -> 26996.698 | AD21: =AL21 -> 26248.412 | AE21: =IFERROR(IF(AC21*AD21<0,"-", IF(AD21<0,-(AC21/AD21-1),(AC21/AD21-1))),0) -> 0.028507874 | AH21: 26996.698 | AI21: 27342.068 | AJ21: 26726.92 | AK21: 26550.413 | AL21: 26248.412 | AM21: 26174.335 | AN21: 26039.097 | AO21: 25784.114 | AP21: 25645.534 | AQ21: 24045.986 | AR21: 24896.21 | AS21: 25045.177 | AT21: 24226.62 | AU21: 24626.604 | AV21: 25468.918 | AW21: 27685.787
B22: 재보험계약부채 | C22: Reinsurance contract liabilities | D22: =I22 -> 0 | E22: =M22 -> 1.3708267 | F22: =IFERROR(IF(D22*E22<0,"-", IF(E22<0,-(D22/E22-1),(D22/E22-1))),0) -> -1 | I22: 0 | J22: 0 | K22: 2.4165891 | L22: 4.3362653 | M22: 1.3708267 | N22: 3.5431381 | O22: 4.7247093 | P22: 5.9267047 | Q22: 0.84792661 | R22: 0.44620526 | S22: 4.5621519 | T22: 5.7090258 | U22: 1.9899343 | V22: 0.71071885 | W22: ='[12]202206 BS(17및39기준)'!$X$249/1000000000 -> 4.5136053 | X22: 8.3379812 | AA22: 재보험계약부채 | AB22: Reinsurance contract liabilities | AC22: =AH22 -> 0 | AD22: =AL22 -> 1.3708267 | AE22: =IFERROR(IF(AC22*AD22<0,"-", IF(AD22<0,-(AC22/AD22-1),(AC22/AD22-1))),0) -> -1 | AH22: 0 | AI22: 0 | AJ22: 2.4165891 | AK22: 4.3362653 | AL22: 1.3708267 | AM22: 3.5431381 | AN22: 4.7247093 | AO22: 5.9267047 | AP22: 0.84792661 | AQ22: 0.44620526 | AR22: 4.5621519 | AS22: 5.7090258 | AT22: 1.9899343 | AU22: 0.71071885 | AV22: 4.5136053 | AW22: 8.3379812
B23: 투자계약부채 | C23: Investment contract liabilities | D23: =I23 -> 2179.7499 | E23: =M23 -> 2425.5571 | F23: =IFERROR(IF(D23*E23<0,"-", IF(E23<0,-(D23/E23-1),(D23/E23-1))),0) -> -0.10134052 | I23: 2179.7499 | J23: 2211.5095 | K23: 2265.6968 | L23: 2314.6336 | M23: 2425.5571 | N23: 2827.468 | O23: 2848.5144 | P23: 2986.4151 | Q23: 3175.2494 | R23: 3899.8098 | S23: 3901.37 | T23: 4010.7684 | U23: 4625.3748 | V23: 5717.6542 | W23: ='[12]202206 BS(17및39기준)'!$X$254/1000000000 -> 5876.9669 | X23: 6050.3652 | AA23: 투자계약부채 | AB23: Investment contract liabilities | AC23: =AH23 -> 2179.7499 | AD23: =AL23 -> 2425.5571 | AE23: =IFERROR(IF(AC23*AD23<0,"-", IF(AD23<0,-(AC23/AD23-1),(AC23/AD23-1))),0) -> -0.10134052 | AH23: 2179.7499 | AI23: 2211.5095 | AJ23: 2265.6968 | AK23: 2314.6336 | AL23: 2425.5571 | AM23: 2827.468 | AN23: 2848.5144 | AO23: 2986.4151 | AP23: 3175.2494 | AQ23: 3899.8098 | AR23: 3901.37 | AS23: 4010.7684 | AT23: 4625.3748 | AU23: 5717.6542 | AV23: 5876.9669 | AW23: 6050.4
B24: 파생상품부채* | C24: Derivatives liabilities | D24: =I24 -> 254.69488 | E24: =M24 -> 284.03899 | F24: -0.43264058 | I24: 254.69488 | J24: 158.40516 | K24: 53.741222 | L24: 219.76782 | M24: 284.03899 | N24: 18.741529 | O24: 94.239883 | P24: 68.457891 | Q24: 20.641073 | R24: 194.00387 | S24: 166.10261 | T24: 0 | U24: 0 | V24: 0 | W24: 0 | X24: 0 | AA24: 파생상품부채 | AB24: Derivatives liabilities | AC24: =AH24 -> 264.30141 | AD24: =AL24 -> 318.41119 | AE24: -0.2982366 | AH24: 264.30141 | AI24: 166.57951 | AJ24: 57.17348 | AK24: 245.86955 | AL24: 318.41119 | AM24: 35.566112 | AN24: 120.49246 | AO24: 82.336924 | AP24: 28.034776 | AQ24: 205.52489 | AR24: 171.69955 | AS24: 234.86755 | AT24: 0 | AV24: 0
B25: 차입부채 | C25: Borrowings | D25: =I25 -> 598.64879 | E25: =M25 -> 499.42995 | F25: =IFERROR(IF(D25*E25<0,"-", IF(E25<0,-(D25/E25-1),(D25/E25-1))),0) -> 0.19866416 | I25: 598.64879 | J25: 299.48975 | K25: 299.4696 | L25: 299.44967 | M25: 499.42995 | N25: 299.40258 | O25: 299.37521 | P25: 299.34813 | Q25: 549.321 | R25: 498.89091 | S25: 498.85706 | T25: 498.82358 | U25: 998.79046 | V25: 498.75798 | W25: ='[12]202206 BS(17및39기준)'!$X$278/1000000000 -> 498.72551 | X25: 498.66878 | AA25: 차입부채 | AB25: Borrowings | AC25: =AH25 -> 598.64879 | AD25: =AL25 -> 499.42995 | AE25: =IFERROR(IF(AC25*AD25<0,"-", IF(AD25<0,-(AC25/AD25-1),(AC25/AD25-1))),0) -> 0.19866416 | AH25: 598.64879 | AI25: 299.48975 | AJ25: 299.4696 | AK25: 299.44967 | AL25: 499.42995 | AM25: 299.40258 | AN25: 299.37521 | AO25: 299.34813 | AP25: 549.321 | AQ25: 498.89091 | AR25: 498.85706 | AS25: 498.82358 | AT25: 998.79046 | AU25: 498.75798 | AV25: 498.72551 | AW25: 498.66878
B26: 확정급여부채 | C26: Defined benefit liabilities | D26: =I26 -> 7.0870528 | E26: =M26 -> 13.107426 | F26: =IFERROR(IF(D26*E26<0,"-", IF(E26<0,-(D26/E26-1),(D26/E26-1))),0) -> -0.4593101 | I26: 7.0870528 | J26: 12.703103 | K26: 13.105233 | L26: 13.158918 | M26: 13.107426 | N26: 11.811167 | O26: 11.694916 | P26: 11.287522 | Q26: 11.286507 | R26: 9.8877 | S26: 10.090391 | T26: 10.227591 | U26: 5.3353768 | V26: 7.1412103 | W26: ='[12]202206 BS(17및39기준)'!$X$288/1000000000 -> 8.0262876 | X26: 9.086525 | AA26: 확정급여부채 | AB26: Defined benefit liabilities | AC26: =AH26 -> 7.0870528 | AD26: =AL26 -> 13.107426 | AE26: =IFERROR(IF(AC26*AD26<0,"-", IF(AD26<0,-(AC26/AD26-1),(AC26/AD26-1))),0) -> -0.4593101 | AH26: 7.0870528 | AI26: 12.703103 | AJ26: 13.105233 | AK26: 13.158918 | AL26: 13.107426 | AM26: 11.811167 | AN26: 11.694916 | AO26: 11.287522 | AP26: 11.286507 | AQ26: 9.8877 | AR26: 10.090391 | AS26: 10.227591 | AT26: 5.3353768 | AU26: 7.1412103 | AV26: 8.0262876 | AW26: 9.086525
B27: 충당부채 | C27: Provisions | D27: =I27 -> 3.0801255 | E27: =M27 -> 2.5117498 | F27: =IFERROR(IF(D27*E27<0,"-", IF(E27<0,-(D27/E27-1),(D27/E27-1))),0) -> 0.22628674 | I27: 3.0801255 | J27: 2.3711717 | K27: 2.5508629 | L27: 2.5500789 | M27: 2.5117498 | N27: 2.0796219 | O27: 2.1344891 | P27: 2.2742992 | Q27: 1.0848891 | R27: 1.0930234 | S27: 1.0551871 | T27: 1.0755425 | U27: 0.97970742 | V27: 1.0115993 | W27: ='[12]202206 BS(17및39기준)'!$X$295/1000000000 -> 0.91826752 | X27: 1.0579353 | AA27: 충당부채 | AB27: Provisions | AC27: =AH27 -> 6.0452451 | AD27: =AL27 -> 5.4752186 | AE27: =IFERROR(IF(AC27*AD27<0,"-", IF(AD27<0,-(AC27/AD27-1),(AC27/AD27-1))),0) -> 0.10411028 | AH27: 6.0452451 | AI27: 5.2850347 | AJ27: 5.4437002 | AK27: 5.4271277 | AL27: 5.4752186 | AM27: 4.9878513 | AN27: 4.9954077 | AO27: 5.2122534 | AP27: 4.03218 | AQ27: 4.0753876 | AR27: 4.0095525 | AS27: 2.9228183 | AT27: 2.8054098 | AU27: 3.029751 | AV27: 2.9317537 | AW27: 3.3462832
B28: 당기/이연법인세부채 | C28: Current/Deferred tax liabilities | D28: =I28 -> 195.36614 | E28: =M28 -> 207.35141 | F28: =IFERROR(IF(D28*E28<0,"-", IF(E28<0,-(D28/E28-1),(D28/E28-1))),0) -> -0.05780173 | I28: 195.36614 | J28: 186.35796 | K28: 184.15353 | L28: 184.10475 | M28: 207.35141 | N28: 240.50888 | O28: 242.99641 | P28: 298.2571 | Q28: 379.82677 | R28: 364.0354 | S28: 361.13438 | T28: 331.98808 | U28: 692.58052 | V28: 912.46387 | W28: ='[12]202206 BS(17및39기준)'!$X$302/1000000000 -> 756.54369 | X28: 525.60829 | AA28: 당기/이연법인세부채 | AB28: Current/Deferred tax liabilities | AC28: =AH28 -> 198.51741 | AD28: =AL28 -> 208.43683 | AE28: =IFERROR(IF(AC28*AD28<0,"-", IF(AD28<0,-(AC28/AD28-1),(AC28/AD28-1))),0) -> -0.047589563 | AH28: 198.51741 | AI28: 185.50014 | AJ28: 183.20022 | AK28: 184.47135 | AL28: 208.43683 | AM28: 245.95059 | AN28: 248.44429 | AO28: 303.71386 | AP28: 384.86042 | AQ28: 353.07511 | AR28: 351.11183 | AS28: 323.69418 | AT28: 677.1 | AU28: 775.26483 | AV28: 647.65256 | AW28: 485.67008
B29: 기타부채 | C29: Other liabilities | D29: =I29 -> 183.35524 | E29: =M29 -> 169.42154 | F29: =IFERROR(IF(D29*E29<0,"-", IF(E29<0,-(D29/E29-1),(D29/E29-1))),0) -> 0.082242832 | I29: 183.35524 | J29: 470.44727 | K29: 196.69154 | L29: 159.37694 | M29: 169.42154 | N29: 125.78916 | O29: 118.11812 | P29: 143.0608 | Q29: 243.37464 | R29: 126.63089 | S29: 169.30767 | T29: =4150.265089409-T23 -> 139.49664 | U29: =4777.97312484492-U23 -> 152.59835 | V29: 135.51201 | W29: =('[12]202206 BS(17및39기준)'!$X$257+'[12]202206 BS(17및39기준)'!$X$303+'[12]202206 BS(17및39기준)'!$X$308)/1000000000 -> 139.96333 | X29: 188.39087 | AA29: 기타부채 | AB29: Other liabilities | AC29: =AH29 -> 221.68205 | AD29: =AL29 -> 209.76865 | AE29: =IFERROR(IF(AC29*AD29<0,"-", IF(AD29<0,-(AC29/AD29-1),(AC29/AD29-1))),0) -> 0.056793028 | AH29: 221.68205 | AI29: 506.36265 | AJ29: 232.96781 | AK29: 197.00589 | AL29: 209.76865 | AM29: 174.79634 | AN29: 160.13858 | AO29: 184.24073 | AP29: 277.34638 | AQ29: 181.26721 | AR29: 268.64374 | AS29: 190.4447 | AT29: 205.0556 | AU29: 183.44712 | AV29: 201.05767 | AW29: 244.2
B31: 부채계 | C31: Total liabilities | D31: =I31 -> 30418.68 | E31: =M31 -> 29851.201 | F31: =IFERROR(IF(D31*E31<0,"-", IF(E31<0,-(D31/E31-1),(D31/E31-1))),0) -> 0.019010275 | I31: =SUM(I21:I29) -> 30418.68 | J31: 30683.352 | K31: 29744.746 | L31: 29747.791 | M31: 29851.201 | N31: =SUM(N21:N29) -> 29703.68 | O31: 29660.895 | P31: 29599.142 | Q31: 30027.166 | R31: =SUM(R21:R30) -> 29140.784 | S31: =SUM(S21:S30) -> 30008.69 | T31: =SUM(T21:T30) -> 30043.266 | U31: =SUM(U21:U30) -> 30704.269 | V31: =SUM(V21:V30) -> 31899.856 | W31: =SUM(W21:W30) -> 32754.576 | X31: 35087.19 | AA31: 부채계 | AB31: Total liabilities | AC31: =AH31 -> 30472.73 | AD31: =AL31 -> 29929.969 | AE31: =IFERROR(IF(AC31*AD31<0,"-", IF(AD31<0,-(AC31/AD31-1),(AC31/AD31-1))),0) -> 0.018134367 | AH31: 30472.73 | AI31: =SUM(AI21:AI29) -> 30729.498 | AJ31: 29786.394 | AK31: 29814.766 | AL31: 29929.969 | AM31: 29777.861 | AN31: 29737.477 | AO31: 29662.595 | AP31: 30076.512 | AQ31: =SUM(AQ21:AQ30) -> 29198.963 | AR31: =SUM(AR21:AR30) -> 30106.555 | AS31: =SUM(AS21:AS30) -> 30322.635 | AT31: =SUM(AT21:AT30) -> 30743.071 | AU31: =SUM(AU21:AU30) -> 31812.61 | AV31: =SUM(AV21:AV30) -> 32708.793 | AW31: 35123.626
B32: 자본금 | C32: Capital stock | D32: =I32 -> 990.71474 | E32: =M32 -> 990.71474 | F32: =IFERROR(IF(D32*E32<0,"-", IF(E32<0,-(D32/E32-1),(D32/E32-1))),0) -> 0 | I32: 990.71474 | J32: 990.71474 | K32: 990.71474 | L32: 990.71474 | M32: 990.71474 | N32: 990.71474 | O32: 990.71474 | P32: 990.71474 | Q32: 990.71474 | R32: 990.71474 | S32: 990.71474 | T32: 990.71474 | U32: 990.71474 | V32: 990.71474 | W32: ='[12]202206 BS(17및39기준)'!$X$336/1000000000 -> 990.71474 | X32: 990.71474 | AA32: 자본금 | AB32: Capital stock | AC32: =AH32 -> 990.71474 | AD32: =AL32 -> 990.71474 | AE32: =IFERROR(IF(AC32*AD32<0,"-", IF(AD32<0,-(AC32/AD32-1),(AC32/AD32-1))),0) -> 0 | AH32: 990.71474 | AI32: 990.71474 | AJ32: 990.71474 | AK32: 990.71474 | AL32: 990.71474 | AM32: 990.71474 | AN32: 990.71474 | AO32: 990.71474 | AP32: 990.71474 | AQ32: 990.71474 | AR32: 990.71474 | AS32: 990.71474 | AT32: 990.71474 | AU32: 990.71474 | AV32: 990.71474 | AW32: 990.71474
B33: 자본잉여금 | C33: Capital surplus | D33: =I33 -> 181.38448 | E33: =M33 -> 181.38448 | F33: =IFERROR(IF(D33*E33<0,"-", IF(E33<0,-(D33/E33-1),(D33/E33-1))),0) -> 0 | I33: 181.38448 | J33: 181.38448 | K33: 181.38448 | L33: 181.38448 | M33: 181.38448 | N33: 181.38448 | O33: 181.38448 | P33: 181.38448 | Q33: 181.38448 | R33: 181.38448 | S33: 181.38448 | T33: 181.38448 | U33: 181.38448 | V33: 181.38448 | W33: ='[12]202206 BS(17및39기준)'!$X$339/1000000000 -> 181.38448 | X33: 181.38448 | AA33: 자본잉여금 | AB33: Capital surplus | AC33: =AH33 -> 181.38448 | AD33: =AL33 -> 181.38448 | AE33: =IFERROR(IF(AC33*AD33<0,"-", IF(AD33<0,-(AC33/AD33-1),(AC33/AD33-1))),0) -> 0 | AH33: 181.38448 | AI33: 181.38448 | AJ33: 181.38448 | AK33: 181.38448 | AL33: 181.38448 | AM33: 181.38448 | AN33: 181.38448 | AO33: 181.38448 | AP33: 181.38448 | AQ33: 181.38448 | AR33: 181.38448 | AS33: 181.38448 | AT33: 181.38448 | AU33: 181.38448 | AV33: 181.38448 | AW33: 181.38448
B34: 이익잉여금 | C34: Retained earnings | D34: =I34 -> 2067.8245 | E34: =M34 -> 1942.9241 | F34: =IFERROR(IF(D34*E34<0,"-", IF(E34<0,-(D34/E34-1),(D34/E34-1))),0) -> 0.06428475 | I34: 2067.8245 | J34: 2064.1213 | K34: 2017.5975 | L34: 1967.2438 | M34: 1942.9241 | N34: 1865.2671 | O34: 1864.2197 | P34: 1850.2079 | Q34: 1817.8844 | R34: 1747.4676 | S34: 1723.0011 | T34: 1688.9715 | U34: 1602.9448 | V34: 1636.4256 | W34: ='[12]202206 BS(17및39기준)'!$X$348/1000000000 -> 1580.4753 | X34: 1535.9903 | AA34: 이익잉여금 | AB34: Retained earnings | AC34: =AH34 -> 2073.912 | AD34: =AL34 -> 1943.1355 | AE34: =IFERROR(IF(AC34*AD34<0,"-", IF(AD34<0,-(AC34/AD34-1),(AC34/AD34-1))),0) -> 0.067301755 | AH34: 2073.912 | AI34: 2068.3668 | AJ34: 2018.6108 | AK34: 1967.9186 | AL34: 1943.1355 | AM34: 1862.0893 | AN34: 1860.2872 | AO34: 1843.5358 | AP34: 1807.02 | AQ34: 1820.0448 | AR34: 1759.6534 | AS34: 1714.3182 | AT34: 1686.3108 | AU34: 1710.9124 | AV34: 1660.9128 | AW34: 1615.976
B35: 자본조정 | C35: Capital adjustment | D35: =I35 -> -371.17545 | E35: =M35 -> -371.17545 | F35: =IFERROR(IF(D35*E35<0,"-", IF(E35<0,-(D35/E35-1),(D35/E35-1))),0) -> 0 | I35: -371.17545 | J35: -371.17545 | K35: -371.17545 | L35: -371.17545 | M35: -371.17545 | N35: -371.17545 | O35: -371.17545 | P35: -371.17545 | Q35: -371.17545 | R35: -371.17545 | S35: -371.17545 | T35: -371.17545 | U35: -371.17545 | V35: -371.17545 | W35: ='[12]202206 BS(17및39기준)'!$X$354/1000000000 -> -371.17545 | X35: -371.19135 | AA35: 자본조정 | AB35: Capital adjustment | AC35: =AH35 -> -371.27625 | AD35: =AL35 -> -371.27625 | AE35: =IFERROR(IF(AC35*AD35<0,"-", IF(AD35<0,-(AC35/AD35-1),(AC35/AD35-1))),0) -> 0 | AH35: -371.27625 | AI35: -371.27625 | AJ35: -371.27625 | AK35: -371.27625 | AL35: -371.27625 | AM35: -371.27625 | AN35: -371.27625 | AO35: -371.27625 | AP35: -371.27625 | AQ35: -371.27625 | AR35: -371.27625 | AS35: -371.27625 | AT35: -371.27625 | AU35: -371.27625 | AV35: -371.27625 | AW35: -371.29216
B36: 기타포괄손익누계액 | C36: Other comprehensive income | D36: =I36 -> -432.24669 | E36: =M36 -> -190.60991 | F36: =IFERROR(IF(D36*E36<0,"-", IF(E36<0,-(D36/E36-1),(D36/E36-1))),0) -> -1.2677032 | I36: -432.24669 | J36: -382.93365 | K36: -347.79837 | L36: -301.37041 | M36: -190.60991 | N36: -137.2176 | O36: -137.44607 | P36: 82.743767 | Q36: 400.21884 | R36: 421.88457 | S36: 418.71856 | T36: 386.33561 | U36: 1684.6568 | V36: 1854.9426 | W36: ='[12]202206 BS(17및39기준)'!$X$358/1000000000 -> 1523.2416 | X36: 1014.3412 | AA36: 기타포괄손익누계액 | AB36: Other comprehensive income | AC36: =AH36 -> -426.6398 | AD36: =AL36 -> -180.30384 | AE36: =IFERROR(IF(AC36*AD36<0,"-", IF(AD36<0,-(AC36/AD36-1),(AC36/AD36-1))),0) -> -1.3662269 | AH36: -426.6398 | AI36: -377.6415 | AJ36: -343.1231 | AK36: -291.32243 | AL36: -180.30384 | AM36: -129.74026 | AN36: -129.27649 | AO36: 91.447125 | AP36: 407.6682 | AQ36: 392.46139 | AR36: 386.35401 | AS36: 351.02706 | AT36: 1599.8132 | AU36: 1743.2277 | AV36: 1418.0242 | AW36: 903.43713
B38: 자본계 | C38: Total equity | D38: =I38 -> 2436.5016 | E38: =M38 -> 2553.2379 | F38: =IFERROR(IF(D38*E38<0,"-", IF(E38<0,-(D38/E38-1),(D38/E38-1))),0) -> -0.045720922 | I38: 2436.5016 | J38: 2482.1114 | K38: 2470.7229 | L38: 2466.7972 | M38: 2553.2379 | N38: =SUM(N32:N36) -> 2528.9733 | O38: 2527.6974 | P38: 2733.8755 | Q38: 3019.0271 | R38: =SUM(R32:R37) -> 2970.276 | S38: =SUM(S32:S37) -> 2942.6434 | T38: =SUM(T32:T37) -> 2876.2309 | U38: =SUM(U32:U37) -> 4088.5253 | V38: =SUM(V32:V37) -> 4292.292 | W38: =SUM(W32:W37) -> 3904.6406 | X38: 3351.2394 | AA38: 자본계 | AB38: Total equity | AC38: =AH38 -> 2448.0951 | AD38: =AL38 -> 2563.6547 | AE38: =IFERROR(IF(AC38*AD38<0,"-", IF(AD38<0,-(AC38/AD38-1),(AC38/AD38-1))),0) -> -0.045076091 | AH38: 2448.0951 | AI38: 2491.5 | AJ38: 2476.3106 | AK38: 2477.4191 | AL38: 2563.6547 | AM38: 2533.172 | AN38: 2531.8337 | AO38: 2735.8059 | AP38: 3015.5111 | AQ38: =SUM(AQ32:AQ37) -> 3013.3291 | AR38: =SUM(AR32:AR37) -> 2946.8304 | AS38: =SUM(AS32:AS37) -> 2866.1683 | AT38: =SUM(AT32:AT37) -> 4086.9469 | AU38: =SUM(AU32:AU37) -> 4254.963 | AV38: =SUM(AV32:AV37) -> 3879.7601 | AW38: =SUM(AW32:AW37) -> 3320.2202
T39: IFRS 17 & 9 ◀ | U39: ▶IFRS 17 + IAS39 | AL39: =AI38/AL38-1 -> -0.028145235 | AS39: IFRS 17 & 9 ◀ | AT39: ▶IFRS 17 + IAS39
B40: ▶ *) FY2024 Q2부터 파생상품 자산, 부채 별도 표기 | AA40: ▶ *) FY2024 Q2부터 파생상품 자산, 부채 별도 표기 | AL40: =AL38-AC38 -> 115.55953
B41: Assets and liabilities of derivatives represented from 24Q2 | AA41: Assets and liabilities of derivatives represented from 24Q2

Sheet KIFRS-IS
B1: =[13]INDEX!G5 -> K-IFRS 손익계산서 | C1: Income Statement K-IFRS | AE1: =B1 -> K-IFRS 손익계산서
B2: (BN KRW, %, %p) | AE2: (BN KRW, %, %p)
B4: 별도 손익계산서 | C4: Unconsolidated I/S | D4: =I4 -> 2025 | E4: =N4 -> 2024 | F4: YoY | I4: 2025 | N4: 2024 | S4: 2023 | X4: 2022 | AE4: 연결 손익계산서 | AF4: Consolidated I/S | AG4: =D4 -> 2025 | AH4: =E4 -> 2024 | AI4: YoY | AL4: 2025 | AQ4: 2024 | AV4: 2023 | BA4: 2022
D5: =I5 -> FY | E5: =N5 -> FY | I5: FY | J5: Q4 | K5: Q3 | L5: Q2 | M5: Q1 | N5: FY | O5: Q4 | P5: Q3 | Q5: Q2 | R5: Q1 | S5: FY | T5: Q4 | U5: Q3 | V5: Q2 | W5: Q1 | X5: FY | Y5: Q4 | Z5: Q3 | AA5: Q2 | AB5: Q1 | AG5: =D5 -> FY | AH5: =E5 -> FY | AL5: FY | AM5: Q4 | AN5: Q3 | AO5: Q2 | AP5: Q1 | AQ5: FY | AR5: Q4 | AS5: Q3 | AT5: Q2 | AU5: Q1 | AV5: FY | AW5: Q4 | AX5: Q3 | AY5: Q2 | AZ5: Q1 | BA5: FY | BB5: Q4 | BC5: Q3 | BD5: Q2 | BE5: Q1
B6: 보험서비스수익 | C6: Insurance service revenue | D6: =SUM(D7:D8) -> 1104.0767 | E6: =SUM(E7:E8) -> 983.39964 | F6: =IFERROR(IF(D6*E6<0,"-",IF(E6<0,-(D6/E6-1),(D6/E6-1))),0) -> 0.12271414 | I6: 1104.0767 | J6: 289.69317 | K6: 282.0901 | L6: 267.28716 | M6: 265.00626 | N6: 983.39964 | O6: 245.80271 | P6: 247.77268 | Q6: 244.15957 | R6: 245.66469 | S6: 918.97865 | T6: 226.98366 | U6: =SUM(U7:U9) -> 231.95241 | V6: =SUM(V7:V9) -> 227.65336 | W6: 232.38922 | X6: =SUM(Y6:AB6) -> 926.47844 | Y6: 226.56971 | Z6: =SUM(Z7:Z9) -> 233.12172 | AA6: =SUM(AA7:AA9) -> 236.90275 | AB6: =SUM(AB7:AB9) -> 229.88425 | AE6: 보험서비스수익 | AF6: Insurance service revenue | AG6: =SUM(AG7:AG8) -> 1104.0767 | AH6: =SUM(AH7:AH8) -> 983.39964 | AI6: =IFERROR(IF(AG6*AH6<0,"-",IF(AH6<0,-(AG6/AH6-1),(AG6/AH6-1))),0) -> 0.12271414 | AL6: =SUM(AM6:AP6) -> 1104.0767 | AM6: 289.69317 | AN6: 282.0901 | AO6: 267.28716 | AP6: 265.00626 | AQ6: 983.39964 | AR6: 245.80271 | AS6: 247.77268 | AT6: 244.15957 | AU6: 245.66469 | AV6: 918.97865 | AW6: 226.98366 | AX6: =SUM(AX7:AX9) -> 231.95241 | AY6: 227.65336 | AZ6: 232.38922 | BA6: =SUM(BB6:BE6) -> 926.47844 | BB6: 226.56971 | BC6: =SUM(BC7:BC9) -> 233.12172 | BD6: 236.90275 | BE6: 229.88425
B7: 일반보험서비스수익 | C7: Insurance service revenue | D7: =SUM(J7:M7) -> 1080.4115 | E7: =SUM(O7:R7) -> 963.96742 | F7: =IFERROR(IF(D7*E7<0,"-",IF(E7<0,-(D7/E7-1),(D7/E7-1))),0) -> 0.12079675 | I7: 1080.4115 | J7: 284.45398 | K7: 275.03755 | L7: 261.69215 | M7: 259.22787 | N7: 964 | O7: 245.75624 | P7: 243.42094 | Q7: 238.82729 | R7: 235.96295 | S7: 901.59925 | T7: 224.78729 | U7: 226.55462 | V7: 224.50184 | W7: 225.75549 | X7: =SUM(Y7:AB7) -> 903.85088 | Y7: 222.82169 | Z7: 226.80642 | AA7: 229.49368 | AB7: 224.72909 | AE7: 일반보험서비스수익 | AF7: Insurance service revenue | AG7: =SUM(AM7:AP7) -> 1080.4115 | AH7: =SUM(AR7:AU7) -> 963.96742 | AI7: =IFERROR(IF(AG7*AH7<0,"-",IF(AH7<0,-(AG7/AH7-1),(AG7/AH7-1))),0) -> 0.12079675 | AL7: =SUM(AM7:AP7) -> 1080.4115 | AM7: 284.45398 | AN7: 275.03755 | AO7: 261.69215 | AP7: 259.22787 | AQ7: 963.96742 | AR7: 245.75624 | AS7: 243.42094 | AT7: 238.82729 | AU7: 235.96295 | AV7: 901.59925 | AW7: 224.78729 | AX7: 226.55462 | AY7: 224.50184 | AZ7: 225.75549 | BA7: =SUM(BB7:BE7) -> 903.85088 | BB7: 222.82169 | BC7: 226.80642 | BD7: 229.49368 | BE7: 224.72909
B8: 출재보험서비스수익 | C8: Reinsurance service revenue | D8: =SUM(J8:M8) -> 23.66514 | E8: =SUM(O8:R8) -> 19.432224 | F8: =IFERROR(IF(D8*E8<0,"-",IF(E8<0,-(D8/E8-1),(D8/E8-1))),0) -> 0.21782971 | I8: 23.66514 | J8: 5.2391892 | K8: 7.0525496 | L8: 5.5950026 | M8: 5.7783983 | N8: 19.4 | O8: 0.046463727 | P8: 4.3517425 | Q8: 5.3322753 | R8: 9.7017426 | S8: 17.379404 | T8: 2.1963687 | U8: 5.3977887 | V8: 3.1515149 | W8: 6.6337314 | X8: =SUM(Y8:AB8) -> 22.627557 | Y8: 3.748025 | Z8: 6.3152986 | AA8: 7.4090743 | AB8: 5.1551594 | AE8: 출재보험서비스수익 | AF8: Reinsurance service revenue | AG8: =SUM(AM8:AP8) -> 23.66514 | AH8: =SUM(AR8:AU8) -> 19.432224 | AI8: =IFERROR(IF(AG8*AH8<0,"-",IF(AH8<0,-(AG8/AH8-1),(AG8/AH8-1))),0) -> 0.21782971 | AL8: =SUM(AM8:AP8) -> 23.66514 | AM8: 5.2391892 | AN8: 7.0525496 | AO8: 5.5950026 | AP8: 5.7783983 | AQ8: 19.432224 | AR8: 0.046463727 | AS8: 4.3517425 | AT8: 5.3322753 | AU8: 9.7017426 | AV8: 17.379404 | AW8: 2.1963687 | AX8: 5.3977887 | AY8: 3.1515149 | AZ8: 6.6337314 | BA8: =SUM(BB8:BE8) -> 22.627557 | BB8: 3.748025 | BC8: 6.3152986 | BD8: 7.4090743 | BE8: 5.1551594
BA9: =SUM(BB9:BE9) -> 0
B10: 보험서비스비용 | C10: Insurance service expense | D10: =SUM(D11:D13) -> 992.08658 | E10: =SUM(E11:E13) -> 864.1241 | F10: =IFERROR(IF(D10*E10<0,"-",IF(E10<0,-(D10/E10-1),(D10/E10-1))),0) -> 0.14808345 | I10: 992.08658 | J10: 295.57384 | K10: 247.78089 | L10: 222.61089 | M10: 226.12096 | N10: 864.1241 | O10: 225.94764 | P10: 216.36852 | Q10: 198.44075 | R10: 223.36718 | S10: 749.97788 | T10: 169.589 | U10: =SUM(U11:U14) -> 204.6125 | V10: =SUM(V11:V14) -> 187.08566 | W10: 188.69072 | X10: =SUM(Y10:AB10) -> 803.53061 | Y10: 204.87386 | Z10: =SUM(Z11:Z14) -> 206.84003 | AA10: =SUM(AA11:AA14) -> 199.63845 | AB10: =SUM(AB11:AB14) -> 192.17826 | AE10: 보험서비스비용 | AF10: Insurance service expense | AG10: =SUM(AG11:AG13) -> 1027.0722 | AH10: =SUM(AH11:AH13) -> 898.56388 | AI10: =IFERROR(IF(AG10*AH10<0,"-",IF(AH10<0,-(AG10/AH10-1),(AG10/AH10-1))),0) -> 0.14301526 | AL10: =SUM(AM10:AP10) -> 1027.0722 | AM10: 307.16749 | AN10: 255.71829 | AO10: 230.63079 | AP10: 233.55566 | AQ10: 898.56388 | AR10: 237.7334 | AS10: 224.18453 | AT10: 191.58131 | AU10: 245.06464 | AV10: 810.1529 | AW10: 182.32493 | AX10: =SUM(AX11:AX14) -> 219.66076 | AY10: 200.27225 | AZ10: 207.89496 | BA10: =SUM(BB10:BE10) -> 882.80179 | BB10: 215.3179 | BC10: =SUM(BC11:BC14) -> 236.05986 | BD10: 218.8214 | BE10: 212.60262
B11: 일반보험서비스비용 | C11: Insurance service expense | D11: =SUM(J11:M11) -> 897.78618 | E11: =SUM(O11:R11) -> 779.3599 | F11: =IFERROR(IF(D11*E11<0,"-",IF(E11<0,-(D11/E11-1),(D11/E11-1))),0) -> 0.15195326 | I11: 897.78618 | J11: 270.42917 | K11: 225.22661 | L11: 200.92326 | M11: 201.20714 | N11: 779.3599 | O11: 204.41137 | P11: 196.21563 | Q11: 177.73855 | R11: 200.99435 | S11: 659.29933 | T11: 143.95537 | U11: 184.73597 | V11: 165.79443 | W11: 164.81356 | X11: =SUM(Y11:AB11) -> 720.23201 | Y11: 180.98392 | Z11: 187.56243 | AA11: 179.99925 | AB11: 171.68641 | AE11: 일반보험서비스비용 | AF11: Insurance service expense | AG11: =SUM(AM11:AP11) -> 897.78618 | AH11: =SUM(AR11:AU11) -> 779.3599 | AI11: =IFERROR(IF(AG11*AH11<0,"-",IF(AH11<0,-(AG11/AH11-1),(AG11/AH11-1))),0) -> 0.15195326 | AL11: =SUM(AM11:AP11) -> 897.78618 | AM11: 270.42917 | AN11: 225.22661 | AO11: 200.92326 | AP11: 201.20714 | AQ11: 779.3599 | AR11: 204.41137 | AS11: 196.21563 | AT11: 177.73855 | AU11: 200.99435 | AV11: 659.29933 | AW11: 143.95537 | AX11: 184.73597 | AY11: 165.79443 | AZ11: 164.81356 | BA11: =SUM(BB11:BE11) -> 720.23201 | BB11: 180.98392 | BC11: 187.56243 | BD11: 179.99925 | BE11: 171.68641
B12: 출재보험서비스비용 | C12: Reinsurance service expense | D12: =SUM(J12:M12) -> 29.462123 | E12: =SUM(O12:R12) -> 17.104903 | F12: =IFERROR(IF(D12*E12<0,"-",IF(E12<0,-(D12/E12-1),(D12/E12-1))),0) -> 0.72243727 | I12: 29.462123 | J12: 6.8472044 | K12: 6.6855331 | L12: 6.5413245 | M12: 9.3880608 | N12: 17.104903 | O12: 0.82575048 | P12: 3.8437934 | Q12: 5.5573099 | R12: 6.8780494 | S12: 23.420482 | T12: 6.6872085 | U12: 4.3825992 | V12: 6.2475129 | W12: 6.1031613 | X12: =SUM(Y12:AB12) -> 23.193321 | Y12: 7.1323686 | Z12: 4.6266731 | AA12: 5.9179821 | AB12: 5.5162974 | AE12: 출재보험서비스비용 | AF12: Reinsurance service expense | AG12: =SUM(AM12:AP12) -> 29.462123 | AH12: =SUM(AR12:AU12) -> 17.104903 | AI12: =IFERROR(IF(AG12*AH12<0,"-",IF(AH12<0,-(AG12/AH12-1),(AG12/AH12-1))),0) -> 0.72243727 | AL12: =SUM(AM12:AP12) -> 29.462123 | AM12: 6.8472044 | AN12: 6.6855331 | AO12: 6.5413245 | AP12: 9.3880608 | AQ12: 17.104903 | AR12: 0.82575048 | AS12: 3.8437934 | AT12: 5.5573099 | AU12: 6.8780494 | AV12: 23.420482 | AW12: 6.6872085 | AX12: 4.3825992 | AY12: 6.2475129 | AZ12: 6.1031613 | BA12: =SUM(BB12:BE12) -> 23.193321 | BB12: 7.1323686 | BC12: 4.6266731 | BD12: 5.9179821 | BE12: 5.5162974
B13: 기타사업비용 | C13: Other expense | D13: =SUM(J13:M13) -> 64.838271 | E13: =SUM(O13:R13) -> 67.659293 | F13: =IFERROR(IF(D13*E13<0,"-",IF(E13<0,-(D13/E13-1),(D13/E13-1))),0) -> -0.041694534 | I13: 64.838271 | J13: 18.297465 | K13: 15.868745 | L13: 15.146306 | M13: 15.525754 | N13: 67.659293 | O13: 20.71052 | P13: 16.309096 | Q13: 15.144894 | R13: 15.494783 | S13: 67.258069 | T13: 18.946424 | U13: 15.493932 | V13: 15.04372 | W13: 17.773994 | X13: =SUM(Y13:AB13) -> 60.105278 | Y13: 16.757573 | Z13: 14.65093 | AA13: 13.721218 | AB13: 14.975558 | AE13: 기타사업비용 | AF13: Other expense | AG13: =SUM(AM13:AP13) -> 99.823925 | AH13: =SUM(AR13:AU13) -> 102.09908 | AI13: =IFERROR(IF(AG13*AH13<0,"-",IF(AH13<0,-(AG13/AH13-1),(AG13/AH13-1))),0) -> -0.022283764 | AL13: =SUM(AM13:AP13) -> 99.823925 | AM13: 29.891118 | AN13: 23.806142 | AO13: 23.166213 | AP13: 22.960453 | AQ13: 102.09908 | AR13: 32.496279 | AS13: 24.125107 | AT13: 8.2854541 | AU13: 37.192237 | AV13: 127.43309 | AW13: 31.682349 | AX13: 30.542194 | AY13: 28.230308 | AZ13: 36.978235 | BA13: =SUM(BB13:BE13) -> 139.37646 | BB13: 27.201606 | BC13: 43.870763 | BD13: 32.904168 | BE13: 35.399921
BA14: =SUM(BB14:BE14) -> 0
B15: 투자서비스수익 | C15: Investment service revenue | D15: =SUM(D16:D20) -> 3947.3207 | E15: =SUM(E16:E20) -> 3670.5623 | F15: =IFERROR(IF(D15*E15<0,"-",IF(E15<0,-(D15/E15-1),(D15/E15-1))),0) -> 0.075399442 | I15: 3947.3207 | J15: 912.85809 | K15: 936.30217 | L15: 1306.6928 | M15: 791.46758 | N15: 3670.5623 | O15: 1236.439 | P15: 370.59488 | Q15: 807.73918 | R15: 1255.7893 | S15: 3956.0401 | T15: 1157.8043 | U15: =SUM(U16:U21) -> 553.35421 | V15: =SUM(V16:V21) -> 936.43613 | W15: 1308.4454 | X15: =SUM(Y15:AB15) -> 5098.5172 | Y15: -32.990686 | Z15: =SUM(Z16:Z21) -> 1585.6088 | AA15: =SUM(AA16:AA21) -> 1978.1162 | AB15: =SUM(AB16:AB21) -> 1567.7829 | AE15: 투자서비스수익 | AF15: Investment service revenue | AG15: =SUM(AG16:AG20) -> 4084.3525 | AH15: =SUM(AH16:AH20) -> 3812.7456 | AI15: =IFERROR(IF(AG15*AH15<0,"-",IF(AH15<0,-(AG15/AH15-1),(AG15/AH15-1))),0) -> 0.071236554 | AL15: =SUM(AM15:AP15) -> 4084.3525 | AM15: 948.13796 | AN15: 972.81029 | AO15: 1350.8049 | AP15: 812.59937 | AQ15: 3812.7456 | AR15: 1280.1356 | AS15: 398.7627 | AT15: 842.05752 | AU15: 1291.7899 | AV15: 4134.4408 | AW15: 1254.1904 | AX15: =SUM(AX16:AX21) -> 572.68191 | AY15: 963.47575 | AZ15: 1344.0928 | BA15: =SUM(BB15:BE15) -> 5255.4749 | BB15: -9.0116594 | BC15: =SUM(BC16:BC21) -> 1650.3424 | BD15: 2015.1613 | BE15: 1598.9829
B16: 보험금융수익 | C16: Insurance financial revenue | D16: =SUM(J16:M16) -> 663.73185 | E16: =SUM(O16:R16) -> 319.18261 | F16: =IFERROR(IF(D16*E16<0,"-",IF(E16<0,-(D16/E16-1),(D16/E16-1))),0) -> 1.0794737 | I16: 663.73185 | J16: 185.32796 | K16: 18.61685 | L16: 183.86293 | M16: 275.92411 | N16: 319.18261 | O16: 11.835091 | P16: 214.57859 | Q16: 80.214362 | R16: 12.554571 | S16: 612.08324 | T16: 263.01093 | U16: 297.1408 | V16: 16.996267 | W16: 34.935246 | X16: =SUM(Y16:AB16) -> 3190.7457 | Y16: 402.69771 | Z16: 491.15596 | AA16: ='[14]공시용PL(변경후)'!$E$13/1000000000 -> 1188.2831 | AB16: 1108.6089 | AE16: 보험금융수익 | AF16: Insurance financial revenue | AG16: =SUM(AM16:AP16) -> 663.73185 | AH16: =SUM(AR16:AU16) -> 319.18261 | AI16: =IFERROR(IF(AG16*AH16<0,"-",IF(AH16<0,-(AG16/AH16-1),(AG16/AH16-1))),0) -> 1.0794737 | AL16: =SUM(AM16:AP16) -> 663.73185 | AM16: 185.32796 | AN16: 18.61685 | AO16: 183.86293 | AP16: 275.92411 | AQ16: 319.18261 | AR16: 11.835091 | AS16: 214.57859 | AT16: 80.214362 | AU16: 12.554571 | AV16: 612.08324 | AW16: 263.01093 | AX16: 297.1408 | AY16: 16.996267 | AZ16: 34.935246 | BA16: =SUM(BB16:BE16) -> 3190.7457 | BB16: 402.69771 | BC16: 491.15596 | BD16: 1188.2831 | BE16: 1108.6089
B17: 재보험금융수익 | C17: Reinsurance financial revenue | D17: =SUM(J17:M17) -> 3.3082494 | E17: =SUM(O17:R17) -> 2.0238661 | F17: =IFERROR(IF(D17*E17<0,"-",IF(E17<0,-(D17/E17-1),(D17/E17-1))),0) -> 0.63461875 | I17: 3.3082494 | J17: 0.85839144 | K17: 0.7929775 | L17: 0.82017629 | M17: 0.83670416 | N17: 2.0238661 | O17: 0.71158538 | P17: 0.44238611 | Q17: 0.45137617 | R17: 0.4185184 | S17: 1.4794636 | T17: 0.42160664 | U17: 0.37672875 | V17: 0.35146594 | W17: 0.32966222 | X17: =SUM(Y17:AB17) -> 1.0572867 | Y17: 0.36241421 | Z17: 0.27015163 | AA17: ='[14]공시용PL(변경후)'!$E$14/1000000000 -> 0.23331848 | AB17: 0.19140241 | AE17: 재보험금융수익 | AF17: Reinsurance financial revenue | AG17: =SUM(AM17:AP17) -> 3.3082494 | AH17: =SUM(AR17:AU17) -> 2.0238661 | AI17: =IFERROR(IF(AG17*AH17<0,"-",IF(AH17<0,-(AG17/AH17-1),(AG17/AH17-1))),0) -> 0.63461875 | AL17: =SUM(AM17:AP17) -> 3.3082494 | AM17: 0.85839144 | AN17: 0.7929775 | AO17: 0.82017629 | AP17: 0.83670416 | AQ17: 2.0238661 | AR17: 0.71158538 | AS17: 0.44238611 | AT17: 0.45137617 | AU17: 0.4185184 | AV17: 1.4794636 | AW17: 0.42160664 | AX17: 0.37672875 | AY17: 0.35146594 | AZ17: 0.32966222 | BA17: =SUM(BB17:BE17) -> 1.0572867 | BB17: 0.36241421 | BC17: 0.27015163 | BD17: 0.23331849 | BE17: 0.19140241
B18: 이자수익 | C18: Interest revenue | D18: =SUM(J18:M18) -> 490.9836 | E18: =SUM(O18:R18) -> 506.2994 | F18: =IFERROR(IF(D18*E18<0,"-",IF(E18<0,-(D18/E18-1),(D18/E18-1))),0) -> -0.030250484 | I18: 490.9836 | J18: 125.13326 | K18: 122.64968 | L18: 121.56156 | M18: 121.63909 | N18: 506.2994 | O18: 125.81762 | P18: 126.31674 | Q18: 126.49902 | R18: 127.66603 | S18: 551.78751 | T18: 139.0991 | U18: 142.30361 | V18: 136.20783 | W18: 136.89489 | X18: =SUM(Y18:AB18) -> 586.69578 | Y18: 147.08113 | Z18: 147.66878 | AA18: ='[14]공시용PL(변경후)'!$E$15/1000000000 -> 147.99681 | AB18: 143.94907 | AE18: 이자수익 | AF18: Interest revenue | AG18: =SUM(AM18:AP18) -> 493.83809 | AH18: =SUM(AR18:AU18) -> 509.57413 | AI18: =IFERROR(IF(AG18*AH18<0,"-",IF(AH18<0,-(AG18/AH18-1),(AG18/AH18-1))),0) -> -0.030880755 | AL18: =SUM(AM18:AP18) -> 493.83809 | AM18: 125.75551 | AN18: 123.29195 | AO18: 122.31264 | AP18: 122.47799 | AQ18: 509.57413 | AR18: 126.76422 | AS18: 126.647 | AT18: 127.71551 | AU18: 128.4474 | AV18: 554.71269 | AW18: 138.36947 | AX18: 141.32101 | AY18: 137.30716 | AZ18: 137.71506 | BA18: =SUM(BB18:BE18) -> 589.42513 | BB18: 147.95977 | BC18: 148.37085 | BD18: 148.55924 | BE18: 144.53527
