Workbook

Sheet cover_Q
B5: Factsheet
C9: 2025년 4분기
E13: Contents
E16: I. 경영실적 Highlights
E17: Ⅱ. 보험료 및 유지율 현황
E18: Ⅲ. 종목별 보험손익
E19: Ⅳ. 운용자산 포트폴리오 및 투자손익
E20: Ⅴ. 요약 손익계산서
E21: Ⅵ. 요약 재무상태표
E22: ※ 재무상태표
E23: ※ 포괄 손익계산서
B27: ※ 본 자료는 2025 년도 4분기 경영실적에 대한 외부 감사인의 감사보고서를 제공 받지 못한 상태에서 투자자의 편의를 위하여 작성된 자료입니다. 따라서 본 경영실적과 관련하여 자료 내용 중 일부는 회계감사 결과에 따라 달라질 수 있음을 양지하시기 바랍니다.

Sheet (1) Highlights
B1: I. 경영실적 Highlights
B4: 1. 보험료
K5: (단위:백만원)
B6: 구 분 | D6: ='(5) IS'!D5 -> 25.3Q | E6: ='[9](5) IS_Q'!E5:I5 -> 2025 | J6: ='[9](5) IS_Q'!J5:K5 -> 2024
E7: ='(5) IS'!E6 -> 25.4Q | H7: ='(5) IS'!H6 -> 25.4Q 누계 | J7: ='(5) IS'!J6 -> 24.4Q | K7: ='(5) IS'!K6 -> 24.4Q 누계
F8: QoQ | G8: YoY | I8: YoY
B9: 일 반 | D9: 458053.09 | E9: 484293.57 | F9: 0.057287 | G9: 0.012223938 | H9: 2095742.6 | I9: 0.055032137 | J9: 478445.09 | K9: 1986425.3
B10: 장 기 (신계약) | D10: 32186.779 | E10: 33935.765 | F10: 0.054338646 | G10: -0.061609823 | H10: 132673.54 | I10: -0.1053272 | J10: 36163.811 | K10: 148292.81
C11: 인보험 (월납환산) | D11: 28675 | E11: 30478 | F11: 0.062877071 | G11: -0.045115609 | H11: 117203 | I11: -0.092919224 | J11: 31918 | K11: 129209
B12: 자 동 차 | D12: 1001249.9 | E12: 996435.89 | F12: -0.0048079885 | G12: -0.053719092 | H12: 4022503.9 | I12: -0.062509636 | J12: 1053002.2 | K12: 4290714.9
B15: 2. 손 익
K16: (단위:백만원)
B17: 구 분 | D17: =D6 -> 25.3Q | E17: =E6 -> 2025 | J17: =J6 -> 2024
E18: =E7 -> 25.4Q | H18: =H7 -> 25.4Q 누계 | J18: =J7 -> 24.4Q | K18: =K7 -> 24.4Q 누계
F19: QoQ | G19: YoY | I19: YoY
B20: 보 험 손 익 | D20: 161430 | E20: -153894.86 | H20: 396111.3 | I20: -0.62025665 | J20: -47761.651 | K20: 1043102.7
B21: - 일 반 | D21: 35219.68 | E21: 40082.154 | F21: 0.13806128 | G21: 0.025950438 | H21: 148847.07 | I21: -0.061291744 | J21: 39068.314 | K21: 158565.85
B22: - 장 기 | D22: 181543.64 | E22: -141874.4 | H22: 338106.64 | I22: -0.60927369 | J22: -10376.958 | K22: 865328.57
C23: 보험계약마진 상각 | D23: 245727.37 | E23: 231488.04 | F23: -0.057947684 | G23: 0.070812155 | H23: 950944.09 | I23: 0.019413554 | J23: 216179.88 | K23: 932834.46
C24: 위험조정 변동 | D24: 36527.979 | E24: 36026.049 | F24: -0.013740968 | G24: 0.062527784 | H24: 136224.49 | I24: 0.028465339 | J24: 33905.983 | K24: 132454.14
B25: - 자동차 | D25: -55333.322 | E25: -52102.614 | H25: -90842.404 | J25: -76453.007 | K25: 19208.258
B26: 투 자 손 익 | D26: 89393.953 | E26: 4452.2331 | F26: -0.95019537 | G26: -0.88524707 | H26: 330285.66 | I26: -0.061832396 | J26: 38798.427 | K26: 352054
B27: 영업외손익 | D27: -6043.5001 | E27: -5932.8464 | H27: -32119.243 | J27: -8528.8482 | K27: -28721.063
B28: 당기순이익 | D28: 183181.17 | E28: -73040.177 | H28: 561106.41 | I28: -0.45559819 | J28: -15735.693 | K28: 1030684.3
B30: 3. 재 무
K31: (단위:백만원)
B32: 구 분 | E32: ='(6) BS'!$G$5 -> 2024. 12월 말 | H32: ='(6) BS'!$D$5 -> 2025. 12월 말
K33: (YTD)
B34: 총 자산 | E34: 47977679 | H34: 49645875 | K34: =H34/E34-1 -> 0.034770249
B35: 보험계약마진 잔액 | E35: 8247672.7 | H35: 8901703.7 | K35: =H35/E35-1 -> 0.07929886
B36: 자기자본 | E36: 4927149.1 | H36: 4883487.5 | K36: =H36/E36-1 -> -0.0088614301
B37: 지급여력비율 (K-ICS) | E37: 1.57 | H37: 1.9014878 | K37: =H37-E37 -> 0.33148775
B38: 주) 보험계약마진 잔액 : 보유 기준

Sheet (2) Premium
B1: II. 보험료 및 유지율 현황
M4: (단위:백만원)
B5: 구 분 | E5: ='(5) IS'!D5:D7 -> 25.3Q | F5: 2025 | L5: 2024
F6: ='(5) IS'!E6:E7 -> 25.4Q | I6: ='(5) IS'!H6:H7 -> 25.4Q 누계 | L6: ='(5) IS'!J6:J7 -> 24.4Q | M6: ='(5) IS'!K6:K7 -> 24.4Q 누계
G7: QoQ | H7: YoY | J7: 구성비 | K7: YoY
B8: 일 반 | E8: 458053.09 | F8: 484293.57 | G8: 0.057287 | H8: 0.012223938 | I8: 2095742.6 | J8: 0.11958585 | K8: 0.055032137 | L8: 478445.09 | M8: 1986425.3
B9: 장 기 (신계약) | E9: 32186.779 | F9: 33935.765 | G9: 0.054338646 | H9: -0.061609823 | I9: 132673.54 | J9: 0.007570528 | K9: -0.1053272 | L9: 36163.811 | M9: 148292.81
B10: 자 동 차 | E10: 1001249.9 | F10: 996435.89 | G10: -0.0048079885 | H10: -0.053719092 | I10: 4022503.9 | J10: 0.2295294 | K10: -0.062509636 | L10: 1053002.2 | M10: 4290714.9
B12: ※ 장기보험 신계약(월납환산) 실적
C13: 상 해 | E13: 19624 | F13: 17592 | G13: -0.10354668 | H13: -0.12281227 | I13: 77514 | J13: 0.60418567 | K13: -0.055755198 | L13: 20055 | M13: 82091
C14: 운전자 | E14: 3032 | F14: 6268 | G14: 1.0672823 | H14: 0.81051415 | I14: 15100 | J14: 0.11769749 | K14: 0.077955454 | L14: 3462 | M14: 14008
C15: 질 병 | E15: 6019 | F15: 6618 | G15: 0.099518192 | H15: -0.21223664 | I15: 24589 | J15: 0.19165985 | K15: -0.25735427 | L15: 8401 | M15: 33110
C16: 인보험 소계 | E16: 28675 | F16: 30478 | G16: 0.062877071 | H16: -0.045115609 | I16: 117203 | J16: 0.91354301 | K16: -0.092919224 | L16: 31918 | M16: 129209
C17: 재 물 | E17: 2325 | F17: 2304 | G17: -0.0090322581 | H17: -0.19327731 | I17: 10100 | J17: 0.078724814 | K17: -0.12250217 | L17: 2856 | M17: 11510
C18: 보장성 소계 | E18: 31000 | F18: 32782 | G18: 0.057483871 | H18: -0.057284178 | I18: 127303 | J18: 0.99226782 | K18: -0.095338938 | L18: 34774 | M18: 140719
C19: 저 축 | E19: 56 | F19: 48 | G19: -0.14285714 | H19: -0.86516854 | I19: 283 | J19: 0.0022058537 | K19: -0.6041958 | L19: 356 | M19: 715
C20: 개인연금 | E20: 129 | F20: 154 | G20: 0.19379845 | H20: 0.033557047 | I20: 709 | J20: 0.005526326 | K20: -0.16489988 | L20: 149 | M20: 849
C21: 저축성 소계 | E21: 185 | F21: 202 | G21: 0.091891892 | H21: -0.6 | I21: 992 | J21: 0.0077321797 | K21: -0.3653231 | L21: 505 | M21: 1563
C22: 합 계 | E22: 31185 | F22: 32984 | G22: 0.057687991 | H22: -0.065052864 | I22: 128295 | J22: 1 | K22: -0.098304775 | L22: 35279 | M22: 142282
B24: 13회차 유지율 | E24: 0.87064069 | F24: 0.86271965 | H24: -0.0039803539 | I24: 0.86594831 | K24: -0.0059516914 | L24: 0.8667 | M24: 0.8719
B25: 25회차 유지율 | E25: 0.7430602 | F25: 0.7292753 | H25: 0.00057530123 | I25: 0.73421571 | K25: 0.00081571461 | L25: 0.7287 | M25: 0.7334

Sheet (3) UW Income
B1: III. 종목별 보험손익
L4: (단위:백만원)
B5: 구 분 | E5: ='(2) Premium'!E5:E7 -> 25.3Q | F5: ='[10](5) IS_Q'!E5 -> 2025 | K5: ='[10](5) IS_Q'!J5 -> 2024
F6: ='(2) Premium'!F6:F7 -> 25.4Q | I6: ='(2) Premium'!I6:I7 -> 25.4Q 누계 | K6: ='(2) Premium'!L6:L7 -> 24.4Q | L6: ='(2) Premium'!M6:M7 -> 24.4Q 누계
G7: QoQ | H7: YoY | J7: YoY
B8: 일반 | C8: 보험료배분법적용수익 | E8: 291379.62 | F8: 296695.25 | G8: 0.018242968 | H8: 0.05865995 | I8: 1129831.9 | J8: 0.040918103 | K8: 280255.48 | L8: 1085418.7
C9: 발생손해액 | E9: 173588.53 | F9: 177462.46 | G9: 0.022316748 | H9: 0.098402478 | I9: 646360.09 | J9: 0.081393416 | K9: 161564.14 | L9: 597710.4
C10: 사업비 | E10: 82571.419 | F10: 79150.642 | G10: -0.041428095 | H10: -0.0059326996 | I10: 334624.78 | J10: 0.016656494 | K10: 79623.021 | L10: 329142.42
C11: 보 험 손 익 | E11: 35219.68 | F11: 40082.154 | G11: 0.13806128 | H11: 0.025950438 | I11: 148847.07 | J11: -0.061291744 | K11: 39068.314 | L11: 158565.85
B12: 장기 | C12: 보험계약마진 상각 (+) | E12: 245727.37 | F12: 231488.04 | G12: -0.057947684 | H12: 0.070812155 | I12: 950944.09 | J12: 0.019413554 | K12: 216179.88 | L12: 932834.46
C13: 위험조정 변동 (+) | E13: 36527.979 | F13: 36026.049 | G13: -0.013740968 | H13: 0.062527784 | I13: 136224.49 | J13: 0.028465339 | K13: 33905.983 | L13: 132454.14
C14: 예상대비 실제 차이 (+) | E14: -67652.993 | F14: -93720.396 | I14: -306114.1 | K14: -98507.07 | L14: -212362.86
C15: - 보험금 예실차 | E15: -90533.914 | F15: -115161.06 | I15: -349811.03 | K15: -110595.4 | L15: -188292.37
D16: 예상손해액 | E16: 1435047 | F16: 1393060.4 | G16: -0.029257961 | H16: 0.053675596 | I16: 5478673.9 | J16: 0.076677226 | K16: 1322096.1 | L16: 5088501.7
D17: 발생손해액 | E17: 1563807.8 | F17: 1588251.9 | G17: 0.015631155 | H17: 0.10023948 | I17: 6043377.2 | J17: 0.1031669 | K17: 1443551.1 | L17: 5478207.5
D18: 발생사고요소조정 | E18: -38226.913 | F18: -80030.437 | I18: -214892.33 | K18: -10859.581 | L18: -201413.47
C19: - 사업비 예실차 | E19: 22880.921 | F19: 21440.665 | G19: -0.062945706 | H19: 0.77366689 | I19: 43696.93 | K19: 12088.327 | L19: -24070.488
D20: 예상사업비 | E20: 169266.24 | F20: 173030.01 | G20: 0.0222358 | H20: 0.056263321 | I20: 677337.31 | J20: 0.054060301 | K20: 163813.33 | L20: 642598.25
D21: 실제사업비 | E21: 150912.1 | F21: 151695.92 | G21: 0.0051938734 | H21: 0.00037612294 | I21: 629217.93 | J21: -0.024621451 | K21: 151638.88 | L21: 645101.26
D22: 기타보험서비스비용 | E22: -4526.7796 | F22: -106.57194 | I22: 4422.4487 | J22: -0.79494831 | K22: 86.119293 | L22: 21567.483
C23: 기타 재보험 손익 (+) | E23: -568.69069 | F23: -4919.3752 | I23: -6965.8402 | K23: -2368.5496 | L23: -8195.2869
C24: 손실부담계약관련비용 (-) | E24: 18508.919 | F24: 296347.07 | G24: 15.011042 | H24: 0.97650805 | I24: 380616.1 | K24: 149934.66 | L24: -51899.39
C25: 기타사업비 (-) | E25: 13981.108 | F25: 14401.652 | G25: 0.030079439 | H25: 0.4920073 | I25: 55365.9 | J25: 0.76880722 | K25: 9652.5345 | L25: 31301.263
C26: 보 험 손 익 | E26: 181543.64 | F26: -141874.4 | I26: 338106.64 | J26: -0.60927369 | K26: -10376.958 | L26: 865328.57
B27: 자동차 | C27: 보험료배분법적용수익 | E27: 972612.3 | F27: 961763.16 | G27: -0.01115464 | H27: -0.062189181 | I27: 3894031.2 | J27: -0.066526631 | K27: 1025540.7 | L27: 4171550.3
C28: 발생손해액 | E28: 883122.8 | F28: 867568.76 | G28: -0.017612542 | H28: -0.088545828 | I28: 3373692.9 | J28: -0.035353515 | K28: 951851.21 | L28: 3497336
C29: 사업비 | E29: 144822.83 | F29: 146297.01 | G29: 0.010179258 | H29: -0.025612176 | I29: 611180.65 | J29: -0.066908398 | K29: 150142.49 | L29: 655006.05
C30: 보 험 손 익 | E30: -55333.322 | F30: -52102.614 | I30: -90842.404 | K30: -76453.007 | L30: 19208.258
B31: 보 험 손 익 합계 | E31: 161430 | F31: -153894.86 | I31: 396111.3 | J31: -0.62025665 | K31: -47761.651 | L31: 1043102.7

Sheet (4) Investment
B1: IV. 운용자산 포트폴리오 및 투자손익
K4: (단위:백만원)
B5: 구 분 | D5: ='(6) BS'!D5:D6 -> 2025. 12월 말 | I5: ='(6) BS'!G5:G6 -> 2024. 12월 말
G6: 구성비 | H6: YTD | K6: 구성비
C7: 운용자산 계 | D7: 47015757 | G7: =D7/$D$7 -> 1 | H7: =IF(D7*I7>0,D7/I7-1,"") -> 0.026833642 | I7: 45787121 | K7: =I7/$I$7 -> 1
C8: 현·예금및예치금 | D8: 1647260.4 | G8: =D8/$D$7 -> 0.035036347 | H8: =IF(D8*I8>0,D8/I8-1,"") -> -0.22248932 | I8: 2118633.8 | K8: =I8/$I$7 -> 0.04627139
C9: 주 식 | D9: 188349.63 | G9: =D9/$D$7 -> 0.0040060958 | H9: =IF(D9*I9>0,D9/I9-1,"") -> 0.18103024 | I9: 159479.09 | K9: =I9/$I$7 -> 0.0034830556
C10: 채 권 | D10: 20213819 | G10: =D10/$D$7 -> 0.42993711 | H10: =IF(D10*I10>0,D10/I10-1,"") -> 0.15144808 | I10: 17555128 | K10: =I10/$I$7 -> 0.38340755
C11: - 국공채 | D11: 11491841 | G11: =D11/$D$7 -> 0.2444253 | H11: =IF(D11*I11>0,D11/I11-1,"") -> 0.23714329 | I11: 9289013.4 | K11: =I11/$I$7 -> 0.20287393
C12: - 특수채 및 금융채 | D12: 6245001.4 | G12: =D12/$D$7 -> 0.13282784 | H12: =IF(D12*I12>0,D12/I12-1,"") -> 0.089383271 | I12: 5732602.6 | K12: =I12/$I$7 -> 0.1252012
C13: - 회사채 | D13: 2476976.7 | G13: =D13/$D$7 -> 0.052683969 | H13: =IF(D13*I13>0,D13/I13-1,"") -> -0.022315072 | I13: 2533512.2 | K13: =I13/$I$7 -> 0.055332419
C14: 수익증권 | D14: 6045080.5 | G14: =D14/$D$7 -> 0.12857563 | H14: =IF(D14*I14>0,D14/I14-1,"") -> 0.00037186644 | I14: 6042833.3 | K14: =I14/$I$7 -> 0.1319767
C15: 외화유가증권 | D15: 6929956.5 | G15: =D15/$D$7 -> 0.14739647 | H15: =IF(D15*I15>0,D15/I15-1,"") -> -0.0050953641 | I15: 6965447.9 | K15: =I15/$I$7 -> 0.15212679
C16: - 채권 | D16: 5837923.4 | G16: =D16/$D$7 -> 0.12416951 | H16: =IF(D16*I16>0,D16/I16-1,"") -> 0.001945194 | I16: 5826589.5 | K16: =I16/$I$7 -> 0.12725389
C17: - 채권 외 | D17: 1092033.1 | G17: =D17/$D$7 -> 0.02322696 | H17: =IF(D17*I17>0,D17/I17-1,"") -> -0.041116033 | I17: 1138858.4 | K17: =I17/$I$7 -> 0.024872899
C18: 출자금 등 | D18: 389415.08 | G18: =D18/$D$7 -> 0.0082826505 | H18: =IF(D18*I18>0,D18/I18-1,"") -> -0.029601782 | I18: 401294.1 | K18: =I18/$I$7 -> 0.0087643444
... C21: 부 동 산 | D21: 1204515.9 | G21: =D21/$D$7 -> 0.025619408 | H21: =IF(D21*I21>0,D21/I21-1,"") -> -0.023813662 | I21: 1233899.5 | K21: =I21/$I$7 -> 0.026948616
K23: (단위:백만원)
B24: 구 분 | D24: ='(5) IS'!D5 -> 25.3Q | E24: ='[10](5) IS_Q'!E5:I5 -> 2025 | J24: ='[10](5) IS_Q'!J5:K5 -> 2024
E25: ='(5) IS'!E6 -> 25.4Q | H25: ='(5) IS'!H6 -> 25.4Q 누계 | J25: ='(5) IS'!J6 -> 24.4Q | K25: ='(5) IS'!K6 -> 24.4Q 누계
F26: QoQ | G26: YoY | I26: YoY
B27: 투 자 손 익 | D27: 89393.953 | E27: 4452.2331 | F27: -0.95019537 | G27: -0.88524707 | H27: 330285.66 | I27: -0.061832396 | J27: 38798.427 | K27: 352054
B28: - 투자수익 | D28: 606922.47 | E28: 510758.98 | F28: -0.15844444 | G28: -0.58145923 | H28: 2847519.5 | I28: -0.094757163 | J28: 1220332.7 | K28: 3145586.3
C29: 보험금융수익 | D29: 14992.662 | E29: 29888.114 | F29: 0.99351615 | G29: -0.36525875 | H29: 122245.75 | I29: 0.031880774 | J29: 47087.083 | K29: 118468.87
C30: 이자/배당 | D30: 669915.82 | E30: 442842 | F30: -0.33895873 | G30: 0.073155197 | H30: 1942242 | I30: 0.11800126 | J30: 412654.2 | K30: 1737244.9
C31: 유가증권평가/처분 등 | D31: 55471.958 | E31: 31726.675 | F31: -0.42805922 | G31: -0.30490863 | H31: 268278.93 | I31: 0.082398565 | J31: 45643.891 | K31: 247855.95
C32: 파생/외환 | D32: -154021.95 | E32: -5193.0447 | H32: 459709.62 | I32: -0.54150874 | J32: 703274.27 | K32: 1002657.3
C33: 기 타 | D33: 20563.981 | E33: 11495.233 | F33: -0.44100159 | G33: -0.015248977 | H33: 55043.192 | I33: 0.39848156 | J33: 11673.238 | K33: 39359.254
B34: - 투자비용 | D34: 517528.52 | E34: 506306.75 | F34: -0.021683385 | G34: -0.57148365 | H34: 2517233.8 | I34: -0.098906496 | J34: 1181534.3 | K34: 2793532.3
C35: 보험금융비용 | D35: 217142.13 | E35: 318907.02 | F35: 0.46865569 | G35: 0.11233986 | H35: 1010349.1 | I35: 0.036421074 | J35: 286699.27 | K35: 974844.18
C36: 유가증권평가/처분 등 | D36: 319718.97 | E36: 61828.832 | F36: -0.80661506 | G36: -0.36347969 | H36: 541382.28 | I36: 0.22729549 | J36: 97135.678 | K36: 441118.12
C37: 파생/외환 | D37: -114118.3 | E37: 30019.667 | G37: -0.95849144 | H37: 598081.8 | I37: -0.45727325 | J37: 723216.34 | K37: 1101994.3
C38: 재산관리비 | D38: 2447.8667 | E38: 2715.3231 | F38: 0.10926101 | G38: 0.44576353 | H38: 10222.374 | I38: 0.21879945 | J38: 1878.1239 | K38: 8387.249
C39: 기 타 | D39: 92337.858 | E39: 92835.907 | F39: 0.0053937675 | G39: 0.27864598 | H39: 357198.3 | I39: 0.33687792 | J39: 72604.856 | K39: 267188.42
B40: 투자손익 (보험금융손익 제외) | D40: 291543.42 | E40: 293471.14 | F40: 0.0066121251 | G40: 0.05409467 | H40: 1218389 | I40: 0.0082418147 | J40: 278410.61 | K40: 1208429.3
C41: 투자이익률 | D41: 0.024745068 | E41: 0.024948514 | F41: 0.0002034468 | G41: 7.7322626e-05 | H41: 0.026606885 | I41: -0.0014705862 | J41: 0.024871192 | K41: 0.028077471

Sheet (5) IS
B1: V. 요약 손익계산서
K4: (단위 : 백만원)
B5: 구 분 | D5: 25.3Q | E5: 2025 | J5: 2024
E6: 25.4Q | H6: 25.4Q 누계 | J6: 24.4Q | K6: 24.4Q 누계
F7: QoQ | G7: YoY | I7: YoY
B8: 보 험 손 익 | D8: 161430 | E8: -153894.86 | H8: 396111.3 | I8: -0.62025665 | J8: -47761.651 | K8: 1043102.7
B9: - 보험수익 | D9: 3609167.6 | E9: 3594738.5 | F9: -0.003997924 | G9: 0.031697768 | H9: 14144826 | I9: 0.031339086 | J9: 3484294.1 | K9: 13715010
C10: 일반모형/변동수수료접근법 | D10: 2086752.2 | E10: 2065262.5 | F10: -0.010298167 | G10: 0.07388702 | H10: 8068372.4 | I10: 0.078458401 | J10: 1923165.5 | K10: 7481394.2
C11: 보험료배분접근법 | D11: 1522415.4 | E11: 1529476 | F11: 0.004637726 | G11: -0.020275474 | H11: 6076453.6 | I11: -0.025212067 | J11: 1561128.6 | K11: 6233615.9
B12: - 보험서비스비용 | D12: 3225549.1 | E12: 3547242 | F12: 0.099732767 | G12: 0.060065061 | H12: 13141518 | I12: 0.098981569 | J12: 3346249.3 | K12: 11957906
C13: 일반모형/변동수수료접근법 | D13: 1887314.2 | E13: 2194517.2 | F13: 0.16277258 | G13: 0.14323135 | H13: 7658667.1 | I13: 0.16739189 | J13: 1919574.1 | K13: 6560493.7
C14: 보험료배분접근법 | D14: 1338234.8 | E14: 1352724.8 | F14: 0.010827636 | G14: -0.051834154 | H14: 5482851.3 | I14: 0.015829601 | J14: 1426675.3 | K14: 5397412.4
B15: - 재보험수익 | D15: 70336.827 | E15: 105910.46 | F15: 0.50576114 | G15: 0.12218063 | H15: 583953.49 | I15: 0.62736411 | J15: 94379.156 | K15: 358833.95
C16: 일반모형 | D16: 5220.4372 | E16: 14680.818 | F16: 1.8121818 | G16: 1.5518215 | H16: 22057.693 | I16: 0.23647661 | J16: 5753.0742 | K16: 17839.151
C17: 보험료배분접근법 | D17: 65116.39 | E17: 91229.643 | F17: 0.40102427 | G17: 0.029376909 | H17: 561895.8 | I17: 0.6478134 | J17: 88626.082 | K17: 340994.8
B18: - 재보험서비스비용 | D18: 267648.89 | E18: 283916.09 | F18: 0.060778129 | G18: 0.069763997 | H18: 1094644.6 | I18: 0.075209112 | J18: 265400.68 | K18: 1018076
C19: 일반모형 | D19: 8633.2903 | E19: 6680.7903 | F19: -0.22615943 | G19: -0.06315702 | H19: 29764.863 | I19: 0.034129441 | J19: 7131.1739 | K19: 28782.531
C20: 보험료배분접근법 | D20: 259015.6 | E20: 277235.3 | F20: 0.070342091 | G20: 0.073434128 | H20: 1064879.7 | I20: 0.076404285 | J20: 258269.5 | K20: 989293.45
B21: - 기타사업비용 | D21: 24876.517 | E21: 23385.702 | F21: -0.05992861 | G21: 0.58172642 | H21: 96505.214 | I21: 0.76235259 | J21: 14784.922 | K21: 54759.311
B22: 투 자 손 익 | D22: 89393.953 | E22: 4452.2331 | F22: -0.95019537 | G22: -0.88524707 | H22: 330285.66 | I22: -0.061832396 | J22: 38798.427 | K22: 352054
B23: - 투자수익 | D23: 606922.47 | E23: 510758.98 | F23: -0.15844444 | G23: -0.58145923 | H23: 2847519.5 | I23: -0.094757163 | J23: 1220332.7 | K23: 3145586.3
B24: - 투자비용 | D24: 517528.52 | E24: 506306.75 | F24: -0.021683385 | G24: -0.57148365 | H24: 2517233.8 | I24: -0.098906496 | J24: 1181534.3 | K24: 2793532.3
B25: 영 업 이 익 | D25: 250823.95 | E25: -149442.63 | H25: 726396.96 | I25: -0.47934381 | J25: -8963.2242 | K25: 1395156.7
B26: 영업외손익 | D26: -6043.5001 | E26: -5932.8464 | H26: -32119.243 | J26: -8528.8482 | K26: -28721.063
B27: 세전이익 | D27: 244780.45 | E27: -155375.48 | H27: 694277.72 | I27: -0.49190601 | J27: -17492.072 | K27: 1366435.6
B28: 법인세비용 | D28: 61599.281 | E28: -82335.3 | H28: 133171.31 | I28: -0.60336323 | J28: -1756.3792 | K28: 335751.3
B29: 당 기 순 이 익 | D29: 183181.17 | E29: -73040.177 | H29: 561106.41 | I29: -0.45559819 | J29: -15735.693 | K29: 1030684.3
B30: (ROE) | D30: 0.1565882 | E30: -0.059860034 | G30: -0.047724349 | H30: 0.12132647 | I30: -0.084531266 | J30: -0.012135685 | K30: 0.20585773
B31: 주) ROE : 연간 환산 기준

Sheet (6) BS
B1: VI. 요약 재무상태표
H4: (단위 : 백만원)
B5: 구 분 | D5: 2025. 12월 말 | G5: 2024. 12월 말
E6: 구성비 | F6: YTD | H6: 구성비
B7: 운 용 자 산 | D7: 47015757 | E7: 1 | F7: 0.026833642 | G7: 45787121 | H7: 1
B8: 현·예금및예치금 | D8: 1647260.4 | E8: 0.035036347 | F8: -0.22248932 | G8: 2118633.8 | H8: 0.04627139
B9: 유가증권 | D9: 34595707 | E9: 0.73583219 | F9: 0.074766959 | G9: 32189031 | H9: 0.70301495
B10: - 당기손익-공정가치측정유가증권 | D10: 8425527.9 | E10: 0.17920647 | F10: -0.0032237669 | G10: 8452777.7 | H10: 0.18461038
B11: - 기타포괄손익-공정가치측정유가증권 | D11: 25341092 | E11: 0.53899148 | F11: 0.11775571 | G11: 22671405 | H11: 0.49514807
B12: - 상각후원가측정유가증권 | D12: 0 | E12: 0 | G12: 0 | H12: 0
B13: - 당기손익인식증권 | E13: 0 | H13: 0
B14: - 매도가능증권 | E14: 0 | H14: 0
B15: - 만기보유증권 | E15: 0 | G15: 0 | H15: 0
B16: - 관계·종속기업투자주식 | D16: 829086.84 | E16: 0.017634234 | F16: -0.22140391 | G16: 1064848.5 | H16: 0.023256506
B17: 대출채권 | D17: 9568273.4 | E17: 0.20351206 | F17: -0.066105113 | G17: 10245557 | H17: 0.22376504
B18: 부동산 | D18: 1204515.9 | E18: 0.025619408 | F18: -0.023813662 | G18: 1233899.5 | H18: 0.026948616
B19: 비 운 용 자 산 | D19: 2595939.9 | F19: 0.19743006 | G19: 2167926.1
B20: (특별계정자산) | D20: 34178.09 | F20: 0.51021717 | G20: 22631.242
B21: 총 자 산 | D21: 49645875 | F21: 0.034770249 | G21: 47977679
B22: 책임준비금 | D22: 39451773 | F22: 0.030031911 | G22: 38301506
B23: - 보험계약부채 | D23: 34852924 | F23: 0.0014649386 | G23: 34801942
C24: 잔여보장요소 | D24: 29865165 | F24: -0.0099618334 | G24: 30165671
C25: 최선추정 | D25: 15522152 | F25: -0.057094795 | G25: 16462049
C26: 위험조정 | D26: 1887969.8 | F26: -0.01040996 | G26: 1907830.3
C27: 보험계약마진 | D27: 8977842.1 | F27: 0.080953084 | G27: 8305487.3
C28: 보험료배분접근법적용 | D28: 3477201.7 | F28: -0.0037539532 | G28: 3490304.1
C29: 발생사고요소 | D29: 4987758.9 | F29: 0.075812676 | G29: 4636270.8
B30: - 재보험계약부채 | D30: 0 | G30: 0
B31: - 투자계약부채 | D31: 4598849 | F31: 0.31412046 | G31: 3499564.2
B32: 계약자지분조정 | D32: 0 | G32: 0
B33: 기타부채 | D33: 5275807 | F33: 0.11601742 | G33: 4727351.9
B34: (특별계정부채) | D34: 34806.783 | F34: 0.60607579 | G34: 21671.943
B35: 부 채 총 계 | D35: 44762387 | F35: 0.039763911 | G35: 43050530
B36: 자 본 금 | D36: 44700 | F36: 0 | G36: 44700
B37: 자본잉여금 | D37: 113152.05 | F37: 0 | G37: 113152.05
B38: 신종자본증권 | D38: 0 | G38: 0
B39: 이익잉여금 | D39: 7952651.9 | F39: 0.075936451 | G39: 7391376.9
B40: - 해약환급금준비금 | D40: 3916614.6 | F40: -0.025314503 | G40: 4018336.8
B41: 자본조정 | D41: -67686.437 | G41: -67686.437
B42: 기타포괄손익 | D42: -3159330 | G42: -2554393.5
...
