Workbook

Sheet Cover
D4: IR Factsheet
D5: As of June. 2026
C8: 재무현황 (Financial Highlights)
C10: 요약재무상태표 (Selected Balance sheet)
C11: 요약손익계산서 (Selected Income Statement)
C13: RA, CSM, BEL Movement
C14: 신계약 CSM (New Business CSM)
C15: 신계약 CSM 배수 (New Business CSM Margin)
C17: 주요지표 (Key Index)
D18: 재무 안정성 (Financial Stability)
D19: 생산성 / 경영효율 (Productivity / Operating Efficiency)
C21: 상품별 수입보험료 (Premium by Product-type)
D22: 상품별 APE (Annualized Premium Equivalent (APE))
D23: 상품별 수입보험료 (Premium Income)
D24: 상품별 초회보험료 (Initial Premium)
D25: 상품별 초년도보험료 (First Year Premium)
C27: 채널별 수입보험료 (Premium by Distribution Channel)
D28: 채널별 APE (Annualized Premium Equivalent (APE))
D29: 채널별 수입보험료 (Premium Income)
D30: 채널별 초년도보험료 (First Year Premium)
C33: 투자영업 현황 (Investment)
D34: 대출 (Loan)/ 자산건전성 (Asset Quality of Loan)
D35: 채권 (Bond)
C37: 재무제표 (Full Financial Statements)
D38: 연결재무상태표 (Consolidated Balance Sheet - KIFRS)
D39: 연결손익계산서 (Consolidated Income Statement - KIFRS)

Sheet FH
F1: 재무현황 (Financial Highlights)
F2: (단위: 십억원) | J2: 45747 | K2: 45838 | L2: 45930 | M2: 46022 | N2: 46112 | O2: 46203 | P2: 46295 | Q2: 46387
A3: Disclaimer & Contact Information | F3: (Unit: KRW bn)
F4: 자산총계 (Total Assets) | J4: 35159.11 | K4: 35613.337 | L4: 35694.263 | M4: 35347.237 | N4: 34495.304 | O4: 35287.666
B5: 재무현황 (Financial Highlights) | G5: 운용자산 (Invested Assets) | J5: 32574.977 | K5: 33014.314 | L5: 33114.563 | M5: 32704.988 | N5: 31850.898 | O5: 32334.841
F6: 부채총계 (Total Liabilities) | J6: 33673.418 | K6: 33960.73 | L6: 34351.543 | M6: 33798.362 | N6: 32650.991 | O6: 32950.699
B7: 요약재무상태표 (Selected Balance sheet) | G7: 보험부채_CSM (Contract Service Margin) | J7: 2661.1771 | K7: 2744.2353 | L7: 2796.9809 | M7: 2457.0955 | N7: 2510.8346 | O7: 2645.7062
B8: 요약손익계산서 (Selected Income Statement) | G8: 신계약CSM (New Business CSM) | J8: 190.38142 | K8: 302.88629 | L8: 425.84844 | M8: 529.13223 | N8: 94.465158 | O8: 242.48659
F9: 자본총계 (Total Shareholders' Equity) | J9: 1485.6917 | K9: 1652.6077 | L9: 1342.7199 | M9: 1548.8747 | N9: 1844.313 | O9: 2336.9666
B10: RA, CSM, BEL Movement | F10: 수입보험료 (Premium Income) | J10: =SUM(J11:J12) -> 993.99903 | K10: =SUM(K11:K12) -> 2060.3062 | L10: =SUM(L11:L12) -> 3290.0986 | M10: =SUM(M11:M12) -> 4814.4476 | N10: =SUM(N11:N12) -> 1237.0425 | O10: =SUM(O11:O12) -> 3598.2557
B11: 신계약 CSM (New Business CSM) | G11: 일반계정 (General Account) | J11: 900.07486 | K11: 1828.9108 | L11: 3001.2197 | M11: 3986.9339 | N11: 1108.0866 | O11: 2393.8077
B12: 신계약 CSM 배수 (New Business CSM Margin) | G12: 특별계정 (Separate Account) | J12: 93.924172 | K12: 231.3954 | L12: 288.87884 | M12: 827.51371 | N12: 128.95594 | O12: 1204.448
F13: 보험손익 (Insurance Profit) | J13: 4.0710674 | K13: 70.419566 | L13: 94.982299 | M13: 113.77081 | N13: 22.386 | O13: 97.012122
B14: 주요지표 (Key Index) | F14: 투자손익 (Investment Profit) | J14: 54.593749 | K14: 29.633785 | L14: 52.81492 | M14: 85.040866 | N14: 8.719 | O14: 20.93199
C15: 재무 안정성 (Financial Stability) | F15: 영업이익 (Operating Profit) | J15: 58.664817 | K15: 100.05335 | L15: 147.79722 | M15: 198.81168 | N15: 31.104 | O15: 117.94411
C16: 생산성 / 경영효율 (Productivity / Operating Efficiency) | F16: 영업외손익(Non-Operating Profit) | J16: -5.0065737 | K16: -3.9254422 | L16: -21.179163 | M16: -23.383389 | N16: -0.105 | O16: 2.636382
F17: 법인세비용차감전순이익 (Earnings Before Income Tax) | J17: 53.658243 | K17: 96.127909 | L17: 126.61806 | M17: 175.42829 | N17: 31 | O17: 120.58049
B18: 상품별 수입보험료 (Premium by Product-type) | F18: 당기순이익 (Net Income) | J18: 46.19408 | K18: 82.412272 | L18: 109.85639 | M18: 124.49364 | N18: 25.024 | O18: 91.929677
C19: 상품별 APE (Annualized Premium Equivalent (APE))
C20: 상품별 수입보험료 (Premium Income)
C21: 상품별 초회보험료 (Initial Premium)
C22: 상품별 초년도보험료 (First Year Premium) | F22: (단위: 십억원) | J22: 45747 | K22: 45838 | L22: 45930 | M22: 46022 | N22: 46112 | O22: 46203 | P22: 46295 | Q22: 46387
F23: (Unit: KRW bn)
B24: 채널별 수입보험료 (Premium by Distribution Channel) | F24: 운용자산 이익율(Net Investment Yield) | J24: 0.038222661 | K24: 0.034722379 | L24: 0.035294828 | M24: 0.03428012 | N24: 0.035862482 | O24: 0.035666469
C25: 채널별 APE (Annualized Premium Equivalent (APE)) | F25: K-ICS 비율 (K-ICS Ratio) | J25: 1.2716316 | K25: 1.7696419 | L25: 1.735948 | M25: 1.7983878 | N25: 1.896 | O25: 2.0499919
C26: 채널별 수입보험료 (Premium Income) | F26: NPL 비율 (NPL Ratio) | J26: 0.0081432905 | K26: 0.017153668 | L26: 0.013365532 | M26: 0.013896943 | N26: 0.019631927 | O26: 0.011486652
C27: 채널별 초년도보험료 (First Year Premium) | F27: BPS (단위 원) (BPS (KRW)) | J27: 9519.8455 | K27: 10589.391 | L27: 8603.7273 | M27: 9924.7024 | N27: 11817.779 | O27: 14974.548
F28: EPS (단위 원) (EPS (KRW)) | J28: 286.28213 | K28: 510.73992 | L28: 680.82145 | M28: 771.53401 | N28: 155.08316 | O28: 589.05649
F29: 총자산이익율 (Retrun on Asset) | J29: 0.0053016209 | K29: 0.004698545 | L29: 0.0041706612 | M29: 0.0035623696 | N29: 0.0028663333 | O29: 0.0052059066
B30: 투자영업 현황 (Investment) | F30: 총자본이익율 (Return on Equity) | J30: 0.10696773 | K30: 0.09102001 | L30: 0.088455652 | M30: 0.070775476 | N30: 0.05899821 | O30: 0.094630398
C31: 대출 (Loan)/ 자산건전성 (Asset Quality of Loan) | F31: *1 K-ICS Ratio : 2026.1H 비율은 추정치로 추후 업데이트 예정
C32: 채권 (Bond) | F32: *2 공통 경과조치 적용 후 기준
B34: 재무제표 (Full Financial Statements)
C35: 재무상태표 (Balance Sheet - KIFRS)
C36: 손익계산서 (Income Statement - KIFRS)

Sheet FS
F1: 요약 재무상태표 (Selected Balance Sheet)
F2: (단위 십억원) | J2: FY25 | N2: FY26 | S2: Accumulated | U2: 증감
A3: Disclaimer & Contact Information | F3: (KRW bn) | J3: 45747 | K3: 45838 | L3: 45930 | M3: 46022 | N3: 46112 | O3: 46203 | P3: 46295 | Q3: 46387 | S3: FY25.1H | T3: FY26.1H | U3: YoY | V3: QoQ
F4: Ⅰ.자산총계 (Total assets) | J4: 35159.11 | K4: 35613.337 | L4: 35694.263 | M4: 35347.237 | N4: 34495.304 | O4: 35287.666 | S4: =K4 -> 35613.337 | T4: =O4 -> 35287.666 | U4: =IF(T4/S4<0,"n.a.",IF(S4>0,ROUND(T4,4)/ROUND(S4,4)-1,IF(S4<0,"n.a."))) -> -0.0091446442 | V4: =IF(O4/N4<0,"n.a.",IF(N4>0,ROUND(O4,4)/ROUND(N4,4)-1,IF(N4<0,"n.a."))) -> 0.022970138
B5: 재무현황 (Financial Highlights) | F5: ⅰ.현금및현금성자산 (Cash and cash equivalents) | G5: ⅰ. 현금및현금성자산 (Cash and cash equivalents) | J5: 244.56302 | K5: 286.41692 | L5: 278.6471 | M5: 250.36968 | N5: 356.19815 | O5: 412.27457 | S5: =K5 -> 286.41692 | T5: =O5 -> 412.27457 | U5: =IF(T5/S5<0,"n.a.",IF(S5>0,ROUND(T5,4)/ROUND(S5,4)-1,IF(S5<0,"n.a."))) -> 0.43942135 | V5: =IF(O5/N5<0,"n.a.",IF(N5>0,ROUND(O5,4)/ROUND(N5,4)-1,IF(N5<0,"n.a."))) -> 0.15743033
G6: ⅱ. 금융자산 (Financial assets) | J6: 33497.119 | K6: 34051.436 | L6: 34166.877 | M6: 33879.553 | N6: 32992.173 | O6: 33996.943 | S6: =K6 -> 34051.436 | T6: =O6 -> 33996.943 | U6: =IF(T6/S6<0,"n.a.",IF(S6>0,ROUND(T6,4)/ROUND(S6,4)-1,IF(S6<0,"n.a."))) -> -0.0016003114 | V6: =IF(O6/N6<0,"n.a.",IF(N6>0,ROUND(O6,4)/ROUND(N6,4)-1,IF(N6<0,"n.a."))) -> 0.030454793
B7: 요약재무상태표 (Selected Balance sheet) | H7: FVPL (Financial assets at fair value through profit or loss) | J7: 5927.7777 | K7: 5799.4486 | L7: 5516.1228 | M7: 5383.2564 | N7: 5180.8617 | O7: 6577.9176 | S7: =K7 -> 5799.4486 | T7: =O7 -> 6577.9176 | U7: =IF(T7/S7<0,"n.a.",IF(S7>0,ROUND(T7,4)/ROUND(S7,4)-1,IF(S7<0,"n.a."))) -> 0.13423155 | V7: =IF(O7/N7<0,"n.a.",IF(N7>0,ROUND(O7,4)/ROUND(N7,4)-1,IF(N7<0,"n.a."))) -> 0.26965705
B8: 요약손익계산서 (Selected Income Statement) | H8: FVOCI (Financial assets at fair value through other comprehensive income) | J8: 20858.794 | K8: 21635.551 | L8: 22988.363 | M8: 22837.835 | N8: 22414.696 | O8: 22307.75 | S8: =K8 -> 21635.551 | T8: =O8 -> 22307.75 | U8: =IF(T8/S8<0,"n.a.",IF(S8>0,ROUND(T8,4)/ROUND(S8,4)-1,IF(S8<0,"n.a."))) -> 0.031069206 | V8: =IF(O8/N8<0,"n.a.",IF(N8>0,ROUND(O8,4)/ROUND(N8,4)-1,IF(N8<0,"n.a."))) -> -0.0047712313
H9: AC (Financial assets at amortized cost) | J9: 6567.0127 | K9: 6444.1106 | L9: 5581.7322 | M9: 5630.3909 | N9: 5395.1925 | O9: 5106.6193 | S9: =K9 -> 6444.1106 | T9: =O9 -> 5106.6193 | U9: =IF(T9/S9<0,"n.a.",IF(S9>0,ROUND(T9,4)/ROUND(S9,4)-1,IF(S9<0,"n.a."))) -> -0.20755251 | V9: =IF(O9/N9<0,"n.a.",IF(N9>0,ROUND(O9,4)/ROUND(N9,4)-1,IF(N9<0,"n.a."))) -> -0.0534871
B10: RA, CSM, BEL Movement | G10: ⅲ. 관계기업투자자산 (Investments accounted for using equity method) | J10: 45.233889 | K10: 28.520989 | L10: 0 | M10: 0 | N10: 0 | O10: 0 | S10: =K10 -> 28.520989 | T10: =O10 -> 0 | U10: =IF(T10/S10<0,"n.a.",IF(S10>0,ROUND(T10,4)/ROUND(S10,4)-1,IF(S10<0,"n.a."))) -> -1 | V10: n.a.
B11: 신계약 CSM (New Business CSM) | G11: ⅳ. 유형자산 (Property, plant and equipment) | J11: 89.902195 | K11: 91.378958 | L11: 84.426651 | M11: 91.038645 | N11: 107.51994 | O11: 96.713842 | S11: =K11 -> 91.378958 | T11: =O11 -> 96.713842 | U11: =IF(T11/S11<0,"n.a.",IF(S11>0,ROUND(T11,4)/ROUND(S11,4)-1,IF(S11<0,"n.a."))) -> 0.058381028 | V11: =IF(O11/N11<0,"n.a.",IF(N11>0,ROUND(O11,4)/ROUND(N11,4)-1,IF(N11<0,"n.a."))) -> -0.10050326
B12: 신계약 CSM 배수 (New Business CSM Margin) | G12: ⅴ. 투자부동산 (Investment properties) | J12: 306.5213 | K12: 304.25952 | L12: 305.78205 | M12: 296.13489 | N12: 300.04131 | O12: 74.350688 | S12: =K12 -> 304.25952 | T12: =O12 -> 74.350688 | U12: =IF(T12/S12<0,"n.a.",IF(S12>0,ROUND(T12,4)/ROUND(S12,4)-1,IF(S12<0,"n.a."))) -> -0.75563392 | V12: =IF(O12/N12<0,"n.a.",IF(N12>0,ROUND(O12,4)/ROUND(N12,4)-1,IF(N12<0,"n.a."))) -> -0.75219845
G13: ⅵ. 무형자산 (Intangible assets other than goodwill) | J13: 17.070498 | K13: 29.952522 | L13: 28.75102 | M13: 27.795714 | N13: 26.13475 | O13: 24.128873 | S13: =K13 -> 29.952522 | T13: =O13 -> 24.128873 | U13: =IF(T13/S13<0,"n.a.",IF(S13>0,ROUND(T13,4)/ROUND(S13,4)-1,IF(S13<0,"n.a."))) -> -0.19442784 | V13: =IF(O13/N13<0,"n.a.",IF(N13>0,ROUND(O13,4)/ROUND(N13,4)-1,IF(N13<0,"n.a."))) -> -0.07675207
B14: 주요지표 (Key Index) | G14: ⅶ. 기타자산 (Other assets) | J14: 485.3665 | K14: 358.01457 | L14: 365.10381 | M14: 353.66306 | N14: 295.88875 | O14: 64.773205 | S14: =K14 -> 358.01457 | T14: =O14 -> 64.773205 | U14: =IF(T14/S14<0,"n.a.",IF(S14>0,ROUND(T14,4)/ROUND(S14,4)-1,IF(S14<0,"n.a."))) -> -0.81907665 | V14: =IF(O14/N14<0,"n.a.",IF(N14>0,ROUND(O14,4)/ROUND(N14,4)-1,IF(N14<0,"n.a."))) -> -0.78108931
C15: 재무 안정성 (Financial Stability) | G15: ⅷ. 재보험계약자산 (Reinsurance contracts assets) | J15: 473.33356 | K15: 463.3578 | L15: 464.67552 | M15: 448.68173 | N15: 417.34774 | O15: 397.10532 | S15: =K15 -> 463.3578 | T15: =O15 -> 397.10532 | U15: =IF(T15/S15<0,"n.a.",IF(S15>0,ROUND(T15,4)/ROUND(S15,4)-1,IF(S15<0,"n.a."))) -> -0.14298346 | V15: =IF(O15/N15<0,"n.a.",IF(N15>0,ROUND(O15,4)/ROUND(N15,4)-1,IF(N15<0,"n.a."))) -> -0.048502484
C16: 생산성 / 경영효율 (Productivity / Operating Efficiency) | F16: Ⅱ. 부채총계 (Total liabilities) | J16: 33673.418 | K16: 33960.73 | L16: 34351.543 | M16: 33798.362 | N16: 32650.991 | O16: 32950.699 | S16: =K16 -> 33960.73 | T16: =O16 -> 32950.699 | U16: =IF(T16/S16<0,"n.a.",IF(S16>0,ROUND(T16,4)/ROUND(S16,4)-1,IF(S16<0,"n.a."))) -> -0.029741122 | V16: =IF(O16/N16<0,"n.a.",IF(N16>0,ROUND(O16,4)/ROUND(N16,4)-1,IF(N16<0,"n.a."))) -> 0.0091791486
G17: ⅰ. 보험계약부채 (Insurance contracts issued that are liabilities) | J17: 29330.677 | K17: 29166.616 | L17: 29392.006 | M17: 28145.079 | N17: 26584.371 | O17: 25971.37 | S17: =K17 -> 29166.616 | T17: =O17 -> 25971.37 | U17: =IF(T17/S17<0,"n.a.",IF(S17>0,ROUND(T17,4)/ROUND(S17,4)-1,IF(S17<0,"n.a."))) -> -0.10955147 | V17: =IF(O17/N17<0,"n.a.",IF(N17>0,ROUND(O17,4)/ROUND(N17,4)-1,IF(N17<0,"n.a."))) -> -0.02305868
B18: 상품별 수입보험료 (Premium by Product-type) | H18: CSM (Contract service margin) | J18: 2661.1771 | K18: 2744.2353 | L18: 2796.9809 | M18: 2457.0955 | N18: 2510.8346 | O18: 2645.7062 | S18: =K18 -> 2744.2353 | T18: =O18 -> 2645.7062 | U18: =IF(T18/S18<0,"n.a.",IF(S18>0,ROUND(T18,4)/ROUND(S18,4)-1,IF(S18<0,"n.a."))) -> -0.035904028 | V18: =IF(O18/N18<0,"n.a.",IF(N18>0,ROUND(O18,4)/ROUND(N18,4)-1,IF(N18<0,"n.a."))) -> 0.053715844
C19: 상품별 APE (Annualized Premium Equivalent (APE)) | G19: ⅱ. 투자계약부채 (Investment contracts liabilities) | J19: 3464.3864 | K19: 3474.4254 | L19: 3460.5865 | M19: 3702.7495 | N19: 3647.1587 | O19: 4461.0323 | S19: =K19 -> 3474.4254 | T19: =O19 -> 4461.0323 | U19: =IF(T19/S19<0,"n.a.",IF(S19>0,ROUND(T19,4)/ROUND(S19,4)-1,IF(S19<0,"n.a."))) -> 0.28396261 | V19: =IF(O19/N19<0,"n.a.",IF(N19>0,ROUND(O19,4)/ROUND(N19,4)-1,IF(N19<0,"n.a."))) -> 0.22315278
C20: 상품별 수입보험료 (Premium Income) | G20: ⅲ. 금융부채 (Financial liabilities) | J20: 814.48125 | K20: 1253.3246 | L20: 1409.0659 | M20: 1881.1728 | N20: 2353.8354 | O20: 2401.0461 | S20: =K20 -> 1253.3246 | T20: =O20 -> 2401.0461 | U20: =IF(T20/S20<0,"n.a.",IF(S20>0,ROUND(T20,4)/ROUND(S20,4)-1,IF(S20<0,"n.a."))) -> 0.91574162 | V20: =IF(O20/N20<0,"n.a.",IF(N20>0,ROUND(O20,4)/ROUND(N20,4)-1,IF(N20<0,"n.a."))) -> 0.020056925
C21: 상품별 초회보험료 (Initial Premium) | H21: 사채 (Borrowings) | J21: 299.09907 | K21: 971.25899 | L21: 994.26689 | M21: 1210.2125 | N21: 1249.5335 | O21: 1263.8484 | S21: =K21 -> 971.25899 | T21: =O21 -> 1263.8484 | U21: =IF(T21/S21<0,"n.a.",IF(S21>0,ROUND(T21,4)/ROUND(S21,4)-1,IF(S21<0,"n.a."))) -> 0.30124756 | V21: =IF(O21/N21<0,"n.a.",IF(N21>0,ROUND(O21,4)/ROUND(N21,4)-1,IF(N21<0,"n.a."))) -> 0.011456195
C22: 상품별 초년도보험료 (First Year Premium) | G22: ⅳ. 기타부채 (Other liabilities) | J22: 52.189581 | K22: 55.463708 | L22: 79.302011 | M22: 59.705326 | N22: 56.75185 | O22: 109.49829 | S22: =K22 -> 55.463708 | T22: =O22 -> 109.49829 | U22: =IF(T22/S22<0,"n.a.",IF(S22>0,ROUND(T22,4)/ROUND(S22,4)-1,IF(S22<0,"n.a."))) -> 0.9742336 | V22: =IF(O22/N22<0,"n.a.",IF(N22>0,ROUND(O22,4)/ROUND(N22,4)-1,IF(N22<0,"n.a."))) -> 0.92942426
G23: ⅴ. 재보험계약부채 (Reinsurance contracts assets) | J23: 11.68372 | K23: 10.899672 | L23: 10.582539 | M23: 9.6561702 | N23: 8.8742228 | O23: 7.7522609 | S23: =K23 -> 10.899672 | T23: =O23 -> 7.7522609 | U23: =IF(T23/S23<0,"n.a.",IF(S23>0,ROUND(T23,4)/ROUND(S23,4)-1,IF(S23<0,"n.a."))) -> -0.28876024 | V23: =IF(O23/N23<0,"n.a.",IF(N23>0,ROUND(O23,4)/ROUND(N23,4)-1,IF(N23<0,"n.a."))) -> -0.12642266
B24: 채널별 수입보험료 (Premium by Distribution Channel) | F24: Ⅲ. 자본총계 (Total Shareholders' Equity) | J24: 1485.6917 | K24: 1652.6077 | L24: 1342.7199 | M24: 1548.8747 | N24: 1844.313 | O24: 2336.9666 | S24: =K24 -> 1652.6077 | T24: =O24 -> 2336.9666 | U24: =IF(T24/S24<0,"n.a.",IF(S24>0,ROUND(T24,4)/ROUND(S24,4)-1,IF(S24<0,"n.a."))) -> 0.4141085 | V24: =IF(O24/N24<0,"n.a.",IF(N24>0,ROUND(O24,4)/ROUND(N24,4)-1,IF(N24<0,"n.a."))) -> 0.26712039
C25: 채널별 APE (Annualized Premium Equivalent (APE)) | G25: ⅰ. 자본금 (Issued capital) | J25: 806.79292 | K25: 806.79292 | L25: 806.79292 | M25: 806.79292 | N25: 806.79292 | O25: 806.79292 | S25: =K25 -> 806.79292 | T25: =O25 -> 806.79292 | U25: =IF(T25/S25<0,"n.a.",IF(S25>0,ROUND(T25,4)/ROUND(S25,4)-1,IF(S25<0,"n.a."))) -> 0 | V25: =IF(O25/N25<0,"n.a.",IF(N25>0,ROUND(O25,4)/ROUND(N25,4)-1,IF(N25<0,"n.a."))) -> 0
C26: 채널별 수입보험료 (Premium Income) | G26: ⅱ. 자본잉여금 (Capital surplus) | J26: 463.68039 | K26: 463.68039 | L26: 463.68039 | M26: 463.68039 | N26: 463.68039 | O26: 463.68039 | S26: =K26 -> 463.68039 | T26: =O26 -> 463.68039 | U26: =IF(T26/S26<0,"n.a.",IF(S26>0,ROUND(T26,4)/ROUND(S26,4)-1,IF(S26<0,"n.a."))) -> 0 | V26: =IF(O26/N26<0,"n.a.",IF(N26>0,ROUND(O26,4)/ROUND(N26,4)-1,IF(N26<0,"n.a."))) -> 0
C27: 채널별 초년도보험료 (First Year Premium) | G27: ⅲ. 신종자본증권 (Hybrid bonds) | J27: 344.56736 | K27: 344.56736 | L27: 0 | M27: 0 | N27: 0 | O27: 0 | S27: =K27 -> 344.56736 | T27: =O27 -> 0 | U27: =IF(T27/S27<0,"n.a.",IF(S27>0,ROUND(T27,4)/ROUND(S27,4)-1,IF(S27<0,"n.a."))) -> -1 | V27: n.a.
G28: ⅴ. 자본조정 (Capital Adjustments) | J28: -59.540575 | K28: -59.540575 | L28: -117.99152 | M28: -116.90631 | N28: -116.90631 | O28: -58.355691 | S28: =K28 -> -59.540575 | T28: =O28 -> -58.355691 | U28: =IF(T28/S28<0,"n.a.",IF(S28>0,ROUND(T28,4)/ROUND(S28,4)-1,IF(S28<0,"n.a."))) -> n.a. | V28: =IF(O28/N28<0,"n.a.",IF(N28>0,ROUND(O28,4)/ROUND(N28,4)-1,IF(N28<0,"n.a."))) -> n.a.
G29: ⅵ. 기타포괄손익누계액 (Accumulated other comprehensive income) | J29: -1621.937 | K29: -1491.2392 | L29: -1414.1059 | M29: -1223.6736 | N29: -953.56612 | O29: -530.12447 | S29: =K29 -> -1491.2392 | T29: =O29 -> -530.12447 | U29: =IF(T29/S29<0,"n.a.",IF(S29>0,ROUND(T29,4)/ROUND(S29,4)-1,IF(S29<0,"n.a."))) -> n.a. | V29: =IF(O29/N29<0,"n.a.",IF(N29>0,ROUND(O29,4)/ROUND(N29,4)-1,IF(N29<0,"n.a."))) -> n.a.
B30: 투자영업 현황 (Investment) | G30: ⅳ. 이익잉여금 (Retained earnings) | J30: 1552.1286 | K30: 1588.3468 | L30: 1604.344 | M30: 1618.9813 | N30: 1644.3121 | O30: 1654.9734 | S30: =K30 -> 1588.3468 | T30: =O30 -> 1654.9734 | U30: =IF(T30/S30<0,"n.a.",IF(S30>0,ROUND(T30,4)/ROUND(S30,4)-1,IF(S30<0,"n.a."))) -> 0.041947136 | V30: =IF(O30/N30<0,"n.a.",IF(N30>0,ROUND(O30,4)/ROUND(N30,4)-1,IF(N30<0,"n.a."))) -> 0.0064837448
C31: 대출 (Loan)/ 자산건전성 (Asset Quality of Loan) | F31: 자본과부채총계 (Total Shareholders' Equity and liabilities) | J31: 35159.11 | K31: 35613.337 | L31: 35694.263 | M31: 35347.237 | N31: 34495.304 | O31: 35287.666 | S31: =K31 -> 35613.337 | T31: =O31 -> 35287.666 | U31: =IF(T31/S31<0,"n.a.",IF(S31>0,ROUND(T31,4)/ROUND(S31,4)-1,IF(S31<0,"n.a."))) -> -0.0091446442 | V31: =IF(O31/N31<0,"n.a.",IF(N31>0,ROUND(O31,4)/ROUND(N31,4)-1,IF(N31<0,"n.a."))) -> 0.022970138
C32: 채권 (Bond)
B34: 재무제표 (Full Financial Statements) | F34: 요약 손익계산서 (Selected Income Statement)
C35: 재무상태표 (Balance Sheet - KIFRS) | F35: (단위 십억원) | J35: FY25 | N35: FY26 | S35: Accumulated | U35: 증감
C36: 손익계산서 (Income Statement - KIFRS) | F36: (KRW bn) | J36: 45747 | K36: 45838 | L36: 45930 | M36: 46022 | N36: 46112 | O36: 46203 | P36: 46295 | Q36: 46387 | S36: FY25.1H | T36: FY26.1H | U36: YoY | V36: QoQ
F37: 보험손익 (Insurance service result) | J37: 4.0710674 | K37: 66.348499 | L37: 24.562732 | M37: 18.788515 | N37: 22.385733 | O37: 74.626389 | S37: =+SUM(J37:K37) -> 70.419566 | T37: =+SUM(N37:Q37) -> 97.012122 | U37: =IF(T37/S37<0,"n.a.",IF(S37>0,ROUND(T37,4)/ROUND(S37,4)-1,IF(S37<0,"n.a."))) -> 0.37762924 | V37: =IF(O37/N37<0,"n.a.",IF(N37>0,ROUND(O37,4)/ROUND(N37,4)-1,IF(N37<0,"n.a."))) -> 2.3336639
G38: CSM 상각 (Amortization of CSM) | J38: 62.317797 | K38: 63.745714 | L38: 63.797646 | M38: 56.890212 | N38: 62.113713 | O38: 63.397781 | S38: =+SUM(J38:K38) -> 126.06351 | T38: =+SUM(N38:Q38) -> 125.51149 | U38: =IF(T38/S38<0,"n.a.",IF(S38>0,ROUND(T38,4)/ROUND(S38,4)-1,IF(S38<0,"n.a."))) -> -0.0043787456 | V38: =IF(O38/N38<0,"n.a.",IF(N38>0,ROUND(O38,4)/ROUND(N38,4)-1,IF(N38<0,"n.a."))) -> 0.020673378
G39: RA 상각 (Amortization of RA) | J39: 11.135398 | K39: 11.008743 | L39: 10.759074 | M39: 10.730104 | N39: 10.272807 | O39: 9.9859833 | S39: =+SUM(J39:K39) -> 22.144141 | T39: =+SUM(N39:Q39) -> 20.25879 | U39: =IF(T39/S39<0,"n.a.",IF(S39>0,ROUND(T39,4)/ROUND(S39,4)-1,IF(S39<0,"n.a."))) -> -0.085137802 | V39: =IF(O39/N39<0,"n.a.",IF(N39>0,ROUND(O39,4)/ROUND(N39,4)-1,IF(N39<0,"n.a."))) -> -0.027918386
G40: 예실차 (Difference between estimated and actual) | J40: -17.649083 | K40: -8.1693348 | L40: -39.308665 | M40: -6.7420452 | N40: -25.088176 | O40: -19.381523 | S40: =+SUM(J40:K40) -> -25.818418 | T40: =+SUM(N40:Q40) -> -44.469699 | U40: =IF(T40/S40<0,"n.a.",IF(S40>0,ROUND(T40,4)/ROUND(S40,4)-1,IF(S40<0,"n.a."))) -> n.a. | V40: =IF(O40/N40<0,"n.a.",IF(N40>0,ROUND(O40,4)/ROUND(N40,4)-1,IF(N40<0,"n.a."))) -> n.a.
H41: 보험금예실차 (Claims experience variance) | J41: -19.417094 | K41: -9.3369303 | L41: -26.88678 | M41: -13.162422 | N41: -21.808594 | O41: -21.527062 | S41: =+SUM(J41:K41) -> -28.754024 | T41: =+SUM(N41:Q41) -> -43.335656 | U41: =IF(T41/S41<0,"n.a.",IF(S41>0,ROUND(T41,4)/ROUND(S41,4)-1,IF(S41<0,"n.a."))) -> n.a. | V41: =IF(O41/N41<0,"n.a.",IF(N41>0,ROUND(O41,4)/ROUND(N41,4)-1,IF(N41<0,"n.a."))) -> n.a.
...

Sheet CSM
F1: BEL, RA, CSM Movement
F2: (단위 십억원) | J2: FY25 | N2: FY26 | S2: Accumulated
A3: Disclaimer & Contact Information | F3: (KRW bn) | J3: 45747 | K3: 45838 | L3: 45930 | M3: 46022 | N3: 46112 | O3: 46203 | P3: 46295 | Q3: 46387 | S3: FY25.1H | T3: FY26.1H | U3: YoY | V3: QoQ
F4: BEL | I4: 기시 BEL (Beginning BEL) | J4: 23292.638 | K4: 24379.767 | L4: 24160.524 | M4: 24315.769 | N4: 23426.845 | O4: 21761.865 | S4: =J4 -> 23292.638 | T4: =N4 -> 23426.845 | U4: =IF(T4/S4<0,"n.a.",IF(S4>0,ROUND(T4,4)/ROUND(S4,4)-1,IF(S4<0,"n.a."))) -> 0.0057617863 | V4: =IF(O4/N4<0,"n.a.",IF(N4>0,ROUND(O4,4)/ROUND(N4,4)-1,IF(N4<0,"n.a."))) -> -0.071071444
B5: 재무현황 (Financial Highlights) | I5: 신계약 (New business) | J5: -206.71097 | K5: -123.42445 | L5: -135.56074 | M5: -112.52749 | N5: -103.94172 | O5: -162.93215 | S5: =+SUM(J5:K5) -> -330.13542 | T5: =+SUM(N5:Q5) -> -266.87387 | U5: =IF(T5/S5<0,"n.a.",IF(S5>0,ROUND(T5,4)/ROUND(S5,4)-1,IF(S5<0,"n.a."))) -> n.a. | V5: =IF(O5/N5<0,"n.a.",IF(N5>0,ROUND(O5,4)/ROUND(N5,4)-1,IF(N5<0,"n.a."))) -> n.a.
I6: 이자부리 (Unwinding) | J6: 224.28293 | K6: 326.06563 | L6: 272.09561 | M6: 291.67364 | N6: 312.79936 | O6: 753.45579 | S6: =+SUM(J6:K6) -> 550.34856 | T6: =+SUM(N6:Q6) -> 1066.2552 | U6: =IF(T6/S6<0,"n.a.",IF(S6>0,ROUND(T6,4)/ROUND(S6,4)-1,IF(S6<0,"n.a."))) -> 0.93741785 | V6: =IF(O6/N6<0,"n.a.",IF(N6>0,ROUND(O6,4)/ROUND(N6,4)-1,IF(N6<0,"n.a."))) -> 1.4087508
B7: 요약재무상태표 (Selected Balance sheet) | I7: 당기 현금흐름 (Cashflow) | J7: -80.928354 | K7: 19.204318 | L7: 212.07019 | M7: -176.78153 | N7: -310.62606 | O7: 37.415239 | S7: =+SUM(J7:K7) -> -61.724036 | T7: =+SUM(N7:Q7) -> -273.21082 | U7: =IF(T7/S7<0,"n.a.",IF(S7>0,ROUND(T7,4)/ROUND(S7,4)-1,IF(S7<0,"n.a."))) -> n.a. | V7: =IF(O7/N7<0,"n.a.",IF(N7>0,ROUND(O7,4)/ROUND(N7,4)-1,IF(N7<0,"n.a."))) -> n.a.
B8: 요약손익계산서 (Selected Income Statement) | I8: 기타 (Others) | J8: 1150.4855 | K8: -441.08821 | L8: -193.35993 | M8: -891.28893 | N8: -1563.2113 | O8: -1379.8324 | S8: =+SUM(J8:K8) -> 709.39731 | T8: =+SUM(N8:Q8) -> -2943.0437 | U8: =IF(T8/S8<0,"n.a.",IF(S8>0,ROUND(T8,4)/ROUND(S8,4)-1,IF(S8<0,"n.a."))) -> n.a. | V8: =IF(O8/N8<0,"n.a.",IF(N8>0,ROUND(O8,4)/ROUND(N8,4)-1,IF(N8<0,"n.a."))) -> n.a.
I9: 기말 BEL (Ending BEL) | J9: 24379.767 | K9: 24160.524 | L9: 24315.769 | M9: 23426.845 | N9: 21761.865 | O9: 21009.972 | S9: =K9 -> 24160.524 | T9: =O9 -> 21009.972 | U9: =IF(T9/S9<0,"n.a.",IF(S9>0,ROUND(T9,4)/ROUND(S9,4)-1,IF(S9<0,"n.a."))) -> -0.13040083 | V9: =IF(O9/N9<0,"n.a.",IF(N9>0,ROUND(O9,4)/ROUND(N9,4)-1,IF(N9<0,"n.a."))) -> -0.034550972
B10: RA, CSM, BEL Movement | F10: RA | I10: 기시 RA (Beginning RA) | J10: 466.33601 | K10: 472.4947 | L10: 488.93878 | M10: 493.99081 | N10: 470.44579 | O10: 489.20572 | S10: =J10 -> 466.33601 | T10: =N10 -> 470.44579 | U10: =IF(T10/S10<0,"n.a.",IF(S10>0,ROUND(T10,4)/ROUND(S10,4)-1,IF(S10<0,"n.a."))) -> 0.0088129589 | V10: =IF(O10/N10<0,"n.a.",IF(N10>0,ROUND(O10,4)/ROUND(N10,4)-1,IF(N10<0,"n.a."))) -> 0.039876857
B11: 신계약 CSM (New Business CSM) | I11: 신계약 (New business) | J11: 17.914724 | K11: 13.116019 | L11: 14.742877 | M11: 12.613123 | N11: 11.750924 | O11: 16.158727 | S11: =+SUM(J11:K11) -> 31.030743 | T11: =+SUM(N11:Q11) -> 27.909651 | U11: =IF(T11/S11<0,"n.a.",IF(S11>0,ROUND(T11,4)/ROUND(S11,4)-1,IF(S11<0,"n.a."))) -> -0.10057781 | V11: =IF(O11/N11<0,"n.a.",IF(N11>0,ROUND(O11,4)/ROUND(N11,4)-1,IF(N11<0,"n.a."))) -> 0.37510318
B12: 신계약 CSM 배수 (New Business CSM Margin) | I12: 이자부리 (Unwinding) | J12: 4.1129863 | K12: 4.2515465 | L12: 4.309212 | M12: 5.2846066 | N12: 4.1300512 | O12: 4.2226775 | S12: =+SUM(J12:K12) -> 8.3645328 | T12: =+SUM(N12:Q12) -> 8.3527287 | U12: =IF(T12/S12<0,"n.a.",IF(S12>0,ROUND(T12,4)/ROUND(S12,4)-1,IF(S12<0,"n.a."))) -> -0.0014107239 | V12: =IF(O12/N12<0,"n.a.",IF(N12>0,ROUND(O12,4)/ROUND(N12,4)-1,IF(N12<0,"n.a."))) -> 0.022420765
I13: RA 상각 (Amortization of RA) | J13: -11.135398 | K13: -11.008743 | L13: -10.759074 | M13: -10.730104 | N13: -10.272807 | O13: -9.9859833 | S13: =+SUM(J13:K13) -> -22.144141 | T13: =+SUM(N13:Q13) -> -20.25879 | U13: =IF(T13/S13<0,"n.a.",IF(S13>0,ROUND(T13,4)/ROUND(S13,4)-1,IF(S13<0,"n.a."))) -> n.a. | V13: =IF(O13/N13<0,"n.a.",IF(N13>0,ROUND(O13,4)/ROUND(N13,4)-1,IF(N13<0,"n.a."))) -> n.a.
B14: 주요지표 (Key Index) | I14: 기타 (Others) | J14: -4.7336266 | K14: 10.085262 | L14: -3.2409879 | M14: -30.712647 | N14: 13.151767 | O14: 23.963908 | S14: =+SUM(J14:K14) -> 5.3516355 | T14: =+SUM(N14:Q14) -> 37.115675 | U14: =IF(T14/S14<0,"n.a.",IF(S14>0,ROUND(T14,4)/ROUND(S14,4)-1,IF(S14<0,"n.a."))) -> 5.9354399 | V14: =IF(O14/N14<0,"n.a.",IF(N14>0,ROUND(O14,4)/ROUND(N14,4)-1,IF(N14<0,"n.a."))) -> 0.8221004
C15: 재무 안정성 (Financial Stability) | I15: 기말 RA (Ending RA) | J15: 472.4947 | K15: 488.93878 | L15: 493.99081 | M15: 470.44579 | N15: 489.20572 | O15: 523.56505 | S15: =K15 -> 488.93878 | T15: =O15 -> 523.56505 | U15: =IF(T15/S15<0,"n.a.",IF(S15>0,ROUND(T15,4)/ROUND(S15,4)-1,IF(S15<0,"n.a."))) -> 0.070819293 | V15: =IF(O15/N15<0,"n.a.",IF(N15>0,ROUND(O15,4)/ROUND(N15,4)-1,IF(N15<0,"n.a."))) -> 0.070235077
C16: 생산성 / 경영효율 (Productivity / Operating Efficiency) | F16: CSM | I16: 기시 CSM (Beginning CSM) | J16: 2671.0889 | K16: 2661.1771 | L16: 2744.2353 | M16: 2796.9809 | N16: 2457.0955 | O16: 2510.8346 | S16: =J16 -> 2671.0889 | T16: =N16 -> 2457.0955 | U16: =IF(T16/S16<0,"n.a.",IF(S16>0,ROUND(T16,4)/ROUND(S16,4)-1,IF(S16<0,"n.a."))) -> -0.080114668 | V16: =IF(O16/N16<0,"n.a.",IF(N16>0,ROUND(O16,4)/ROUND(N16,4)-1,IF(N16<0,"n.a."))) -> 0.021870985
I17: 신계약 (New business) | J17: 190.38142 | K17: 112.50486 | L17: 122.96216 | M17: 103.28378 | N17: 94.465158 | O17: 148.02143 | S17: =+SUM(J17:K17) -> 302.88629 | T17: =+SUM(N17:Q17) -> 242.48659 | U17: =IF(T17/S17<0,"n.a.",IF(S17>0,ROUND(T17,4)/ROUND(S17,4)-1,IF(S17<0,"n.a."))) -> -0.19941377 | V17: =IF(O17/N17<0,"n.a.",IF(N17>0,ROUND(O17,4)/ROUND(N17,4)-1,IF(N17<0,"n.a."))) -> 0.56694105
B18: 상품별 수입보험료 (Premium by Product-type) | I18: 이자부리 (Unwinding) | J18: 27.804562 | K18: 27.189727 | L18: 27.696868 | M18: 27.814268 | N18: 24.745961 | O18: 25.598145 | S18: =+SUM(J18:K18) -> 54.994289 | T18: =+SUM(N18:Q18) -> 50.344105 | U18: =IF(T18/S18<0,"n.a.",IF(S18>0,ROUND(T18,4)/ROUND(S18,4)-1,IF(S18<0,"n.a."))) -> -0.084557854 | V18: =IF(O18/N18<0,"n.a.",IF(N18>0,ROUND(O18,4)/ROUND(N18,4)-1,IF(N18<0,"n.a."))) -> 0.034433848
C19: 상품별 APE (Annualized Premium Equivalent (APE)) | I19: CSM 상각 (Amortization of CSM) | J19: -62.317686 | K19: -63.745714 | L19: -63.797646 | M19: -56.890212 | N19: -62.113713 | O19: -63.397781 | S19: =+SUM(J19:K19) -> -126.0634 | T19: =+SUM(N19:Q19) -> -125.51149 | U19: =IF(T19/S19<0,"n.a.",IF(S19>0,ROUND(T19,4)/ROUND(S19,4)-1,IF(S19<0,"n.a."))) -> n.a. | V19: =IF(O19/N19<0,"n.a.",IF(N19>0,ROUND(O19,4)/ROUND(N19,4)-1,IF(N19<0,"n.a."))) -> n.a.
C20: 상품별 수입보험료 (Premium Income) | I20: 기타 (Others) | J20: -165.78003 | K20: 7.1092549 | L20: -34.115748 | M20: -414.09326 | N20: -3.35827 | O20: 24.649774 | S20: =+SUM(J20:K20) -> -158.67078 | T20: =+SUM(N20:Q20) -> 21.291504 | U20: =IF(T20/S20<0,"n.a.",IF(S20>0,ROUND(T20,4)/ROUND(S20,4)-1,IF(S20<0,"n.a."))) -> n.a. | V20: =IF(O20/N20<0,"n.a.",IF(N20>0,ROUND(O20,4)/ROUND(N20,4)-1,IF(N20<0,"n.a."))) -> n.a.
C21: 상품별 초회보험료 (Initial Premium) | I21: 기말 CSM (Ending CSM) | J21: 2661.1771 | K21: 2744.2353 | L21: 2796.9809 | M21: 2457.0955 | N21: 2510.8346 | O21: 2645.7062 | S21: =K21 -> 2744.2353 | T21: =O21 -> 2645.7062 | U21: =IF(T21/S21<0,"n.a.",IF(S21>0,ROUND(T21,4)/ROUND(S21,4)-1,IF(S21<0,"n.a."))) -> -0.035904028 | V21: =IF(O21/N21<0,"n.a.",IF(N21>0,ROUND(O21,4)/ROUND(N21,4)-1,IF(N21<0,"n.a."))) -> 0.053715844
C22: 상품별 초년도보험료 (First Year Premium)
B24: 채널별 수입보험료 (Premium by Distribution Channel) | F24: 신계약 CSM (New Business CSM)
C25: 채널별 APE (Annualized Premium Equivalent (APE)) | F25: (단위 십억원, %) | J25: FY25 | N25: FY26 | S25: Accumulated
C26: 채널별 수입보험료 (Premium Income) | F26: (KRW bn, %) | J26: 45747 | K26: 45838 | L26: 45930 | M26: 46022 | N26: 46112 | O26: 46203 | P26: 46295 | Q26: 46387 | S26: FY25.1H | T26: FY26.1H | U26: YoY | V26: QoQ
C27: 채널별 초년도보험료 (First Year Premium) | F27: 보장성 (Protection-type) | J27: 190.08209 | K27: 111.85241 | L27: 118.75089 | M27: 100.53123 | N27: 85.627267 | O27: 133.20411 | S27: =+SUM(J27:K27) -> 301.9345 | T27: =+SUM(N27:Q27) -> 218.83138 | U27: =IF(T27/S27<0,"n.a.",IF(S27>0,ROUND(T27,4)/ROUND(S27,4)-1,IF(S27<0,"n.a."))) -> -0.27523552 | V27: =IF(O27/N27<0,"n.a.",IF(N27>0,ROUND(O27,4)/ROUND(N27,4)-1,IF(N27<0,"n.a."))) -> 0.55562653
H28: 사망 (Death) | J28: 24.36491 | K28: 20.799178 | L28: 24.486239 | M28: 33.3637 | N28: 32.12895 | O28: 73.297422 | S28: =+SUM(J28:K28) -> 45.164087 | T28: =+SUM(N28:Q28) -> 105.42637 | U28: =IF(T28/S28<0,"n.a.",IF(S28>0,ROUND(T28,4)/ROUND(S28,4)-1,IF(S28<0,"n.a."))) -> 1.3342965 | V28: =IF(O28/N28<0,"n.a.",IF(N28>0,ROUND(O28,4)/ROUND(N28,4)-1,IF(N28<0,"n.a."))) -> 1.2813471
H29: 건강 (Health) | J29: 165.71718 | K29: 91.053229 | L29: 94.264653 | M29: 67.167528 | N29: 53.498317 | O29: 59.906689 | S29: =+SUM(J29:K29) -> 256.77041 | T29: =+SUM(N29:Q29) -> 113.40501 | U29: =IF(T29/S29<0,"n.a.",IF(S29>0,ROUND(T29,4)/ROUND(S29,4)-1,IF(S29<0,"n.a."))) -> -0.55834084 | V29: =IF(O29/N29<0,"n.a.",IF(N29>0,ROUND(O29,4)/ROUND(N29,4)-1,IF(N29<0,"n.a."))) -> 0.11978698
B30: 투자영업 현황 (Investment) | F30: 저축성 (Savings/Annuities) | J30: 0.29932859 | K30: 0.65245749 | L30: 4.211266 | M30: 2.7525558 | N30: 8.8378914 | O30: 14.817323 | S30: =+SUM(J30:K30) -> 0.95178609 | T30: =+SUM(N30:Q30) -> 23.655215 | U30: =IF(T30/S30<0,"n.a.",IF(S30>0,ROUND(T30,4)/ROUND(S30,4)-1,IF(S30<0,"n.a."))) -> 23.85312 | V30: =IF(O30/N30<0,"n.a.",IF(N30>0,ROUND(O30,4)/ROUND(N30,4)-1,IF(N30<0,"n.a."))) -> 0.67656344
C31: 대출 (Loan)/ 자산건전성 (Asset Quality of Loan) | F31: 합계 (Total) | J31: 190.38142 | K31: 112.50486 | L31: 122.96216 | M31: 103.28378 | N31: 94.465158 | O31: 148.02143 | S31: =+SUM(J31:K31) -> 302.88629 | T31: =+SUM(N31:Q31) -> 242.48659 | U31: =IF(T31/S31<0,"n.a.",IF(S31>0,ROUND(T31,4)/ROUND(S31,4)-1,IF(S31<0,"n.a."))) -> -0.19941377 | V31: =IF(O31/N31<0,"n.a.",IF(N31>0,ROUND(O31,4)/ROUND(N31,4)-1,IF(N31<0,"n.a."))) -> 0.56694105
C32: 채권 (Bond)
B34: 재무제표 (Full Financial Statements) | F34: APE 대비 신계약 CSM 배수 (New Business CSM Margin compared to New Business APE)
C35: 재무상태표 (Balance Sheet - KIFRS) | F35: (단위 십억원, %) | J35: FY25 | N35: FY26 | S35: Accumulated
C36: 손익계산서 (Income Statement - KIFRS) | F36: (KRW bn, %) | J36: 45747 | K36: 45838 | L36: 45930 | M36: 46022 | N36: 46112 | O36: 46203 | P36: 46295 | Q36: 46387 | S36: FY25.1H | T36: FY26.1H | U36: YoY | V36: QoQ
F37: 보장성 (Protection-type) | J37: 1.0389893 | K37: 0.73349618 | L37: 0.76006571 | M37: 0.74501429 | N37: 0.72366426 | O37: 0.79080181 | S37: 0.9001116 | T37: 0.76309975 | U37: =T37-S37 -> -0.13701185 | V37: =O37-N37 -> 0.067137557
H38: 사망 (Death) | J38: 0.36687917 | K38: 0.42548371 | L38: 0.49007954 | M38: 0.57811709 | N38: 0.62758905 | O38: 0.68467673 | S38: 0.39172677 | T38: 0.66620853 | U38: =T38-S38 -> 0.27448176 | V38: =O38-N38 -> 0.057087675
H39: 건강 (Health) | J39: 1.422004 | K39: 0.87881972 | L39: 0.88699754 | M39: 0.86973381 | N39: 0.79693216 | O39: 0.9758732 | S39: 1.1663625 | T39: 0.88240489 | U39: =T39-S39 -> -0.28395765 | V39: =O39-N39 -> 0.17894104
F40: 저축성 (Savings/Annuities) | J40: 0.21196606 | K40: 0.19958942 | L40: 0.15686798 | M40: 0.32997678 | N40: 0.42429236 | O40: 0.38929627 | S40: 0.20332306 | T40: 0.40167426 | U40: =T40-S40 -> 0.19835121 | V40: =O40-N40 -> -0.034996089
F41: 합계 (Total) | J41: 1.0326545 | K41: 0.72229095 | L41: 0.67161758 | M41: 0.72085114 | N41: 0.67885189 | O41: 0.71679814 | S41: 0.8905216 | T41: 0.70152181 | U41: =T41-S41 -> -0.18899979 | V41: =O41-N41 -> 0.037946241
F44: 월초P 대비 신계약 CSM 배수 (New Business CSM Margin compared to Monthly initial premium)
...

Sheet Stability
F1: 재무안정성 (Financial Stability Index)
A3: Disclaimer & Contact Information | F3: <K-ICS 기준>
F4: (단위 십억원) | J4: FY25 | N4: FY26 | S4: 증감
B5: 재무현황 (Financial Highlights) | F5: (KRW bn) | J5: 45747 | K5: 45838 | L5: 45930 | M5: 46022 | N5: 46112 | O5: 46203 | P5: 46295 | Q5: 46387 | S5: YoY | T5: QoQ
F6: 지급여력비율 (K-ICS ratio) (A)÷(B) | J6: =J7/J8 -> 1.2716316 | K6: =K7/K8 -> 1.7696419 | L6: =L7/L8 -> 1.735948 | M6: =M7/M8 -> 1.7983878 | N6: =N7/N8 -> 1.8955182 | O6: =O7/O8 -> 2.0499919 | S6: =O6-K6 -> 0.28035005 | T6: =O6-N6 -> 0.15447376
B7: 요약재무상태표 (Selected Balance sheet) | G7: 지급여력금액 (Available Capital) (A) | J7: 3386.1573 | K7: 4285.0285 | L7: 4020.0403 | M7: 4059.4964 | N7: 4345.7256 | O7: 4927.3892 | S7: =IF(O7/K7<0,"n.a.",IF(K7>0,ROUND(O7,4)/ROUND(K7,4)-1,IF(K7<0,"n.a."))) -> 0.14990815 | T7: =IF(O7/N7<0,"n.a.",IF(N7>0,ROUND(O7,4)/ROUND(N7,4)-1,IF(N7<0,"n.a."))) -> 0.13384729
B8: 요약손익계산서 (Selected Income Statement) | G8: 지급여력기준금액 (Required Capital) (B) | J8: 2662.8445 | K8: 2421.41 | L8: 2315.7608 | M8: 2257.2976 | N8: 2292.632 | O8: 2403.6139 | S8: =IF(O8/K8<0,"n.a.",IF(K8>0,ROUND(O8,4)/ROUND(K8,4)-1,IF(K8<0,"n.a."))) -> -0.0073494782 | T8: =IF(O8/N8<0,"n.a.",IF(N8>0,ROUND(O8,4)/ROUND(N8,4)-1,IF(N8<0,"n.a."))) -> 0.048408074
H9: 보험위험액 (Insurance Risk) | J9: 1955.9436 | K9: 1997.3053 | L9: 2016.3067 | M9: 1863.7667 | N9: 1984.2305 | O9: 2166.102 | S9: =IF(O9/K9<0,"n.a.",IF(K9>0,ROUND(O9,4)/ROUND(K9,4)-1,IF(K9<0,"n.a."))) -> 0.084512218 | T9: =IF(O9/N9<0,"n.a.",IF(N9>0,ROUND(O9,4)/ROUND(N9,4)-1,IF(N9<0,"n.a."))) -> 0.091658454
B10: RA, CSM, BEL Movement | H10: 시장위험액 (Market Risk) | J10: 1219.7393 | K10: 867.3994 | L10: 612.62056 | M10: 669.76496 | N10: 665.03461 | O10: 684.43741 | S10: =IF(O10/K10<0,"n.a.",IF(K10>0,ROUND(O10,4)/ROUND(K10,4)-1,IF(K10<0,"n.a."))) -> -0.21093167 | T10: =IF(O10/N10<0,"n.a.",IF(N10>0,ROUND(O10,4)/ROUND(N10,4)-1,IF(N10<0,"n.a."))) -> 0.029175625
B11: 신계약 CSM (New Business CSM) | H11: 신용위험액 (Credit Risk) | J11: 627.84819 | K11: 665.54097 | L11: 588.82625 | M11: 589.58549 | N11: 576.58746 | O11: 585.78746 | S11: =IF(O11/K11<0,"n.a.",IF(K11>0,ROUND(O11,4)/ROUND(K11,4)-1,IF(K11<0,"n.a."))) -> -0.11983259 | T11: =IF(O11/N11<0,"n.a.",IF(N11>0,ROUND(O11,4)/ROUND(N11,4)-1,IF(N11<0,"n.a."))) -> 0.015955948
B12: 신계약 CSM 배수 (New Business CSM Margin) | H12: 운영위험액 (Operation Risk) | J12: 151.63117 | K12: 141.85425 | L12: 195.73361 | M12: 245.18693 | N12: 268.65444 | O12: 318.11633 | S12: =IF(O12/K12<0,"n.a.",IF(K12>0,ROUND(O12,4)/ROUND(K12,4)-1,IF(K12<0,"n.a."))) -> 1.2425582 | T12: =IF(O12/N12<0,"n.a.",IF(N12>0,ROUND(O12,4)/ROUND(N12,4)-1,IF(N12<0,"n.a."))) -> 0.18410977
F13: *1 K-ICS Ratio : 2026.1H 비율은 추정치로 추후 업데이트 예정
B14: 주요지표 (Key Index) | F14: *2 공통 경과조치 적용 후 기준
C15: 재무 안정성 (Financial Stability)
C16: 생산성 / 경영효율 (Productivity / Operating Efficiency)
F17: (단위 십억원) | J17: FY25 | N17: FY26 | S17: 증감
B18: 상품별 수입보험료 (Premium by Product-type) | F18: (KRW bn) | J18: 45747 | K18: 45838 | L18: 45930 | M18: 46022 | N18: 46112 | O18: 46203 | P18: 46295 | Q18: 46387 | S18: YoY | T18: QoQ
C19: 상품별 APE (Annualized Premium Equivalent (APE)) | F19: 책임준비금 (Premium Reserve Breakdown) | J19: 29579.996 | K19: 29788.906 | L19: 30268.852 | M19: 30352.361 | N19: 30252.027 | O19: 30487.415 | S19: =IF(O19/K19<0,"n.a.",IF(K19>0,ROUND(O19,4)/ROUND(K19,4)-1,IF(K19<0,"n.a."))) -> 0.023448636 | T19: =IF(O19/N19<0,"n.a.",IF(N19>0,ROUND(O19,4)/ROUND(N19,4)-1,IF(N19<0,"n.a."))) -> 0.0077808967
C20: 상품별 수입보험료 (Premium Income) | G20: 연동이율 (Floating rate) | J20: 0.41094196 | K20: 0.40217874 | L20: 0.3984 | M20: 0.39293181 | N20: 0.37965838 | O20: 0.37180702 | S20: =O20-K20 -> -0.03037172 | T20: =O20-N20 -> -0.0078513567
C21: 상품별 초회보험료 (Initial Premium) | G21: 고정이율 (Fixed rate) | J21: 0.58905804 | K21: 0.59782126 | L21: 0.6017 | M21: 0.60706819 | N21: 0.62034162 | O21: 0.62819298 | S21: =O21-K21 -> 0.03037172 | T21: =O21-N21 -> 0.0078513567
C22: 상품별 초년도보험료 (First Year Premium) | H22: ≥ 6.0% | J22: 0.075259446 | K22: 0.074639296 | L22: 0.0733 | M22: 0.072856848 | N22: 0.072971375 | O22: 0.072187384 | S22: =O22-K22 -> -0.0024519121 | T22: =O22-N22 -> -0.00078399109
H23: ＜ 6.0% | J23: 0.5137986 | K23: 0.52318196 | L23: 0.5284 | M23: 0.53421134 | N23: 0.54737025 | O23: 0.55600559 | S23: =O23-K23 -> 0.032823632 | T23: =O23-N23 -> 0.0086353477
B24: 채널별 수입보험료 (Premium by Distribution Channel) | F24: 부담이율 (Crediting rate) | J24: 0.035551845 | K24: 0.035492069 | L24: 0.035638137 | M24: 0.03574576 | N24: 0.036067514 | O24: 0.036931006 | S24: =O24-K24 -> 0.0014389368 | T24: =O24-N24 -> 0.00086349134
C25: 채널별 APE (Annualized Premium Equivalent (APE)) | F25: 운용자산 이익율 (Net Investment Yield) (F) | J25: 0.038222661 | K25: 0.034722379 | L25: 0.035294828 | M25: 0.03428012 | N25: 0.035862482 | O25: 0.035666469 | S25: =O25-K25 -> 0.00094409046 | T25: =O25-N25 -> -0.00019601259
C26: 채널별 수입보험료 (Premium Income) | F26: 스프레드 (Spread) (F)－(E) | J26: =J25-J24 -> 0.0026708165 | K26: =K25-K24 -> -0.00076968995 | L26: =L25-L24 -> -0.00034330942 | M26: =M25-M24 -> -0.0014656408 | N26: =N25-N24 -> -0.00020503236 | O26: =O25-O24 -> -0.0012645363 | S26: =O26-K26 -> -0.00049484634 | T26: =O26-N26 -> -0.0010595039
C27: 채널별 초년도보험료 (First Year Premium)
B30: 투자영업 현황 (Investment)
C31: 대출 (Loan)/ 자산건전성 (Asset Quality of Loan)
C32: 채권 (Bond)
B34: 재무제표 (Full Financial Statements)
C35: 재무상태표 (Balance Sheet - KIFRS)
C36: 손익계산서 (Income Statement - KIFRS)

Sheet Productivity
F1: 생산성/경영효율 (Productivity / Operating Efficiency)
F2: (단위 십억원, 명, %) | J2: FY25 | N2: FY26 | S2: 증감
A3: Disclaimer & Contact Information | F3: (KRW bn, persons, %) | J3: 45747 | K3: 45838 | L3: 45930 | M3: 46022 | N3: 46112 | O3: 46203 | P3: 46295 | Q3: 46387 | S3: YoY | T3: QoQ
F4: 신계약 비율 (New Business ratio)
B5: 재무현황 (Financial Highlights) | G5: 일반계정 (General Account) | J5: 0.014338999 | K5: 0.024947613 | L5: 0.03958901 | M5: 0.054271011 | N5: 0.01474388 | O5: 0.035923147 | S5: =O5-K5 -> 0.010975535 | T5: =O5-N5 -> 0.021179268
G6: 특별계정 (Separate Account) | J6: 7.9135192e-05 | K6: 0.0001185179 | L6: 0.00018433945 | M6: 0.0040072716 | N6: 0.00011096503 | O6: 0.0016942914 | S6: =O6-K6 -> 0.0015757735 | T6: =O6-N6 -> 0.0015833263
B7: 요약재무상태표 (Selected Balance sheet) | F7: 효력상실해약 비율 (Lapses & Surrenders Ratio)
B8: 요약손익계산서 (Selected Income Statement) | G8: 일반계정 (General Account) | J8: 0.020696707 | K8: 0.038037782 | L8: 0.054206474 | M8: 0.069134891 | N8: 0.017749656 | O8: 0.034387837 | S8: =O8-K8 -> -0.0036499453 | T8: =O8-N8 -> 0.01663818
G9: 특별계정 (Separate Account) | J9: 0.016496223 | K9: 0.035185052 | L9: 0.046912739 | M9: 0.060952619 | N9: 0.026312964 | O9: 0.056248341 | S9: =O9-K9 -> 0.021063289 | T9: =O9-N9 -> 0.029935377
B10: RA, CSM, BEL Movement | F10: 전체 유지율 (Persistency Ratio)
B11: 신계약 CSM (New Business CSM) | G11: 13회차 (13th month) | J11: 0.89433798 | K11: 0.89740794 | L11: 0.8992024 | M11: 0.89866683 | N11: 0.89469318 | O11: 0.89052152 | S11: =O11-K11 -> -0.006886419 | T11: =O11-N11 -> -0.0041716619
B12: 신계약 CSM 배수 (New Business CSM Margin) | G12: 25회차 (25th month) | J12: 0.78729115 | K12: 0.81167789 | L12: 0.83585764 | M12: 0.78552608 | N12: 0.80286634 | O12: 0.81026345 | S12: =O12-K12 -> -0.0014144453 | T12: =O12-N12 -> 0.0073971097
F13: 보장성 유지율 (Protection-type Persistency Ratio)
B14: 주요지표 (Key Index) | G14: 13회차 (13th month) | J14: 0.88719516 | K14: 0.88596781 | L14: 0.89507224 | M14: 0.89326946 | N14: 0.89321803 | O14: 0.88945289 | S14: =O14-K14 -> 0.003485081 | T14: =O14-N14 -> -0.0037651398
C15: 재무 안정성 (Financial Stability) | G15: 25회차 (25th month) | J15: 0.71177674 | K15: 0.74013702 | L15: 0.77708952 | M15: 0.77215343 | N15: 0.82394914 | O15: 0.79378328 | S15: =O15-K15 -> 0.053646263 | T15: =O15-N15 -> -0.030165862
C16: 생산성 / 경영효율 (Productivity / Operating Efficiency) | F16: 손해율
G17: 위험보험료 | J17: 155.96826 | K17: 313.99646 | L17: 473.71381 | M17: 634.73319 | N17: 161.28534 | O17: 324.18271 | S17: =IF(O17/K17<0,"n.a.",IF(K17>0,ROUND(O17,4)/ROUND(K17,4)-1,IF(K17<0,"n.a."))) -> 0.032440489 | T17: =IF(O17/N17<0,"n.a.",IF(N17>0,ROUND(O17,4)/ROUND(N17,4)-1,IF(N17<0,"n.a."))) -> 1.0099953
B18: 상품별 수입보험료 (Premium by Product-type) | G18: 사고보험금 | J18: 143.56175 | K18: 282.45168 | L18: 435.23598 | M18: 579.64822 | N18: 161.00965 | O18: 319.70036 | S18: =IF(O18/K18<0,"n.a.",IF(K18>0,ROUND(O18,4)/ROUND(K18,4)-1,IF(K18<0,"n.a."))) -> 0.13187635 | T18: =IF(O18/N18<0,"n.a.",IF(N18>0,ROUND(O18,4)/ROUND(N18,4)-1,IF(N18<0,"n.a."))) -> 0.98559714
C19: 상품별 APE (Annualized Premium Equivalent (APE)) | G19: IBNR비용 | J19: 7.9477561 | K19: 13.770922 | L19: 22.681382 | M19: 28.484494 | N19: 3.9919162 | O19: 11.259486 | S19: =IF(O19/K19<0,"n.a.",IF(K19>0,ROUND(O19,4)/ROUND(K19,4)-1,IF(K19<0,"n.a."))) -> -0.18237007 | T19: =IF(O19/N19<0,"n.a.",IF(N19>0,ROUND(O19,4)/ROUND(N19,4)-1,IF(N19<0,"n.a."))) -> 1.8205867
C20: 상품별 수입보험료 (Premium Income) | G20: 손해율 | J20: 0.97141245 | K20: 0.94339472 | L20: 0.96665402 | M20: 0.95809188 | N20: 1.0230413 | O20: 1.0209053 | S20: =O20-K20 -> 0.077510573 | T20: =O20-N20 -> -0.0021360026
C21: 상품별 초회보험료 (Initial Premium) | G21: IBNR제외시 손해율 | J21: 0.92045492 | K21: 0.89953779 | L21: 0.9187741 | M21: 0.91321556 | N21: 0.99829065 | O21: 0.98617338 | S21: =O21-K21 -> 0.086635592 | T21: =O21-N21 -> -0.012117272
C22: 상품별 초년도보험료 (First Year Premium) | F22: 전속설계사 (# of Tied Agents) | J22: 1558 | K22: 1589 | L22: 1585 | M22: 1644 | N22: 1586 | O22: 1782 | S22: =IF(O22/K22<0,"n.a.",IF(K22>0,ROUND(O22,4)/ROUND(K22,4)-1,IF(K22<0,"n.a."))) -> 0.12146004 | T22: =IF(O22/N22<0,"n.a.",IF(N22>0,ROUND(O22,4)/ROUND(N22,4)-1,IF(N22<0,"n.a."))) -> 0.12358134
B24: 채널별 수입보험료 (Premium by Distribution Channel)
C25: 채널별 APE (Annualized Premium Equivalent (APE))
C26: 채널별 수입보험료 (Premium Income)
C27: 채널별 초년도보험료 (First Year Premium)
B30: 투자영업 현황 (Investment)
C31: 대출 (Loan)/ 자산건전성 (Asset Quality of Loan)
C32: 채권 (Bond)
B34: 재무제표 (Full Financial Statements)
C35: 재무상태표 (Balance Sheet - KIFRS)
C36: 손익계산서 (Income Statement - KIFRS)

Sheet APE by P.T
F1: APE by Product-type (1/2) | G1: 상품별 APE (APE by Product-type)
F2: Total (General acc. + Separate acc.) | G2: 합계 (일반계정 + 특별계정) (Total (General acc. + Separate acc.))
A3: Disclaimer & Contact Information | J3: Accumulated Data | L3: Quarterly Data
F4: (KRW mn) | G4: 단위 십억원 (KRW bn) | J4: Jun '26 | K4: Jun '25 | L4: Jun '26 | M4: Jun '25 | N4: 46112 | O4: YoY | P4: QoQ
B5: 재무현황 (Financial Highlights) | F5: Individual | G5: 개인보험 (Individual) | J5: =SUM(J6,J10,J14) -> 345.65795 | K5: =SUM(K6,K10,K14) -> 340.12234 | L5: =SUM(L6,L10,L14) -> 206.50365 | M5: =SUM(M6,M10,M14) -> 155.76114 | N5: =SUM(N6,N10,N14) -> 139.1543 | O5: =IF(J5/K5<0,"n.a.",IF(K5>0,ROUND(J5,4)/ROUND(K5,4)-1,IF(K5<0,"n.a."))) -> 0.016275616 | P5: =IF(L5/N5<0,"n.a.",IF(N5>0,ROUND(L5,4)/ROUND(N5,4)-1,IF(N5<0,"n.a."))) -> 0.48399079
G6: 보장성보험 (Protection-type) | J6: =SUM(J7:J9) -> 286.76641 | K6: =SUM(K7:K9) -> 335.44118 | L6: =SUM(L7:L9) -> 168.44184 | M6: =SUM(M7:M9) -> 152.49215 | N6: =SUM(N7:N9) -> 118.32458 | O6: =IF(J6/K6<0,"n.a.",IF(K6>0,ROUND(J6,4)/ROUND(K6,4)-1,IF(K6<0,"n.a."))) -> -0.1451068 | P6: =IF(L6/N6<0,"n.a.",IF(N6>0,ROUND(L6,4)/ROUND(N6,4)-1,IF(N6<0,"n.a."))) -> 0.42355689
B7: 요약재무상태표 (Selected Balance sheet) | H7: 종신/CI/정기 (Whole life/CI/Term life) | J7: 158.27297 | K7: 115.30587 | L7: 107.07872 | M7: 48.886779 | N7: 51.194249 | O7: =IF(J7/K7<0,"n.a.",IF(K7>0,ROUND(J7,4)/ROUND(K7,4)-1,IF(K7<0,"n.a."))) -> 0.37263575 | P7: =IF(L7/N7<0,"n.a.",IF(N7>0,ROUND(L7,4)/ROUND(N7,4)-1,IF(N7<0,"n.a."))) -> 1.0916178
B8: 요약손익계산서 (Selected Income Statement) | H8: 변액종신/CI (Variable whole life/CI) | J8: -0.000613284 | K8: -0.011003604 | L8: -0.000613284 | M8: -0.003173796 | N8: 0
H9: 기타보장 (Other protection-type) | J9: 128.49406 | K9: 220.14631 | L9: 61.363734 | M9: 103.60854 | N9: 67.130327 | O9: =IF(J9/K9<0,"n.a.",IF(K9>0,ROUND(J9,4)/ROUND(K9,4)-1,IF(K9<0,"n.a."))) -> -0.41632405 | P9: =IF(L9/N9<0,"n.a.",IF(N9>0,ROUND(L9,4)/ROUND(N9,4)-1,IF(N9<0,"n.a."))) -> -0.085901597
B10: RA, CSM, BEL Movement | G10: 연금보험 (Annuities) | J10: =SUM(J11:J13) -> 58.686549 | K10: =SUM(K11:K13) -> 4.365706 | L10: =SUM(L11:L13) -> 37.982231 | M10: =SUM(M11:M13) -> 3.1650245 | N10: =SUM(N11:N13) -> 20.704319 | O10: =IF(J10/K10<0,"n.a.",IF(K10>0,ROUND(J10,4)/ROUND(K10,4)-1,IF(K10<0,"n.a."))) -> 12.442632 | P10: =IF(L10/N10<0,"n.a.",IF(N10>0,ROUND(L10,4)/ROUND(N10,4)-1,IF(N10<0,"n.a."))) -> 0.83450781
B11: 신계약 CSM (New Business CSM) | H11: 금리확정형 (Fixed-rate) | J11: 0.047386415 | K11: 0.045906351 | L11: 0.020211099 | M11: 0.027818386 | N11: 0.027175316 | O11: =IF(J11/K11<0,"n.a.",IF(K11>0,ROUND(J11,4)/ROUND(K11,4)-1,IF(K11<0,"n.a."))) -> 0.032679739 | P11: =IF(L11/N11<0,"n.a.",IF(N11>0,ROUND(L11,4)/ROUND(N11,4)-1,IF(N11<0,"n.a."))) -> -0.25735294
B12: 신계약 CSM 배수 (New Business CSM Margin) | H12: 금리연동형 (Floating-rate) | J12: 58.639163 | K12: 4.3197997 | L12: 37.96202 | M12: 3.1372061 | N12: 20.677143 | O12: =IF(J12/K12<0,"n.a.",IF(K12>0,ROUND(J12,4)/ROUND(K12,4)-1,IF(K12<0,"n.a."))) -> 12.574517 | P12: =IF(L12/N12<0,"n.a.",IF(N12>0,ROUND(L12,4)/ROUND(N12,4)-1,IF(N12<0,"n.a."))) -> 0.83594411
H13: 변액연금 (Variable) | J13: 0 | K13: 0 | L13: 0 | M13: 0 | N13: 0
B14: 주요지표 (Key Index) | G14: 저축보험 (Savings) | J14: =SUM(J15:J17) -> 0.20498741 | K14: =SUM(K15:K17) -> 0.31544573 | L14: =SUM(L15:L17) -> 0.079585444 | M14: =SUM(M15:M17) -> 0.10397389 | N14: =SUM(N15:N17) -> 0.12540197 | O14: =IF(J14/K14<0,"n.a.",IF(K14>0,ROUND(J14,4)/ROUND(K14,4)-1,IF(K14<0,"n.a."))) -> -0.35003171 | P14: =IF(L14/N14<0,"n.a.",IF(N14>0,ROUND(L14,4)/ROUND(N14,4)-1,IF(N14<0,"n.a."))) -> -0.36523126
C15: 재무 안정성 (Financial Stability) | H15: 금리확정형 (Fixed-rate) | J15: 0 | K15: 0 | L15: 0 | M15: 0 | N15: 0
C16: 생산성 / 경영효율 (Productivity / Operating Efficiency) | H16: 금리연동형 (Floating-rate) | J16: 0.20498741 | K16: 0.31544573 | L16: 0.079585444 | M16: 0.10397389 | N16: 0.12540197 | O16: =IF(J16/K16<0,"n.a.",IF(K16>0,ROUND(J16,4)/ROUND(K16,4)-1,IF(K16<0,"n.a."))) -> -0.35003171 | P16: =IF(L16/N16<0,"n.a.",IF(N16>0,ROUND(L16,4)/ROUND(N16,4)-1,IF(N16<0,"n.a."))) -> -0.36523126
H17: 변액저축 (Variable) | J17: 0 | K17: 0 | L17: 0 | M17: 0 | N17: 0
B18: 상품별 수입보험료 (Premium by Product-type) | F18: Group | G18: 단체보험 (Group) | J18: =SUM(J19:J20) -> 0 | K18: =SUM(K19:K20) -> 0 | L18: =SUM(L19:L20) -> 0 | M18: =SUM(M19:M20) -> 0 | N18: =SUM(N19:N20) -> 0
C19: 상품별 APE (Annualized Premium Equivalent (APE)) | G19: 단체보장 (Protection-type) | J19: 0 | K19: 0 | L19: 0 | M19: 0 | N19: 0
C20: 상품별 수입보험료 (Premium Income) | G20: 단체저축 (Savings) | J20: 0 | K20: 0 | L20: 0 | M20: 0 | N20: 0
C21: 상품별 초회보험료 (Initial Premium) | G21: 개인보험 + 단체보험 (Individual+Group) | J21: =SUM(J22:J24) -> 345.65795 | K21: =SUM(K22:K24) -> 340.12234 | L21: =SUM(L22:L24) -> 206.50365 | M21: =SUM(M22:M24) -> 155.76114 | N21: =SUM(N22:N24) -> 139.1543 | O21: =IF(J21/K21<0,"n.a.",IF(K21>0,ROUND(J21,4)/ROUND(K21,4)-1,IF(K21<0,"n.a."))) -> 0.016275616 | P21: =IF(L21/N21<0,"n.a.",IF(N21>0,ROUND(L21,4)/ROUND(N21,4)-1,IF(N21<0,"n.a."))) -> 0.48399079
C22: 상품별 초년도보험료 (First Year Premium) | F22: Individual+Group | G22: 보장성보험 (Protection-type) | J22: =SUM(J6,J19) -> 286.76641 | K22: =SUM(K6,K19) -> 335.44118 | L22: =SUM(L6,L19) -> 168.44184 | M22: =SUM(M6,M19) -> 152.49215 | N22: =SUM(N6,N19) -> 118.32458 | O22: =IF(J22/K22<0,"n.a.",IF(K22>0,ROUND(J22,4)/ROUND(K22,4)-1,IF(K22<0,"n.a."))) -> -0.1451068 | P22: =IF(L22/N22<0,"n.a.",IF(N22>0,ROUND(L22,4)/ROUND(N22,4)-1,IF(N22<0,"n.a."))) -> 0.42355689
G23: 연금보험 (Annuities) | J23: =J10 -> 58.686549 | K23: =K10 -> 4.365706 | L23: =L10 -> 37.982231 | M23: =M10 -> 3.1650245 | N23: =N10 -> 20.704319 | O23: =IF(J23/K23<0,"n.a.",IF(K23>0,ROUND(J23,4)/ROUND(K23,4)-1,IF(K23<0,"n.a."))) -> 12.442632 | P23: =IF(L23/N23<0,"n.a.",IF(N23>0,ROUND(L23,4)/ROUND(N23,4)-1,IF(N23<0,"n.a."))) -> 0.83450781
B24: 채널별 수입보험료 (Premium by Distribution Channel) | G24: 저축보험 (Savings) | J24: =SUM(J14,J20) -> 0.20498741 | K24: =SUM(K14,K20) -> 0.31544573 | L24: =SUM(L14,L20) -> 0.079585444 | M24: =SUM(M14,M20) -> 0.10397389 | N24: =SUM(N14,N20) -> 0.12540197 | O24: =IF(J24/K24<0,"n.a.",IF(K24>0,ROUND(J24,4)/ROUND(K24,4)-1,IF(K24<0,"n.a."))) -> -0.35003171 | P24: =IF(L24/N24<0,"n.a.",IF(N24>0,ROUND(L24,4)/ROUND(N24,4)-1,IF(N24<0,"n.a."))) -> -0.36523126
C25: 채널별 APE (Annualized Premium Equivalent (APE)) | G25: 퇴직관련 보험 (Retirement-related) | J25: =SUM(J26:J27) -> 13.746759 | K25: =SUM(K26:K27) -> 0.15814577 | L25: =SUM(L26:L27) -> 11.805564 | M25: =SUM(M26:M27) -> 0.030803075 | N25: =SUM(N26:N27) -> 1.9411947 | O25: =IF(J25/K25<0,"n.a.",IF(K25>0,ROUND(J25,4)/ROUND(K25,4)-1,IF(K25<0,"n.a."))) -> 85.950032 | P25: =IF(L25/N25<0,"n.a.",IF(N25>0,ROUND(L25,4)/ROUND(N25,4)-1,IF(N25<0,"n.a."))) -> 5.081599
C26: 채널별 수입보험료 (Premium Income) | F26: Retirement-related | G26: 퇴직보험 (Retirement insurance) | J26: 0 | K26: 0 | L26: 0 | M26: 0 | N26: 0
C27: 채널별 초년도보험료 (First Year Premium) | G27: 퇴직연금 (Corporate pension) | J27: 13.746759 | K27: 0.15814577 | L27: 11.805564 | M27: 0.030803075 | N27: 1.9411947 | O27: =IF(J27/K27<0,"n.a.",IF(K27>0,ROUND(J27,4)/ROUND(K27,4)-1,IF(K27<0,"n.a."))) -> 85.950032 | P27: =IF(L27/N27<0,"n.a.",IF(N27>0,ROUND(L27,4)/ROUND(N27,4)-1,IF(N27<0,"n.a."))) -> 5.081599
B30: 투자영업 현황 (Investment)
C31: 대출 (Loan)/ 자산건전성 (Asset Quality of Loan) | F31: Premium Income by Product-type (2/2)
C32: 채권 (Bond) | F32: General Account
B34: 재무제표 (Full Financial Statements) | F34: (KRW mn)
C35: 재무상태표 (Balance Sheet - KIFRS) | F35: Individual
C36: 손익계산서 (Income Statement - KIFRS)
F48: Group
F52: Individual+Group
F56: Retirement-related
F60: Separate Account
F62: (KRW mn)
F63: Individual
F76: Group
...

Sheet Premium Income by P.T.(GA+SA)
F1: APE by Product-type (1/2) | G1: 상품별 수입보험료 (Premium Income by Product-type(GA+SA)
F2: Total (General acc. + Separate acc.) | G2: 합계 (일반계정 + 특별계정) (Total (General acc. + Separate acc.))
A3: Disclaimer & Contact Information | J3: Accumulated Data | L3: Quarterly Data
F4: (KRW mn) | G4: 단위 십억원 (KRW bn) | J4: Jun '26 | K4: Jun '25 | L4: Jun '26 | M4: Jun '25 | N4: 46112 | O4: YoY | P4: QoQ
B5: 재무현황 (Financial Highlights) | F5: Individual | G5: 개인보험 (Individual) | J5: =SUM(J6,J10,J14) -> 2422.9979 | K5: =SUM(K6,K10,K14) -> 1852.7689 | L5: =SUM(L6,L10,L14) -> 1303.2229 | M5: =SUM(M6,M10,M14) -> 940.3237 | N5: =SUM(N6,N10,N14) -> 1119.775 | O5: =IF(J5/K5<0,"n.a.",IF(K5>0,ROUND(J5,4)/ROUND(K5,4)-1,IF(K5<0,"n.a."))) -> 0.30777125 | P5: =IF(L5/N5<0,"n.a.",IF(N5>0,ROUND(L5,4)/ROUND(N5,4)-1,IF(N5<0,"n.a."))) -> 0.16382568
G6: 보장성보험 (Protection-type) | J6: =SUM(J7:J9) -> 1672.4269 | K6: =SUM(K7:K9) -> 1601.7945 | L6: =SUM(L7:L9) -> 840.00158 | M6: =SUM(M7:M9) -> 809.86168 | N6: =SUM(N7:N9) -> 832.42531 | O6: =IF(J6/K6<0,"n.a.",IF(K6>0,ROUND(J6,4)/ROUND(K6,4)-1,IF(K6<0,"n.a."))) -> 0.044095794 | P6: =IF(L6/N6<0,"n.a.",IF(N6>0,ROUND(L6,4)/ROUND(N6,4)-1,IF(N6<0,"n.a."))) -> 0.0091014773
B7: 요약재무상태표 (Selected Balance sheet) | H7: 종신/CI/정기 (Whole life/CI/Term life) | J7: 767.80564 | K7: 755.72088 | L7: 385.43555 | M7: 378.76417 | N7: 382.37009 | O7: =IF(J7/K7<0,"n.a.",IF(K7>0,ROUND(J7,4)/ROUND(K7,4)-1,IF(K7<0,"n.a."))) -> 0.015990956 | P7: =IF(L7/N7<0,"n.a.",IF(N7>0,ROUND(L7,4)/ROUND(N7,4)-1,IF(N7<0,"n.a."))) -> 0.0080171018
B8: 요약손익계산서 (Selected Income Statement) | H8: 변액종신/CI (Variable whole life/CI) | J8: 37.977042 | K8: 41.70247 | L8: 18.766878 | M8: 20.660828 | N8: 19.210164 | O8: =IF(J8/K8<0,"n.a.",IF(K8>0,ROUND(J8,4)/ROUND(K8,4)-1,IF(K8<0,"n.a."))) -> -0.089335172 | P8: =IF(L8/N8<0,"n.a.",IF(N8>0,ROUND(L8,4)/ROUND(N8,4)-1,IF(N8<0,"n.a."))) -> -0.023076282
H9: 기타보장 (Other protection-type) | J9: 866.64421 | K9: 804.37115 | L9: 435.79916 | M9: 410.43669 | N9: 430.84506 | O9: =IF(J9/K9<0,"n.a.",IF(K9>0,ROUND(J9,4)/ROUND(K9,4)-1,IF(K9<0,"n.a."))) -> 0.077418237 | P9: =IF(L9/N9<0,"n.a.",IF(N9>0,ROUND(L9,4)/ROUND(N9,4)-1,IF(N9<0,"n.a."))) -> 0.011498564
B10: RA, CSM, BEL Movement | G10: 연금보험 (Annuities) | J10: =SUM(J11:J13) -> 635.93934 | K10: =SUM(K11:K13) -> 114.33653 | L10: =SUM(L11:L13) -> 404.9494 | M10: =SUM(M11:M13) -> 65.420963 | N10: =SUM(N11:N13) -> 230.98994 | O10: =IF(J10/K10<0,"n.a.",IF(K10>0,ROUND(J10,4)/ROUND(K10,4)-1,IF(K10<0,"n.a."))) -> 4.5619973 | P10: =IF(L10/N10<0,"n.a.",IF(N10>0,ROUND(L10,4)/ROUND(N10,4)-1,IF(N10<0,"n.a."))) -> 0.75310436
B11: 신계약 CSM (New Business CSM) | H11: 금리확정형 (Fixed-rate) | J11: 0.64890327 | K11: 0.69800452 | L11: 0.31240078 | M11: 0.39482719 | N11: 0.33650249 | O11: =IF(J11/K11<0,"n.a.",IF(K11>0,ROUND(J11,4)/ROUND(K11,4)-1,IF(K11<0,"n.a."))) -> -0.07034384 | P11: =IF(L11/N11<0,"n.a.",IF(N11>0,ROUND(L11,4)/ROUND(N11,4)-1,IF(N11<0,"n.a."))) -> -0.071619614
B12: 신계약 CSM 배수 (New Business CSM Margin) | H12: 금리연동형 (Floating-rate) | J12: 630.61834 | K12: 107.43377 | L12: 402.3862 | M12: 62.039884 | N12: 228.23214 | O12: =IF(J12/K12<0,"n.a.",IF(K12>0,ROUND(J12,4)/ROUND(K12,4)-1,IF(K12<0,"n.a."))) -> 4.8698315 | P12: =IF(L12/N12<0,"n.a.",IF(N12>0,ROUND(L12,4)/ROUND(N12,4)-1,IF(N12<0,"n.a."))) -> 0.76305699
H13: 변액연금 (Variable) | J13: 4.6720909 | K13: 6.2047563 | L13: 2.2508019 | M13: 2.9862513 | N13: 2.4212889 | O13: =IF(J13/K13<0,"n.a.",IF(K13>0,ROUND(J13,4)/ROUND(K13,4)-1,IF(K13<0,"n.a."))) -> -0.24701844 | P13: =IF(L13/N13<0,"n.a.",IF(N13>0,ROUND(L13,4)/ROUND(N13,4)-1,IF(N13<0,"n.a."))) -> -0.070416718
B14: 주요지표 (Key Index) | G14: 저축보험 (Savings) | J14: =SUM(J15:J17) -> 114.63165 | K14: =SUM(K15:K17) -> 136.63787 | L14: =SUM(L15:L17) -> 58.271889 | M14: =SUM(M15:M17) -> 65.04106 | N14: =SUM(N15:N17) -> 56.359766 | O14: =IF(J14/K14<0,"n.a.",IF(K14>0,ROUND(J14,4)/ROUND(K14,4)-1,IF(K14<0,"n.a."))) -> -0.16105488 | P14: =IF(L14/N14<0,"n.a.",IF(N14>0,ROUND(L14,4)/ROUND(N14,4)-1,IF(N14<0,"n.a."))) -> 0.033926664
C15: 재무 안정성 (Financial Stability) | H15: 금리확정형 (Fixed-rate) | J15: 5.877932 | K15: 6.7415457 | L15: 2.889184 | M15: 3.3210674 | N15: 2.9887479 | O15: =IF(J15/K15<0,"n.a.",IF(K15>0,ROUND(J15,4)/ROUND(K15,4)-1,IF(K15<0,"n.a."))) -> -0.12810205 | P15: =IF(L15/N15<0,"n.a.",IF(N15>0,ROUND(L15,4)/ROUND(N15,4)-1,IF(N15<0,"n.a."))) -> -0.033292067
C16: 생산성 / 경영효율 (Productivity / Operating Efficiency) | H16: 금리연동형 (Floating-rate) | J16: 95.064418 | K16: 124.62336 | L16: 45.375018 | M16: 59.374272 | N16: 49.6894 | O16: =IF(J16/K16<0,"n.a.",IF(K16>0,ROUND(J16,4)/ROUND(K16,4)-1,IF(K16<0,"n.a."))) -> -0.2371866 | P16: =IF(L16/N16<0,"n.a.",IF(N16>0,ROUND(L16,4)/ROUND(N16,4)-1,IF(N16<0,"n.a."))) -> -0.086827372
H17: 변액저축 (Variable) | J17: 13.689305 | K17: 5.2729595 | L17: 10.007687 | M17: 2.3457205 | N17: 3.6816176 | O17: =IF(J17/K17<0,"n.a.",IF(K17>0,ROUND(J17,4)/ROUND(K17,4)-1,IF(K17<0,"n.a."))) -> 1.5961123 | P17: =IF(L17/N17<0,"n.a.",IF(N17>0,ROUND(L17,4)/ROUND(N17,4)-1,IF(N17<0,"n.a."))) -> 1.7183018
B18: 상품별 수입보험료 (Premium by Product-type) | F18: Group | G18: 단체보험 (Group) | J18: =SUM(J19:J20) -> 0.12118571 | K18: =SUM(K19:K20) -> 0.17078142 | L18: =SUM(L19:L20) -> 0.059519668 | M18: =SUM(M19:M20) -> 0.081796296 | N18: =SUM(N19:N20) -> 0.061666038 | O18: =IF(J18/K18<0,"n.a.",IF(K18>0,ROUND(J18,4)/ROUND(K18,4)-1,IF(K18<0,"n.a."))) -> -0.29039813 | P18: =IF(L18/N18<0,"n.a.",IF(N18>0,ROUND(L18,4)/ROUND(N18,4)-1,IF(N18<0,"n.a."))) -> -0.035656402
C19: 상품별 APE (Annualized Premium Equivalent (APE)) | G19: 단체보장 (Protection-type) | J19: 0.1120359 | K19: 0.16056863 | L19: 0.054980407 | M19: 0.076853593 | N19: 0.057055497 | O19: =IF(J19/K19<0,"n.a.",IF(K19>0,ROUND(J19,4)/ROUND(K19,4)-1,IF(K19<0,"n.a."))) -> -0.30261519 | P19: =IF(L19/N19<0,"n.a.",IF(N19>0,ROUND(L19,4)/ROUND(N19,4)-1,IF(N19<0,"n.a."))) -> -0.036777583
C20: 상품별 수입보험료 (Premium Income) | G20: 단체저축 (Savings) | J20: 0.009149802 | K20: 0.010212798 | L20: 0.004539261 | M20: 0.004942703 | N20: 0.004610541 | O20: =IF(J20/K20<0,"n.a.",IF(K20>0,ROUND(J20,4)/ROUND(K20,4)-1,IF(K20<0,"n.a."))) -> -0.10784314 | P20: =IF(L20/N20<0,"n.a.",IF(N20>0,ROUND(L20,4)/ROUND(N20,4)-1,IF(N20<0,"n.a."))) -> -0.02173913
C21: 상품별 초회보험료 (Initial Premium) | G21: 개인보험 + 단체보험 (Individual+Group) | J21: =SUM(J22:J24) -> 2423.1191 | K21: =SUM(K22:K24) -> 1852.9397 | L21: =SUM(L22:L24) -> 1303.2824 | M21: =SUM(M22:M24) -> 940.4055 | N21: =SUM(N22:N24) -> 1119.8367 | O21: =IF(J21/K21<0,"n.a.",IF(K21>0,ROUND(J21,4)/ROUND(K21,4)-1,IF(K21<0,"n.a."))) -> 0.30771611 | P21: =IF(L21/N21<0,"n.a.",IF(N21>0,ROUND(L21,4)/ROUND(N21,4)-1,IF(N21<0,"n.a."))) -> 0.16381469
C22: 상품별 초년도보험료 (First Year Premium) | F22: Individual+Group | G22: 보장성보험 (Protection-type) | J22: =SUM(J6,J19) -> 1672.5389 | K22: =SUM(K6,K19) -> 1601.9551 | L22: =SUM(L6,L19) -> 840.05656 | M22: =SUM(M6,M19) -> 809.93854 | N22: =SUM(N6,N19) -> 832.48237 | O22: =IF(J22/K22<0,"n.a.",IF(K22>0,ROUND(J22,4)/ROUND(K22,4)-1,IF(K22<0,"n.a."))) -> 0.044061035 | P22: =IF(L22/N22<0,"n.a.",IF(N22>0,ROUND(L22,4)/ROUND(N22,4)-1,IF(N22<0,"n.a."))) -> 0.0090983305
G23: 연금보험 (Annuities) | J23: =J10 -> 635.93934 | K23: =K10 -> 114.33653 | L23: =L10 -> 404.9494 | M23: =M10 -> 65.420963 | N23: =N10 -> 230.98994 | O23: =IF(J23/K23<0,"n.a.",IF(K23>0,ROUND(J23,4)/ROUND(K23,4)-1,IF(K23<0,"n.a."))) -> 4.5619973 | P23: =IF(L23/N23<0,"n.a.",IF(N23>0,ROUND(L23,4)/ROUND(N23,4)-1,IF(N23<0,"n.a."))) -> 0.75310436
B24: 채널별 수입보험료 (Premium by Distribution Channel) | G24: 저축보험 (Savings) | J24: =SUM(J14,J20) -> 114.6408 | K24: =SUM(K14,K20) -> 136.64808 | L24: =SUM(L14,L20) -> 58.276428 | M24: =SUM(M14,M20) -> 65.046002 | N24: =SUM(N14,N20) -> 56.364376 | O24: =IF(J24/K24<0,"n.a.",IF(K24>0,ROUND(J24,4)/ROUND(K24,4)-1,IF(K24<0,"n.a."))) -> -0.1610509 | P24: =IF(L24/N24<0,"n.a.",IF(N24>0,ROUND(L24,4)/ROUND(N24,4)-1,IF(N24<0,"n.a."))) -> 0.033922121
C25: 채널별 APE (Annualized Premium Equivalent (APE)) | G25: 퇴직관련 보험 (Retirement-related) | J25: =SUM(J26:J27) -> 1175.1367 | K25: =SUM(K26:K27) -> 207.36649 | L25: =SUM(L26:L27) -> 1057.9308 | M25: =SUM(M26:M27) -> 125.90165 | N25: =SUM(N26:N27) -> 117.20582 | O25: =IF(J25/K25<0,"n.a.",IF(K25>0,ROUND(J25,4)/ROUND(K25,4)-1,IF(K25<0,"n.a."))) -> 4.6669554 | P25: =IF(L25/N25<0,"n.a.",IF(N25>0,ROUND(L25,4)/ROUND(N25,4)-1,IF(N25<0,"n.a."))) -> 8.0262666
C26: 채널별 수입보험료 (Premium Income) | F26: Retirement-related | G26: 퇴직보험 (Retirement insurance) | J26: 0 | K26: 0 | L26: 0 | M26: 0 | N26: 0
C27: 채널별 초년도보험료 (First Year Premium) | G27: 퇴직연금 (Corporate pension) | J27: 1175.1367 | K27: 207.36649 | L27: 1057.9308 | M27: 125.90165 | N27: 117.20582 | O27: =IF(J27/K27<0,"n.a.",IF(K27>0,ROUND(J27,4)/ROUND(K27,4)-1,IF(K27<0,"n.a."))) -> 4.6669554 | P27: =IF(L27/N27<0,"n.a.",IF(N27>0,ROUND(L27,4)/ROUND(N27,4)-1,IF(N27<0,"n.a."))) -> 8.0262666
B30: 투자영업 현황 (Investment)
C31: 대출 (Loan)/ 자산건전성 (Asset Quality of Loan) | F31: Premium Income by Product-type (2/2)
C32: 채권 (Bond) | F32: General Account
B34: 재무제표 (Full Financial Statements) | F34: (KRW mn)
C35: 재무상태표 (Balance Sheet - KIFRS) | F35: Individual
C36: 손익계산서 (Income Statement - KIFRS)
F48: Group
F52: Individual+Group
F56: Retirement-related
F60: Separate Account
F62: (KRW mn)
F63: Individual
F76: Group
...

Sheet Premium Income by P.T.
F1: APE by Product-type (1/2) | G1: 상품별 수입보험료 (Premium Income by Product type)
F2: Total (General acc. + Separate acc.) | G2: 일반계정 (General Account)
A3: Disclaimer & Contact Information | J3: Accumulated Data | L3: Quarterly Data
F4: (KRW mn) | G4: 단위 십억원 (KRW bn) | J4: Jun '26 | K4: Jun '25 | L4: Jun '26 | M4: Jun '25 | N4: 46112 | O4: YoY | P4: QoQ
B5: 재무현황 (Financial Highlights) | F5: Individual | G5: 개인보험 (Individual) | J5: =SUM(J6,J10,J14) -> 2393.5736 | K5: =SUM(K6,K10,K14) -> 1828.6148 | L5: =SUM(L6,L10,L14) -> 1285.593 | M5: =SUM(M6,M10,M14) -> 928.68874 | N5: =SUM(N6,N10,N14) -> 1107.9806 | O5: =IF(J5/K5<0,"n.a.",IF(K5>0,ROUND(J5,4)/ROUND(K5,4)-1,IF(K5<0,"n.a."))) -> 0.30895452 | P5: =IF(L5/N5<0,"n.a.",IF(N5>0,ROUND(L5,4)/ROUND(N5,4)-1,IF(N5<0,"n.a."))) -> 0.16030281
G6: 보장성보험 (Protection-type) | J6: =SUM(J7:J9) -> 1660.4037 | K6: =SUM(K7:K9) -> 1588.1851 | L6: =SUM(L7:L9) -> 834.08409 | M6: =SUM(M7:M9) -> 803.11801 | N6: =SUM(N7:N9) -> 826.31957 | O6: =IF(J6/K6<0,"n.a.",IF(K6>0,ROUND(J6,4)/ROUND(K6,4)-1,IF(K6<0,"n.a."))) -> 0.045472407 | P6: =IF(L6/N6<0,"n.a.",IF(N6>0,ROUND(L6,4)/ROUND(N6,4)-1,IF(N6<0,"n.a."))) -> 0.0093964853
B7: 요약재무상태표 (Selected Balance sheet) | H7: 종신/CI/정기 (Whole life/CI/Term life) | J7: 767.80564 | K7: 755.72088 | L7: 385.43555 | M7: 378.76417 | N7: 382.37009 | O7: =IF(J7/K7<0,"n.a.",IF(K7>0,ROUND(J7,4)/ROUND(K7,4)-1,IF(K7<0,"n.a."))) -> 0.015990956 | P7: =IF(L7/N7<0,"n.a.",IF(N7>0,ROUND(L7,4)/ROUND(N7,4)-1,IF(N7<0,"n.a."))) -> 0.0080171018
B8: 요약손익계산서 (Selected Income Statement) | H8: 변액종신/CI (Variable whole life/CI) | J8: 25.953808 | K8: 28.093063 | L8: 12.849382 | M8: 13.917158 | N8: 13.104426 | O8: =IF(J8/K8<0,"n.a.",IF(K8>0,ROUND(J8,4)/ROUND(K8,4)-1,IF(K8<0,"n.a."))) -> -0.076150371 | P8: =IF(L8/N8<0,"n.a.",IF(N8>0,ROUND(L8,4)/ROUND(N8,4)-1,IF(N8<0,"n.a."))) -> -0.019459113
